# Author: Arrrg
# From: Minecraft Forums

uniqueMinDistance=4000

unacceptable_target_blocks=bedrock,magma,gravel,nether_brick,glowstone,flowing_lava,lava,Natura:Cloud,red_mushroom_block,brown_mushroom_block,planks,cobblestone,end_stone,obsidian,purpur_block,iron_bars,purpur_slab,purpur_pillar,netherrack,soul_sand,quartz_ore

biomesToSpawnIn=kelp forest,ocean,ocean oil field,oceanic abyss,coral reef
weight=1
embed_into_distance=-32
dimensions=42,12,12
allowable_overhang=150
max_cut_in=0
cut_in_buffer=0
max_leveling=0
leveling_buffer=0
preserve_water=0
preserve_lava=1
preserve_plants=1

rule1=0,100,preserveBlock
rule2=0,100,grass
rule3=0,100,sandstone
rule4=0,100,ice
rule5=0,100,planks
rule6=0,50,ice
rule7=0,100,leaves
rule8=0,100,fence
rule9=0,100,wool-0
rule10=0,100,wool-4
rule11=0,100,wool-2
rule12=0,100,wool-3
rule13=0,100,wool-15
rule14=2,100,rail

layer
1,1,1,1,1,1,1,1,1,1,1,1
1,1,1,1,1,1,1,1,1,1,1,1
1,1,1,1,1,1,1,1,1,1,1,1
1,1,1,1,1,1,1,1,1,1,1,1
1,1,1,1,1,1,1,1,1,1,1,1
1,1,1,1,1,1,1,1,1,1,1,1
1,1,1,1,1,1,1,1,1,1,1,1
1,1,1,1,1,1,1,1,1,1,1,1
1,1,1,1,1,1,1,1,1,1,1,1
1,1,1,1,1,1,1,1,1,1,1,1
1,1,1,1,1,1,1,1,1,1,1,1
1,1,1,1,1,1,1,1,1,1,1,1
endlayer

layer
1,1,1,1,1,1,1,1,1,1,1,1
1,1,1,1,1,1,1,1,1,1,1,1
1,1,1,1,1,1,1,1,1,1,1,1
1,1,1,1,1,1,1,1,1,1,1,1
1,1,1,1,1,1,1,1,1,1,1,1
1,1,1,1,1,1,1,1,1,1,1,1
1,1,1,1,1,1,1,1,1,1,1,1
1,1,1,1,1,1,1,1,1,1,1,1
1,1,1,1,1,1,1,1,1,1,1,1
1,1,1,1,1,1,1,1,1,1,1,1
1,1,1,1,1,1,1,1,1,1,1,1
1,1,1,1,1,1,1,1,1,1,1,1
endlayer

layer
1,1,1,1,1,1,1,1,1,1,1,1
1,1,1,1,1,1,1,1,1,1,1,1
1,1,1,1,1,1,1,1,1,1,1,1
1,1,1,1,1,1,1,1,1,1,1,1
1,1,1,1,1,1,1,1,1,1,1,1
1,1,1,1,1,1,1,1,1,1,1,1
1,1,1,1,1,1,1,1,1,1,1,1
1,1,1,1,1,1,1,1,1,1,1,1
1,1,1,1,1,1,1,1,1,1,1,1
1,1,1,1,1,1,1,1,1,1,1,1
1,1,1,1,1,1,1,1,1,1,1,1
1,1,1,1,1,1,1,1,1,1,1,1
endlayer

layer
1,1,1,1,1,1,1,1,1,1,1,1
1,1,1,1,1,1,1,1,1,1,1,1
1,1,1,1,1,1,1,1,1,1,1,1
1,1,1,1,1,1,1,1,1,1,1,1
1,1,1,1,1,1,1,1,1,1,1,1
1,1,1,1,1,1,1,1,1,1,1,1
1,1,1,1,1,1,1,1,1,1,1,1
1,1,1,1,1,1,1,1,1,1,1,1
1,1,1,1,1,1,1,1,1,1,1,1
1,1,1,1,1,1,1,1,1,1,1,1
1,1,1,1,1,1,1,1,1,1,1,1
1,1,1,1,1,1,1,1,1,1,1,1
endlayer

layer
1,1,1,1,1,1,1,1,1,1,1,1
1,1,1,1,1,1,1,1,1,1,1,1
1,1,1,1,1,1,1,1,1,1,1,1
1,1,1,1,1,1,1,1,1,1,1,1
1,1,1,1,1,1,1,1,1,1,1,1
1,1,1,1,1,1,1,1,1,1,1,1
1,1,1,1,1,1,1,1,1,1,1,1
1,1,1,1,1,1,1,1,1,1,1,1
1,1,1,1,1,1,1,1,1,1,1,1
1,1,1,1,1,1,1,1,1,1,1,1
1,1,1,1,1,1,1,1,1,1,1,1
1,1,1,1,1,1,1,1,1,1,1,1
endlayer

layer
1,1,1,1,1,1,1,1,1,1,1,1
1,1,1,1,1,1,1,1,1,1,1,1
1,1,1,1,1,1,1,1,1,1,1,1
1,1,1,1,1,1,1,1,1,1,1,1
1,1,1,1,1,1,1,1,1,1,1,1
1,1,1,1,1,1,1,1,1,1,1,1
1,1,1,1,1,1,1,1,1,1,1,1
1,1,1,1,1,1,1,1,1,1,1,1
1,1,1,1,1,1,1,1,1,1,1,1
1,1,1,1,1,1,1,1,1,1,1,1
1,1,1,1,1,1,1,1,1,1,1,1
1,1,1,1,1,1,1,1,1,1,1,1
endlayer

layer
1,1,1,1,1,1,1,1,1,1,1,1
1,1,1,1,1,1,1,1,1,1,1,1
1,1,1,1,1,1,1,1,1,1,1,1
1,1,1,1,1,1,1,1,1,1,1,1
1,1,1,1,1,1,1,1,1,1,1,1
1,1,1,1,1,1,1,1,1,1,1,1
1,1,1,1,1,1,1,1,1,1,1,1
1,1,1,1,1,1,1,1,1,1,1,1
1,1,1,1,1,1,1,1,1,1,1,1
1,1,1,1,1,1,1,1,1,1,1,1
1,1,1,1,1,1,1,1,1,1,1,1
1,1,1,1,1,1,1,1,1,1,1,1
endlayer

layer
1,1,1,1,1,1,1,1,1,1,1,1
1,1,1,1,1,1,1,1,1,1,1,1
1,1,1,1,1,1,1,1,1,1,1,1
1,1,1,1,1,1,1,1,1,1,1,1
1,1,1,1,1,1,1,1,1,1,1,1
1,1,1,1,1,1,1,1,1,1,1,1
1,1,1,1,1,1,1,1,1,1,1,1
1,1,1,1,1,1,1,1,1,1,1,1
1,1,1,1,1,1,1,1,1,1,1,1
1,1,1,1,1,1,1,1,1,1,1,1
1,1,1,1,1,1,1,1,1,1,1,1
1,1,1,1,1,1,1,1,1,1,1,1
endlayer

layer
1,1,1,1,1,1,1,1,1,1,1,1
1,1,1,1,1,1,1,1,1,1,1,1
1,1,1,1,1,1,1,1,1,1,1,1
1,1,1,1,1,1,1,1,1,1,1,1
1,1,1,1,1,1,1,1,1,1,1,1
1,1,1,1,1,1,1,1,1,1,1,1
1,1,1,1,1,1,1,1,1,1,1,1
1,1,1,1,1,1,1,1,1,1,1,1
1,1,1,1,1,1,1,1,1,1,1,1
1,1,1,1,1,1,1,1,1,1,1,1
1,1,1,1,1,1,1,1,1,1,1,1
1,1,1,1,1,1,1,1,1,1,1,1
endlayer

layer
1,1,1,1,1,1,1,1,1,1,1,1
1,1,1,1,1,1,1,1,1,1,1,1
1,1,1,1,1,1,1,1,1,1,1,1
1,1,1,1,1,1,1,1,1,1,1,1
1,1,1,1,1,1,1,1,1,1,1,1
1,1,1,1,1,1,1,1,1,1,1,1
1,1,1,1,1,1,1,1,1,1,1,1
1,1,1,1,1,1,1,1,1,1,1,1
1,1,1,1,1,1,1,1,1,1,1,1
1,1,1,1,1,1,1,1,1,1,1,1
1,1,1,1,1,1,1,1,1,1,1,1
1,1,1,1,1,1,1,1,1,1,1,1
endlayer

layer
1,1,1,1,1,1,1,1,1,1,1,1
1,1,1,1,1,1,1,1,1,1,1,1
1,1,1,1,1,1,1,1,1,1,1,1
1,1,1,1,1,1,1,1,1,1,1,1
1,1,1,1,1,1,1,1,1,1,1,1
1,1,1,1,1,1,1,1,1,1,1,1
1,1,1,1,1,1,1,1,1,1,1,1
1,1,1,1,1,1,1,1,1,1,1,1
1,1,1,1,1,1,1,1,1,1,1,1
1,1,1,1,1,1,1,1,1,1,1,1
1,1,1,1,1,1,1,1,1,1,1,1
1,1,1,1,1,1,1,1,1,1,1,1
endlayer

layer
1,1,1,1,1,1,1,1,1,1,1,1
1,1,1,1,1,1,1,1,1,1,1,1
1,1,1,1,1,1,1,1,1,1,1,1
1,1,1,1,1,1,1,1,1,1,1,1
1,1,1,1,1,1,1,1,1,1,1,1
1,1,1,1,1,1,1,1,1,1,1,1
1,1,1,1,1,1,1,1,1,1,1,1
1,1,1,1,1,1,1,1,1,1,1,1
1,1,1,1,1,1,1,1,1,1,1,1
1,1,1,1,1,1,1,1,1,1,1,1
1,1,1,1,1,1,1,1,1,1,1,1
1,1,1,1,1,1,1,1,1,1,1,1
endlayer

layer
1,1,1,1,1,1,1,1,1,1,1,1
1,1,1,1,1,1,1,1,1,1,1,1
1,1,1,1,1,1,1,1,1,1,1,1
1,1,1,1,1,1,1,1,1,1,1,1
1,1,1,1,1,1,1,1,1,1,1,1
1,1,1,1,1,1,1,1,1,1,1,1
1,1,1,1,1,1,1,1,1,1,1,1
1,1,1,1,1,1,1,1,1,1,1,1
1,1,1,1,1,1,1,1,1,1,1,1
1,1,1,1,1,1,1,1,1,1,1,1
1,1,1,1,1,1,1,1,1,1,1,1
1,1,1,1,1,1,1,1,1,1,1,1
endlayer

layer
1,1,1,1,1,1,1,1,1,1,1,1
1,1,1,1,1,1,1,1,1,1,1,1
1,1,1,1,1,1,1,1,1,1,1,1
1,1,1,1,1,1,1,1,1,1,1,1
1,1,1,1,1,1,1,1,1,1,1,1
1,1,1,1,1,1,1,1,1,1,1,1
1,1,1,1,1,1,1,1,1,1,1,1
1,1,1,1,1,1,1,1,1,1,1,1
1,1,1,1,1,1,1,1,1,1,1,1
1,1,1,1,1,1,1,1,1,1,1,1
1,1,1,1,1,1,1,1,1,1,1,1
1,1,1,1,1,1,1,1,1,1,1,1
endlayer

layer
1,1,1,1,1,1,1,1,1,1,1,1
1,1,1,1,1,1,1,1,1,1,1,1
1,1,1,1,1,1,1,1,1,1,1,1
1,1,1,1,1,1,1,1,1,1,1,1
1,1,1,1,1,1,1,1,1,1,1,1
1,1,1,1,1,1,1,1,1,1,1,1
1,1,1,1,1,1,1,1,1,1,1,1
1,1,1,1,1,1,1,1,1,1,1,1
1,1,1,1,1,1,1,1,1,1,1,1
1,1,1,1,1,1,1,1,1,1,1,1
1,1,1,1,1,1,1,1,1,1,1,1
1,1,1,1,1,1,1,1,1,1,1,1
endlayer

layer
1,1,1,1,1,1,1,1,1,1,1,1
1,1,1,1,1,1,1,1,1,1,1,1
1,1,1,1,1,1,1,1,1,1,1,1
1,1,1,1,1,1,1,1,1,1,1,1
1,1,1,1,1,1,1,1,1,1,1,1
1,1,1,1,1,1,1,1,1,1,1,1
1,1,1,1,1,1,1,1,1,1,1,1
1,1,1,1,1,1,1,1,1,1,1,1
1,1,1,1,1,1,1,1,1,1,1,1
1,1,1,1,1,1,1,1,1,1,1,1
1,1,1,1,1,1,1,1,1,1,1,1
1,1,1,1,1,1,1,1,1,1,1,1
endlayer

layer
1,1,1,1,1,1,1,1,1,1,1,1
1,1,1,1,1,1,1,1,1,1,1,1
1,1,1,1,1,1,1,1,1,1,1,1
1,1,1,1,1,1,1,1,1,1,1,1
1,1,1,1,1,1,1,1,1,1,1,1
1,1,1,1,1,1,1,1,1,1,1,1
1,1,1,1,1,1,1,1,1,1,1,1
1,1,1,1,1,1,1,1,1,1,1,1
1,1,1,1,1,1,1,1,1,1,1,1
1,1,1,1,1,1,1,1,1,1,1,1
1,1,1,1,1,1,1,1,1,1,1,1
1,1,1,1,1,1,1,1,1,1,1,1
endlayer

layer
1,1,1,1,1,1,1,1,1,1,1,1
1,1,1,1,1,1,1,1,1,1,1,1
1,1,1,1,1,1,1,1,1,1,1,1
1,1,1,1,1,1,1,1,1,1,1,1
1,1,1,1,1,1,1,1,1,1,1,1
1,1,1,1,1,1,1,1,1,1,1,1
1,1,1,1,1,1,1,1,1,1,1,1
1,1,1,1,1,1,1,1,1,1,1,1
1,1,1,1,1,1,1,1,1,1,1,1
1,1,1,1,1,1,1,1,1,1,1,1
1,1,1,1,1,1,1,1,1,1,1,1
1,1,1,1,1,1,1,1,1,1,1,1
endlayer

layer
1,1,1,1,1,1,1,1,1,1,1,1
1,1,1,1,1,1,1,1,1,1,1,1
1,1,1,1,1,1,1,1,1,1,1,1
1,1,1,1,1,1,1,1,1,1,1,1
1,1,1,1,1,1,1,1,1,1,1,1
1,1,1,1,1,1,1,1,1,1,1,1
1,1,1,1,1,1,1,1,1,1,1,1
1,1,1,1,1,1,1,1,1,1,1,1
1,1,1,1,1,1,1,1,1,1,1,1
1,1,1,1,1,1,1,1,1,1,1,1
1,1,1,1,1,1,1,1,1,1,1,1
1,1,1,1,1,1,1,1,1,1,1,1
endlayer

layer
1,1,1,1,1,1,1,1,1,1,1,1
1,1,1,1,1,1,1,1,1,1,1,1
1,1,1,1,1,1,1,1,1,1,1,1
1,1,1,1,1,1,1,1,1,1,1,1
1,1,1,1,1,1,1,1,1,1,1,1
1,1,1,1,1,1,1,1,1,1,1,1
1,1,1,1,1,1,1,1,1,1,1,1
1,1,1,1,1,1,1,1,1,1,1,1
1,1,1,1,1,1,1,1,1,1,1,1
1,1,1,1,1,1,1,1,1,1,1,1
1,1,1,1,1,1,1,1,1,1,1,1
1,1,1,1,1,1,1,1,1,1,1,1
endlayer

layer
1,1,1,1,1,1,1,1,1,1,1,1
1,1,1,1,1,1,1,1,1,1,1,1
1,1,1,1,1,1,1,1,1,1,1,1
1,1,1,1,1,1,1,1,1,1,1,1
1,1,1,1,1,1,1,1,1,1,1,1
1,1,1,1,1,5,5,1,1,1,1,1
1,1,1,1,1,5,5,1,1,1,1,1
1,1,1,1,1,1,1,1,1,1,1,1
1,1,1,1,1,1,1,1,1,1,1,1
1,1,1,1,1,1,1,1,1,1,1,1
1,1,1,1,1,1,1,1,1,1,1,1
1,1,1,1,1,1,1,1,1,1,1,1
endlayer

layer
1,1,1,1,1,1,1,1,1,1,1,1
1,1,1,1,1,1,1,1,1,1,1,1
1,1,1,1,1,1,1,1,1,1,1,1
1,1,1,1,1,1,1,1,1,1,1,1
1,1,1,1,8,1,1,8,1,1,1,1
1,1,1,1,1,0,0,1,1,1,1,1
1,1,1,1,1,0,0,1,1,1,1,1
1,1,1,1,8,1,1,8,1,1,1,1
1,1,1,1,1,1,1,1,1,1,1,1
1,1,1,1,1,1,1,1,1,1,1,1
1,1,1,1,1,1,1,1,1,1,1,1
1,1,1,1,1,1,1,1,1,1,1,1
endlayer

layer
1,1,1,1,1,1,1,1,1,1,1,1
1,1,1,1,1,1,1,1,1,1,1,1
1,1,1,1,1,1,1,1,1,1,1,1
1,1,1,1,1,1,1,1,1,1,1,1
1,1,1,1,8,0,0,8,1,1,1,1
1,1,1,1,0,0,0,0,1,1,1,1
1,1,1,1,0,0,0,0,1,1,1,1
1,1,1,1,8,0,0,8,1,1,1,1
1,1,1,1,1,1,1,1,1,1,1,1
1,1,1,1,1,1,1,1,1,1,1,1
1,1,1,1,1,1,1,1,1,1,1,1
1,1,1,1,1,1,1,1,1,1,1,1
endlayer

layer
1,1,1,1,1,1,1,1,1,1,1,1
1,1,1,1,1,1,1,1,1,1,1,1
1,1,1,1,1,1,1,1,1,1,1,1
1,1,1,1,1,1,1,1,1,1,1,1
1,1,1,1,8,0,0,8,1,1,1,1
1,1,1,1,0,0,0,0,1,1,1,1
1,1,1,1,0,0,0,0,1,1,1,1
1,1,1,1,8,0,0,8,1,1,1,1
1,1,1,1,1,1,1,1,1,1,1,1
1,1,1,1,1,1,1,1,1,1,1,1
1,1,1,1,1,1,1,1,1,1,1,1
1,1,1,1,1,1,1,1,1,1,1,1
endlayer

layer
1,1,1,1,1,1,1,1,1,1,1,1
1,1,1,1,1,1,1,1,1,1,1,1
1,1,1,1,1,1,1,1,1,1,1,1
1,1,1,1,1,1,1,1,1,1,1,1
1,1,1,1,8,9,9,8,1,1,1,1
1,1,1,1,12,0,0,10,1,1,1,1
1,1,1,1,12,0,0,10,1,1,1,1
1,1,1,1,8,11,11,8,1,1,1,1
1,1,1,1,1,1,1,1,1,1,1,1
1,1,1,1,1,1,1,1,1,1,1,1
1,1,1,1,1,1,1,1,1,1,1,1
1,1,1,1,1,1,1,1,1,1,1,1
endlayer

layer
1,1,1,1,1,1,1,1,1,1,1,1
1,1,1,1,1,1,1,1,1,1,1,1
1,1,1,1,1,1,1,1,1,1,1,1
1,1,1,8,1,1,1,1,8,1,1,1
1,1,1,1,1,9,9,1,1,1,1,1
1,1,1,1,12,0,0,10,1,1,1,1
1,1,1,1,12,0,0,10,1,1,1,1
1,1,1,1,1,11,11,1,1,1,1,1
1,1,1,8,1,1,1,1,8,1,1,1
1,1,1,1,1,1,1,1,1,1,1,1
1,1,1,1,1,1,1,1,1,1,1,1
1,1,1,1,1,1,1,1,1,1,1,1
endlayer

layer
1,1,1,1,1,1,1,1,1,1,1,1
1,1,1,1,1,1,1,1,1,1,1,1
1,1,1,1,1,1,1,1,1,1,1,1
1,1,1,8,1,9,13,1,8,1,1,1
1,1,1,1,9,0,0,10,1,1,1,1
1,1,1,13,0,0,0,0,10,1,1,1
1,1,1,12,0,0,0,0,13,1,1,1
1,1,1,1,12,0,0,11,1,1,1,1
1,1,1,8,1,13,11,1,8,1,1,1
1,1,1,1,1,1,1,1,1,1,1,1
1,1,1,1,1,1,1,1,1,1,1,1
1,1,1,1,1,1,1,1,1,1,1,1
endlayer

layer
1,1,1,1,1,1,1,1,1,1,1,1
1,1,1,1,1,1,1,1,1,1,1,1
1,1,1,1,1,1,1,1,1,1,1,1
1,1,1,8,1,9,13,1,8,1,1,1
1,1,1,1,9,0,0,10,1,1,1,1
1,1,1,13,0,0,0,0,10,1,1,1
1,1,1,12,0,0,0,0,13,1,1,1
1,1,1,1,12,0,0,11,1,1,1,1
1,1,1,8,1,13,11,1,8,1,1,1
1,1,1,1,1,1,1,1,1,1,1,1
1,1,1,1,1,1,1,1,1,1,1,1
1,1,1,1,1,1,1,1,1,1,1,1
endlayer

layer
1,1,1,1,1,1,1,1,1,1,1,1
1,1,1,1,1,1,1,1,1,1,1,1
1,1,1,1,1,1,1,1,1,1,1,1
1,1,1,8,9,13,10,10,8,1,1,1
1,1,1,9,0,0,0,0,10,1,1,1
1,1,1,9,0,0,0,0,13,1,1,1
1,1,1,13,0,0,0,0,11,1,1,1
1,1,1,12,0,0,0,0,11,1,1,1
1,1,1,8,12,12,13,11,8,1,1,1
1,1,1,1,1,1,1,1,1,1,1,1
1,1,1,1,1,1,1,1,1,1,1,1
1,1,1,1,1,1,1,1,1,1,1,1
endlayer

layer
1,1,1,1,1,1,1,1,1,1,1,1
1,1,1,1,1,1,1,1,1,1,1,1
1,1,1,1,1,1,1,1,1,1,1,1
1,1,1,8,9,13,10,10,8,1,1,1
1,1,1,9,0,0,0,0,10,1,1,1
1,1,1,9,0,0,0,0,13,1,1,1
1,1,1,13,0,0,0,0,11,1,1,1
1,1,1,12,0,0,0,0,11,1,1,1
1,1,1,8,12,12,13,11,8,1,1,1
1,1,1,1,1,1,1,1,1,1,1,1
1,1,1,1,1,1,1,1,1,1,1,1
1,1,1,1,1,1,1,1,1,1,1,1
endlayer

layer
1,1,1,1,1,1,1,1,1,1,1,1
1,1,1,1,1,1,1,1,1,1,1,1
1,1,1,1,13,10,10,10,1,1,1,1
1,1,1,9,0,0,0,0,10,1,1,1
1,1,9,0,0,0,0,0,0,13,1,1
1,1,9,0,0,0,0,0,0,11,1,1
1,1,9,0,0,0,0,0,0,11,1,1
1,1,13,0,0,0,0,0,0,11,1,1
1,1,1,12,0,0,0,10,11,1,1,1
1,1,1,1,12,12,12,13,1,1,1,1
1,1,1,1,1,1,1,1,1,1,1,1
1,1,1,1,1,1,1,1,1,1,1,1
endlayer

layer
1,1,1,1,1,1,1,1,1,1,1,1
1,1,1,1,1,1,1,1,1,1,1,1
1,1,1,1,13,10,10,10,1,1,1,1
1,1,1,9,0,0,0,0,10,1,1,1
1,1,9,0,0,0,0,0,0,13,1,1
1,1,9,0,0,0,0,0,0,11,1,1
1,1,9,0,0,0,0,0,0,11,1,1
1,1,13,0,0,0,0,0,0,11,1,1
1,1,1,12,0,0,0,10,11,1,1,1
1,1,1,1,12,12,12,13,1,1,1,1
1,1,1,1,1,1,1,1,1,1,1,1
1,1,1,1,1,1,1,1,1,1,1,1
endlayer

layer
1,1,1,1,1,1,1,1,1,1,1,1
1,1,1,1,10,10,10,10,1,1,1,1
1,1,1,13,0,0,0,0,10,1,1,1
1,1,9,0,0,0,0,0,0,13,1,1
1,9,0,0,0,0,0,0,0,0,11,1
1,9,0,0,0,0,0,0,0,0,11,1
1,9,0,0,0,0,0,0,0,0,11,1
1,9,0,0,0,0,0,0,0,0,11,1
1,1,13,0,0,0,0,0,0,11,1,1
1,1,1,12,0,0,0,0,13,1,1,1
1,1,1,1,12,12,12,12,1,1,1,1
1,1,1,1,1,1,1,1,1,1,1,1
endlayer

layer
1,1,1,1,1,1,1,1,1,1,1,1
1,1,1,1,10,10,10,10,1,1,1,1
1,1,1,13,0,0,0,0,10,1,1,1
1,1,9,0,0,0,0,0,0,13,1,1
1,9,0,0,0,0,0,0,0,0,11,1
1,9,0,0,0,0,0,0,0,0,11,1
1,9,0,0,0,0,0,0,0,0,11,1
1,9,0,0,0,0,0,0,0,0,11,1
1,1,13,0,0,0,0,0,0,11,1,1
1,1,1,12,0,0,0,0,13,1,1,1
1,1,1,1,12,12,12,12,1,1,1,1
1,1,1,1,1,1,1,1,1,1,1,1
endlayer

layer
1,1,1,1,10,10,10,10,1,1,1,1
1,1,1,10,0,0,0,0,10,1,1,1
1,1,13,0,0,0,0,0,0,13,1,1
1,9,0,0,0,0,0,0,0,0,11,1
9,0,0,0,0,0,0,0,0,0,0,11
9,0,0,0,0,0,0,0,0,0,0,11
9,0,0,0,0,0,0,0,0,0,0,11
9,0,0,0,0,0,0,0,0,0,0,11
1,9,0,0,0,0,0,0,0,0,11,1
1,1,13,0,0,0,0,0,0,13,1,1
1,1,1,12,0,0,0,0,12,1,1,1
1,1,1,1,12,12,12,12,1,1,1,1
endlayer

layer
1,1,1,1,10,10,10,10,1,1,1,1
1,1,1,10,0,0,0,0,10,1,1,1
1,1,13,0,0,0,0,0,0,13,1,1
1,9,0,0,0,0,0,0,0,0,11,1
9,0,0,0,0,0,0,0,0,0,0,11
9,0,0,0,0,0,0,0,0,0,0,11
9,0,0,0,0,0,0,0,0,0,0,11
9,0,0,0,0,0,0,0,0,0,0,11
1,9,0,0,0,0,0,0,0,0,11,1
1,1,13,0,0,0,0,0,0,13,1,1
1,1,1,12,0,0,0,0,12,1,1,1
1,1,1,1,12,12,12,12,1,1,1,1
endlayer

layer
1,1,1,1,10,10,10,10,1,1,1,1
1,1,1,10,0,0,0,0,13,1,1,1
1,1,10,0,0,0,0,0,0,11,1,1
1,13,0,0,0,0,0,0,0,0,11,1
9,0,0,0,0,0,0,0,0,0,0,11
9,0,0,0,0,0,0,0,0,0,0,11
9,0,0,0,0,0,0,0,0,0,0,11
9,0,0,0,0,0,0,0,0,0,0,11
1,9,0,0,0,0,0,0,0,0,13,1
1,1,9,0,0,0,0,0,0,12,1,1
1,1,1,13,0,0,0,0,12,1,1,1
1,1,1,1,12,12,12,12,1,1,1,1
endlayer

layer
1,1,1,1,10,10,10,10,1,1,1,1
1,1,1,10,0,0,0,0,13,1,1,1
1,1,10,0,0,0,0,0,0,11,1,1
1,13,0,0,0,0,0,0,0,0,11,1
9,0,0,0,0,0,0,0,0,0,0,11
9,0,0,0,0,0,0,0,0,0,0,11
9,0,0,0,0,0,0,0,0,0,0,11
9,0,0,0,0,0,0,0,0,0,0,11
1,9,0,0,0,0,0,0,0,0,13,1
1,1,9,0,0,0,0,0,0,12,1,1
1,1,1,13,0,0,0,0,12,1,1,1
1,1,1,1,12,12,12,12,1,1,1,1
endlayer

layer
1,1,1,1,1,1,1,1,1,1,1,1
1,1,1,1,10,10,10,13,1,1,1,1
1,1,1,10,0,0,0,0,11,1,1,1
1,1,10,0,0,0,0,0,0,11,1,1
1,13,0,0,0,0,0,0,0,0,11,1
1,9,0,0,0,0,0,0,0,0,11,1
1,9,0,0,0,0,0,0,0,0,11,1
1,9,0,0,0,0,0,0,0,0,13,1
1,1,9,0,0,0,0,0,0,12,1,1
1,1,1,9,0,0,0,0,12,1,1,1
1,1,1,1,13,12,12,12,1,1,1,1
1,1,1,1,1,1,1,1,1,1,1,1
endlayer

layer
1,1,1,1,1,1,1,1,1,1,1,1
1,1,1,1,10,10,10,13,1,1,1,1
1,1,1,10,0,0,0,0,11,1,1,1
1,1,10,0,0,0,0,0,0,11,1,1
1,13,0,0,0,0,0,0,0,0,11,1
1,9,0,0,0,0,0,0,0,0,11,1
1,9,0,0,0,0,0,0,0,0,11,1
1,9,0,0,0,0,0,0,0,0,13,1
1,1,9,0,0,0,0,0,0,12,1,1
1,1,1,9,0,0,0,0,12,1,1,1
1,1,1,1,13,12,12,12,1,1,1,1
1,1,1,1,1,1,1,1,1,1,1,1
endlayer

layer
1,1,1,1,1,1,1,1,1,1,1,1
1,1,1,1,1,1,1,1,1,1,1,1
1,1,1,1,10,10,13,11,1,1,1,1
1,1,1,10,0,0,0,0,11,1,1,1
1,1,10,0,0,0,0,0,0,11,1,1
1,1,13,0,0,0,0,0,0,11,1,1
1,1,9,0,0,0,0,0,0,13,1,1
1,1,9,0,0,0,0,0,0,12,1,1
1,1,1,9,0,0,0,0,12,1,1,1
1,1,1,1,9,13,12,12,1,1,1,1
1,1,1,1,1,1,1,1,1,1,1,1
1,1,1,1,1,1,1,1,1,1,1,1
endlayer

layer
1,1,1,1,1,1,1,1,1,1,1,1
1,1,1,1,1,1,1,1,1,1,1,1
1,1,1,1,1,1,1,1,1,1,1,1
1,1,1,1,10,13,11,11,1,1,1,1
1,1,1,10,10,13,11,11,11,1,1,1
1,1,1,10,10,10,12,13,13,1,1,1
1,1,1,13,13,9,12,12,12,1,1,1
1,1,1,9,9,9,13,12,12,1,1,1
1,1,1,1,9,9,13,12,1,1,1,1
1,1,1,1,1,1,1,1,1,1,1,1
1,1,1,1,1,1,1,1,1,1,1,1
1,1,1,1,1,1,1,1,1,1,1,1
endlayer
