# Author: RoofFiddler
#From: Minecraft Forums
# Template: Orthanc

biomesToSpawnIn=crag,badlands,dead forest,dead swamp,deadlands,ominous woods,canyon,canyon ravine,thick ominous woods,volcano,wasteland
weight=10
uniqueMinDistance=1000
embed_into_distance=0
unacceptable_target_blocks=flowing_water,water,flowing_lava,lava,Natura:Cloud,red_mushroom_block,brown_mushroom_block,planks,cobblestone,end_stone,obsidian,purpur_block,iron_bars,purpur_slab,purpur_pillar,netherrack,soul_sand,quartz_ore
dimensions=46,12,12
allowable_overhang=0
max_cut_in=2
cut_in_buffer=1
max_leveling=2
leveling_buffer=1
preserve_water=0
preserve_lava=0
preserve_plants=0


rule1=0,100,obsidian
rule2=0,100,ladder-3
rule3=0,100,ladder-2



layer
1,1,1,1,1,1,1,1,1,1,1,1
1,1,1,1,1,1,1,1,1,1,1,1
1,1,1,1,1,1,1,1,1,1,1,1
1,1,1,1,1,1,1,1,1,1,1,1
1,1,1,1,1,1,1,1,1,1,1,1
1,1,1,1,1,1,1,1,1,1,1,1
1,1,1,1,1,1,1,1,1,1,1,1
1,1,1,1,1,1,1,1,1,1,1,1
1,1,1,1,1,1,1,1,1,1,1,1
1,1,1,1,1,1,1,1,1,1,1,1
1,1,1,1,1,1,1,1,1,1,1,1
1,1,1,1,1,1,1,1,1,1,1,1
endlayer


layer
1,1,1,1,1,0,0,1,1,1,1,1
1,0,0,1,1,1,1,1,1,0,0,1
1,0,1,1,0,0,0,0,1,1,0,1
1,1,1,0,0,0,0,0,0,1,1,1
1,1,0,0,0,0,0,0,0,0,1,1
0,0,0,0,0,0,0,0,2,1,1,0
0,0,0,0,0,0,0,0,2,1,1,0
1,1,0,0,0,0,0,0,0,0,1,1
1,1,1,0,0,0,0,0,0,1,1,1
1,0,1,1,0,0,0,0,1,1,0,1
1,0,0,1,1,1,1,1,1,0,0,1
1,1,1,1,1,0,0,1,1,1,1,1
endlayer


layer
1,1,1,1,1,0,0,1,1,1,1,1
1,0,0,1,1,1,1,1,1,0,0,1
1,0,1,1,0,0,0,0,1,1,0,1
1,1,1,0,0,0,0,0,0,1,1,1
1,1,0,0,0,0,0,0,0,0,1,1
0,0,0,0,0,0,0,0,2,1,1,0
0,0,0,0,0,0,0,0,2,1,1,0
1,1,0,0,0,0,0,0,0,0,1,1
1,1,1,0,0,0,0,0,0,1,1,1
1,0,1,1,0,0,0,0,1,1,0,1
1,0,0,1,1,1,1,1,1,0,0,1
1,1,1,1,1,0,0,1,1,1,1,1
endlayer


layer
1,1,1,1,1,0,0,1,1,1,1,1
1,0,0,1,1,1,1,1,1,0,0,1
1,0,1,1,0,0,0,0,1,1,0,1
1,1,1,0,0,0,0,0,0,1,1,1
1,1,0,0,0,0,0,0,0,0,1,1
0,1,0,0,0,0,0,0,2,1,1,0
0,1,0,0,0,0,0,0,2,1,1,0
1,1,0,0,0,0,0,0,0,0,1,1
1,1,1,0,0,0,0,0,0,1,1,1
1,0,1,1,0,0,0,0,1,1,0,1
1,0,0,1,1,1,1,1,1,0,0,1
1,1,1,1,1,0,0,1,1,1,1,1
endlayer


layer
1,1,1,1,1,0,0,1,1,1,1,1
1,0,0,1,1,1,1,1,1,0,0,1
1,0,1,1,1,1,1,1,1,1,0,1
1,1,1,1,1,1,1,1,1,1,1,1
1,1,1,1,1,1,1,1,1,1,1,1
0,1,1,1,1,1,1,1,2,1,1,0
0,1,1,1,1,1,1,1,2,1,1,0
1,1,1,1,1,1,1,1,1,1,1,1
1,1,1,1,1,1,1,1,1,1,1,1
1,0,1,1,1,1,1,1,1,1,0,1
1,0,0,1,1,1,1,1,1,0,0,1
1,1,1,1,1,0,0,1,1,1,1,1
endlayer


layer
1,1,1,1,1,0,0,1,1,1,1,1
1,0,0,1,1,1,1,1,1,0,0,1
1,0,1,1,0,0,0,0,1,1,0,1
1,1,1,0,0,0,0,0,0,1,1,1
1,1,0,0,0,0,0,0,0,0,1,1
0,1,0,0,0,0,0,0,2,1,1,0
0,1,0,0,0,0,0,0,2,1,1,0
1,1,0,0,0,0,0,0,0,0,1,1
1,1,1,0,0,0,0,0,0,1,1,1
1,0,1,1,0,0,0,0,1,1,0,1
1,0,0,1,1,1,1,1,1,0,0,1
1,1,1,1,1,0,0,1,1,1,1,1
endlayer


layer
1,1,1,1,1,0,0,1,1,1,1,1
1,0,0,1,1,0,0,1,1,0,0,1
1,0,1,1,0,0,0,0,1,1,0,1
1,1,1,0,0,0,0,0,0,1,1,1
1,1,0,0,0,0,0,0,0,0,1,1
0,0,0,0,0,0,0,0,2,1,1,0
0,0,0,0,0,0,0,0,2,1,1,0
1,1,0,0,0,0,0,0,0,0,1,1
1,1,1,0,0,0,0,0,0,1,1,1
1,0,1,1,0,0,0,0,1,1,0,1
1,0,0,1,1,0,0,1,1,0,0,1
1,1,1,1,1,0,0,1,1,1,1,1
endlayer


layer
1,1,1,1,1,0,0,1,1,1,1,1
1,0,0,1,1,1,1,1,1,0,0,1
1,0,1,1,0,0,0,0,1,1,0,1
1,1,1,0,0,0,0,0,0,1,1,1
1,1,0,0,0,0,0,0,0,0,1,1
0,1,0,0,0,0,0,0,2,1,1,0
0,1,0,0,0,0,0,0,2,1,1,0
1,1,0,0,0,0,0,0,0,0,1,1
1,1,1,0,0,0,0,0,0,1,1,1
1,0,1,1,0,0,0,0,1,1,0,1
1,0,0,1,1,1,1,1,1,0,0,1
1,1,1,1,1,0,0,1,1,1,1,1
endlayer



layer
1,1,1,1,1,0,0,1,1,1,1,1
1,0,0,1,1,1,1,1,1,0,0,1
1,0,1,1,1,1,1,1,1,1,0,1
1,1,1,1,1,1,1,1,1,1,1,1
1,1,1,1,1,1,1,1,1,1,1,1
0,1,1,1,1,1,1,1,2,1,1,0
0,1,1,1,1,1,1,1,2,1,1,0
1,1,1,1,1,1,1,1,1,1,1,1
1,1,1,1,1,1,1,1,1,1,1,1
1,0,1,1,1,1,1,1,1,1,0,1
1,0,0,1,1,1,1,1,1,0,0,1
1,1,1,1,1,0,0,1,1,1,1,1
endlayer



layer
1,1,1,1,1,0,0,1,1,1,1,1
1,0,0,1,1,1,1,1,1,0,0,1
1,0,1,1,0,0,0,0,1,1,0,1
1,1,1,0,0,0,0,0,0,1,1,1
1,1,0,0,0,0,0,0,0,0,1,1
0,1,0,0,0,0,0,0,2,1,1,0
0,1,0,0,0,0,0,0,2,1,1,0
1,1,0,0,0,0,0,0,0,0,1,1
1,1,1,0,0,0,0,0,0,1,1,1
1,0,1,1,0,0,0,0,1,1,0,1
1,0,0,1,1,1,1,1,1,0,0,1
1,1,1,1,1,0,0,1,1,1,1,1
endlayer



layer
1,1,1,1,1,0,0,1,1,1,1,1
1,0,0,1,1,0,0,1,1,0,0,1
1,0,1,1,0,0,0,0,1,1,0,1
1,1,1,0,0,0,0,0,0,1,1,1
1,1,0,0,0,0,0,0,0,0,1,1
0,0,0,0,0,0,0,0,2,1,1,0
0,0,0,0,0,0,0,0,2,1,1,0
1,1,0,0,0,0,0,0,0,0,1,1
1,1,1,0,0,0,0,0,0,1,1,1
1,0,1,1,0,0,0,0,1,1,0,1
1,0,0,1,1,0,0,1,1,0,0,1
1,1,1,1,1,0,0,1,1,1,1,1
endlayer



layer
1,1,1,1,1,0,0,1,1,1,1,1
1,0,0,1,1,1,1,1,1,0,0,1
1,0,1,1,0,0,0,0,1,1,0,1
1,1,1,0,0,0,0,0,0,1,1,1
1,1,0,0,0,0,0,0,0,0,1,1
0,1,0,0,0,0,0,0,2,1,1,0
0,1,0,0,0,0,0,0,2,1,1,0
1,1,0,0,0,0,0,0,0,0,1,1
1,1,1,0,0,0,0,0,0,1,1,1
1,0,1,1,0,0,0,0,1,1,0,1
1,0,0,1,1,1,1,1,1,0,0,1
1,1,1,1,1,0,0,1,1,1,1,1
endlayer



layer
1,1,1,1,1,0,0,1,1,1,1,1
1,0,0,1,1,1,1,1,1,0,0,1
1,0,1,1,1,1,1,1,1,1,0,1
1,1,1,1,1,1,1,1,1,1,1,1
1,1,1,1,1,1,1,1,1,1,1,1
0,1,1,1,1,1,1,1,2,1,1,0
0,1,1,1,1,1,1,1,2,1,1,0
1,1,1,1,1,1,1,1,1,1,1,1
1,1,1,1,1,1,1,1,1,1,1,1
1,0,1,1,1,1,1,1,1,1,0,1
1,0,0,1,1,1,1,1,1,0,0,1
1,1,1,1,1,0,0,1,1,1,1,1
endlayer



layer
0,0,0,0,0,0,0,0,0,0,0,0
0,1,1,1,1,0,0,1,1,1,1,0
0,1,0,1,1,1,1,1,1,0,1,0
0,1,1,1,0,0,0,0,1,1,1,0
0,1,1,0,0,0,0,0,0,1,1,0
0,0,1,1,3,0,0,0,0,1,0,0
0,0,1,1,3,0,0,0,0,1,0,0
0,1,1,0,0,0,0,0,0,1,1,0
0,1,1,1,0,0,0,0,1,1,1,0
0,1,0,1,1,1,1,1,1,0,1,0
0,1,1,1,1,0,0,1,1,1,1,0
0,0,0,0,0,0,0,0,0,0,0,0
endlayer



layer
0,0,0,0,0,0,0,0,0,0,0,0
0,1,1,1,1,0,0,1,1,1,1,0
0,1,0,1,1,0,0,1,1,0,1,0
0,1,1,1,0,0,0,0,1,1,1,0
0,1,1,0,0,0,0,0,0,1,1,0
0,0,1,1,3,0,0,0,0,0,0,0
0,0,1,1,3,0,0,0,0,0,0,0
0,1,1,0,0,0,0,0,0,1,1,0
0,1,1,1,0,0,0,0,1,1,1,0
0,1,0,1,1,0,0,1,1,0,1,0
0,1,1,1,1,0,0,1,1,1,1,0
0,0,0,0,0,0,0,0,0,0,0,0
endlayer



layer
0,0,0,0,0,0,0,0,0,0,0,0
0,1,1,1,1,0,0,1,1,1,1,0
0,1,0,1,1,1,1,1,1,0,1,0
0,1,1,1,0,0,0,0,1,1,1,0
0,1,1,0,0,0,0,0,0,1,1,0
0,0,1,1,3,0,0,0,0,1,0,0
0,0,1,1,3,0,0,0,0,1,0,0
0,1,1,0,0,0,0,0,0,1,1,0
0,1,1,1,0,0,0,0,1,1,1,0
0,1,0,1,1,1,1,1,1,0,1,0
0,1,1,1,1,0,0,1,1,1,1,0
0,0,0,0,0,0,0,0,0,0,0,0
endlayer



layer
0,0,0,0,0,0,0,0,0,0,0,0
0,1,1,1,1,0,0,1,1,1,1,0
0,1,0,1,1,1,1,1,1,0,1,0
0,1,1,1,1,1,1,1,1,1,1,0
0,1,1,1,1,1,1,1,1,1,1,0
0,0,1,1,3,1,1,1,1,1,0,0
0,0,1,1,3,1,1,1,1,1,0,0
0,1,1,1,1,1,1,1,1,1,1,0
0,1,1,1,1,1,1,1,1,1,1,0
0,1,0,1,1,1,1,1,1,0,1,0
0,1,1,1,1,0,0,1,1,1,1,0
0,0,0,0,0,0,0,0,0,0,0,0
endlayer



layer
0,0,0,0,0,0,0,0,0,0,0,0
0,1,1,1,1,0,0,1,1,1,1,0
0,1,0,1,1,1,1,1,1,0,1,0
0,1,1,1,0,0,0,0,1,1,1,0
0,1,1,0,0,0,0,0,0,1,1,0
0,0,1,1,3,0,0,0,0,1,0,0
0,0,1,1,3,0,0,0,0,1,0,0
0,1,1,0,0,0,0,0,0,1,1,0
0,1,1,1,0,0,0,0,1,1,1,0
0,1,0,1,1,1,1,1,1,0,1,0
0,1,1,1,1,0,0,1,1,1,1,0
0,0,0,0,0,0,0,0,0,0,0,0
endlayer



layer
0,0,0,0,0,0,0,0,0,0,0,0
0,1,1,1,1,0,0,1,1,1,1,0
0,1,0,1,1,0,0,1,1,0,1,0
0,1,1,1,0,0,0,0,1,1,1,0
0,1,1,0,0,0,0,0,0,1,1,0
0,0,1,1,3,0,0,0,0,0,0,0
0,0,1,1,3,0,0,0,0,0,0,0
0,1,1,0,0,0,0,0,0,1,1,0
0,1,1,1,0,0,0,0,1,1,1,0
0,1,0,1,1,0,0,1,1,0,1,0
0,1,1,1,1,0,0,1,1,1,1,0
0,0,0,0,0,0,0,0,0,0,0,0
endlayer



layer
0,0,0,0,0,0,0,0,0,0,0,0
0,1,1,1,1,0,0,1,1,1,1,0
0,1,0,1,1,1,1,1,1,0,1,0
0,1,1,1,0,0,0,0,1,1,1,0
0,1,1,0,0,0,0,0,0,1,1,0
0,0,1,1,3,0,0,0,0,1,0,0
0,0,1,1,3,0,0,0,0,1,0,0
0,1,1,0,0,0,0,0,0,1,1,0
0,1,1,1,0,0,0,0,1,1,1,0
0,1,0,1,1,1,1,1,1,0,1,0
0,1,1,1,1,0,0,1,1,1,1,0
0,0,0,0,0,0,0,0,0,0,0,0
endlayer



layer
0,0,0,0,0,0,0,0,0,0,0,0
0,1,1,1,1,0,0,1,1,1,1,0
0,1,0,1,1,1,1,1,1,0,1,0
0,1,1,1,1,1,1,1,1,1,1,0
0,1,1,1,1,1,1,1,1,1,1,0
0,0,1,1,3,1,1,1,1,1,0,0
0,0,1,1,3,1,1,1,1,1,0,0
0,1,1,1,1,1,1,1,1,1,1,0
0,1,1,1,1,1,1,1,1,1,1,0
0,1,0,1,1,1,1,1,1,0,1,0
0,1,1,1,1,0,0,1,1,1,1,0
0,0,0,0,0,0,0,0,0,0,0,0
endlayer



layer
0,0,0,0,0,0,0,0,0,0,0,0
0,1,1,1,1,0,0,1,1,1,1,0
0,1,0,1,1,1,1,1,1,0,1,0
0,1,1,1,0,0,0,0,1,1,1,0
0,1,1,0,0,0,0,0,0,1,1,0
0,0,1,1,3,0,0,0,0,1,0,0
0,0,1,1,3,0,0,0,0,1,0,0
0,1,1,0,0,0,0,0,0,1,1,0
0,1,1,1,0,0,0,0,1,1,1,0
0,1,0,1,1,1,1,1,1,0,1,0
0,1,1,1,1,0,0,1,1,1,1,0
0,0,0,0,0,0,0,0,0,0,0,0
endlayer



layer
0,0,0,0,0,0,0,0,0,0,0,0
0,1,1,1,1,0,0,1,1,1,1,0
0,1,0,1,1,0,0,1,1,0,1,0
0,1,1,1,0,0,0,0,1,1,1,0
0,1,1,0,0,0,0,0,0,1,1,0
0,0,1,1,3,0,0,0,0,0,0,0
0,0,1,1,3,0,0,0,0,0,0,0
0,1,1,0,0,0,0,0,0,1,1,0
0,1,1,1,0,0,0,0,1,1,1,0
0,1,0,1,1,0,0,1,1,0,1,0
0,1,1,1,1,0,0,1,1,1,1,0
0,0,0,0,0,0,0,0,0,0,0,0
endlayer



layer
0,0,0,0,0,0,0,0,0,0,0,0
0,1,1,1,1,0,0,1,1,1,1,0
0,1,0,1,1,1,1,1,1,0,1,0
0,1,1,1,0,0,0,0,1,1,1,0
0,1,1,0,0,0,0,0,0,1,1,0
0,0,1,1,3,0,0,0,0,1,0,0
0,0,1,1,3,0,0,0,0,1,0,0
0,1,1,0,0,0,0,0,0,1,1,0
0,1,1,1,0,0,0,0,1,1,1,0
0,1,0,1,1,1,1,1,1,0,1,0
0,1,1,1,1,0,0,1,1,1,1,0
0,0,0,0,0,0,0,0,0,0,0,0
endlayer



layer
0,0,0,0,0,0,0,0,0,0,0,0
0,1,1,1,1,0,0,1,1,1,1,0
0,1,0,1,1,1,1,1,1,0,1,0
0,1,1,1,1,1,1,1,1,1,1,0
0,1,1,1,1,1,1,1,1,1,1,0
0,0,1,1,3,1,1,1,1,1,0,0
0,0,1,1,3,1,1,1,1,1,0,0
0,1,1,1,1,1,1,1,1,1,1,0
0,1,1,1,1,1,1,1,1,1,1,0
0,1,0,1,1,1,1,1,1,0,1,0
0,1,1,1,1,0,0,1,1,1,1,0
0,0,0,0,0,0,0,0,0,0,0,0
endlayer



layer
0,0,0,0,0,0,0,0,0,0,0,0
0,0,0,0,0,0,0,0,0,0,0,0
0,0,1,1,1,0,0,1,1,1,0,0
0,0,1,1,1,1,1,1,1,1,0,0
0,0,1,1,0,0,0,0,1,1,0,0
0,0,0,1,0,0,2,1,1,0,0,0
0,0,0,1,0,0,2,1,1,0,0,0
0,0,1,1,0,0,0,0,1,1,0,0
0,0,1,1,1,1,1,1,1,1,0,0
0,0,1,1,1,0,0,1,1,1,0,0
0,0,0,0,0,0,0,0,0,0,0,0
0,0,0,0,0,0,0,0,0,0,0,0
endlayer



layer
0,0,0,0,0,0,0,0,0,0,0,0
0,0,0,0,0,0,0,0,0,0,0,0
0,0,1,1,1,0,0,1,1,1,0,0
0,0,1,1,1,0,0,1,1,1,0,0
0,0,1,1,0,0,0,0,1,1,0,0
0,0,0,0,0,0,2,1,1,0,0,0
0,0,0,0,0,0,2,1,1,0,0,0
0,0,1,1,0,0,0,0,1,1,0,0
0,0,1,1,1,0,0,1,1,1,0,0
0,0,1,1,1,0,0,1,1,1,0,0
0,0,0,0,0,0,0,0,0,0,0,0
0,0,0,0,0,0,0,0,0,0,0,0
endlayer



layer
0,0,0,0,0,0,0,0,0,0,0,0
0,0,0,0,0,0,0,0,0,0,0,0
0,0,1,1,1,0,0,1,1,1,0,0
0,0,1,1,1,1,1,1,1,1,0,0
0,0,1,1,0,0,0,0,1,1,0,0
0,0,0,1,0,0,2,1,1,0,0,0
0,0,0,1,0,0,2,1,1,0,0,0
0,0,1,1,0,0,0,0,1,1,0,0
0,0,1,1,1,1,1,1,1,1,0,0
0,0,1,1,1,0,0,1,1,1,0,0
0,0,0,0,0,0,0,0,0,0,0,0
0,0,0,0,0,0,0,0,0,0,0,0
endlayer



layer
0,0,0,0,0,0,0,0,0,0,0,0
0,0,0,0,0,0,0,0,0,0,0,0
0,0,1,1,1,0,0,1,1,1,0,0
0,0,1,1,1,1,1,1,1,1,0,0
0,0,1,1,1,1,1,1,1,1,0,0
0,0,0,1,1,1,2,1,1,0,0,0
0,0,0,1,1,1,2,1,1,0,0,0
0,0,1,1,1,1,1,1,1,1,0,0
0,0,1,1,1,1,1,1,1,1,0,0
0,0,1,1,1,0,0,1,1,1,0,0
0,0,0,0,0,0,0,0,0,0,0,0
0,0,0,0,0,0,0,0,0,0,0,0
endlayer



layer
0,0,0,0,0,0,0,0,0,0,0,0
0,0,0,0,0,0,0,0,0,0,0,0
0,0,1,1,1,0,0,1,1,1,0,0
0,0,1,1,1,1,1,1,1,1,0,0
0,0,1,1,0,0,0,0,1,1,0,0
0,0,0,1,0,0,2,1,1,0,0,0
0,0,0,1,0,0,2,1,1,0,0,0
0,0,1,1,0,0,0,0,1,1,0,0
0,0,1,1,1,1,1,1,1,1,0,0
0,0,1,1,1,0,0,1,1,1,0,0
0,0,0,0,0,0,0,0,0,0,0,0
0,0,0,0,0,0,0,0,0,0,0,0
endlayer



layer
0,0,0,0,0,0,0,0,0,0,0,0
0,0,0,0,0,0,0,0,0,0,0,0
0,0,1,1,1,0,0,1,1,1,0,0
0,0,1,1,1,0,0,1,1,1,0,0
0,0,1,1,0,0,0,0,1,1,0,0
0,0,0,0,0,0,2,1,1,0,0,0
0,0,0,0,0,0,2,1,1,0,0,0
0,0,1,1,0,0,0,0,1,1,0,0
0,0,1,1,1,0,0,1,1,1,0,0
0,0,1,1,1,0,0,1,1,1,0,0
0,0,0,0,0,0,0,0,0,0,0,0
0,0,0,0,0,0,0,0,0,0,0,0
endlayer



layer
0,0,0,0,0,0,0,0,0,0,0,0
0,0,0,0,0,0,0,0,0,0,0,0
0,0,1,1,1,0,0,1,1,1,0,0
0,0,1,1,1,1,1,1,1,1,0,0
0,0,1,1,0,0,0,0,1,1,0,0
0,0,0,1,0,0,2,1,1,0,0,0
0,0,0,1,0,0,2,1,1,0,0,0
0,0,1,1,0,0,0,0,1,1,0,0
0,0,1,1,1,1,1,1,1,1,0,0
0,0,1,1,1,0,0,1,1,1,0,0
0,0,0,0,0,0,0,0,0,0,0,0
0,0,0,0,0,0,0,0,0,0,0,0
endlayer



layer
0,0,0,0,0,0,0,0,0,0,0,0
0,0,0,0,0,0,0,0,0,0,0,0
0,0,1,1,1,0,0,1,1,1,0,0
0,0,1,1,1,1,1,1,1,1,0,0
0,0,1,1,1,1,1,1,1,1,0,0
0,0,0,1,1,1,2,1,1,0,0,0
0,0,0,1,1,1,2,1,1,0,0,0
0,0,1,1,1,1,1,1,1,1,0,0
0,0,1,1,1,1,1,1,1,1,0,0
0,0,1,1,1,0,0,1,1,1,0,0
0,0,0,0,0,0,0,0,0,0,0,0
0,0,0,0,0,0,0,0,0,0,0,0
endlayer



layer
0,0,0,0,0,0,0,0,0,0,0,0
0,0,0,0,0,0,0,0,0,0,0,0
0,0,1,1,1,0,0,1,1,1,0,0
0,0,1,1,1,1,1,1,1,1,0,0
0,0,1,1,0,0,0,0,1,1,0,0
0,0,0,1,0,0,2,1,1,0,0,0
0,0,0,1,0,0,2,1,1,0,0,0
0,0,1,1,0,0,0,0,1,1,0,0
0,0,1,1,1,1,1,1,1,1,0,0
0,0,1,1,1,0,0,1,1,1,0,0
0,0,0,0,0,0,0,0,0,0,0,0
0,0,0,0,0,0,0,0,0,0,0,0
endlayer



layer
0,0,0,0,0,0,0,0,0,0,0,0
0,1,1,0,0,0,0,0,0,1,1,0
0,1,1,1,1,0,0,1,1,1,1,0
0,0,1,1,1,0,0,1,1,1,0,0
0,0,1,1,0,0,0,0,1,1,0,0
0,0,0,0,0,0,2,1,1,0,0,0
0,0,0,0,0,0,2,1,1,0,0,0
0,0,1,1,0,0,0,0,1,1,0,0
0,0,1,1,1,0,0,1,1,1,0,0
0,1,1,1,1,0,0,1,1,1,1,0
0,1,1,0,0,0,0,0,0,1,1,0
0,0,0,0,0,0,0,0,0,0,0,0
endlayer



layer
0,0,0,0,0,0,0,0,0,0,0,0
0,1,1,1,0,0,0,0,1,1,1,0
0,1,1,1,1,0,0,1,1,1,1,0
0,1,1,1,1,1,1,1,1,1,1,0
0,0,1,1,0,0,0,0,1,1,0,0
0,0,0,1,0,0,2,1,1,0,0,0
0,0,0,1,0,0,2,1,1,0,0,0
0,0,1,1,0,0,0,0,1,1,0,0
0,1,1,1,1,1,1,1,1,1,1,0
0,1,1,1,1,0,0,1,1,1,1,0
0,1,1,1,0,0,0,0,1,1,1,0
0,0,0,0,0,0,0,0,0,0,0,0
endlayer



layer
1,1,1,0,0,0,0,0,0,1,1,1
1,1,1,1,0,0,0,0,1,1,1,1
1,1,1,1,1,0,0,1,1,1,1,1
0,1,1,1,1,1,1,1,1,1,1,0
0,0,1,1,1,1,1,1,1,1,0,0
0,0,0,1,1,1,2,1,1,0,0,0
0,0,0,1,1,1,2,1,1,0,0,0
0,0,1,1,1,1,1,1,1,1,0,0
0,1,1,1,1,1,1,1,1,1,1,0
1,1,1,1,1,0,0,1,1,1,1,1
1,1,1,1,0,0,0,0,1,1,1,1
1,1,1,0,0,0,0,0,0,1,1,1
endlayer



layer
1,1,0,0,0,0,0,0,0,0,1,1
1,1,1,1,0,0,0,0,1,1,1,1
0,1,1,1,1,0,0,1,1,1,1,0
0,1,1,1,1,0,0,1,1,1,1,0
0,0,1,1,0,0,0,0,1,1,0,0
0,0,0,0,0,0,0,0,0,0,0,0
0,0,0,0,0,0,0,0,0,0,0,0
0,0,1,1,0,0,0,0,1,1,0,0
0,1,1,1,1,0,0,1,1,1,1,0
0,1,1,1,1,0,0,1,1,1,1,0
1,1,1,1,0,0,0,0,1,1,1,1
1,1,0,0,0,0,0,0,0,0,1,1
endlayer



layer
0,1,0,0,0,0,0,0,0,0,1,0
1,1,1,0,0,0,0,0,0,1,1,1
0,1,1,1,0,0,0,0,1,1,1,0
0,0,1,1,0,0,0,0,1,1,0,0
0,0,0,0,0,0,0,0,0,0,0,0
0,0,0,0,0,0,0,0,0,0,0,0
0,0,0,0,0,0,0,0,0,0,0,0
0,0,0,0,0,0,0,0,0,0,0,0
0,0,1,1,0,0,0,0,1,1,0,0
0,1,1,1,0,0,0,0,1,1,1,0
1,1,1,0,0,0,0,0,0,1,1,1
0,1,0,0,0,0,0,0,0,0,1,0
endlayer



layer
0,0,0,0,0,0,0,0,0,0,0,0
0,1,1,0,0,0,0,0,0,1,1,0
0,1,1,1,0,0,0,0,1,1,1,0
0,0,1,1,0,0,0,0,1,1,0,0
0,0,0,0,0,0,0,0,0,0,0,0
0,0,0,0,0,0,0,0,0,0,0,0
0,0,0,0,0,0,0,0,0,0,0,0
0,0,0,0,0,0,0,0,0,0,0,0
0,0,1,1,0,0,0,0,1,1,0,0
0,1,1,1,0,0,0,0,1,1,1,0
0,1,1,0,0,0,0,0,0,1,1,0
0,0,0,0,0,0,0,0,0,0,0,0
endlayer



layer
0,0,0,0,0,0,0,0,0,0,0,0
0,1,1,0,0,0,0,0,0,1,1,0
0,1,1,1,0,0,0,0,1,1,1,0
0,0,1,0,0,0,0,0,0,1,0,0
0,0,0,0,0,0,0,0,0,0,0,0
0,0,0,0,0,0,0,0,0,0,0,0
0,0,0,0,0,0,0,0,0,0,0,0
0,0,0,0,0,0,0,0,0,0,0,0
0,0,1,0,0,0,0,0,0,1,0,0
0,1,1,1,0,0,0,0,1,1,1,0
0,1,1,0,0,0,0,0,0,1,1,0
0,0,0,0,0,0,0,0,0,0,0,0
endlayer



layer
0,0,0,0,0,0,0,0,0,0,0,0
0,1,1,0,0,0,0,0,0,1,1,0
0,1,1,1,0,0,0,0,1,1,1,0
0,0,1,0,0,0,0,0,0,1,0,0
0,0,0,0,0,0,0,0,0,0,0,0
0,0,0,0,0,0,0,0,0,0,0,0
0,0,0,0,0,0,0,0,0,0,0,0
0,0,0,0,0,0,0,0,0,0,0,0
0,0,1,0,0,0,0,0,0,1,0,0
0,1,1,1,0,0,0,0,1,1,1,0
0,1,1,0,0,0,0,0,0,1,1,0
0,0,0,0,0,0,0,0,0,0,0,0
endlayer



layer
0,0,0,0,0,0,0,0,0,0,0,0
0,0,1,0,0,0,0,0,0,1,0,0
0,1,1,0,0,0,0,0,0,1,1,0
0,0,0,0,0,0,0,0,0,0,0,0
0,0,0,0,0,0,0,0,0,0,0,0
0,0,0,0,0,0,0,0,0,0,0,0
0,0,0,0,0,0,0,0,0,0,0,0
0,0,0,0,0,0,0,0,0,0,0,0
0,0,0,0,0,0,0,0,0,0,0,0
0,1,1,0,0,0,0,0,0,1,1,0
0,0,1,0,0,0,0,0,0,1,0,0
0,0,0,0,0,0,0,0,0,0,0,0
endlayer



layer
0,0,0,0,0,0,0,0,0,0,0,0
0,0,0,0,0,0,0,0,0,0,0,0
0,0,1,0,0,0,0,0,0,1,0,0
0,0,0,0,0,0,0,0,0,0,0,0
0,0,0,0,0,0,0,0,0,0,0,0
0,0,0,0,0,0,0,0,0,0,0,0
0,0,0,0,0,0,0,0,0,0,0,0
0,0,0,0,0,0,0,0,0,0,0,0
0,0,0,0,0,0,0,0,0,0,0,0
0,0,1,0,0,0,0,0,0,1,0,0
0,0,0,0,0,0,0,0,0,0,0,0
0,0,0,0,0,0,0,0,0,0,0,0
endlayer



layer
0,0,0,0,0,0,0,0,0,0,0,0
0,0,0,0,0,0,0,0,0,0,0,0
0,0,1,0,0,0,0,0,0,1,0,0
0,0,0,0,0,0,0,0,0,0,0,0
0,0,0,0,0,0,0,0,0,0,0,0
0,0,0,0,0,0,0,0,0,0,0,0
0,0,0,0,0,0,0,0,0,0,0,0
0,0,0,0,0,0,0,0,0,0,0,0
0,0,0,0,0,0,0,0,0,0,0,0
0,0,1,0,0,0,0,0,0,1,0,0
0,0,0,0,0,0,0,0,0,0,0,0
0,0,0,0,0,0,0,0,0,0,0,0
endlayer



layer
0,0,0,0,0,0,0,0,0,0,0,0
0,0,0,0,0,0,0,0,0,0,0,0
0,0,1,0,0,0,0,0,0,1,0,0
0,0,0,0,0,0,0,0,0,0,0,0
0,0,0,0,0,0,0,0,0,0,0,0
0,0,0,0,0,0,0,0,0,0,0,0
0,0,0,0,0,0,0,0,0,0,0,0
0,0,0,0,0,0,0,0,0,0,0,0
0,0,0,0,0,0,0,0,0,0,0,0
0,0,1,0,0,0,0,0,0,1,0,0
0,0,0,0,0,0,0,0,0,0,0,0
0,0,0,0,0,0,0,0,0,0,0,0
endlayer
