biomesToSpawnIn=desert,desert oil field,deserthills,dunes,lush desert,mountainous desert,desert_hills,desert_defiled,desert_shrubland,mutated_desert
weight=5
uniqueMinDistance=1000
embed_into_distance=1
unacceptable_target_blocks=flowing_water,water,flowing_lava,lava,Natura:Cloud,red_mushroom_block,brown_mushroom_block,planks,cobblestone,end_stone,obsidian,purpur_block,iron_bars,purpur_slab,purpur_pillar,netherrack,soul_sand,quartz_ore
dimensions=7,42,19
max_leveling=2
cut_in_buffer=0
leveling_buffer=0
preserve_water=0
preserve_lava=0
preserve_plants=0
max_cut_in=10



rule1=0,100,sand
rule2=0,100,sandstone
rule3=0,100,MediumMobSpawn,MediumMobSpawn,MediumMobSpawn,sandstone
rule4=0,100,MediumChest,MediumChest,sandstone,sandstone
rule5=0,100,sandstone-2
rule6=0,100,stone_slab-1
rule7=0,100,sandstone-1


layer
1,1,1,1,1,1,1,1,1,1,1,1,1,1,1,1,1,1,1
1,1,1,2,2,2,2,2,2,2,2,2,2,2,2,2,1,1,1
1,1,2,2,2,2,2,2,2,2,2,2,2,2,2,2,2,1,1
1,2,2,2,2,2,2,2,2,2,2,2,2,2,2,2,2,2,1
1,2,2,2,2,2,2,2,2,2,2,2,2,2,2,2,2,2,1
1,2,2,2,2,2,2,2,2,2,2,2,2,2,2,2,2,2,1
1,2,2,2,2,2,2,2,2,2,2,2,2,2,2,2,2,2,1
1,2,2,2,2,2,2,2,2,2,2,2,2,2,2,2,2,2,1
1,2,2,2,2,2,2,2,2,2,2,2,2,2,2,2,2,2,1
1,2,2,2,2,2,2,2,2,2,2,2,2,2,2,2,2,2,1
1,2,2,2,2,2,2,2,2,2,2,2,2,2,2,2,2,2,1
1,2,2,2,2,2,2,2,2,2,2,2,2,2,2,2,2,2,1
1,2,2,2,2,2,2,2,2,2,2,2,2,2,2,2,2,2,1
1,2,2,2,2,2,2,2,2,2,2,2,2,2,2,2,2,2,1
1,2,2,2,2,2,2,2,2,2,2,2,2,2,2,2,2,2,1
1,2,2,2,2,2,2,2,2,2,2,2,2,2,2,2,2,2,1
1,2,2,2,2,2,2,2,2,2,2,2,2,2,2,2,2,2,1
1,2,2,2,2,2,2,2,2,2,2,2,2,2,2,2,2,2,1
1,2,2,2,2,3,2,2,2,2,2,2,2,4,2,2,2,2,1
1,2,2,2,2,4,2,2,2,2,2,2,2,3,2,2,2,2,1
1,2,2,2,2,2,2,2,2,2,2,2,2,2,2,2,2,2,1
1,2,2,2,2,2,2,2,2,2,2,2,2,2,2,2,2,2,1
1,2,2,2,2,2,2,2,2,2,2,2,2,2,2,2,2,2,1
1,2,2,2,2,2,2,2,2,2,2,2,2,2,2,2,2,2,1
1,2,2,2,2,2,2,2,2,2,2,2,2,2,2,2,2,2,1
1,2,2,2,2,4,2,2,2,2,2,2,2,3,2,2,2,2,1
1,2,2,2,2,3,2,2,2,2,2,2,2,4,2,2,2,2,1
1,2,2,2,2,2,2,2,2,2,2,2,2,2,2,2,2,2,1
1,2,2,2,2,2,2,2,2,2,2,2,2,2,2,2,2,2,1
1,2,2,2,2,2,2,2,2,2,2,2,2,2,2,2,2,2,1
1,2,2,2,2,2,2,2,2,2,2,2,2,2,2,2,2,2,1
1,2,2,2,2,2,2,2,2,2,2,2,2,2,2,2,2,2,1
1,2,2,2,2,2,2,2,2,2,2,2,2,2,2,2,2,2,1
1,2,2,2,2,2,2,2,2,2,2,2,2,2,2,2,2,2,1
1,2,2,2,2,2,2,2,2,2,2,2,2,2,2,2,2,2,1
1,2,2,2,2,2,2,2,2,2,2,2,2,2,2,2,2,2,1
1,2,2,2,2,2,2,2,2,2,2,2,2,2,2,2,2,2,1
1,2,2,2,2,2,2,2,2,2,2,2,2,2,2,2,2,2,1
1,2,2,2,2,2,2,2,2,2,2,2,2,2,2,2,2,2,1
1,1,2,2,2,2,2,2,2,2,2,2,2,2,2,2,2,1,1
1,1,1,2,2,2,2,2,2,2,2,2,2,2,2,2,1,1,1
1,1,1,1,1,1,1,1,1,1,1,1,1,1,1,1,1,1,1
endlayer

layer
0,0,0,0,0,0,0,0,0,0,0,0,0,0,0,0,0,0,0
0,0,0,1,1,1,1,1,1,1,1,1,1,1,1,1,0,0,0
0,0,1,2,2,2,2,2,2,2,2,2,2,2,2,2,1,0,0
0,1,1,2,2,2,2,2,2,2,2,2,2,2,2,2,1,1,0
0,1,2,2,2,2,2,2,2,2,2,2,2,2,2,2,2,1,0
0,1,2,2,2,2,2,2,2,2,2,2,2,2,2,2,2,1,0
0,1,2,2,2,2,2,2,2,2,2,2,2,2,2,2,2,1,0
0,1,2,2,2,2,2,2,2,2,2,2,2,2,2,2,2,1,0
0,1,2,2,2,2,5,5,5,5,5,5,5,2,2,2,2,1,0
0,1,2,2,2,5,7,0,0,7,0,0,7,5,2,2,2,1,0
0,1,2,2,2,5,0,0,0,0,0,0,0,5,2,2,2,1,0
0,1,2,2,2,5,0,0,0,0,0,0,0,5,2,2,2,1,0
0,1,2,2,2,5,0,0,0,0,0,0,0,5,2,2,2,1,0
0,1,2,2,2,2,5,7,0,0,0,7,5,2,2,2,2,1,0
0,1,2,2,2,2,5,0,0,0,0,0,5,2,2,2,2,1,0
0,1,2,2,2,2,5,0,0,0,0,0,5,2,2,2,2,1,0
0,1,2,2,2,5,5,0,0,0,0,0,5,5,2,2,2,1,0
0,1,2,2,5,0,0,7,0,0,0,7,0,0,5,2,2,1,0
0,1,2,5,5,6,0,0,0,0,0,0,0,6,5,5,2,1,0
0,1,2,5,5,6,0,0,0,0,0,0,0,6,5,5,2,1,0
0,1,2,2,5,0,0,7,0,0,0,7,0,0,5,2,2,1,0
0,1,2,2,2,5,5,0,0,0,0,0,5,5,2,2,2,1,0
0,1,2,2,2,2,5,0,0,0,0,0,5,2,2,2,2,1,0
0,1,2,2,2,5,5,0,0,0,0,0,5,5,2,2,2,1,0
0,1,2,2,5,0,0,7,0,0,0,7,0,0,5,2,2,1,0
0,1,2,5,5,6,0,0,0,0,0,0,0,6,5,5,2,1,0
0,1,2,5,5,6,0,0,0,0,0,0,0,6,5,5,2,1,0
0,1,2,2,5,0,0,7,0,0,0,7,0,0,5,2,2,1,0
0,1,2,2,2,5,5,0,0,0,0,0,5,5,2,2,2,1,0
0,1,2,2,2,2,5,0,0,0,0,0,5,2,2,2,2,1,0
0,1,2,2,2,2,5,0,0,0,0,0,5,2,2,2,2,1,0
0,1,2,2,2,2,5,7,0,0,0,7,5,2,2,2,2,1,0
0,1,2,2,2,5,0,0,0,0,0,0,0,5,2,2,2,1,0
0,1,2,2,2,5,0,0,0,0,0,0,0,5,2,2,2,1,0
0,1,2,2,2,5,0,0,0,0,0,0,0,5,2,2,2,1,0
0,1,2,2,2,5,7,0,0,7,0,0,7,5,2,2,2,1,0
0,1,2,2,2,2,5,5,5,5,5,5,5,2,2,2,2,1,0
0,1,2,2,2,2,2,2,2,2,2,2,2,2,2,2,2,1,0
0,1,1,2,2,2,2,2,2,2,2,2,2,2,2,2,1,1,0
0,0,1,2,2,2,2,2,2,2,2,2,2,2,2,2,1,0,0
0,0,0,1,1,1,1,1,1,1,1,1,1,1,1,1,0,0,0
0,0,0,0,0,0,0,0,0,0,0,0,0,0,0,0,0,0,0
endlayer

layer
0,0,0,0,0,0,0,0,0,0,0,0,0,0,0,0,0,0,0
0,0,0,0,0,0,0,0,0,0,0,0,0,0,0,0,0,0,0
0,0,0,1,1,1,1,1,1,1,1,1,1,1,1,1,0,0,0
0,0,0,1,1,1,1,1,1,1,1,1,1,1,1,1,0,0,0
0,0,1,1,2,2,2,2,2,2,2,2,2,2,2,1,1,0,0
0,0,1,2,2,2,2,2,2,2,2,2,2,2,2,2,1,0,0
0,0,1,2,2,2,2,2,2,2,2,2,2,2,2,2,1,0,0
0,0,1,2,2,2,2,2,2,2,2,2,2,2,2,2,1,0,0
0,0,1,2,2,2,5,5,5,5,5,5,5,2,2,2,1,0,0
0,0,1,2,2,5,7,0,0,7,0,0,7,5,2,2,1,0,0
0,0,1,2,2,5,0,0,0,0,0,0,0,5,2,2,1,0,0
0,0,1,2,2,5,0,0,0,0,0,0,0,5,2,2,1,0,0
0,0,1,2,2,5,0,0,0,0,0,0,0,5,2,2,1,0,0
0,0,1,2,2,2,5,7,0,0,0,7,5,2,2,2,1,0,0
0,0,1,2,2,2,5,0,0,0,0,0,5,2,2,2,1,0,0
0,0,1,2,2,2,5,0,0,0,0,0,5,2,2,2,1,0,0
0,0,1,2,2,5,5,0,0,0,0,0,5,5,2,2,1,0,0
0,0,1,2,5,0,0,7,0,0,0,7,0,0,5,2,1,0,0
0,0,1,5,0,0,0,0,0,0,0,0,0,0,0,5,1,0,0
0,0,1,5,0,0,0,0,0,0,0,0,0,0,0,5,1,0,0
0,0,1,2,5,0,0,7,0,0,0,7,0,0,5,2,1,0,0
0,0,1,2,2,5,5,0,0,0,0,0,5,5,2,2,1,0,0
0,0,1,2,2,2,5,0,0,0,0,0,5,2,2,2,1,0,0
0,0,1,2,2,5,5,0,0,0,0,0,5,5,2,2,1,0,0
0,0,1,2,5,0,0,7,0,0,0,7,0,0,5,2,1,0,0
0,0,1,5,0,0,0,0,0,0,0,0,0,0,0,5,1,0,0
0,0,1,5,0,0,0,0,0,0,0,0,0,0,0,5,1,0,0
0,0,1,2,5,0,0,7,0,0,0,7,0,0,5,2,1,0,0
0,0,1,2,2,5,5,0,0,0,0,0,5,5,2,2,1,0,0
0,0,1,2,2,2,5,0,0,0,0,0,5,2,2,2,1,0,0
0,0,1,2,2,2,5,0,0,0,0,0,5,2,2,2,1,0,0
0,0,1,2,2,2,5,7,0,0,0,7,5,2,2,2,1,0,0
0,0,1,2,2,5,0,0,0,0,0,0,0,5,2,2,1,0,0
0,0,1,2,2,5,0,0,0,0,0,0,0,5,2,2,1,0,0
0,0,1,2,2,5,0,0,0,0,0,0,0,5,2,2,1,0,0
0,0,1,2,2,5,7,0,0,7,0,0,7,5,2,2,1,0,0
0,0,1,2,2,2,5,5,5,5,5,5,5,2,2,2,1,0,0
0,0,1,1,2,2,2,2,2,2,2,2,2,2,2,1,1,0,0
0,0,0,1,1,1,1,1,1,1,1,1,1,1,1,1,0,0,0
0,0,0,1,1,1,1,1,1,1,1,1,1,1,1,1,0,0,0
0,0,0,0,0,0,0,0,0,0,0,0,0,0,0,0,0,0,0
0,0,0,0,0,0,0,0,0,0,0,0,0,0,0,0,0,0,0
endlayer

layer
0,0,0,0,0,0,0,0,0,0,0,0,0,0,0,0,0,0,0
0,0,0,0,0,0,0,0,0,0,0,0,0,0,0,0,0,0,0
0,0,0,0,0,0,0,0,0,0,0,0,0,0,0,0,0,0,0
0,0,0,0,0,0,0,0,0,0,0,0,0,0,0,0,0,0,0
0,0,0,0,1,1,1,1,1,1,1,1,1,1,1,0,0,0,0
0,0,0,1,1,2,2,2,2,2,2,2,2,2,1,1,0,0,0
0,0,0,1,2,2,2,2,2,2,2,2,2,2,2,1,0,0,0
0,0,0,1,2,2,2,2,2,2,2,2,2,2,2,1,0,0,0
0,0,0,1,2,2,2,2,2,2,2,2,2,2,2,1,0,0,0
0,0,0,1,2,2,5,5,5,5,5,5,5,2,2,1,0,0,0
0,0,0,1,2,2,5,5,5,5,5,5,5,2,2,1,0,0,0
0,0,0,1,2,2,5,5,5,5,5,5,5,2,2,1,0,0,0
0,0,0,1,2,2,5,5,5,5,5,5,5,2,2,1,0,0,0
0,0,0,1,2,2,2,5,5,5,5,5,2,2,2,1,0,0,0
0,0,0,1,2,2,2,5,5,5,5,5,2,2,2,1,0,0,0
0,0,0,1,2,2,2,5,5,5,5,5,2,2,2,1,0,0,0
0,0,0,1,2,2,2,5,5,5,5,5,2,2,2,1,0,0,0
0,0,0,1,2,5,5,5,5,5,5,5,5,5,2,1,0,0,0
0,0,0,1,5,5,5,5,5,5,5,5,5,5,5,1,0,0,0
0,0,0,1,5,5,5,5,5,5,5,5,5,5,5,1,0,0,0
0,0,0,1,2,5,5,5,5,5,5,5,5,5,2,1,0,0,0
0,0,0,1,2,2,2,5,5,5,5,5,2,2,2,1,0,0,0
0,0,0,1,2,2,2,5,5,5,5,5,2,2,2,1,0,0,0
0,0,0,1,2,2,2,5,5,5,5,5,2,2,2,1,0,0,0
0,0,0,1,2,5,5,5,5,5,5,5,5,5,2,1,0,0,0
0,0,0,1,5,5,5,5,5,5,5,5,5,5,5,1,0,0,0
0,0,0,1,5,5,5,5,5,5,5,5,5,5,5,1,0,0,0
0,0,0,1,2,5,5,5,5,5,5,5,5,5,2,1,0,0,0
0,0,0,1,2,2,2,5,5,5,5,5,2,2,2,1,0,0,0
0,0,0,1,2,2,2,5,5,5,5,5,2,2,2,1,0,0,0
0,0,0,1,2,2,2,5,5,5,5,5,2,2,2,1,0,0,0
0,0,0,1,2,2,2,5,5,5,5,5,2,2,2,1,0,0,0
0,0,0,1,2,2,5,5,5,5,5,5,5,2,2,1,0,0,0
0,0,0,1,2,2,5,5,5,5,5,5,5,2,2,1,0,0,0
0,0,0,1,2,2,5,5,5,5,5,5,5,2,2,1,0,0,0
0,0,0,1,2,2,5,5,5,5,5,5,5,2,2,1,0,0,0
0,0,0,1,1,2,2,2,2,2,2,2,2,2,1,1,0,0,0
0,0,0,0,1,1,1,1,1,1,1,1,1,1,1,0,0,0,0
0,0,0,0,0,0,0,0,0,0,0,0,0,0,0,0,0,0,0
0,0,0,0,0,0,0,0,0,0,0,0,0,0,0,0,0,0,0
0,0,0,0,0,0,0,0,0,0,0,0,0,0,0,0,0,0,0
0,0,0,0,0,0,0,0,0,0,0,0,0,0,0,0,0,0,0
endlayer

layer
0,0,0,0,0,0,0,0,0,0,0,0,0,0,0,0,0,0,0
0,0,0,0,0,0,0,0,0,0,0,0,0,0,0,0,0,0,0
0,0,0,0,0,0,0,0,0,0,0,0,0,0,0,0,0,0,0
0,0,0,0,0,0,0,0,0,0,0,0,0,0,0,0,0,0,0
0,0,0,0,0,0,0,0,0,0,0,0,0,0,0,0,0,0,0
0,0,0,0,0,1,1,1,1,1,1,1,1,1,0,0,0,0,0
0,0,0,0,1,1,1,1,1,1,1,1,1,1,1,0,0,0,0
0,0,0,0,1,2,2,2,2,2,2,2,2,2,1,0,0,0,0
0,0,0,0,1,2,2,2,2,2,2,2,2,2,1,0,0,0,0
0,0,0,0,1,2,2,2,2,2,2,2,2,2,1,0,0,0,0
0,0,0,0,1,2,2,2,2,2,2,2,2,2,1,0,0,0,0
0,0,0,0,1,2,2,2,2,2,2,2,2,2,1,0,0,0,0
0,0,0,0,1,2,2,2,2,2,2,2,2,2,1,0,0,0,0
0,0,0,0,1,2,2,2,2,2,2,2,2,2,1,0,0,0,0
0,0,0,0,1,2,2,2,2,2,2,2,2,2,1,0,0,0,0
0,0,0,0,1,2,2,2,2,2,2,2,2,2,1,0,0,0,0
0,0,0,0,1,2,2,2,2,2,2,2,2,2,1,0,0,0,0
0,0,0,0,1,2,2,2,2,2,2,2,2,2,1,0,0,0,0
0,0,0,0,1,2,2,2,2,2,2,2,2,2,1,0,0,0,0
0,0,0,0,1,2,2,2,2,2,2,2,2,2,1,0,0,0,0
0,0,0,0,1,2,2,2,2,2,2,2,2,2,1,0,0,0,0
0,0,0,0,1,2,2,2,2,2,2,2,2,2,1,0,0,0,0
0,0,0,0,1,2,2,2,2,2,2,2,2,2,1,0,0,0,0
0,0,0,0,1,2,2,2,2,2,2,2,2,2,1,0,0,0,0
0,0,0,0,1,2,2,2,2,2,2,2,2,2,1,0,0,0,0
0,0,0,0,1,2,2,2,2,2,2,2,2,2,1,0,0,0,0
0,0,0,0,1,2,2,2,2,2,2,2,2,2,1,0,0,0,0
0,0,0,0,1,2,2,2,2,2,2,2,2,2,1,0,0,0,0
0,0,0,0,1,2,2,2,2,2,2,2,2,2,1,0,0,0,0
0,0,0,0,1,2,2,2,2,2,2,2,2,2,1,0,0,0,0
0,0,0,0,1,2,2,2,2,2,2,2,2,2,1,0,0,0,0
0,0,0,0,1,2,2,2,2,2,2,2,2,2,1,0,0,0,0
0,0,0,0,1,2,2,2,2,2,2,2,2,2,1,0,0,0,0
0,0,0,0,1,2,2,2,2,2,2,2,2,2,1,0,0,0,0
0,0,0,0,1,2,2,2,2,2,2,2,2,2,1,0,0,0,0
0,0,0,0,1,1,1,1,1,1,1,1,1,1,1,0,0,0,0
0,0,0,0,0,1,1,1,1,1,1,1,1,1,0,0,0,0,0
0,0,0,0,0,0,0,0,0,0,0,0,0,0,0,0,0,0,0
0,0,0,0,0,0,0,0,0,0,0,0,0,0,0,0,0,0,0
0,0,0,0,0,0,0,0,0,0,0,0,0,0,0,0,0,0,0
0,0,0,0,0,0,0,0,0,0,0,0,0,0,0,0,0,0,0
0,0,0,0,0,0,0,0,0,0,0,0,0,0,0,0,0,0,0
endlayer

layer
0,0,0,0,0,0,0,0,0,0,0,0,0,0,0,0,0,0,0
0,0,0,0,0,0,0,0,0,0,0,0,0,0,0,0,0,0,0
0,0,0,0,0,0,0,0,0,0,0,0,0,0,0,0,0,0,0
0,0,0,0,0,0,0,0,0,0,0,0,0,0,0,0,0,0,0
0,0,0,0,0,0,0,0,0,0,0,0,0,0,0,0,0,0,0
0,0,0,0,0,0,0,0,0,0,0,0,0,0,0,0,0,0,0
0,0,0,0,0,0,0,0,0,0,0,0,0,0,0,0,0,0,0
0,0,0,0,0,1,1,1,1,1,1,1,1,1,0,0,0,0,0
0,0,0,0,0,1,2,2,2,2,2,2,2,1,0,0,0,0,0
0,0,0,0,0,1,2,2,2,2,2,2,2,1,0,0,0,0,0
0,0,0,0,0,1,2,2,2,2,2,2,2,1,0,0,0,0,0
0,0,0,0,0,1,2,2,2,2,2,2,2,1,0,0,0,0,0
0,0,0,0,0,1,2,2,2,2,2,2,2,1,0,0,0,0,0
0,0,0,0,0,1,2,2,2,2,2,2,2,1,0,0,0,0,0
0,0,0,0,0,1,2,2,2,2,2,2,2,1,0,0,0,0,0
0,0,0,0,0,1,2,2,2,2,2,2,2,1,0,0,0,0,0
0,0,0,0,0,1,2,2,2,2,2,2,2,1,0,0,0,0,0
0,0,0,0,0,1,2,2,2,2,2,2,2,1,0,0,0,0,0
0,0,0,0,0,1,2,2,2,2,2,2,2,1,0,0,0,0,0
0,0,0,0,0,1,2,2,2,2,2,2,2,1,0,0,0,0,0
0,0,0,0,0,1,2,2,2,2,2,2,2,1,0,0,0,0,0
0,0,0,0,0,1,2,2,2,2,2,2,2,1,0,0,0,0,0
0,0,0,0,0,1,2,2,2,2,2,2,2,1,0,0,0,0,0
0,0,0,0,0,1,2,2,2,2,2,2,2,1,0,0,0,0,0
0,0,0,0,0,1,2,2,2,2,2,2,2,1,0,0,0,0,0
0,0,0,0,0,1,2,2,2,2,2,2,2,1,0,0,0,0,0
0,0,0,0,0,1,2,2,2,2,2,2,2,1,0,0,0,0,0
0,0,0,0,0,1,2,2,2,2,2,2,2,1,0,0,0,0,0
0,0,0,0,0,1,2,2,2,2,2,2,2,1,0,0,0,0,0
0,0,0,0,0,1,2,2,2,2,2,2,2,1,0,0,0,0,0
0,0,0,0,0,1,2,2,2,2,2,2,2,1,0,0,0,0,0
0,0,0,0,0,1,2,2,2,2,2,2,2,1,0,0,0,0,0
0,0,0,0,0,1,2,2,2,2,2,2,2,1,0,0,0,0,0
0,0,0,0,0,1,2,2,2,2,2,2,2,1,0,0,0,0,0
0,0,0,0,0,1,1,1,1,1,1,1,1,1,0,0,0,0,0
0,0,0,0,0,0,0,0,0,0,0,0,0,0,0,0,0,0,0
0,0,0,0,0,0,0,0,0,0,0,0,0,0,0,0,0,0,0
0,0,0,0,0,0,0,0,0,0,0,0,0,0,0,0,0,0,0
0,0,0,0,0,0,0,0,0,0,0,0,0,0,0,0,0,0,0
0,0,0,0,0,0,0,0,0,0,0,0,0,0,0,0,0,0,0
0,0,0,0,0,0,0,0,0,0,0,0,0,0,0,0,0,0,0
0,0,0,0,0,0,0,0,0,0,0,0,0,0,0,0,0,0,0
endlayer

layer
0,0,0,0,0,0,0,0,0,0,0,0,0,0,0,0,0,0,0
0,0,0,0,0,0,0,0,0,0,0,0,0,0,0,0,0,0,0
0,0,0,0,0,0,0,0,0,0,0,0,0,0,0,0,0,0,0
0,0,0,0,0,0,0,0,0,0,0,0,0,0,0,0,0,0,0
0,0,0,0,0,0,0,0,0,0,0,0,0,0,0,0,0,0,0
0,0,0,0,0,0,0,0,0,0,0,0,0,0,0,0,0,0,0
0,0,0,0,0,0,0,0,0,0,0,0,0,0,0,0,0,0,0
0,0,0,0,0,0,0,0,0,0,0,0,0,0,0,0,0,0,0
0,0,0,0,0,0,1,1,1,1,1,1,1,0,0,0,0,0,0
0,0,0,0,0,0,1,1,1,1,1,1,1,0,0,0,0,0,0
0,0,0,0,0,0,1,1,1,1,1,1,1,0,0,0,0,0,0
0,0,0,0,0,0,1,1,1,1,1,1,1,0,0,0,0,0,0
0,0,0,0,0,0,1,1,1,1,1,1,1,0,0,0,0,0,0
0,0,0,0,0,0,1,1,1,1,1,1,1,0,0,0,0,0,0
0,0,0,0,0,0,1,1,1,1,1,1,1,0,0,0,0,0,0
0,0,0,0,0,0,1,1,1,1,1,1,1,0,0,0,0,0,0
0,0,0,0,0,0,1,1,1,1,1,1,1,0,0,0,0,0,0
0,0,0,0,0,0,1,1,1,1,1,1,1,0,0,0,0,0,0
0,0,0,0,0,0,1,1,1,1,1,1,1,0,0,0,0,0,0
0,0,0,0,0,0,1,1,1,1,1,1,1,0,0,0,0,0,0
0,0,0,0,0,0,1,1,1,1,1,1,1,0,0,0,0,0,0
0,0,0,0,0,0,1,1,1,1,1,1,1,0,0,0,0,0,0
0,0,0,0,0,0,1,1,1,1,1,1,1,0,0,0,0,0,0
0,0,0,0,0,0,1,1,1,1,1,1,1,0,0,0,0,0,0
0,0,0,0,0,0,1,1,1,1,1,1,1,0,0,0,0,0,0
0,0,0,0,0,0,1,1,1,1,1,1,1,0,0,0,0,0,0
0,0,0,0,0,0,1,1,1,1,1,1,1,0,0,0,0,0,0
0,0,0,0,0,0,1,1,1,1,1,1,1,0,0,0,0,0,0
0,0,0,0,0,0,1,1,1,1,1,1,1,0,0,0,0,0,0
0,0,0,0,0,0,1,1,1,1,1,1,1,0,0,0,0,0,0
0,0,0,0,0,0,1,1,1,1,1,1,1,0,0,0,0,0,0
0,0,0,0,0,0,1,1,1,1,1,1,1,0,0,0,0,0,0
0,0,0,0,0,0,1,1,1,1,1,1,1,0,0,0,0,0,0
0,0,0,0,0,0,1,1,1,1,1,1,1,0,0,0,0,0,0
0,0,0,0,0,0,0,0,0,0,0,0,0,0,0,0,0,0,0
0,0,0,0,0,0,0,0,0,0,0,0,0,0,0,0,0,0,0
0,0,0,0,0,0,0,0,0,0,0,0,0,0,0,0,0,0,0
0,0,0,0,0,0,0,0,0,0,0,0,0,0,0,0,0,0,0
0,0,0,0,0,0,0,0,0,0,0,0,0,0,0,0,0,0,0
0,0,0,0,0,0,0,0,0,0,0,0,0,0,0,0,0,0,0
0,0,0,0,0,0,0,0,0,0,0,0,0,0,0,0,0,0,0
0,0,0,0,0,0,0,0,0,0,0,0,0,0,0,0,0,0,0
endlayer

