# Author: Arrrg
# From: Minecraft Forums

biomesToSpawnIn=desert,desert oil field,deserthills,dunes,lush desert,mountainous desert,desert_hills,desert_defiled,desert_shrubland,mutated_desert
weight=4
uniqueMinDistance=2000
embed_into_distance=62
unacceptable_target_blocks=flowing_water,water,flowing_lava,lava,Natura:Cloud,red_mushroom_block,brown_mushroom_block,planks,cobblestone,end_stone,obsidian,purpur_block,iron_bars,purpur_slab,purpur_pillar,netherrack,soul_sand,quartz_ore
dimensions=69,5,5
allowable_overhang=10
max_cut_in=0
cut_in_buffer=0
max_leveling=1
leveling_buffer=0
preserve_water=0
preserve_lava=0
preserve_plants=0

rule1=0,100,preserveBlock
rule2=1,75,stone_slab-2
rule3=2,100,torch
rule4=0,100,cobblestone,mossy_cobblestone,mossy_cobblestone
rule5=0,90,planks
rule6=2,90,oak_stairs-0
rule7=2,90,oak_stairs-1
rule8=0,100,flowing_water
rule9=0,100,glass
rule10=0,100,stone_slab-3
rule11=2,100,ladder-2
rule12=2,100,ladder-3
rule13=0,100,gravel
rule14=0,100,diamond_ore

layer
1,1,1,1,1
1,1,1,1,1
1,0,1,1,1
1,1,1,1,1
1,1,1,1,1
endlayer
 
layer
1,1,1,1,1
1,1,0,1,1
1,0,1,0,1
1,0,0,1,1
1,1,1,1,1
endlayer
 
layer
1,1,1,1,1
1,0,0,0,1
1,0,0,0,1
1,0,0,0,1
1,1,1,1,1
endlayer
 
layer
10,10,10,10,10
10,0,0,0,10
10,0,0,0,10
10,0,0,0,10
10,10,10,10,10
endlayer
 
layer
0,0,0,0,0
0,0,0,0,0
0,0,0,0,0
0,0,0,0,0
0,0,0,0,0
endlayer
 
layer
0,0,0,0,0
0,0,0,0,0
0,0,0,0,0
0,0,0,0,0
0,0,0,0,0
endlayer
 
layer
3,1,1,1,3
1,8,8,8,1
1,8,8,8,1
1,8,8,8,1
3,1,1,1,3
endlayer
 
layer
1,1,1,1,1
1,0,0,0,1
1,0,0,0,1
1,0,0,0,1
1,1,1,1,1
endlayer
 
layer
1,1,1,1,1
1,0,0,0,1
1,0,0,0,1
1,0,0,0,1
1,1,1,1,1
endlayer
 
layer
1,1,1,1,1
1,0,0,0,1
1,0,0,0,1
1,0,0,0,1
1,1,1,1,1
endlayer
 
layer
1,1,1,1,1
1,0,0,0,1
1,0,0,0,1
1,0,0,0,1
1,1,1,1,1
endlayer
 
layer
1,1,1,1,1
1,0,0,0,1
0,0,0,0,0
1,0,0,0,1
1,1,1,1,1
endlayer
 
layer
1,1,1,1,1
1,0,0,0,1
1,0,0,0,1
1,0,0,0,1
1,1,1,1,1
endlayer
 
layer
1,1,1,1,1
1,0,0,0,1
1,0,0,0,1
1,0,0,0,1
1,1,1,1,1
endlayer
 
layer
1,1,1,1,1
1,0,0,0,1
1,0,0,0,1
1,0,0,0,1
1,1,1,1,1
endlayer
 
layer
1,1,1,1,1
1,0,0,0,1
1,0,0,0,1
1,0,0,0,1
1,1,1,1,1
endlayer
 
layer
1,1,1,1,1
1,0,0,0,1
1,0,0,0,1
1,0,0,0,1
1,1,1,1,1
endlayer
 
layer
1,1,1,1,1
1,0,0,0,1
1,0,0,0,1
1,0,0,0,1
1,1,1,1,1
endlayer
 
layer
1,1,1,1,1
1,0,0,0,1
1,0,0,0,1
1,0,0,0,1
1,1,1,1,1
endlayer
 
layer
1,1,1,1,1
1,0,0,0,1
1,0,0,0,1
1,0,0,0,1
1,1,1,1,1
endlayer
 
layer
1,1,1,1,1
1,0,0,0,1
1,0,0,0,1
1,0,0,0,1
1,1,1,1,1
endlayer
 
layer
1,1,1,1,1
1,0,0,0,1
1,0,0,0,1
1,0,0,0,1
1,1,1,1,1
endlayer
 
layer
1,1,1,1,1
1,0,0,0,1
1,0,0,0,1
1,0,0,0,1
1,1,1,1,1
endlayer
 
layer
1,1,1,1,1
1,0,0,0,1
1,0,0,0,1
1,0,0,0,1
1,1,1,1,1
endlayer
 
layer
1,1,1,1,1
1,0,0,0,1
1,0,0,0,1
1,0,0,0,1
1,1,1,1,1
endlayer
 
layer
1,1,1,1,1
1,0,0,0,1
1,0,0,0,1
1,0,0,0,1
1,1,1,1,1
endlayer
 
layer
1,1,1,1,1
1,0,0,0,1
1,0,0,0,1
1,0,0,0,1
1,1,1,1,1
endlayer
 
layer
1,1,1,1,1
1,0,0,0,1
1,0,0,0,1
1,0,0,0,1
1,1,1,1,1
endlayer
 
layer
1,1,1,1,1
1,0,0,0,1
1,0,0,0,1
1,0,0,0,1
1,1,1,1,1
endlayer
 
layer
1,1,1,1,1
1,0,0,0,1
1,0,0,0,1
1,0,0,0,1
1,1,1,1,1
endlayer
 
layer
1,1,1,1,1
1,0,0,0,1
1,0,0,0,1
1,0,0,0,1
1,1,1,1,1
endlayer
 
layer
1,1,1,1,1
1,0,0,0,1
1,0,0,0,1
1,0,0,0,1
1,1,1,1,1
endlayer
 
layer
1,1,1,1,1
1,0,0,0,1
1,0,0,0,1
1,0,0,0,1
1,1,1,1,1
endlayer
 
layer
1,1,1,1,1
1,0,0,0,1
1,0,0,0,1
1,0,0,0,1
1,1,1,1,1
endlayer
 
layer
1,1,1,1,1
1,0,0,0,1
1,0,0,0,1
1,0,0,0,1
1,1,1,1,1
endlayer
 
layer
1,1,1,1,1
1,0,0,0,1
1,0,0,0,1
1,0,0,0,1
1,1,1,1,1
endlayer
 
layer
1,1,1,1,1
1,0,0,0,1
1,0,0,0,1
0,3,0,0,1
1,1,1,1,1
endlayer
 
layer
1,1,1,1,1
1,0,0,0,1
1,3,0,0,1
0,13,0,0,1
1,1,0,1,1
endlayer
 
layer
1,1,1,1,1
1,0,0,0,1
1,13,3,0,1
0,0,0,0,1
1,1,1,1,1
endlayer
 
layer
1,1,1,1,1
1,0,0,0,1
1,0,13,0,1
0,0,0,0,1
1,1,1,1,1
endlayer

layer
1,4,4,4,1
4,0,3,0,4
4,3,0,3,4
4,0,3,0,4
1,4,4,4,1
endlayer
 
layer
1,0,4,0,1
0,3,13,3,0
12,13,0,13,11
0,3,13,3,0
1,0,4,0,1
endlayer
 
layer
1,4,4,4,1
4,13,13,13,4
13,13,0,13,13
4,13,13,13,4
1,4,4,4,1
endlayer
 
layer
1,13,13,13,1
13,0,0,0,13
13,0,14,0,13
13,0,0,0,13
1,13,13,13,1
endlayer
 
layer
1,13,13,13,0
13,0,0,0,8
13,0,0,0,13
8,0,0,0,13
0,13,13,13,1
endlayer
 
layer
1,4,13,4,0
13,0,0,0,3
13,11,0,12,13
3,0,0,0,13
0,4,13,4,1
endlayer
 
layer
1,1,1,1,1
13,0,0,0,13
13,11,0,12,13
13,0,0,0,13
1,1,1,1,1
endlayer
 
layer
1,1,1,1,1
1,0,0,0,1
13,11,0,12,13
1,0,0,0,1
1,1,1,1,1
endlayer
 
layer
1,1,1,1,1
1,0,0,0,1
1,11,0,12,1
1,0,0,0,1
1,1,1,1,1
endlayer
 
layer
1,1,1,1,1
1,0,0,0,1
1,11,0,12,1
1,0,0,0,1
1,1,1,1,1
endlayer
 
layer
1,1,1,1,1
1,0,0,0,1
1,11,0,12,1
1,0,0,0,1
1,1,1,1,1
endlayer
 
layer
1,1,1,1,1
1,0,0,0,1
1,11,0,12,1
1,0,0,0,1
1,1,1,1,1
endlayer
 
layer
1,1,1,1,1
1,0,0,0,1
1,11,0,12,1
1,0,0,0,1
1,1,1,1,1
endlayer
 
layer
1,1,1,1,1
1,0,0,0,1
1,11,0,12,1
1,0,0,0,1
1,1,1,1,1
endlayer
 
layer
1,1,1,1,1
1,0,0,0,1
1,11,0,12,1
1,0,0,0,1
1,1,1,1,1
endlayer
 
layer
1,1,1,1,1
1,0,0,0,1
1,11,0,12,1
1,0,0,0,1
1,1,1,1,1
endlayer
 
layer
1,1,1,1,1
1,0,0,0,1
1,11,0,12,1
1,0,0,0,1
1,1,1,1,1
endlayer
 
layer
1,1,1,1,1
1,0,0,0,1
1,11,0,12,1
1,0,0,0,1
1,1,1,1,1
endlayer
 
layer
1,1,1,1,1
1,0,0,0,1
1,11,0,12,1
1,0,0,0,1
1,1,1,1,0
endlayer
 
layer
1,4,4,4,1
4,0,0,0,4
4,11,0,12,4
4,0,0,0,4
1,4,4,4,1
endlayer
 
layer
1,4,4,4,1
4,0,0,0,4
4,11,0,12,4
4,0,0,0,4
1,4,4,4,1
endlayer
 
layer
1,4,4,4,1
4,0,0,0,4
4,11,0,12,4
4,0,0,0,4
1,4,4,4,1
endlayer
 
layer
1,4,4,4,1
4,0,0,0,4
4,11,0,12,4
4,0,0,0,4
1,4,4,4,1
endlayer
 
layer
0,0,0,0,0
0,0,0,0,0
5,11,0,12,5
0,0,0,0,0
0,0,0,0,0
endlayer
 
layer
0,0,0,0,0
0,0,0,0,0
5,11,0,12,5
0,0,0,0,0
0,0,0,0,0
endlayer
 
layer
0,0,0,0,0
0,0,0,0,0
5,11,0,12,5
0,0,0,0,0
0,0,0,0,0
endlayer
 
layer
6,6,6,6,6
5,0,0,0,5
5,3,0,3,5
5,0,0,0,5
7,7,7,7,7
endlayer
 
layer
0,0,0,0,0
6,6,6,6,6
5,5,5,5,5
7,7,7,7,7
0,0,0,0,0
endlayer

layer
0,0,0,0,0
0,0,0,0,0
2,2,2,2,2
0,0,0,0,0
0,0,0,0,0
endlayer











































