# Pyramid
# Author: Arrrg
# From: Minecraft Forums

biomesToSpawnIn=desert,desert oil field,deserthills,dunes,lush desert,mountainous desert,desert_hills,desert_defiled,desert_shrubland,mutated_desert
weight=4
embed_into_distance=18
unacceptable_target_blocks=flowing_water,water,flowing_lava,lava,Natura:Cloud,red_mushroom_block,brown_mushroom_block,planks,cobblestone,end_stone,obsidian,purpur_block,iron_bars,purpur_slab,purpur_pillar,netherrack,soul_sand,quartz_ore
dimensions=39,30,30
allowable_overhang=9000
max_cut_in=5
cut_in_buffer=0
max_leveling=19
leveling_buffer=0
preserve_water=0
preserve_lava=0
preserve_plants=0

rule1=0,100,preserveBlock
rule2=0,100,stone_slab-1
rule3=0,100,sand,sand,sand,sand,sandstone
rule4=0,100,sandstone
rule5=0,100,sand
rule6=1,100,torch
rule7=0,100,glass
rule8=0,100,flowing_water
rule9=0,100,HardChest
rule10=0,100,obsidian
rule11=0,100,netherrack
rule12=0,100,flowing_lava
rule13=0,100,wool-0
rule14=0,100,wool-15
rule15=0,100,wool-11
rule16=0,100,EasyMobSpawn
rule17=0,100,lapis_block
rule18=0,100,diamond_block
rule19=0,100,gold_block
rule20=0,100,fire
rule21=0,100,ladder-5
rule22=0,100,ladder-4
rule23=0,100,ladder-2
rule24=0,100,ladder-3

layer
4,4,4,4,4,4,4,4,4,4,4,4,4,4,4,4,4,4,4,4,4,4,4,4,4,4,4,4,4,4
4,11,11,11,11,11,11,11,11,11,11,11,11,11,11,11,11,11,11,11,11,11,11,11,11,11,11,11,4,4
4,11,11,11,11,11,11,11,11,11,11,11,11,11,11,11,11,11,11,11,11,11,11,11,11,11,11,11,4,4
4,11,11,11,11,11,11,11,11,11,11,11,11,11,11,11,11,11,11,11,11,11,11,11,11,11,11,11,4,4
4,11,11,11,11,11,11,11,11,11,11,11,11,11,11,11,11,11,11,11,11,11,11,11,11,11,11,11,4,4
4,11,11,11,11,11,11,11,11,11,11,11,11,11,11,11,11,11,11,11,11,11,11,11,11,11,11,11,4,4
4,11,11,11,11,11,11,11,11,11,11,11,11,11,11,11,11,11,11,11,11,11,11,11,11,11,11,11,4,4
4,11,11,11,11,11,11,11,11,11,11,11,11,11,11,11,11,11,11,11,11,11,11,11,11,11,11,11,4,4
4,11,11,11,11,11,11,11,11,11,11,11,11,11,11,11,11,11,11,11,11,11,11,11,11,11,11,11,4,4
4,11,11,11,11,11,11,11,11,11,11,11,11,11,11,11,11,11,11,11,11,11,11,11,11,11,11,11,4,4
4,11,11,11,11,11,11,11,11,11,11,11,11,11,11,11,11,11,11,11,11,11,11,11,11,11,11,11,4,4
4,11,11,11,11,11,11,11,11,11,11,11,11,11,11,11,11,11,11,11,11,11,11,11,11,11,11,11,4,4
4,11,11,11,11,11,11,11,11,11,11,11,11,11,11,11,11,11,11,11,11,11,11,11,11,11,11,11,4,4
4,11,11,11,11,11,11,11,11,11,11,11,11,11,11,11,11,11,11,11,11,11,11,11,11,11,11,11,4,4
4,11,11,11,11,11,11,11,11,11,11,11,11,11,11,11,11,11,11,11,11,11,11,11,11,11,11,11,4,4
4,11,11,11,11,11,11,11,11,11,11,11,11,11,11,11,11,11,11,11,11,11,11,11,11,11,11,11,4,4
4,11,11,11,11,11,11,11,11,11,11,11,11,11,11,11,11,11,11,11,11,11,11,11,11,11,11,11,4,4
4,11,11,11,11,11,11,11,11,11,11,11,11,11,11,11,11,11,11,11,11,11,11,11,11,11,11,11,4,4
4,11,11,11,11,11,11,11,11,11,11,11,11,11,11,11,11,11,11,11,11,11,11,11,11,11,11,11,4,4
4,11,11,11,11,11,11,11,11,11,11,11,11,11,11,11,11,11,11,11,11,11,11,11,11,11,11,11,4,4
4,11,11,11,11,11,11,11,11,11,11,11,11,11,11,11,11,11,11,11,11,11,11,11,11,11,11,11,4,4
4,11,11,11,11,11,11,11,11,11,11,11,11,11,11,11,11,11,11,11,11,11,11,11,11,11,11,11,4,4
4,11,11,11,11,11,11,11,11,11,11,11,11,11,11,11,11,11,11,11,11,11,11,11,11,11,11,11,4,4
4,11,11,11,11,11,11,11,11,11,11,11,11,11,11,11,11,11,11,11,11,11,11,11,11,11,11,11,4,4
4,11,11,11,11,11,11,11,11,11,11,11,11,11,11,11,11,11,11,11,11,11,11,11,11,11,11,11,4,4
4,11,11,11,11,11,11,11,11,11,11,11,11,11,11,11,11,11,11,11,11,11,11,11,11,11,11,11,4,4
4,11,11,11,11,11,11,11,11,11,11,11,11,11,11,11,11,11,11,11,11,11,11,11,11,11,11,11,4,4
4,11,11,11,11,11,11,11,11,11,11,11,11,11,11,11,11,11,11,11,11,11,11,11,11,11,11,11,4,4
4,11,11,11,11,11,11,11,11,11,11,11,11,11,11,11,11,11,11,11,11,11,11,11,11,11,11,11,4,4
4,4,4,4,4,4,4,4,4,4,4,4,4,4,4,4,4,4,4,4,4,4,4,4,4,4,4,4,4,4
endlayer

layer
4,4,4,4,4,4,4,4,4,4,4,4,4,4,4,4,4,4,4,4,4,4,4,4,4,4,4,4,4,4
4,11,11,11,11,11,11,11,11,11,11,11,11,11,11,11,11,11,11,11,11,11,11,11,11,11,11,11,5,4
4,11,11,11,11,11,11,0,0,0,0,0,0,0,0,0,0,0,0,11,11,11,11,11,11,11,0,0,5,4
4,11,11,11,11,11,0,0,0,0,0,0,0,0,0,0,0,0,0,0,11,0,0,0,0,0,0,0,5,4
4,11,11,11,11,0,0,0,0,0,0,0,0,0,0,0,0,0,0,0,0,0,0,0,0,0,0,0,14,4
4,11,11,11,0,11,16,0,0,0,0,0,0,0,0,0,0,0,0,0,0,0,0,0,0,0,0,0,14,4
4,11,11,0,0,0,0,0,11,0,0,0,0,0,0,0,0,0,0,0,0,0,0,0,11,0,0,0,14,4
4,11,0,0,0,0,0,11,11,11,0,0,0,0,0,0,0,0,0,0,0,0,0,11,11,11,0,0,14,4
4,11,0,0,0,0,11,11,11,11,0,0,0,0,0,0,0,0,0,0,0,0,0,11,11,0,0,0,5,4
4,11,0,0,0,0,0,11,11,0,0,0,0,0,0,0,0,0,0,0,0,0,11,11,0,0,0,0,5,4
4,11,11,0,0,0,0,0,0,0,0,0,0,0,0,0,0,0,0,0,11,11,11,11,0,0,0,0,5,4
4,11,11,0,0,0,0,0,0,0,0,0,0,0,11,11,11,11,11,11,11,11,11,11,11,0,0,0,5,4
4,11,11,11,0,0,0,0,0,0,0,0,0,11,11,11,11,11,11,11,11,11,11,11,11,0,0,0,5,4
4,11,11,11,0,0,0,0,0,0,0,0,0,11,11,11,11,11,11,11,11,11,11,11,11,11,0,0,5,4
4,11,11,11,11,0,0,0,0,0,0,0,0,11,11,11,11,11,11,11,11,11,11,11,11,11,0,0,5,4
4,11,11,11,11,0,0,0,0,0,0,0,0,11,11,11,11,11,11,11,11,11,11,11,11,11,0,0,14,4
4,11,11,11,0,0,0,0,0,0,0,0,0,11,11,11,11,11,11,11,11,11,11,11,11,0,0,0,5,4
4,11,11,11,0,0,0,0,0,0,0,0,0,20,11,11,11,11,11,11,11,11,11,11,0,0,0,0,5,4
4,11,11,0,0,0,0,0,0,0,0,0,0,0,11,11,11,11,0,0,0,0,0,0,0,0,0,0,5,4
4,11,11,0,0,0,0,0,0,0,0,0,0,11,11,11,11,0,0,0,0,0,0,0,0,0,0,0,5,4
4,11,0,0,0,0,0,0,0,0,0,0,11,11,11,11,0,0,0,0,0,0,0,0,0,0,0,0,5,4
4,11,0,0,0,0,0,0,0,0,0,11,11,11,0,0,0,0,0,0,0,0,0,0,0,0,0,0,5,4
4,11,0,0,0,0,0,0,0,0,11,11,11,0,0,0,0,0,0,0,0,0,0,0,20,11,11,11,5,4
4,11,11,0,0,0,0,0,0,0,11,11,0,0,0,0,0,0,0,0,0,11,11,11,11,11,11,11,5,4
4,11,11,11,11,16,0,0,0,0,0,0,0,0,0,0,0,0,0,0,11,11,11,11,11,11,11,11,5,4
4,11,11,11,11,0,0,0,0,0,0,0,0,0,0,0,0,0,11,11,11,11,11,11,11,11,11,11,5,4
4,11,11,11,11,11,0,0,0,0,0,0,0,0,0,0,0,11,11,11,11,11,11,11,11,11,11,11,5,4
4,11,11,11,11,11,11,0,0,0,0,0,0,0,0,0,11,11,11,11,11,11,11,11,11,11,11,11,5,4
4,11,11,11,11,11,11,11,11,11,11,11,11,11,11,11,11,11,11,11,11,11,11,11,11,11,11,11,5,4
4,4,4,4,4,4,4,4,4,4,4,4,4,4,4,4,4,4,4,4,4,4,4,4,4,4,4,4,4,4
endlayer

layer
4,4,4,4,4,4,4,4,4,4,4,4,4,4,4,4,4,4,4,4,4,4,4,4,4,4,4,4,4,4
4,11,11,11,11,11,11,11,11,11,11,11,11,11,11,11,11,11,11,11,11,11,11,11,11,11,11,11,5,4
4,11,11,11,11,11,0,0,0,0,0,0,0,0,0,0,0,0,11,11,11,11,11,11,11,0,0,0,5,4
4,11,11,11,11,0,0,0,0,0,0,0,0,0,0,0,0,0,0,11,11,11,11,0,0,0,0,0,14,4
4,11,11,11,0,0,0,0,0,0,0,0,0,0,0,0,0,0,0,0,0,0,0,0,0,0,0,0,14,4
4,11,11,0,0,0,0,0,0,0,0,0,0,0,0,0,0,0,0,0,0,0,0,0,0,0,0,0,14,4
4,11,0,0,0,0,0,0,0,0,0,0,0,0,0,0,0,0,0,0,0,0,0,0,0,0,0,0,5,4
4,11,0,0,0,0,0,11,11,0,0,0,0,0,0,0,0,0,0,0,0,0,0,0,11,0,0,0,14,4
4,11,0,0,0,0,0,11,11,0,0,0,0,0,0,0,0,0,0,0,0,0,0,0,0,0,0,0,14,4
4,11,0,0,0,0,0,0,0,0,0,0,0,0,0,0,0,0,0,0,0,0,0,0,0,0,0,0,14,4
4,11,11,0,0,0,0,0,0,0,0,0,0,0,11,11,11,11,11,11,11,11,0,0,0,0,0,0,5,4
4,11,11,0,0,0,0,0,0,0,0,0,0,11,11,11,11,11,11,11,11,11,11,0,0,0,0,0,5,4
4,11,11,11,0,0,0,0,0,0,0,0,11,11,11,11,11,11,11,11,11,11,11,11,0,0,0,0,5,4
4,11,11,11,0,0,0,0,0,0,0,0,11,11,11,11,11,11,11,11,11,11,11,11,11,0,0,0,5,4
4,11,11,11,0,0,0,0,0,0,0,0,11,11,11,11,11,11,11,0,11,11,11,11,11,0,0,0,5,4
4,11,11,11,0,0,0,0,0,0,0,0,11,11,11,11,11,11,11,11,11,11,11,11,11,0,0,0,14,4
4,11,11,11,0,0,0,0,0,0,0,0,11,11,11,11,11,11,11,11,11,11,11,11,0,0,0,0,14,4
4,11,11,0,0,0,0,0,0,0,0,0,11,11,11,11,11,11,11,11,11,11,11,0,0,0,0,0,5,4
4,11,11,0,0,0,0,0,0,0,0,0,0,11,11,11,11,11,11,11,11,11,0,0,0,0,0,0,5,4
4,11,0,0,0,0,0,0,0,0,0,0,0,0,0,0,0,0,0,0,0,0,0,0,0,0,0,0,5,4
4,11,0,0,0,0,0,0,0,0,0,0,0,0,0,0,0,0,0,0,0,0,0,0,0,0,0,0,5,4
4,11,0,0,0,0,0,0,0,0,0,11,0,0,0,0,0,0,0,0,0,0,0,0,0,0,0,0,5,4
4,11,0,0,0,0,0,0,0,0,11,11,11,0,0,0,0,0,0,0,0,0,0,0,0,0,0,0,5,4
4,11,11,0,0,0,0,0,0,0,0,11,0,0,0,0,0,0,0,0,0,0,11,11,0,0,0,0,5,4
4,11,11,11,0,0,0,0,0,0,0,0,0,0,0,0,0,0,0,11,11,11,11,11,11,11,11,11,5,4
4,11,11,11,11,0,0,0,0,0,0,0,0,0,0,0,0,0,11,11,11,11,11,11,11,11,11,11,5,4
4,11,11,11,11,11,0,0,0,0,0,0,0,0,0,0,0,11,11,11,11,11,11,11,11,11,11,11,5,4
4,11,11,11,11,11,11,0,0,0,0,0,0,0,0,0,11,11,11,11,11,11,11,11,11,11,11,11,5,4
4,11,11,11,11,11,11,11,11,11,11,11,11,11,11,11,11,11,11,11,11,11,11,11,11,11,11,11,5,4
4,4,4,4,4,4,4,4,4,4,4,4,4,4,4,4,4,4,4,4,4,4,4,4,4,4,4,4,4,4
endlayer

layer
3,3,3,3,3,3,3,3,3,3,3,3,3,3,3,3,3,3,3,3,3,3,3,3,3,3,3,3,3,3
3,11,11,11,11,11,11,11,11,11,11,11,11,11,11,11,11,11,11,11,11,11,11,11,11,11,11,11,5,3
3,11,11,11,11,11,0,0,0,0,0,0,0,0,0,0,0,0,11,11,11,11,11,11,0,0,0,0,5,3
3,11,11,11,11,0,0,0,0,0,0,0,0,0,0,0,0,0,0,11,11,11,0,0,0,0,0,0,5,3
3,11,11,11,0,0,0,0,0,0,0,0,0,0,0,0,0,0,0,0,0,0,0,0,0,0,0,0,14,3
3,11,11,0,0,0,0,0,0,0,0,0,0,0,0,0,0,0,0,0,0,0,0,0,0,0,0,0,5,3
3,11,0,0,0,0,0,0,0,0,0,0,0,0,0,0,0,0,0,0,0,0,0,0,0,0,0,0,5,3
3,11,0,0,0,0,0,11,0,0,0,0,0,0,0,0,0,0,0,0,0,0,0,0,20,0,0,0,5,3
3,11,0,0,0,0,0,0,0,0,0,0,0,0,0,0,0,0,0,0,0,0,0,0,0,0,0,0,5,3
3,11,0,0,0,0,0,0,0,0,0,0,0,0,0,0,0,0,0,0,0,0,0,0,0,0,0,0,14,3
3,11,0,0,0,0,0,0,0,0,0,0,0,11,11,11,11,11,11,11,11,0,0,0,0,0,0,0,14,3
3,11,20,0,0,0,0,0,0,0,0,0,11,11,11,11,11,11,11,11,11,11,0,0,0,0,0,0,14,3
3,11,11,0,0,0,0,0,0,0,0,11,11,11,11,11,11,11,11,0,11,11,11,0,0,0,0,0,5,3
3,11,11,0,0,0,0,0,0,0,0,11,11,11,11,11,11,11,11,11,11,11,11,11,0,0,0,0,5,3
3,11,11,11,0,0,0,0,0,0,0,11,11,11,11,11,11,11,11,0,11,11,11,11,0,0,0,0,5,3
3,11,11,11,0,0,0,0,0,0,0,11,11,11,11,11,11,11,11,0,11,11,11,11,0,0,0,0,14,3
3,11,11,0,0,0,0,0,0,0,0,11,11,11,11,11,11,11,11,11,11,11,11,0,0,0,0,0,14,3
3,11,11,0,0,0,0,0,0,0,0,11,11,11,11,11,11,11,11,11,11,11,0,0,0,0,0,0,5,3
3,11,0,0,0,0,0,0,0,0,0,0,11,11,11,11,11,11,11,11,11,0,0,0,0,0,0,0,5,3
3,11,0,0,0,0,0,0,0,0,0,0,0,11,11,11,11,11,11,11,0,0,0,0,0,0,0,0,5,3
3,11,0,0,0,0,0,0,0,0,0,0,0,0,0,0,0,0,0,0,0,0,0,0,0,0,0,0,5,3
3,11,0,0,0,0,0,0,0,0,0,0,0,0,0,0,0,0,0,0,0,0,0,0,0,0,0,0,5,3
3,11,0,0,0,0,0,0,0,0,0,11,0,0,0,0,0,0,0,0,0,0,0,0,0,0,0,0,5,3
3,11,0,0,0,0,0,0,0,0,0,0,0,0,0,0,0,0,0,0,0,11,11,0,0,0,0,0,5,3
3,11,11,0,0,0,0,0,0,0,0,0,0,0,0,0,0,0,0,11,11,11,11,11,11,11,11,11,5,3
3,11,11,11,0,0,0,0,0,0,0,0,0,0,0,0,0,0,11,11,11,11,11,11,11,11,11,11,5,3
3,11,11,11,11,0,0,0,0,0,0,0,0,0,0,0,0,11,11,11,11,11,11,11,11,11,11,11,5,3
3,11,11,11,11,11,0,0,0,0,0,0,0,0,0,0,11,11,11,11,11,11,11,11,11,11,11,11,5,3
3,11,11,11,11,11,11,11,11,11,11,11,11,11,11,11,11,11,11,11,11,11,11,11,11,11,11,11,5,3
3,3,3,3,3,3,3,3,3,3,3,3,3,3,3,3,3,3,3,3,3,3,3,3,3,3,3,3,3,3
endlayer

layer
4,4,4,4,4,4,4,4,4,4,4,4,4,4,4,4,4,4,4,4,4,4,4,4,4,4,4,4,4,4
4,11,11,11,11,11,11,11,11,11,11,11,11,11,11,11,11,11,11,11,11,11,11,11,11,11,11,11,5,4
4,11,11,11,11,11,11,0,0,0,0,0,0,0,0,0,0,0,0,11,11,11,11,11,0,0,0,0,5,4
4,11,11,11,11,11,0,0,0,0,0,0,0,0,0,0,0,0,0,0,11,0,0,0,0,0,0,0,5,4
4,11,11,11,11,0,0,0,0,0,0,0,0,0,0,0,0,0,0,0,0,0,0,0,0,0,0,0,5,4
4,11,11,11,0,0,0,0,0,0,0,0,0,0,0,0,0,0,0,0,0,0,0,0,0,0,0,0,5,4
4,11,11,0,0,0,0,0,0,0,0,0,0,0,0,0,0,0,0,0,0,0,0,0,0,0,0,0,5,4
4,11,0,0,0,0,0,20,0,0,0,0,0,0,0,0,0,0,0,0,0,0,0,0,0,0,0,0,5,4
4,11,0,0,0,0,0,0,0,0,0,0,0,0,0,0,0,0,0,0,0,0,0,0,0,0,0,0,5,4
4,11,0,0,0,0,0,0,0,0,0,0,0,0,0,0,0,0,0,0,0,0,0,0,0,0,0,0,5,4
4,11,0,0,0,0,0,0,0,0,0,0,11,11,11,11,11,11,11,11,0,0,0,0,0,0,0,0,5,4
4,11,0,0,0,0,0,0,0,0,0,11,11,11,11,11,11,11,11,8,11,0,0,0,0,0,0,0,14,4
4,11,0,0,0,0,0,0,0,0,11,11,11,11,11,11,11,11,11,0,11,11,0,0,0,0,0,0,14,4
4,11,0,0,0,0,0,0,0,0,11,11,11,11,11,11,11,11,11,6,11,11,11,0,0,0,0,0,14,4
4,11,11,0,0,0,0,0,0,0,11,11,11,11,11,11,11,11,11,0,11,11,11,0,0,0,0,0,5,4
4,11,11,0,0,0,0,0,0,0,11,11,11,11,11,11,11,11,11,0,11,11,11,0,0,0,0,0,14,4
4,11,0,0,0,0,0,0,0,0,11,11,11,11,11,11,11,11,11,11,11,11,0,0,0,0,0,0,14,4
4,11,0,0,0,0,0,0,0,0,11,11,11,11,11,11,11,11,11,11,11,0,0,0,0,0,0,0,5,4
4,11,0,0,0,0,0,0,0,0,0,11,11,11,11,11,11,11,11,11,0,0,0,0,0,0,0,0,5,4
4,11,0,0,0,0,0,0,0,0,0,0,11,11,11,11,11,11,11,0,0,0,0,0,0,0,0,0,5,4
4,11,0,0,0,0,0,0,0,0,0,0,0,0,0,0,0,0,0,0,0,0,0,0,0,0,0,0,5,4
4,11,0,0,0,0,0,0,0,0,0,0,0,0,0,0,0,0,0,0,0,0,0,0,0,0,0,0,5,4
4,11,0,0,0,0,0,0,0,0,0,0,0,0,0,0,0,0,0,0,0,0,0,0,0,0,0,0,5,4
4,11,11,0,0,0,0,0,0,0,0,0,0,0,0,0,0,0,0,0,0,0,11,11,0,0,0,0,5,4
4,11,11,11,0,0,0,0,0,0,0,0,0,0,0,0,0,0,0,0,11,11,11,11,11,0,0,11,5,4
4,11,11,11,11,0,0,0,0,0,0,0,0,0,0,0,0,0,0,11,11,11,11,11,11,11,11,11,5,4
4,11,11,11,11,11,0,0,0,0,0,0,0,0,0,0,0,0,11,11,11,11,11,11,11,11,11,11,5,4
4,11,11,11,11,11,11,0,0,0,0,0,0,0,0,0,0,11,11,11,11,11,11,11,11,11,11,11,5,4
4,11,11,11,11,11,11,11,11,11,11,11,11,11,11,11,11,11,11,11,11,11,11,11,11,11,11,11,5,4
4,4,4,4,4,4,4,4,4,4,4,4,4,4,4,4,4,4,4,4,4,4,4,4,4,4,4,4,4,4
endlayer

layer
4,4,4,4,4,4,4,4,4,4,4,4,4,4,4,4,4,4,4,4,4,4,4,4,4,4,4,4,4,4
4,11,11,11,11,11,11,11,11,11,11,11,11,11,11,11,11,11,11,11,11,11,11,11,11,11,11,11,5,4
4,11,11,11,11,11,11,0,0,0,0,0,0,0,0,0,0,0,0,11,11,11,11,0,0,0,0,0,5,4
4,11,11,11,11,11,0,0,0,0,0,0,0,0,0,0,0,0,0,0,11,0,0,0,0,0,0,0,5,4
4,11,11,11,11,0,0,0,0,0,0,0,0,0,0,0,0,0,0,0,0,0,0,0,0,0,0,0,5,4
4,11,11,11,0,0,0,0,0,0,0,0,0,0,0,0,0,0,0,0,0,0,0,0,0,0,0,0,5,4
4,11,11,0,0,0,0,0,0,0,0,0,0,0,0,0,0,0,0,0,0,0,0,0,0,0,0,0,5,4
4,11,0,0,0,0,0,0,0,0,0,0,0,0,0,0,0,0,0,0,0,0,0,0,0,0,0,0,5,4
4,11,0,0,0,0,0,0,0,0,0,0,0,0,0,0,0,0,0,0,0,0,0,0,0,0,0,0,5,4
4,11,0,0,0,0,0,0,0,0,0,0,0,0,0,0,0,0,0,0,0,0,0,0,0,0,0,0,5,4
4,11,0,0,0,0,0,0,0,0,0,11,11,11,11,11,11,11,11,11,0,0,0,0,0,0,0,0,5,4
4,11,0,0,0,0,0,0,0,0,11,11,11,11,11,11,11,11,11,11,11,0,0,0,0,0,0,0,5,4
4,11,0,0,0,0,0,0,0,11,11,11,11,11,11,11,11,11,11,0,11,0,0,0,0,0,0,0,14,4
4,11,0,0,0,0,0,0,0,11,11,11,11,11,11,11,11,11,11,5,11,11,0,0,0,0,0,0,14,4
4,11,0,0,0,0,0,0,0,11,11,11,11,11,11,11,11,11,11,21,11,11,0,0,0,0,0,0,14,4
4,11,0,0,0,0,0,0,0,11,11,11,11,11,11,11,11,11,11,0,11,11,0,0,0,0,0,0,14,4
4,11,0,0,0,0,0,0,0,11,11,11,11,11,11,11,11,11,11,11,11,0,0,0,0,0,0,0,14,4
4,11,0,0,0,0,0,0,0,11,11,11,11,11,11,11,11,11,11,11,0,0,0,0,0,0,0,0,14,4
4,11,0,0,0,0,0,0,0,11,11,11,11,11,11,11,11,11,11,11,0,0,0,0,0,0,0,0,5,4
4,11,0,0,0,0,0,0,0,0,11,11,11,11,11,11,11,11,11,0,0,0,0,0,0,0,0,0,5,4
4,11,0,0,0,0,0,0,0,0,0,0,0,0,0,0,0,0,0,0,0,0,0,0,0,0,0,0,5,4
4,11,0,0,0,0,0,0,0,0,0,0,0,0,0,0,0,0,0,0,0,0,0,0,0,0,0,0,5,4
4,11,0,0,0,0,0,0,0,0,0,0,0,0,0,0,0,0,0,0,0,0,0,0,0,0,0,0,5,4
4,11,11,0,0,0,0,0,0,0,0,0,0,0,0,0,0,0,0,0,0,0,0,11,11,0,0,0,5,4
4,11,11,11,0,0,0,0,0,0,0,0,0,0,0,0,0,0,0,0,0,0,0,0,11,0,0,0,5,4
4,11,11,11,11,0,0,0,0,0,0,0,0,0,0,0,0,0,0,0,11,11,11,0,0,0,0,11,5,4
4,11,11,11,11,11,0,0,0,0,0,0,0,0,0,0,0,0,0,11,11,11,11,11,0,0,11,11,5,4
4,11,11,11,11,11,11,0,0,0,0,0,0,0,0,0,0,0,11,11,11,11,11,11,11,11,11,11,5,4
4,11,11,11,11,11,11,11,11,11,11,11,11,11,11,11,11,11,11,11,11,11,11,11,11,11,11,11,5,4
4,4,4,4,4,4,4,4,4,4,4,4,4,4,4,4,4,4,4,4,4,4,4,4,4,4,4,4,4,4
endlayer

layer
4,4,4,4,4,4,4,4,4,4,4,4,4,4,4,4,4,4,4,4,4,4,4,4,4,4,4,4,4,4
4,11,11,11,11,11,11,11,11,11,11,11,11,11,11,11,11,11,11,11,11,11,11,11,11,11,11,11,5,4
4,11,11,11,11,11,0,0,0,0,0,0,0,0,0,0,0,0,11,11,11,11,11,0,0,0,0,0,5,4
4,11,11,11,11,0,0,0,0,0,0,0,0,0,0,0,0,0,0,11,11,11,0,0,0,0,0,0,5,4
4,11,11,11,0,0,0,0,0,0,0,0,0,0,0,0,0,0,0,0,0,0,0,0,0,0,0,0,5,4
4,11,11,0,0,0,0,0,0,0,0,0,0,0,0,0,0,0,0,0,0,0,0,0,0,0,0,0,5,4
4,11,0,0,0,0,0,0,0,0,0,0,0,0,0,0,0,0,0,0,0,0,0,0,0,0,0,0,5,4
4,11,0,0,0,0,0,0,0,0,0,0,0,0,0,0,0,0,0,0,0,0,0,0,0,0,0,0,5,4
4,11,0,0,0,0,0,0,0,0,0,0,0,0,0,0,0,0,0,0,0,0,0,0,0,0,0,0,5,4
4,11,0,0,0,0,0,0,0,0,0,0,0,0,0,0,0,0,0,0,0,0,0,0,0,0,0,0,14,4
4,11,0,0,0,0,0,0,0,0,11,11,11,11,11,11,11,11,11,0,0,0,0,0,0,0,0,0,14,4
4,11,0,0,0,0,0,0,0,11,11,11,11,11,11,11,11,11,11,11,0,0,0,0,0,0,0,0,14,4
4,11,0,0,0,0,0,0,0,11,11,4,4,4,4,4,4,4,11,0,0,0,0,0,0,0,0,0,13,4
4,11,0,0,0,0,0,0,11,11,11,4,4,4,4,4,4,4,11,5,0,0,0,0,0,0,0,0,13,4
4,11,0,0,0,0,0,0,11,11,4,4,4,4,4,4,4,4,11,5,11,0,0,0,0,0,0,0,13,4
4,11,0,0,0,0,0,0,11,11,4,4,4,4,4,4,4,4,11,21,11,0,0,0,0,0,0,0,13,4
4,11,0,0,0,0,0,0,11,11,11,4,4,4,4,4,4,4,11,11,0,0,0,0,0,0,0,0,13,4
4,11,0,0,0,0,0,0,0,11,11,4,4,4,4,4,4,4,11,11,0,0,0,0,0,0,0,0,13,4
4,11,0,0,0,0,0,0,0,11,11,11,11,11,11,11,11,11,11,11,0,0,0,0,0,0,0,0,14,4
4,11,0,0,0,0,0,0,0,0,11,11,11,11,11,11,11,11,11,0,0,0,0,0,0,0,0,0,14,4
4,11,0,0,0,0,0,0,0,0,0,0,0,0,0,0,0,0,0,0,0,0,0,0,0,0,0,0,5,4
4,11,0,0,0,0,0,0,0,0,0,0,0,0,0,0,0,0,0,0,0,0,0,0,0,0,0,0,5,4
4,11,0,0,0,0,0,0,0,0,0,0,0,0,0,0,0,0,0,0,0,0,0,0,0,0,0,0,5,4
4,11,0,0,0,0,0,0,0,0,0,0,0,0,0,0,0,0,0,0,0,0,0,11,11,0,0,0,5,4
4,11,11,0,0,0,0,0,0,0,0,0,0,0,0,0,0,0,0,0,0,0,0,0,11,0,0,0,5,4
4,11,11,11,0,0,0,0,0,0,0,0,0,0,0,0,0,0,0,0,0,11,0,0,0,0,0,0,5,4
4,11,11,11,11,0,0,0,0,0,0,0,0,0,0,0,0,0,0,0,11,11,11,0,0,0,0,11,5,4
4,11,11,11,11,11,0,0,0,0,0,0,0,0,0,0,0,0,0,11,11,11,11,11,0,0,11,11,5,4
4,11,11,11,11,11,11,11,11,11,11,11,11,11,11,11,11,11,11,11,11,11,11,11,11,11,11,11,5,4
4,4,4,4,4,4,4,4,4,4,4,4,4,4,4,4,4,4,4,4,4,4,4,4,4,4,4,4,4,4
endlayer

layer
3,3,3,3,3,3,3,3,3,3,3,3,3,3,3,3,3,3,3,3,3,3,3,3,3,3,3,3,3,3
3,11,11,11,11,11,11,11,11,11,11,11,11,11,11,11,11,11,11,11,11,11,11,11,11,11,11,11,5,3
3,11,11,11,11,0,0,0,0,0,0,0,0,0,0,0,0,0,11,11,11,11,11,11,0,0,0,0,5,3
3,11,11,11,0,0,0,0,0,0,0,0,0,0,0,0,0,0,0,11,11,11,0,0,0,0,0,0,14,3
3,11,11,0,0,0,0,0,0,0,0,0,0,0,0,0,0,0,0,0,11,0,0,0,0,0,0,0,14,3
3,11,0,0,0,0,0,0,0,0,0,0,0,0,0,0,0,0,0,0,0,0,0,0,0,0,0,0,14,3
3,11,0,0,0,0,0,0,0,0,0,0,0,0,0,0,0,0,0,0,0,0,0,0,0,0,0,0,14,3
3,11,0,0,0,0,0,0,0,0,0,0,0,0,0,0,0,0,0,0,0,0,0,0,0,0,0,0,14,3
3,11,0,0,0,0,0,0,0,0,0,0,0,0,0,0,0,0,0,0,0,0,0,0,0,0,0,0,14,3
3,11,0,0,0,0,0,0,0,0,11,11,11,11,11,11,11,11,11,0,0,0,0,0,0,0,0,0,13,3
3,11,0,0,0,0,0,0,0,11,3,3,4,3,3,3,3,4,3,11,0,0,0,0,0,0,0,0,13,3
3,11,0,0,0,0,0,0,0,11,3,4,5,4,4,4,4,5,4,11,0,0,0,0,0,0,0,0,13,3
3,11,0,0,0,0,0,0,11,11,3,4,6,0,9,9,0,6,4,0,0,0,0,0,0,0,0,0,13,3
3,11,0,0,0,0,0,0,11,11,3,4,0,0,0,0,0,0,10,5,0,0,0,0,0,0,0,0,13,3
3,11,0,0,0,0,0,11,11,11,4,0,0,0,0,0,0,0,10,5,0,0,0,0,0,0,0,0,15,3
3,11,0,0,0,0,0,11,11,11,4,0,0,0,0,0,0,0,10,5,0,0,0,0,0,0,0,0,15,3
3,11,0,0,0,0,0,0,11,11,3,4,0,0,0,0,0,0,10,0,0,0,0,0,0,0,0,0,15,3
3,11,0,0,0,0,0,0,11,11,3,4,6,0,9,9,0,6,4,11,0,0,0,0,0,0,0,0,13,3
3,11,0,0,0,0,0,0,0,11,3,4,5,4,4,4,4,5,4,11,0,0,0,0,0,0,0,0,13,3
3,11,0,0,0,0,0,0,0,11,3,3,4,3,3,3,3,4,3,11,0,0,0,0,0,0,0,0,13,3
3,11,0,0,0,0,0,0,0,0,11,11,11,11,11,11,11,11,11,0,0,0,0,0,0,0,0,0,14,3
3,11,0,0,0,0,0,0,0,0,0,0,0,0,0,0,0,0,0,0,0,0,0,0,0,0,0,0,5,3
3,11,0,0,0,0,0,0,0,0,0,0,0,0,0,0,0,0,0,0,0,0,0,0,0,0,0,0,5,3
3,11,0,0,0,0,0,0,0,0,0,0,0,0,0,0,0,0,0,0,0,0,0,0,11,0,0,0,5,3
3,11,0,0,0,0,0,0,0,0,0,0,0,0,0,0,0,0,0,0,0,0,0,0,0,0,0,0,5,3
3,11,11,0,0,0,0,0,0,0,0,0,0,0,0,0,0,0,0,0,0,11,0,0,0,0,0,0,5,3
3,11,11,11,0,0,0,0,0,0,0,0,0,0,0,0,0,0,0,0,11,11,11,0,0,0,0,0,5,3
3,11,11,11,11,0,0,0,0,0,0,0,0,0,0,0,0,0,0,11,11,11,11,11,0,0,0,11,5,3
3,11,11,11,11,11,11,11,11,11,11,11,11,11,11,11,11,11,11,11,11,11,11,11,11,11,11,11,5,3
3,3,3,3,3,3,3,3,3,3,3,3,3,3,3,3,3,3,3,3,3,3,3,3,3,3,3,3,3,3
endlayer

layer
3,3,3,3,3,3,3,3,3,3,3,3,3,3,3,3,3,3,3,3,3,3,3,3,3,3,3,3,4,3
3,11,11,11,11,11,11,11,11,11,11,11,11,11,11,11,11,11,11,11,11,11,11,11,11,11,11,11,5,3
3,11,11,11,0,0,0,0,0,0,0,0,0,0,0,0,0,0,0,11,11,11,0,0,0,0,0,0,5,3
3,11,11,0,0,0,0,0,0,0,0,0,0,0,0,0,0,0,0,0,11,0,0,0,0,0,0,0,14,3
3,11,0,0,0,0,0,0,0,0,0,0,0,0,0,0,0,0,0,0,0,0,0,0,0,0,0,0,14,3
3,11,0,0,0,0,0,0,0,0,0,0,0,0,0,0,0,0,0,0,0,0,0,0,0,0,0,0,14,3
3,11,0,0,0,0,0,0,0,0,0,0,0,0,0,0,0,0,0,0,0,0,0,0,0,0,0,0,14,3
3,11,0,0,0,0,0,0,0,0,0,0,0,0,11,0,0,0,0,0,0,0,0,0,0,0,0,0,14,3
3,11,0,0,0,0,0,0,0,0,0,0,0,11,11,11,0,0,0,0,0,0,0,0,0,0,0,0,13,3
3,11,0,0,0,0,0,0,0,11,11,11,11,11,4,11,11,11,11,11,0,0,0,0,0,0,0,0,13,3
3,11,0,0,0,0,0,0,11,3,3,3,4,4,8,4,3,4,3,11,0,0,0,0,0,0,0,0,13,3
3,11,0,0,0,0,0,0,11,3,3,4,5,4,0,4,4,5,4,11,0,0,0,0,0,0,0,0,13,3
3,11,0,0,0,0,0,11,11,3,3,4,5,0,17,0,0,5,4,0,0,0,0,0,0,0,0,0,13,3
3,11,0,0,0,0,0,11,11,3,3,4,0,0,0,0,0,0,10,0,0,0,0,0,0,0,0,0,15,3
3,11,0,0,0,0,0,11,11,4,0,0,0,0,0,0,0,0,0,5,0,0,0,0,0,0,0,0,15,3
3,11,0,0,0,0,0,11,11,4,0,0,0,0,0,0,0,0,0,5,0,0,0,0,0,0,0,0,18,3
3,11,0,0,0,0,0,11,11,3,3,4,0,0,0,0,0,0,10,0,0,0,0,0,0,0,0,0,15,3
3,11,0,0,0,0,0,11,11,3,3,4,5,0,0,19,0,5,4,0,0,0,0,0,0,0,0,0,15,3
3,11,0,0,0,0,0,0,11,3,3,4,5,4,4,0,4,5,4,11,0,0,0,0,0,0,0,0,13,3
3,11,0,0,0,0,0,0,11,3,3,3,4,3,4,8,4,4,3,11,0,0,0,0,0,0,0,0,13,3
3,11,0,0,0,0,0,0,0,11,11,11,11,11,11,4,11,11,11,11,0,0,0,0,0,0,0,0,14,3
3,11,0,0,0,0,0,0,0,0,0,0,0,0,11,11,11,0,0,0,0,0,0,0,0,0,0,0,5,3
3,11,0,0,0,0,0,0,0,0,0,0,0,0,0,11,0,0,0,0,0,0,0,0,0,0,0,0,5,3
3,11,0,0,0,0,0,0,0,0,0,0,0,0,0,0,0,0,0,0,0,0,0,0,11,0,0,0,5,3
3,11,0,0,0,0,0,0,0,0,0,0,0,0,0,0,0,0,0,0,0,0,0,0,0,0,0,0,5,3
3,11,0,0,0,0,0,0,0,0,0,0,0,0,0,0,0,0,0,0,11,0,0,0,0,0,0,0,5,3
3,11,11,0,0,0,0,0,0,0,0,0,0,0,0,0,0,0,0,11,11,11,0,0,0,0,0,11,5,3
3,11,11,11,0,0,0,0,0,0,0,0,0,0,0,0,0,0,11,11,11,11,11,0,0,0,11,11,5,3
3,11,11,11,11,11,11,11,11,11,11,11,11,11,11,11,11,11,11,11,11,11,11,11,11,11,11,11,5,3
3,3,3,3,3,3,3,3,3,3,3,3,3,3,3,3,3,3,3,3,3,3,3,3,3,3,3,3,4,3
endlayer

layer
4,4,4,4,4,4,4,4,4,4,4,4,4,4,4,4,4,4,4,4,4,4,4,4,4,4,4,4,4,4
4,11,11,11,11,11,11,11,11,11,11,11,11,11,11,11,11,11,11,11,11,11,11,11,11,11,11,11,5,4
4,11,11,0,0,0,0,0,0,0,0,0,0,0,0,0,0,0,0,0,11,20,0,0,0,0,0,0,5,4
4,11,0,0,0,0,0,0,0,0,0,0,0,0,0,0,0,0,0,0,0,0,0,0,0,0,0,0,5,4
4,11,0,0,0,0,0,0,0,0,0,0,0,0,0,0,0,0,0,0,0,0,0,0,0,0,0,0,5,4
4,11,0,0,0,0,0,0,0,0,0,0,0,0,0,0,0,0,0,0,0,0,0,0,0,0,0,0,5,4
4,11,0,0,0,0,0,0,0,0,0,0,0,0,0,0,0,0,0,0,0,0,0,0,0,0,0,0,5,4
4,11,0,0,0,0,0,0,0,0,0,0,0,0,0,0,0,0,0,0,0,0,0,0,0,0,0,0,5,4
4,11,0,0,0,0,0,0,0,0,0,0,0,11,11,11,0,0,0,0,0,0,0,0,0,0,0,0,14,4
4,11,0,0,0,0,0,0,0,0,11,11,11,11,4,11,11,11,11,11,0,0,0,0,0,0,0,0,14,4
4,11,0,0,0,0,0,0,0,0,11,4,4,4,0,4,4,4,4,11,0,0,0,0,0,0,0,0,14,4
4,11,0,0,0,0,0,0,0,11,11,4,4,4,4,4,4,4,4,11,0,0,0,0,0,0,0,0,13,4
4,11,0,0,0,0,0,11,11,11,11,4,5,0,0,0,0,5,4,0,0,0,0,0,0,0,0,0,13,4
4,11,0,0,0,0,0,11,4,4,4,4,0,0,0,0,0,0,10,0,0,0,0,0,0,0,0,0,13,4
4,11,0,0,0,0,0,11,4,0,0,0,0,0,0,0,0,0,0,5,0,0,0,0,0,0,0,0,15,4
4,11,0,0,0,0,0,11,4,0,0,0,0,0,0,0,0,0,0,5,0,0,0,0,0,0,0,0,15,4
4,11,0,0,0,0,0,11,4,4,4,4,0,0,0,0,0,0,10,0,0,0,0,0,0,0,0,0,15,4
4,11,0,0,0,0,0,11,11,11,11,4,5,0,0,0,0,5,4,0,0,0,0,0,0,0,0,0,13,4
4,11,0,0,0,0,0,0,0,11,11,4,4,4,4,4,4,4,4,11,0,0,0,0,0,0,0,0,13,4
4,11,0,0,0,0,0,0,0,0,11,4,4,4,4,0,4,4,4,11,0,0,0,0,0,0,0,0,14,4
4,11,0,0,0,0,0,0,0,0,11,11,11,11,11,4,11,11,11,11,0,0,0,0,0,0,0,0,5,4
4,11,0,0,0,0,0,0,0,0,0,0,0,0,11,11,11,0,0,0,0,0,0,0,0,0,0,0,5,4
4,11,0,0,0,0,0,0,0,0,0,0,0,0,0,0,0,0,0,0,0,0,0,0,0,0,0,0,5,4
4,11,0,0,0,0,0,0,0,0,0,0,0,0,0,0,0,0,0,0,0,0,0,0,20,0,0,0,5,4
4,11,0,0,0,0,0,0,0,0,0,0,0,0,0,0,0,0,0,0,0,0,0,0,0,0,0,0,5,4
4,11,0,0,0,0,0,0,0,0,0,0,0,0,0,0,0,0,0,0,0,0,0,0,0,0,0,0,5,4
4,11,0,0,0,0,0,0,0,0,0,0,0,0,0,0,0,0,0,0,11,0,0,0,0,0,0,11,5,4
4,11,11,0,0,0,0,0,0,0,0,0,0,0,0,0,0,0,0,11,11,11,0,0,0,0,11,11,5,4
4,11,11,11,11,11,11,11,11,11,11,11,11,11,11,11,11,11,11,11,11,11,11,11,11,11,11,11,5,4
4,4,4,4,4,4,4,4,4,4,4,4,4,4,4,4,4,4,4,4,4,4,4,4,4,4,4,4,4,4
endlayer

layer
3,3,3,3,3,3,3,3,3,3,3,3,3,3,3,3,3,3,3,3,3,3,3,3,3,3,3,3,3,3
3,11,11,11,11,11,11,11,11,11,11,11,11,11,11,11,11,11,11,11,11,11,11,11,11,11,11,11,5,3
3,11,11,11,0,0,0,0,0,0,0,0,0,0,0,0,0,0,0,11,11,11,0,0,0,0,0,11,5,3
3,11,11,0,0,0,0,0,0,0,0,0,0,0,0,0,0,0,0,0,11,0,0,0,0,0,0,0,5,3
3,11,0,0,0,0,0,0,0,0,0,0,0,0,0,0,0,0,0,0,0,0,0,0,0,0,0,0,5,3
3,11,0,0,0,0,0,0,0,0,0,0,0,0,0,0,0,0,0,0,0,0,0,0,0,0,0,0,5,3
3,11,0,0,0,0,0,0,0,0,0,0,0,0,0,0,0,0,0,0,0,0,0,0,0,0,0,0,5,3
3,11,0,0,0,0,0,0,0,0,0,0,0,0,0,0,0,0,0,0,0,0,0,0,0,0,0,0,5,3
3,11,0,0,0,0,0,0,0,0,11,11,11,11,11,11,11,11,11,11,0,0,0,0,0,0,0,0,5,3
3,11,0,0,0,0,0,0,0,0,11,3,3,4,4,4,4,3,3,11,0,0,0,0,0,0,0,0,5,3
3,11,0,0,0,0,0,0,0,11,11,3,3,4,0,0,4,3,3,11,0,0,0,0,0,0,0,0,5,3
3,11,0,0,0,0,0,0,11,11,11,3,4,4,4,4,4,4,3,11,0,0,0,0,0,0,0,0,14,3
3,11,0,0,0,0,11,11,11,11,11,4,5,0,0,0,0,5,4,0,0,0,0,0,0,0,0,0,14,3
3,11,0,0,0,0,11,3,3,3,3,4,21,0,0,0,0,21,10,0,0,0,0,0,0,0,0,0,14,3
3,11,0,0,0,0,11,4,0,0,0,0,0,0,0,0,0,0,0,5,0,0,0,0,0,0,0,0,14,3
3,11,0,0,0,0,11,4,0,0,0,0,0,0,0,0,0,0,0,5,0,0,0,0,0,0,0,0,14,3
3,11,0,0,0,0,11,3,3,3,3,4,22,0,0,0,0,22,10,0,0,0,0,0,0,0,0,0,14,3
3,11,0,0,0,0,11,11,11,11,11,4,5,0,0,0,0,5,4,11,0,0,0,0,0,0,0,0,14,3
3,11,0,0,0,0,0,0,11,11,11,3,4,4,4,4,4,4,3,11,11,0,0,0,0,0,0,0,14,3
3,11,0,0,0,0,0,0,0,11,11,3,3,4,0,0,4,3,3,11,11,0,0,0,0,0,0,0,5,3
3,11,0,0,0,0,0,0,0,0,11,3,3,4,4,4,4,3,3,11,0,0,0,0,0,0,0,0,5,3
3,11,0,0,0,0,0,0,0,0,11,11,11,11,11,11,11,11,11,11,0,0,0,0,0,0,0,0,5,3
3,11,0,0,0,0,0,0,0,0,0,0,0,0,0,0,0,0,0,0,0,0,0,0,0,0,0,0,5,3
3,11,0,0,0,0,0,0,0,0,0,0,0,0,0,0,0,0,0,0,0,0,0,0,0,0,0,0,5,3
3,11,0,0,0,0,0,0,0,0,0,0,0,0,0,0,0,0,0,0,0,0,0,0,0,0,0,0,5,3
3,11,0,0,0,0,0,0,0,0,0,0,0,0,0,0,0,0,0,0,0,0,0,0,0,0,0,11,5,3
3,11,11,0,0,0,0,0,0,0,0,0,0,0,0,0,0,0,0,0,0,0,0,0,0,0,11,11,5,3
3,11,11,11,0,0,0,0,0,0,0,0,0,0,0,0,0,0,0,0,20,0,0,0,0,11,11,11,5,3
3,11,11,11,11,11,11,11,11,11,11,11,11,11,11,11,11,11,11,11,11,11,11,11,11,11,11,11,5,3
3,3,3,3,3,3,3,3,3,3,3,3,3,3,3,3,3,3,3,3,3,3,3,3,3,3,3,3,3,3
endlayer

layer
3,3,3,3,3,3,3,3,3,3,3,3,3,3,3,3,3,3,3,3,3,3,3,3,3,3,3,3,3,3
3,11,11,11,11,11,11,11,11,11,11,11,11,11,11,11,11,11,11,11,11,11,11,11,11,11,11,11,5,3
3,11,11,11,11,0,0,0,0,0,0,0,0,0,0,0,0,0,11,11,11,11,11,0,0,0,11,11,5,3
3,11,11,11,0,0,0,0,0,0,0,0,0,0,0,0,0,0,0,11,11,11,0,0,0,0,0,11,5,3
3,11,11,0,0,0,0,0,0,0,0,0,0,0,0,0,0,0,0,0,11,0,0,0,0,0,0,0,5,3
3,11,0,0,0,0,0,0,0,0,0,0,0,0,0,0,0,0,0,0,0,0,0,0,0,0,0,0,5,3
3,11,0,0,0,0,0,0,0,0,0,0,0,0,0,0,0,0,0,0,0,0,0,0,0,0,0,0,5,3
3,11,0,0,0,0,0,0,0,0,0,0,0,0,0,0,0,0,0,0,0,0,0,0,0,0,0,0,5,3
3,11,0,0,0,0,0,0,0,0,11,11,11,11,11,11,11,11,11,11,0,0,0,0,0,0,0,0,5,3
3,11,0,0,0,0,0,0,0,11,11,3,3,4,4,4,4,3,3,11,0,0,0,0,0,0,0,0,5,3
3,11,0,0,0,0,0,0,11,11,11,3,4,0,0,0,0,4,3,11,0,0,0,0,0,0,0,0,5,3
3,11,0,0,0,0,0,11,11,11,11,3,4,4,4,4,4,4,3,11,0,0,0,0,0,0,0,0,5,3
3,11,0,0,0,11,11,11,11,11,11,4,5,4,0,0,4,5,4,0,0,0,0,0,0,0,0,0,5,3
3,11,0,0,0,11,3,3,3,3,3,4,5,0,0,0,0,5,10,0,0,0,0,0,0,0,0,0,5,3
3,11,0,0,0,11,4,0,0,0,0,0,21,0,0,0,0,21,10,11,0,0,0,0,0,0,0,0,5,3
3,11,0,0,0,11,4,0,0,0,0,0,22,0,0,0,0,22,10,11,0,0,0,0,0,0,0,0,5,3
3,11,0,0,0,11,3,3,3,3,3,4,5,0,0,0,0,5,10,11,0,0,0,0,0,0,0,0,5,3
3,11,0,0,0,11,11,11,11,11,11,4,5,4,0,0,4,5,4,11,11,0,0,0,0,0,0,0,5,3
3,11,0,0,0,0,0,11,11,11,11,3,5,4,4,4,4,4,3,11,11,11,0,0,0,0,0,0,5,3
3,11,0,0,0,0,0,0,11,11,11,3,4,0,0,0,0,4,3,11,11,11,0,0,0,0,0,0,5,3
3,11,0,0,0,0,0,0,0,11,11,3,3,4,4,4,4,3,3,11,11,0,0,0,0,0,0,0,5,3
3,11,0,0,0,0,0,0,0,0,11,11,11,11,11,11,11,11,11,11,0,0,0,0,0,0,0,0,5,3
3,11,0,0,0,0,0,0,0,0,0,0,0,0,0,0,0,0,0,0,0,0,0,0,0,0,0,0,5,3
3,11,0,0,0,0,0,0,0,0,0,0,0,0,0,0,0,0,0,0,0,0,0,0,0,0,0,0,5,3
3,11,0,0,0,0,0,0,0,0,0,0,0,0,0,0,0,0,0,0,0,0,0,0,0,0,0,0,5,3
3,11,11,0,0,0,0,0,0,0,0,0,0,0,0,0,0,0,0,0,0,0,0,0,0,0,0,11,5,3
3,11,11,11,0,0,0,0,0,0,0,0,0,0,0,0,0,0,0,0,11,0,0,0,0,0,11,11,5,3
3,11,11,11,11,0,0,0,0,0,0,0,0,0,0,0,0,0,0,11,11,11,0,0,0,11,11,11,5,3
3,11,11,11,11,11,11,11,11,11,11,11,11,11,11,11,11,11,11,11,11,11,11,11,11,11,11,11,5,3
3,3,3,3,3,3,3,3,3,3,3,3,3,3,3,3,3,3,3,3,3,3,3,3,3,3,3,3,3,3
endlayer

layer
3,3,3,3,3,3,3,3,3,3,3,3,3,3,3,3,3,3,3,3,3,3,3,3,3,3,3,3,3,3
3,11,11,11,11,11,11,11,11,11,11,11,11,11,11,11,11,11,11,11,11,11,11,11,11,11,11,11,5,3
3,11,11,11,11,11,11,11,11,11,11,11,11,11,11,11,11,11,11,11,11,11,11,11,11,11,11,11,5,3
3,11,11,11,11,11,11,11,11,11,11,11,11,11,11,11,11,11,11,11,11,11,11,11,11,11,11,11,5,3
3,11,11,11,11,11,11,11,11,11,11,11,11,11,11,11,11,11,11,11,11,11,11,11,11,11,11,11,5,3
3,11,11,11,11,11,11,11,11,11,11,11,11,11,11,11,11,11,11,11,11,11,11,11,11,11,11,11,5,3
3,11,11,11,11,11,11,11,11,11,11,11,11,11,11,11,11,11,11,11,11,11,11,11,11,11,11,11,5,3
3,11,11,11,11,11,11,11,11,11,11,11,11,11,11,11,11,11,11,11,11,11,11,11,11,11,11,11,5,3
3,11,11,11,11,11,11,11,11,11,11,11,11,11,11,11,11,11,11,11,11,11,11,11,11,11,11,11,5,3
3,11,11,11,11,11,11,11,11,11,11,3,3,4,3,3,4,3,3,11,11,11,11,11,11,11,11,11,5,3
3,11,11,11,11,11,11,11,11,11,11,3,4,0,4,4,0,4,3,11,11,11,11,11,11,11,11,11,5,3
3,11,11,11,11,11,11,11,11,11,11,4,4,0,4,4,0,4,4,11,11,11,11,11,11,11,11,11,5,3
3,11,11,11,11,11,11,11,11,11,11,4,5,0,4,4,0,5,23,0,11,11,11,11,11,11,11,11,5,3
3,11,11,11,11,3,3,3,3,3,3,4,5,4,4,4,4,4,4,11,11,11,11,11,11,11,11,11,5,3
3,11,11,11,11,4,0,0,0,0,0,0,5,4,4,4,4,4,4,11,11,11,11,11,11,11,11,11,5,3
3,11,11,11,11,4,0,0,0,0,0,0,5,4,4,4,4,4,4,11,11,11,11,11,11,11,11,11,5,3
3,11,11,11,11,3,3,3,3,3,3,4,5,4,4,4,4,4,4,11,11,11,11,11,11,11,11,11,5,3
3,11,11,11,11,11,11,11,11,11,11,4,5,0,4,4,0,5,4,11,11,11,11,11,11,11,11,11,5,3
3,11,11,11,11,11,11,11,11,11,11,4,4,0,4,4,0,4,3,11,11,11,11,11,11,11,11,11,5,3
3,11,11,11,11,11,11,11,11,11,11,3,4,0,4,4,0,4,3,11,11,11,11,11,11,11,11,11,5,3
3,11,11,11,11,11,11,11,11,11,11,3,3,4,3,3,4,3,3,11,11,11,11,11,11,11,11,11,5,3
3,11,11,11,11,11,11,11,11,11,11,11,11,11,11,11,11,11,11,11,11,11,11,11,11,11,11,11,5,3
3,11,11,11,11,11,11,11,11,11,11,11,11,11,11,11,11,11,11,11,11,11,11,11,11,11,11,11,5,3
3,11,11,11,11,11,11,11,11,11,11,11,11,11,11,11,11,11,11,11,11,11,11,11,11,11,11,11,5,3
3,11,11,11,11,11,11,11,11,11,11,11,11,11,11,11,11,11,11,11,11,11,11,11,11,11,11,11,5,3
3,11,11,11,11,11,11,11,11,11,11,11,11,11,11,11,11,11,11,11,11,11,11,11,11,11,11,11,5,3
3,11,11,11,11,11,11,11,11,11,11,11,11,11,11,11,11,11,11,11,11,11,11,11,11,11,11,11,5,3
3,11,11,11,11,11,11,11,11,11,11,11,11,11,11,11,11,11,11,11,11,11,11,11,11,11,11,11,5,3
3,11,11,11,11,11,11,11,11,11,11,11,11,11,11,11,11,11,11,11,11,11,11,11,11,11,11,11,5,3
3,3,3,3,3,3,3,3,3,3,3,3,3,3,3,3,3,3,3,3,3,3,3,3,3,3,3,3,3,3
endlayer

layer
4,4,4,4,4,4,4,4,4,4,4,4,4,4,4,4,4,4,4,4,4,4,4,4,4,4,4,4,4,4
4,4,4,4,4,4,4,4,4,4,4,4,4,4,4,4,4,4,4,4,4,4,4,4,4,4,4,4,4,4
4,4,4,4,4,4,4,4,4,4,4,4,4,4,4,4,4,4,4,4,4,4,4,4,4,4,4,4,4,4
4,4,4,4,4,4,4,4,4,4,4,4,4,4,4,4,4,4,4,4,4,4,4,4,4,4,4,4,4,4
4,4,4,4,4,4,4,4,4,4,4,4,4,4,4,4,4,4,4,4,4,4,4,4,4,4,4,4,4,4
4,4,4,4,4,4,4,4,4,4,4,4,4,4,4,4,4,4,4,4,4,4,4,4,4,4,4,4,4,4
4,4,4,4,4,4,4,4,4,4,4,4,4,4,4,4,4,4,4,4,4,4,4,4,4,4,4,4,4,4
4,4,4,4,4,4,4,4,4,4,4,4,4,4,4,4,4,4,4,4,4,4,4,4,4,4,4,4,4,4
4,4,4,4,4,4,4,4,4,4,4,4,4,4,4,4,4,4,4,4,4,4,4,4,4,4,4,4,4,4
4,4,4,4,4,4,4,4,4,4,4,4,4,4,4,4,4,4,4,4,4,4,4,4,4,4,4,4,4,4
4,4,4,4,4,4,4,4,4,4,4,4,4,4,4,4,4,4,4,4,4,4,4,4,4,4,4,4,4,4
4,4,4,4,4,4,4,4,4,4,4,4,4,4,4,4,4,4,4,4,4,4,4,4,4,4,4,4,4,4
4,4,4,4,4,4,4,4,4,4,4,4,12,4,4,4,4,12,5,23,4,4,4,4,4,4,4,4,4,4
4,4,4,4,4,4,4,4,4,4,4,4,5,4,4,4,4,4,4,4,4,4,4,4,4,4,4,4,4,4
4,4,4,4,4,0,0,0,0,4,0,0,5,4,4,4,4,4,4,4,4,4,4,4,4,4,4,4,4,4
4,4,4,4,4,0,0,0,0,4,0,0,5,4,4,4,4,4,4,4,4,4,4,4,4,4,4,4,4,4
4,4,4,4,4,4,4,4,4,4,4,4,5,4,4,4,4,4,4,4,4,4,4,4,4,4,4,4,4,4
4,4,4,4,4,4,4,4,4,4,4,4,12,4,4,4,4,12,4,4,4,4,4,4,4,4,4,4,4,4
4,4,4,4,4,4,4,4,4,4,4,4,4,4,4,4,4,4,4,4,4,4,4,4,4,4,4,4,4,4
4,4,4,4,4,4,4,4,4,4,4,4,4,4,4,4,4,4,4,4,4,4,4,4,4,4,4,4,4,4
4,4,4,4,4,4,4,4,4,4,4,4,4,4,4,4,4,4,4,4,4,4,4,4,4,4,4,4,4,4
4,4,4,4,4,4,4,4,4,4,4,4,4,4,4,4,4,4,4,4,4,4,4,4,4,4,4,4,4,4
4,4,4,4,4,4,4,4,4,4,4,4,4,4,4,4,4,4,4,4,4,4,4,4,4,4,4,4,4,4
4,4,4,4,4,4,4,4,4,4,4,4,4,4,4,4,4,4,4,4,4,4,4,4,4,4,4,4,4,4
4,4,4,4,4,4,4,4,4,4,4,4,4,4,4,4,4,4,4,4,4,4,4,4,4,4,4,4,4,4
4,4,4,4,4,4,4,4,4,4,4,4,4,4,4,4,4,4,4,4,4,4,4,4,4,4,4,4,4,4
4,4,4,4,4,4,4,4,4,4,4,4,4,4,4,4,4,4,4,4,4,4,4,4,4,4,4,4,4,4
4,4,4,4,4,4,4,4,4,4,4,4,4,4,4,4,4,4,4,4,4,4,4,4,4,4,4,4,4,4
4,4,4,4,4,4,4,4,4,4,4,4,4,4,4,4,4,4,4,4,4,4,4,4,4,4,4,4,4,4
4,4,4,4,4,4,4,4,4,4,4,4,4,4,4,4,4,4,4,4,4,4,4,4,4,4,4,4,4,4
endlayer

layer
3,3,3,3,3,3,3,3,3,3,3,3,3,3,3,3,3,3,3,3,3,3,3,3,3,3,3,3,3,3
3,3,3,3,3,3,3,3,3,3,3,3,3,3,3,3,3,3,3,3,3,3,3,3,3,3,3,3,3,3
3,3,3,3,3,3,3,3,3,3,3,3,3,3,3,3,3,3,3,3,3,3,3,3,3,3,3,3,3,3
3,3,3,3,3,3,3,3,3,3,3,3,3,3,3,3,3,3,3,3,3,3,3,3,3,3,3,3,3,3
3,3,3,3,3,3,3,3,3,3,3,3,3,3,3,3,3,3,3,3,3,3,3,3,3,3,3,3,3,3
3,3,3,3,3,3,3,3,3,3,3,3,3,3,3,3,3,3,3,3,3,3,3,3,3,3,3,3,3,3
3,3,3,3,3,3,3,3,3,3,3,3,3,3,3,3,3,3,3,3,3,3,3,3,3,3,3,3,3,3
3,3,3,3,3,3,3,3,3,3,3,3,3,3,3,3,3,3,3,3,3,3,3,3,3,3,3,3,3,3
3,3,3,3,3,3,3,3,3,3,3,3,3,3,3,3,3,3,3,3,3,3,3,3,3,3,3,3,3,3
3,3,3,3,3,3,3,3,3,3,3,3,3,3,3,3,3,3,3,3,3,3,3,3,3,3,3,3,3,3
3,3,3,3,3,3,3,3,3,3,3,3,3,3,3,3,3,3,3,3,3,3,3,3,3,3,3,3,3,3
3,3,3,3,3,3,3,3,3,3,3,3,4,3,3,3,3,4,3,3,3,3,3,3,3,3,3,3,3,3
3,3,3,3,3,3,3,3,3,3,3,3,0,3,3,3,3,0,5,5,3,3,3,3,3,3,3,3,3,3
3,3,3,3,3,3,3,3,3,3,3,3,5,3,3,3,3,3,3,3,3,3,3,3,3,3,3,3,3,3
3,3,3,4,0,0,0,0,4,3,0,0,5,3,3,3,3,3,3,3,3,3,3,3,3,3,3,3,3,3
3,3,3,4,0,0,0,0,4,3,0,0,5,3,3,3,3,3,3,3,3,3,3,3,3,3,3,3,3,3
3,3,3,3,3,3,3,3,3,3,3,3,5,3,3,3,3,3,3,3,3,3,3,3,3,3,3,3,3,3
3,3,3,3,3,3,3,3,3,3,3,3,0,3,3,3,3,0,3,3,3,3,3,3,3,3,3,3,3,3
3,3,3,3,3,3,3,3,3,3,3,3,4,3,3,3,3,4,3,3,3,3,3,3,3,3,3,3,3,3
3,3,3,3,3,3,3,3,3,3,3,3,3,3,3,3,3,3,3,3,3,3,3,3,3,3,3,3,3,3
3,3,3,3,3,3,3,3,3,3,3,3,3,3,3,3,3,3,3,3,3,3,3,3,3,3,3,3,3,3
3,3,3,3,3,3,3,3,3,3,3,3,3,3,3,3,3,3,3,3,3,3,3,3,3,3,3,3,3,3
3,3,3,3,3,3,3,3,3,3,3,3,3,3,3,3,3,3,3,3,3,3,3,3,3,3,3,3,3,3
3,3,3,3,3,3,3,3,3,3,3,3,3,3,3,3,3,3,3,3,3,3,3,3,3,3,3,3,3,3
3,3,3,3,3,3,3,3,3,3,3,3,3,3,3,3,3,3,3,3,3,3,3,3,3,3,3,3,3,3
3,3,3,3,3,3,3,3,3,3,3,3,3,3,3,3,3,3,3,3,3,3,3,3,3,3,3,3,3,3
3,3,3,3,3,3,3,3,3,3,3,3,3,3,3,3,3,3,3,3,3,3,3,3,3,3,3,3,3,3
3,3,3,3,3,3,3,3,3,3,3,3,3,3,3,3,3,3,3,3,3,3,3,3,3,3,3,3,3,3
3,3,3,3,3,3,3,3,3,3,3,3,3,3,3,3,3,3,3,3,3,3,3,3,3,3,3,3,3,3
3,3,3,3,3,3,3,3,3,3,3,3,3,3,3,3,3,3,3,3,3,3,3,3,3,3,3,3,3,3
endlayer

layer
3,3,3,3,3,3,3,3,3,3,3,3,3,3,3,3,3,3,3,3,3,3,3,3,3,3,3,3,3,3
3,3,3,3,3,3,3,3,3,3,3,3,3,3,3,3,3,3,3,3,3,3,3,3,3,3,3,3,3,3
3,3,3,3,3,3,3,3,3,3,3,3,3,3,3,3,3,3,3,3,3,3,3,3,3,3,3,3,3,3
3,3,3,3,3,3,3,3,3,3,3,3,3,3,3,3,3,3,3,3,3,3,3,3,3,3,3,3,3,3
3,3,3,3,3,3,3,3,3,3,3,3,3,3,3,3,3,3,3,3,3,3,3,3,3,3,3,3,3,3
3,3,3,3,3,3,3,3,3,3,3,3,3,3,3,3,3,3,3,3,3,3,3,3,3,3,3,3,3,3
3,3,3,3,3,3,3,3,3,3,3,3,3,3,3,3,3,3,3,3,3,3,3,3,3,3,3,3,3,3
3,3,3,3,3,3,3,3,3,3,3,3,3,3,3,3,3,3,3,3,3,3,3,3,3,3,3,3,3,3
3,3,3,3,3,3,3,3,3,3,3,3,3,3,3,3,3,3,3,3,3,3,3,3,3,3,3,3,3,3
3,3,3,3,3,3,3,3,3,3,3,3,3,3,3,3,3,3,3,3,3,3,3,3,3,3,3,3,3,3
3,3,3,3,3,3,3,3,3,3,3,3,3,3,3,3,3,3,3,3,3,3,3,3,3,3,3,3,3,3
3,3,3,3,3,3,3,3,3,3,3,3,4,3,3,3,3,4,3,3,3,3,3,3,3,3,3,3,3,3
3,3,3,3,3,3,3,3,3,3,3,4,0,4,3,3,4,0,4,4,4,3,3,3,3,3,3,3,3,3
3,3,3,3,3,3,3,3,3,3,3,3,5,3,3,3,3,4,3,3,3,3,3,3,3,3,3,3,3,3
3,3,4,0,0,0,0,4,3,3,0,0,5,3,3,3,3,3,3,3,3,3,3,3,3,3,3,3,3,3
3,3,4,0,0,0,0,4,3,3,0,0,5,3,3,3,3,3,3,3,3,3,3,3,3,3,3,3,3,3
3,3,3,3,3,3,3,3,3,3,3,3,5,3,3,3,3,4,3,3,3,3,3,3,3,3,3,3,3,3
3,3,3,3,3,3,3,3,3,3,3,4,0,4,3,3,4,0,4,3,3,3,3,3,3,3,3,3,3,3
3,3,3,3,3,3,3,3,3,3,3,3,4,3,3,3,3,4,3,3,3,3,3,3,3,3,3,3,3,3
3,3,3,3,3,3,3,3,3,3,3,3,3,3,3,3,3,3,3,3,3,3,3,3,3,3,3,3,3,3
3,3,3,3,3,3,3,3,3,3,3,3,3,3,3,3,3,3,3,3,3,3,3,3,3,3,3,3,3,3
3,3,3,3,3,3,3,3,3,3,3,3,3,3,3,3,3,3,3,3,3,3,3,3,3,3,3,3,3,3
3,3,3,3,3,3,3,3,3,3,3,3,3,3,3,3,3,3,3,3,3,3,3,3,3,3,3,3,3,3
3,3,3,3,3,3,3,3,3,3,3,3,3,3,3,3,3,3,3,3,3,3,3,3,3,3,3,3,3,3
3,3,3,3,3,3,3,3,3,3,3,3,3,3,3,3,3,3,3,3,3,3,3,3,3,3,3,3,3,3
3,3,3,3,3,3,3,3,3,3,3,3,3,3,3,3,3,3,3,3,3,3,3,3,3,3,3,3,3,3
3,3,3,3,3,3,3,3,3,3,3,3,3,3,3,3,3,3,3,3,3,3,3,3,3,3,3,3,3,3
3,3,3,3,3,3,3,3,3,3,3,3,3,3,3,3,3,3,3,3,3,3,3,3,3,3,3,3,3,3
3,3,3,3,3,3,3,3,3,3,3,3,3,3,3,3,3,3,3,3,3,3,3,3,3,3,3,3,3,3
3,3,3,3,3,3,3,3,3,3,3,3,3,3,3,3,3,3,3,3,3,3,3,3,3,3,3,3,3,3
endlayer

layer
3,3,3,3,3,3,3,3,3,3,3,3,3,3,3,3,3,3,3,3,3,3,3,3,3,3,3,3,3,3
3,3,3,3,3,3,3,3,3,3,3,3,3,3,3,3,3,3,3,3,3,3,3,3,3,3,3,3,3,3
3,3,3,3,3,3,3,3,3,3,3,3,3,3,3,3,3,3,3,3,3,3,3,3,3,3,3,3,3,3
3,3,3,3,3,3,3,3,3,3,3,3,3,3,3,3,3,3,3,3,3,3,3,3,3,3,3,3,3,3
3,3,3,3,3,3,3,3,3,3,3,3,3,3,3,3,3,3,3,3,3,3,3,3,3,3,3,3,3,3
3,3,3,3,3,3,3,3,3,3,3,3,3,3,3,3,3,3,3,3,3,3,3,3,3,3,3,3,3,3
3,3,3,3,3,3,3,3,3,3,3,3,3,3,3,3,3,3,3,3,3,3,3,3,3,3,3,3,3,3
3,3,3,3,3,3,3,3,3,3,3,3,3,3,3,3,3,3,3,3,3,3,3,3,3,3,3,3,3,3
3,3,3,3,3,3,3,3,3,3,3,3,3,3,3,3,3,3,3,3,3,3,3,3,3,3,3,3,3,3
3,3,3,3,3,3,3,3,3,3,3,3,3,3,3,3,3,3,3,3,3,3,3,3,3,3,3,3,3,3
3,3,3,3,3,3,3,3,3,3,3,3,3,3,3,3,3,3,3,3,3,3,3,3,3,3,3,3,3,3
3,3,3,3,3,3,3,3,3,3,3,3,4,3,3,3,3,4,3,3,3,3,3,3,3,3,3,3,3,3
3,3,3,3,3,3,3,3,3,3,3,4,0,4,3,3,4,0,4,4,4,3,3,3,3,3,3,3,3,3
3,3,3,3,3,3,3,3,3,3,3,3,4,3,3,3,3,4,3,3,3,3,3,3,3,3,3,3,3,3
3,4,0,0,0,0,4,3,3,3,0,0,5,3,3,3,3,3,3,3,3,3,3,3,3,3,3,3,3,3
3,4,0,0,0,0,4,3,3,3,0,0,5,3,3,3,3,3,3,3,3,3,3,3,3,3,3,3,3,3
3,3,3,3,3,3,3,3,3,3,3,3,4,3,3,3,3,4,3,3,3,3,3,3,3,3,3,3,3,3
3,3,3,3,3,3,3,3,3,3,3,4,0,4,3,3,4,0,4,3,3,3,3,3,3,3,3,3,3,3
3,3,3,3,3,3,3,3,3,3,3,3,4,3,3,3,3,4,3,3,3,3,3,3,3,3,3,3,3,3
3,3,3,3,3,3,3,3,3,3,3,3,3,3,3,3,3,3,3,3,3,3,3,3,3,3,3,3,3,3
3,3,3,3,3,3,3,3,3,3,3,3,3,3,3,3,3,3,3,3,3,3,3,3,3,3,3,3,3,3
3,3,3,3,3,3,3,3,3,3,3,3,3,3,3,3,3,3,3,3,3,3,3,3,3,3,3,3,3,3
3,3,3,3,3,3,3,3,3,3,3,3,3,3,3,3,3,3,3,3,3,3,3,3,3,3,3,3,3,3
3,3,3,3,3,3,3,3,3,3,3,3,3,3,3,3,3,3,3,3,3,3,3,3,3,3,3,3,3,3
3,3,3,3,3,3,3,3,3,3,3,3,3,3,3,3,3,3,3,3,3,3,3,3,3,3,3,3,3,3
3,3,3,3,3,3,3,3,3,3,3,3,3,3,3,3,3,3,3,3,3,3,3,3,3,3,3,3,3,3
3,3,3,3,3,3,3,3,3,3,3,3,3,3,3,3,3,3,3,3,3,3,3,3,3,3,3,3,3,3
3,3,3,3,3,3,3,3,3,3,3,3,3,3,3,3,3,3,3,3,3,3,3,3,3,3,3,3,3,3
3,3,3,3,3,3,3,3,3,3,3,3,3,3,3,3,3,3,3,3,3,3,3,3,3,3,3,3,3,3
3,3,3,3,3,3,3,3,3,3,3,3,3,3,3,3,3,3,3,3,3,3,3,3,3,3,3,3,3,3
endlayer

layer
4,4,4,4,4,4,4,4,4,4,4,4,4,4,4,4,4,4,4,4,4,4,4,4,4,4,4,4,4,4
4,4,4,4,4,4,4,4,4,4,4,4,4,4,4,4,4,4,4,4,4,4,4,4,4,4,4,4,4,4
4,4,4,4,4,4,4,4,4,4,4,4,4,4,4,4,4,4,4,4,4,4,4,4,4,4,4,4,4,4
4,4,4,4,4,4,4,4,4,4,4,4,4,4,4,4,4,4,4,4,4,4,4,4,4,4,4,4,4,4
4,4,4,4,4,4,4,4,4,4,4,4,4,4,4,4,4,4,4,4,4,4,4,4,4,4,4,4,4,4
4,4,4,4,4,4,4,4,4,4,4,4,4,4,4,4,4,4,4,4,4,4,4,4,4,4,4,4,4,4
4,4,4,4,4,4,4,4,4,4,4,4,4,4,4,4,4,4,4,4,4,4,4,4,4,4,4,4,4,4
4,4,4,4,4,4,4,4,4,4,4,4,4,4,4,4,4,4,4,4,4,4,4,4,4,4,4,4,4,4
4,4,4,4,4,4,4,4,4,4,4,4,4,4,4,4,4,4,4,4,4,4,4,4,4,4,4,4,4,4
4,4,4,4,4,4,4,4,4,4,4,4,4,4,4,4,4,4,4,4,4,4,4,4,4,4,4,4,4,4
4,4,4,4,4,4,4,4,4,4,4,4,4,4,4,4,4,4,4,4,4,4,4,4,4,4,4,4,4,4
4,4,4,4,4,4,4,4,4,4,4,4,4,4,4,4,4,4,4,4,4,4,4,4,4,4,4,4,4,4
4,4,4,4,4,4,4,4,4,4,4,4,0,4,4,4,4,0,4,4,4,4,4,4,4,4,4,4,4,4
4,4,4,4,4,4,4,4,4,4,4,4,4,4,4,4,4,4,4,4,4,4,4,4,4,4,4,4,4,4
4,0,0,0,0,4,4,4,4,4,0,0,4,4,4,4,4,4,4,4,4,4,4,4,4,4,4,4,4,4
4,0,0,0,0,4,4,4,4,4,0,0,4,4,4,4,4,4,4,4,4,4,4,4,4,4,4,4,4,4
4,4,4,4,4,4,4,4,4,4,4,4,4,4,4,4,4,4,4,4,4,4,4,4,4,4,4,4,4,4
4,4,4,4,4,4,4,4,4,4,4,4,0,4,4,4,4,0,4,4,4,4,4,4,4,4,4,4,4,4
4,4,4,4,4,4,4,4,4,4,4,4,4,4,4,4,4,4,4,4,4,4,4,4,4,4,4,4,4,4
4,4,4,4,4,4,4,4,4,4,4,4,4,4,4,4,4,4,4,4,4,4,4,4,4,4,4,4,4,4
4,4,4,4,4,4,4,4,4,4,4,4,4,4,4,4,4,4,4,4,4,4,4,4,4,4,4,4,4,4
4,4,4,4,4,4,4,4,4,4,4,4,4,4,4,4,4,4,4,4,4,4,4,4,4,4,4,4,4,4
4,4,4,4,4,4,4,4,4,4,4,4,4,4,4,4,4,4,4,4,4,4,4,4,4,4,4,4,4,4
4,4,4,4,4,4,4,4,4,4,4,4,4,4,4,4,4,4,4,4,4,4,4,4,4,4,4,4,4,4
4,4,4,4,4,4,4,4,4,4,4,4,4,4,4,4,4,4,4,4,4,4,4,4,4,4,4,4,4,4
4,4,4,4,4,4,4,4,4,4,4,4,4,4,4,4,4,4,4,4,4,4,4,4,4,4,4,4,4,4
4,4,4,4,4,4,4,4,4,4,4,4,4,4,4,4,4,4,4,4,4,4,4,4,4,4,4,4,4,4
4,4,4,4,4,4,4,4,4,4,4,4,4,4,4,4,4,4,4,4,4,4,4,4,4,4,4,4,4,4
4,4,4,4,4,4,4,4,4,4,4,4,4,4,4,4,4,4,4,4,4,4,4,4,4,4,4,4,4,4
4,4,4,4,4,4,4,4,4,4,4,4,4,4,4,4,4,4,4,4,4,4,4,4,4,4,4,4,4,4
endlayer

layer
1,1,1,1,1,1,1,1,1,1,1,1,1,1,0,0,1,1,1,1,1,1,1,1,1,1,1,1,1,1
1,5,5,5,5,5,5,5,5,5,5,5,5,4,0,0,4,5,5,5,5,5,5,5,5,5,5,5,5,1
1,5,4,4,4,4,4,4,4,4,4,4,4,4,0,0,4,4,4,4,4,4,4,4,4,4,4,4,5,1
1,5,4,5,5,5,5,5,5,5,5,5,5,4,0,0,4,5,5,5,5,5,5,5,5,5,5,4,5,1
1,5,4,5,5,5,5,5,5,5,5,5,5,5,0,0,5,5,5,5,5,5,5,5,5,5,5,4,5,1
1,5,4,5,5,0,0,0,0,0,0,0,0,5,0,0,5,0,0,0,0,0,0,0,0,5,5,4,5,1
1,5,4,5,5,0,5,5,5,5,5,5,0,5,0,0,5,0,5,5,5,5,5,5,0,5,5,4,5,1
1,5,4,5,5,0,5,0,0,0,5,5,0,5,0,0,5,0,5,5,0,0,0,5,0,5,5,4,5,1
1,5,4,5,5,0,5,0,5,0,0,0,0,5,0,0,5,0,0,0,0,5,0,5,0,5,5,4,5,1
1,5,4,5,5,0,5,0,5,0,5,5,5,5,0,0,5,5,5,5,0,5,0,5,0,5,5,4,5,1
1,5,4,5,5,0,5,0,5,0,0,0,0,0,0,0,0,0,0,0,0,5,0,5,0,5,5,4,5,1
1,5,4,5,5,0,5,0,5,5,5,5,4,5,5,5,5,4,5,5,5,5,0,5,0,5,5,4,5,1
1,5,4,5,5,0,5,0,0,0,0,0,0,4,5,5,4,0,0,0,0,0,0,5,0,5,5,4,5,1
1,4,4,4,5,0,5,5,5,5,5,5,4,5,5,5,5,4,5,5,5,5,5,5,0,5,4,4,4,1
0,0,0,0,4,0,5,5,5,5,0,0,0,0,0,0,0,0,0,0,0,0,0,0,0,0,0,0,0,0
0,0,0,0,4,0,5,5,5,5,0,0,0,0,0,0,0,0,0,0,0,0,0,0,0,0,0,0,0,0
1,4,4,4,5,0,5,5,5,5,5,5,4,5,5,5,5,4,5,5,5,5,5,5,0,5,4,4,4,1
1,5,4,5,5,0,5,0,0,0,0,0,0,4,5,5,4,0,0,0,0,0,0,5,0,5,5,4,5,1
1,5,4,5,5,0,5,0,5,5,5,5,4,5,5,5,5,4,5,5,5,5,0,5,0,5,5,4,5,1
1,5,4,5,5,0,5,0,5,0,0,0,0,0,0,0,0,0,0,0,0,5,0,5,0,5,5,4,5,1
1,5,4,5,5,0,5,0,5,0,5,5,5,5,0,0,5,5,5,5,0,5,0,5,0,5,5,4,5,1
1,5,4,5,5,0,5,0,5,0,0,0,0,5,0,0,5,0,0,0,0,5,0,5,0,5,5,4,5,1
1,5,4,5,5,0,5,0,0,0,5,5,0,5,0,0,5,0,5,5,0,0,0,5,0,5,5,4,5,1
1,5,4,5,5,0,5,5,5,5,5,5,0,5,0,0,5,0,5,5,5,5,5,5,0,5,5,4,5,1
1,5,4,5,5,0,0,0,0,0,0,0,0,5,0,0,5,0,0,0,0,0,0,0,0,5,5,4,5,1
1,5,4,5,5,5,5,5,5,5,5,5,5,5,0,0,5,5,5,5,5,5,5,5,5,5,5,4,5,1
1,5,4,5,5,5,5,5,5,5,5,5,5,4,0,0,4,5,5,5,5,5,5,5,5,5,5,4,5,1
1,5,4,4,4,4,4,4,4,4,4,4,4,4,0,0,4,4,4,4,4,4,4,4,4,4,4,4,5,1
1,5,5,5,5,5,5,5,5,5,5,5,5,4,0,0,4,5,5,5,5,5,5,5,5,5,5,5,5,1
1,1,1,1,1,1,1,1,1,1,1,1,1,1,0,0,1,1,1,1,1,1,1,1,1,1,1,1,1,1
endlayer

layer
1,1,1,1,1,1,1,1,1,1,1,1,1,0,0,0,0,1,1,1,1,1,1,1,1,1,1,1,1,1
1,1,1,1,1,1,1,1,1,1,1,1,1,4,0,0,4,1,1,1,1,1,1,1,1,1,1,1,1,1
1,1,5,5,5,5,5,5,5,5,5,5,5,4,0,0,4,5,5,5,5,5,5,5,5,5,5,5,1,1
1,1,5,4,4,4,4,4,4,4,4,4,4,4,0,0,4,4,4,4,4,4,4,4,4,4,4,5,1,1
1,1,5,4,5,5,5,5,5,5,5,5,5,5,0,0,5,5,5,5,5,5,5,5,5,5,4,5,1,1
1,1,5,4,5,0,0,0,0,0,0,0,0,5,0,0,5,0,0,0,0,0,0,0,0,5,4,5,1,1
1,1,5,4,5,0,5,5,5,5,5,5,0,5,0,0,5,0,5,5,5,5,5,5,0,5,4,5,1,1
1,1,5,4,5,0,5,0,0,0,5,5,0,5,0,0,5,0,5,5,0,0,0,5,0,5,4,5,1,1
1,1,5,4,5,0,5,0,5,0,0,0,0,5,0,0,5,0,0,0,0,5,0,5,0,5,4,5,1,1
1,1,5,4,5,0,5,0,5,0,5,5,5,5,0,0,5,5,5,5,0,5,0,5,0,5,4,5,1,1
1,1,5,4,5,0,5,0,5,0,0,0,0,0,0,0,0,0,0,0,0,5,0,5,0,5,4,5,1,1
1,1,5,4,5,0,5,0,5,5,5,5,4,5,5,5,5,4,5,5,5,5,0,5,0,5,4,5,1,1
1,1,5,4,5,0,5,0,0,0,0,0,0,4,5,5,4,0,0,0,0,0,0,5,0,5,4,5,1,1
0,4,4,4,5,0,5,5,5,5,5,5,4,5,5,5,5,4,5,5,5,5,5,5,0,5,4,4,4,0
0,0,0,0,4,0,5,5,5,5,0,0,0,0,0,0,0,0,0,0,0,0,0,0,0,0,0,0,0,0
0,0,0,0,4,0,5,5,5,5,0,0,0,0,0,0,0,0,0,0,0,0,0,0,0,0,0,0,0,0
0,4,4,4,5,0,5,5,5,5,5,5,4,5,5,5,5,4,5,5,5,5,5,5,0,5,4,4,4,0
1,1,5,4,5,0,5,0,0,0,0,0,0,4,5,5,4,0,0,0,0,0,0,5,0,5,4,5,1,1
1,1,5,4,5,0,5,0,5,5,5,5,4,5,5,5,5,4,5,5,5,5,0,5,0,5,4,5,1,1
1,1,5,4,5,0,5,0,5,0,0,0,0,0,0,0,0,0,0,0,0,5,0,5,0,5,4,5,1,1
1,1,5,4,5,0,5,0,5,0,5,5,5,5,0,0,5,5,5,5,0,5,0,5,0,5,4,5,1,1
1,1,5,4,5,0,5,0,5,0,0,0,0,5,0,0,5,0,0,0,0,5,0,5,0,5,4,5,1,1
1,1,5,4,5,0,5,0,0,0,5,5,0,5,0,0,5,0,5,5,0,0,0,5,0,5,4,5,1,1
1,1,5,4,5,0,5,5,5,5,5,5,0,5,0,0,5,0,5,5,5,5,5,5,0,5,4,5,1,1
1,1,5,4,5,0,0,0,0,0,0,0,0,5,0,0,5,0,0,0,0,0,0,0,0,5,4,5,1,1
1,1,5,4,5,5,5,5,5,5,5,5,5,5,0,0,5,5,5,5,5,5,5,5,5,5,4,5,1,1
1,1,5,4,4,4,4,4,4,4,4,4,4,4,0,0,4,4,4,4,4,4,4,4,4,4,4,5,1,1
1,1,5,5,5,5,5,5,5,5,5,5,5,4,0,0,4,5,5,5,5,5,5,5,5,5,5,5,1,1
1,1,1,1,1,1,1,1,1,1,1,1,1,4,0,0,4,1,1,1,1,1,1,1,1,1,1,1,1,1
1,1,1,1,1,1,1,1,1,1,1,1,1,0,0,0,0,1,1,1,1,1,1,1,1,1,1,1,1,1
endlayer

layer
1,1,1,1,1,1,1,1,1,1,1,1,0,0,0,0,0,0,1,1,1,1,1,1,1,1,1,1,1,1
1,1,1,1,1,1,1,1,1,1,1,1,1,4,0,0,4,1,1,1,1,1,1,1,1,1,1,1,1,1
1,1,1,1,1,1,1,1,1,1,1,1,1,4,0,0,4,1,1,1,1,1,1,1,1,1,1,1,1,1
1,1,1,4,4,4,4,4,4,4,4,4,4,4,0,0,4,4,4,4,4,4,4,4,4,4,4,1,1,1
1,1,1,4,5,5,5,5,5,5,5,5,5,5,0,0,5,5,5,5,5,5,5,5,5,5,4,1,1,1
1,1,1,4,5,0,0,0,6,0,0,0,0,5,0,0,5,0,0,0,0,6,0,0,0,5,4,1,1,1
1,1,1,4,5,0,5,5,5,5,5,5,0,5,0,0,5,0,5,5,5,5,5,5,0,5,4,1,1,1
1,1,1,4,5,0,5,0,0,0,5,5,0,5,0,0,5,0,5,5,0,0,0,5,0,5,4,1,1,1
1,1,1,4,5,0,5,0,5,0,0,0,0,5,0,0,5,0,0,0,0,5,0,5,0,5,4,1,1,1
1,1,1,4,5,0,5,0,5,0,5,5,5,5,0,0,5,5,5,5,0,5,0,5,0,5,4,1,1,1
1,1,1,4,5,0,5,0,5,0,0,0,0,0,0,0,0,0,0,0,0,5,0,5,0,5,4,1,1,1
1,1,1,4,5,0,5,0,5,5,5,5,4,5,5,5,5,4,5,5,5,5,0,5,0,5,4,1,1,1
0,1,1,4,5,0,5,0,0,0,0,0,0,4,5,5,4,0,0,0,0,0,0,5,0,5,4,1,1,0
0,4,4,4,5,0,5,5,5,5,5,5,4,5,5,5,5,4,5,5,5,5,5,5,0,5,4,4,4,0
0,0,0,0,5,0,5,5,5,5,0,0,0,0,0,0,0,0,0,0,0,0,0,0,0,0,0,0,0,0
0,0,0,0,5,0,5,5,5,5,0,0,0,0,0,0,0,0,0,0,0,0,0,0,0,0,0,0,0,0
0,4,4,4,5,0,5,5,5,5,5,5,4,5,5,5,5,4,5,5,5,5,5,5,0,5,4,4,4,0
0,1,1,4,5,0,5,0,0,0,0,0,0,4,5,5,4,0,0,0,0,0,0,5,0,5,4,1,1,0
1,1,1,4,5,0,5,0,5,5,5,5,4,5,5,5,5,4,5,5,5,5,0,5,0,5,4,1,1,1
1,1,1,4,5,0,5,0,5,0,0,0,0,0,0,0,0,0,0,0,0,5,0,5,0,5,4,1,1,1
1,1,1,4,5,0,5,0,5,0,5,5,5,5,0,0,5,5,5,5,0,5,0,5,0,5,4,1,1,1
1,1,1,4,5,0,5,0,5,0,0,0,0,5,0,0,5,0,0,0,0,5,0,5,0,5,4,1,1,1
1,1,1,4,5,0,5,0,0,0,5,5,0,5,0,0,5,0,5,5,0,0,0,5,0,5,4,1,1,1
1,1,1,4,5,0,5,5,5,5,5,5,0,5,0,0,5,0,5,5,5,5,5,5,0,5,4,1,1,1
1,1,1,4,5,0,0,0,6,0,0,0,0,5,0,0,5,0,0,0,0,6,0,0,0,5,4,1,1,1
1,1,1,4,5,5,5,5,5,5,5,5,5,5,0,0,5,5,5,5,5,5,5,5,5,5,4,1,1,1
1,1,1,4,4,4,4,4,4,4,4,4,4,4,0,0,4,4,4,4,4,4,4,4,4,4,4,1,1,1
1,1,1,1,1,1,1,1,1,1,1,1,1,4,1,1,4,1,1,1,1,1,1,1,1,1,1,1,1,1
1,1,1,1,1,1,1,1,1,1,1,1,1,4,1,1,4,1,1,1,1,1,1,1,1,1,1,1,1,1
1,1,1,1,1,1,1,1,1,1,1,1,1,0,1,1,0,1,1,1,1,1,1,1,1,1,1,1,1,1
endlayer

layer
1,1,1,1,1,1,1,1,1,1,1,0,0,0,0,0,0,0,0,1,1,1,1,1,1,1,1,1,1,1
1,1,1,1,1,1,1,1,1,1,1,1,1,1,4,4,1,1,1,1,1,1,1,1,1,1,1,1,1,1
1,1,1,1,1,1,1,1,1,1,1,1,1,1,4,4,1,1,1,1,1,1,1,1,1,1,1,1,1,1
1,1,1,1,1,1,1,1,1,1,1,1,1,1,4,4,1,1,1,1,1,1,1,1,1,1,1,1,1,1
1,1,1,1,5,5,5,5,5,5,5,5,5,5,4,4,5,5,5,5,5,5,5,5,5,5,1,1,1,1
1,1,1,1,5,4,4,4,4,4,4,4,4,4,4,4,4,4,4,4,4,4,4,4,4,5,1,1,1,1
1,1,1,1,5,4,5,5,5,5,5,5,4,5,4,4,5,4,5,5,5,5,5,5,4,5,1,1,1,1
1,1,1,1,5,4,5,4,4,4,5,5,4,5,4,4,5,4,5,5,4,4,4,5,4,5,1,1,1,1
1,1,1,1,5,4,5,4,5,4,4,4,4,5,4,4,5,4,4,4,4,5,4,5,4,5,1,1,1,1
1,1,1,1,5,4,5,4,5,4,5,5,5,5,4,4,5,5,5,5,4,5,4,5,4,5,1,1,1,1
1,1,1,1,5,4,5,4,5,4,4,4,4,4,4,4,4,4,4,4,4,5,4,5,4,5,1,1,1,1
0,1,1,1,5,4,5,4,5,5,5,5,4,5,5,5,5,4,5,5,5,5,4,5,4,5,1,1,1,0
0,1,1,1,5,4,5,4,4,4,4,4,0,4,5,5,4,0,4,4,4,4,4,5,4,5,1,1,1,0
0,1,1,1,5,4,5,5,5,5,5,5,4,5,5,5,5,4,5,5,5,5,5,5,4,5,1,1,1,0
0,4,4,4,5,4,5,5,5,5,4,4,4,4,4,4,4,4,4,4,4,4,4,4,4,4,4,4,4,0
0,4,4,4,5,4,5,5,5,5,4,4,4,4,4,4,4,4,4,4,4,4,4,4,4,4,4,4,4,0
0,1,1,1,5,4,5,5,5,5,5,5,4,5,5,5,5,4,5,5,5,5,5,5,4,5,1,1,1,0
0,1,1,1,5,4,5,4,4,4,4,4,0,4,5,5,4,0,4,4,4,4,4,5,4,5,1,1,1,0
0,1,1,1,5,4,5,4,5,5,5,5,4,5,5,5,5,4,5,5,5,5,4,5,4,5,1,1,1,0
1,1,1,1,5,4,5,4,5,4,4,4,4,4,4,4,4,4,4,4,4,5,4,5,4,5,1,1,1,1
1,1,1,1,5,4,5,4,5,4,5,5,5,5,4,4,5,5,5,5,4,5,4,5,4,5,1,1,1,1
1,1,1,1,5,4,5,4,5,4,4,4,4,5,4,4,5,4,4,4,4,5,4,5,4,5,1,1,1,1
1,1,1,1,5,4,5,4,4,4,5,5,4,5,4,4,5,4,5,5,4,4,4,5,4,5,1,1,1,1
1,1,1,1,5,4,5,5,5,5,5,5,4,5,4,4,5,4,5,5,5,5,5,5,4,5,1,1,1,1
1,1,1,1,5,4,4,4,4,4,4,4,4,4,4,4,4,4,4,4,4,4,4,4,4,5,1,1,1,1
1,1,1,1,5,5,5,5,5,5,5,5,5,5,4,4,5,5,5,5,5,5,5,5,5,5,1,1,1,1
1,1,1,1,1,1,1,1,1,1,1,1,1,1,4,4,1,1,1,1,1,1,1,1,1,1,1,1,1,1
1,1,1,1,1,1,1,1,1,1,1,1,1,1,4,4,1,1,1,1,1,1,1,1,1,1,1,1,1,1
1,1,1,1,1,1,1,1,1,1,1,1,1,1,4,4,1,1,1,1,1,1,1,1,1,1,1,1,1,1
1,1,1,1,1,1,1,1,1,1,1,0,0,0,0,0,0,0,0,1,1,1,1,1,1,1,1,1,1,1
endlayer

layer
1,1,1,1,1,1,1,1,1,1,0,0,0,0,0,0,0,0,0,0,1,1,1,1,1,1,1,1,1,1
1,1,1,1,1,1,1,1,1,1,1,1,1,1,1,1,1,1,1,1,1,1,1,1,1,1,1,1,1,1
1,1,1,1,1,1,1,1,1,1,1,1,1,1,1,1,1,1,1,1,1,1,1,1,1,1,1,1,1,1
1,1,1,1,1,1,1,1,1,1,1,1,1,1,1,1,1,1,1,1,1,1,1,1,1,1,1,1,1,1
1,1,1,1,1,1,1,1,1,1,1,1,1,1,1,1,1,1,1,1,1,1,1,1,1,1,1,1,1,1
1,1,1,1,1,5,5,5,5,5,5,5,5,5,5,5,5,5,5,5,5,5,5,5,5,1,1,1,1,1
1,1,1,1,1,5,4,4,4,4,4,4,4,4,4,4,4,4,4,4,4,4,4,4,5,1,1,1,1,1
1,1,1,1,1,5,4,5,5,5,5,5,5,5,5,5,5,5,5,5,5,5,5,4,5,1,1,1,1,1
1,1,1,1,1,5,4,5,5,5,5,5,5,5,5,5,5,5,5,5,5,5,5,4,5,1,1,1,1,1
1,1,1,1,1,5,4,5,5,5,5,5,5,5,5,5,5,5,5,5,5,5,5,4,5,1,1,1,1,1
0,1,1,1,1,5,4,5,5,5,5,5,5,5,5,5,5,5,5,5,5,5,5,4,5,1,1,1,1,0
0,1,1,1,1,5,4,5,5,5,5,5,4,5,5,5,5,4,5,5,5,5,5,4,5,1,1,1,1,0
0,1,1,1,1,5,4,5,5,5,5,4,0,4,5,5,4,0,4,5,5,5,5,4,5,1,1,1,1,0
0,1,1,1,1,5,4,5,5,5,5,5,4,5,5,5,5,4,5,5,5,5,5,4,5,1,1,1,1,0
0,1,1,1,1,5,4,5,5,5,5,5,5,5,5,5,5,5,5,5,5,5,5,4,5,1,1,1,1,0
0,1,1,1,1,5,4,5,5,5,5,5,5,5,5,5,5,5,5,5,5,5,5,4,5,1,1,1,1,0
0,1,1,1,1,5,4,5,5,5,5,5,4,5,5,5,5,4,5,5,5,5,5,4,5,1,1,1,1,0
0,1,1,1,1,5,4,5,5,5,5,4,0,4,5,5,4,0,4,5,5,5,5,4,5,1,1,1,1,0
0,1,1,1,1,5,4,5,5,5,5,5,4,5,5,5,5,4,5,5,5,5,5,4,5,1,1,1,1,0
0,1,1,1,1,5,4,5,5,5,5,5,5,5,5,5,5,5,5,5,5,5,5,4,5,1,1,1,1,0
1,1,1,1,1,5,4,5,5,5,5,5,5,5,5,5,5,5,5,5,5,5,5,4,5,1,1,1,1,1
1,1,1,1,1,5,4,5,5,5,5,5,5,5,5,5,5,5,5,5,5,5,5,4,5,1,1,1,1,1
1,1,1,1,1,5,4,5,5,5,5,5,5,5,5,5,5,5,5,5,5,5,5,4,5,1,1,1,1,1
1,1,1,1,1,5,4,4,4,4,4,4,4,4,4,4,4,4,4,4,4,4,4,4,5,1,1,1,1,1
1,1,1,1,1,5,5,5,5,5,5,5,5,5,5,5,5,5,5,5,5,5,5,5,5,1,1,1,1,1
1,1,1,1,1,1,1,1,1,1,1,1,1,1,1,1,1,1,1,1,1,1,1,1,1,1,1,1,1,1
1,1,1,1,1,1,1,1,1,1,1,1,1,1,1,1,1,1,1,1,1,1,1,1,1,1,1,1,1,1
1,1,1,1,1,1,1,1,1,1,1,1,1,1,1,1,1,1,1,1,1,1,1,1,1,1,1,1,1,1
1,1,1,1,1,1,1,1,1,1,1,1,1,1,1,1,1,1,1,1,1,1,1,1,1,1,1,1,1,1
1,1,1,1,1,1,1,1,1,1,0,0,0,0,0,0,0,0,0,0,1,1,1,1,1,1,1,1,1,1
endlayer

layer
1,1,1,1,1,1,1,1,1,0,0,0,0,0,0,0,0,0,0,0,0,1,1,1,1,1,1,1,1,1
1,1,1,1,1,1,1,1,1,1,1,1,1,1,1,1,1,1,1,1,1,1,1,1,1,1,1,1,1,1
1,1,1,1,1,1,1,1,1,1,1,1,1,1,1,1,1,1,1,1,1,1,1,1,1,1,1,1,1,1
1,1,1,1,1,1,1,1,1,1,1,1,1,1,1,1,1,1,1,1,1,1,1,1,1,1,1,1,1,1
1,1,1,1,1,1,1,1,1,1,1,1,1,1,1,1,1,1,1,1,1,1,1,1,1,1,1,1,1,1
1,1,1,1,1,1,1,1,1,1,1,1,1,1,1,1,1,1,1,1,1,1,1,1,1,1,1,1,1,1
1,1,1,1,1,1,4,4,4,4,4,4,4,4,4,4,4,4,4,4,4,4,4,4,1,1,1,1,1,1
1,1,1,1,1,1,4,5,5,5,5,5,5,5,5,5,5,5,5,5,5,5,5,4,1,1,1,1,1,1
1,1,1,1,1,1,4,5,5,5,5,5,5,5,5,5,5,5,5,5,5,5,5,4,1,1,1,1,1,1
0,1,1,1,1,1,4,5,5,5,5,5,5,5,5,5,5,5,5,5,5,5,5,4,1,1,1,1,1,0
0,1,1,1,1,1,4,5,5,5,5,5,5,5,5,5,5,5,5,5,5,5,5,4,1,1,1,1,1,0
0,1,1,1,1,1,4,5,5,5,5,5,4,5,5,5,5,4,5,5,5,5,5,4,1,1,1,1,1,0
0,1,1,1,1,1,4,5,5,5,5,4,0,4,5,5,4,0,4,5,5,5,5,4,1,1,1,1,1,0
0,1,1,1,1,1,4,5,5,5,5,5,4,5,5,5,5,4,5,5,5,5,5,4,1,1,1,1,1,0
0,1,1,1,1,1,4,5,5,5,5,5,5,5,5,5,5,5,5,5,5,5,5,4,1,1,1,1,1,0
0,1,1,1,1,1,4,5,5,5,5,5,5,5,5,5,5,5,5,5,5,5,5,4,1,1,1,1,1,0
0,1,1,1,1,1,4,5,5,5,5,5,4,5,5,5,5,4,5,5,5,5,5,4,1,1,1,1,1,0
0,1,1,1,1,1,4,5,5,5,5,4,0,4,5,5,4,0,4,5,5,5,5,4,1,1,1,1,1,0
0,1,1,1,1,1,4,5,5,5,5,5,4,5,5,5,5,4,5,5,5,5,5,4,1,1,1,1,1,0
0,1,1,1,1,1,4,5,5,5,5,5,5,5,5,5,5,5,5,5,5,5,5,4,1,1,1,1,1,0
0,1,1,1,1,1,4,5,5,5,5,5,5,5,5,5,5,5,5,5,5,5,5,4,1,1,1,1,1,0
1,1,1,1,1,1,4,5,5,5,5,5,5,5,5,5,5,5,5,5,5,5,5,4,1,1,1,1,1,1
1,1,1,1,1,1,4,5,5,5,5,5,5,5,5,5,5,5,5,5,5,5,5,4,1,1,1,1,1,1
1,1,1,1,1,1,4,4,4,4,4,4,4,4,4,4,4,4,4,4,4,4,4,4,1,1,1,1,1,1
1,1,1,1,1,1,1,1,1,1,1,1,1,1,1,1,1,1,1,1,1,1,1,1,1,1,1,1,1,1
1,1,1,1,1,1,1,1,1,1,1,1,1,1,1,1,1,1,1,1,1,1,1,1,1,1,1,1,1,1
1,1,1,1,1,1,1,1,1,1,1,1,1,1,1,1,1,1,1,1,1,1,1,1,1,1,1,1,1,1
1,1,1,1,1,1,1,1,1,1,1,1,1,1,1,1,1,1,1,1,1,1,1,1,1,1,1,1,1,1
1,1,1,1,1,1,1,1,1,1,1,1,1,1,1,1,1,1,1,1,1,1,1,1,1,1,1,1,1,1
1,1,1,1,1,1,1,1,1,0,0,0,0,0,0,0,0,0,0,0,0,1,1,1,1,1,1,1,1,1
endlayer

layer
1,1,1,1,1,1,1,1,0,0,0,0,0,0,0,0,0,0,0,0,0,0,1,1,1,1,1,1,1,1
1,1,1,1,1,1,1,1,1,1,1,1,1,1,1,1,1,1,1,1,1,1,1,1,1,1,1,1,1,1
1,1,1,1,1,1,1,1,1,1,1,1,1,1,1,1,1,1,1,1,1,1,1,1,1,1,1,1,1,1
1,1,1,1,1,1,1,1,1,1,1,1,1,1,1,1,1,1,1,1,1,1,1,1,1,1,1,1,1,1
1,1,1,1,1,1,1,1,1,1,1,1,1,1,1,1,1,1,1,1,1,1,1,1,1,1,1,1,1,1
1,1,1,1,1,1,1,1,1,1,1,1,1,1,1,1,1,1,1,1,1,1,1,1,1,1,1,1,1,1
1,1,1,1,1,1,1,1,1,1,1,1,1,1,1,1,1,1,1,1,1,1,1,1,1,1,1,1,1,1
1,1,1,1,1,1,1,5,5,5,5,5,5,5,5,5,5,5,5,5,5,5,5,1,1,1,1,1,1,1
0,1,1,1,1,1,1,5,4,4,4,4,4,4,4,4,4,4,4,4,4,4,5,1,1,1,1,1,1,0
0,1,1,1,1,1,1,5,4,5,5,5,5,5,5,5,5,5,5,5,5,4,5,1,1,1,1,1,1,0
0,1,1,1,1,1,1,5,4,5,5,5,5,5,5,5,5,5,5,5,5,4,5,1,1,1,1,1,1,0
0,1,1,1,1,1,1,5,4,5,5,5,4,5,5,5,5,4,5,5,5,4,5,1,1,1,1,1,1,0
0,1,1,1,1,1,1,5,4,5,5,4,0,4,5,5,4,0,4,5,5,4,5,1,1,1,1,1,1,0
0,1,1,1,1,1,1,5,4,5,5,5,4,5,5,5,5,4,5,5,5,4,5,1,1,1,1,1,1,0
0,1,1,1,1,1,1,5,4,5,5,5,5,5,5,5,5,5,5,5,5,4,5,1,1,1,1,1,1,0
0,1,1,1,1,1,1,5,4,5,5,5,5,5,5,5,5,5,5,5,5,4,5,1,1,1,1,1,1,0
0,1,1,1,1,1,1,5,4,5,5,5,4,5,5,5,5,4,5,5,5,4,5,1,1,1,1,1,1,0
0,1,1,1,1,1,1,5,4,5,5,4,0,4,5,5,4,0,4,5,5,4,5,1,1,1,1,1,1,0
0,1,1,1,1,1,1,5,4,5,5,5,4,5,5,5,5,4,5,5,5,4,5,1,1,1,1,1,1,0
0,1,1,1,1,1,1,5,4,5,5,5,5,5,5,5,5,5,5,5,5,4,5,1,1,1,1,1,1,0
0,1,1,1,1,1,1,5,4,5,5,5,5,5,5,5,5,5,5,5,5,4,5,1,1,1,1,1,1,0
0,1,1,1,1,1,1,5,4,4,4,4,4,4,4,4,4,4,4,4,4,4,5,1,1,1,1,1,1,0
1,1,1,1,1,1,1,5,5,5,5,5,5,5,5,5,5,5,5,5,5,5,5,1,1,1,1,1,1,1
1,1,1,1,1,1,1,1,1,1,1,1,1,1,1,1,1,1,1,1,1,1,1,1,1,1,1,1,1,1
1,1,1,1,1,1,1,1,1,1,1,1,1,1,1,1,1,1,1,1,1,1,1,1,1,1,1,1,1,1
1,1,1,1,1,1,1,1,1,1,1,1,1,1,1,1,1,1,1,1,1,1,1,1,1,1,1,1,1,1
1,1,1,1,1,1,1,1,1,1,1,1,1,1,1,1,1,1,1,1,1,1,1,1,1,1,1,1,1,1
1,1,1,1,1,1,1,1,1,1,1,1,1,1,1,1,1,1,1,1,1,1,1,1,1,1,1,1,1,1
1,1,1,1,1,1,1,1,1,1,1,1,1,1,1,1,1,1,1,1,1,1,1,1,1,1,1,1,1,1
1,1,1,1,1,1,1,1,0,0,0,0,0,0,0,0,0,0,0,0,0,0,1,1,1,1,1,1,1,1
endlayer

layer
1,1,1,1,1,1,1,0,0,0,0,0,0,0,0,0,0,0,0,0,0,0,0,1,1,1,1,1,1,1
1,1,1,1,1,1,1,1,1,1,1,1,1,1,1,1,1,1,1,1,1,1,1,1,1,1,1,1,1,1
1,1,1,1,1,1,1,1,1,1,1,1,1,1,1,1,1,1,1,1,1,1,1,1,1,1,1,1,1,1
1,1,1,1,1,1,1,1,1,1,1,1,1,1,1,1,1,1,1,1,1,1,1,1,1,1,1,1,1,1
1,1,1,1,1,1,1,1,1,1,1,1,1,1,1,1,1,1,1,1,1,1,1,1,1,1,1,1,1,1
1,1,1,1,1,1,1,1,1,1,1,1,1,1,1,1,1,1,1,1,1,1,1,1,1,1,1,1,1,1
1,1,1,1,1,1,1,1,1,1,1,1,1,1,1,1,1,1,1,1,1,1,1,1,1,1,1,1,1,1
0,1,1,1,1,1,1,1,1,1,1,1,1,1,1,1,1,1,1,1,1,1,1,1,1,1,1,1,1,0
0,1,1,1,1,1,1,1,5,5,5,5,5,5,5,5,5,5,5,5,5,5,1,1,1,1,1,1,1,0
0,1,1,1,1,1,1,1,5,4,4,4,4,4,4,4,4,4,4,4,4,5,1,1,1,1,1,1,1,0
0,1,1,1,1,1,1,1,5,4,5,5,5,5,5,5,5,5,5,5,4,5,1,1,1,1,1,1,1,0
0,1,1,1,1,1,1,1,5,4,5,5,4,5,5,5,5,4,5,5,4,5,1,1,1,1,1,1,1,0
0,1,1,1,1,1,1,1,5,4,5,4,0,4,5,5,4,0,4,5,4,5,1,1,1,1,1,1,1,0
0,1,1,1,1,1,1,1,5,4,5,5,4,5,5,5,5,4,5,5,4,5,1,1,1,1,1,1,1,0
0,1,1,1,1,1,1,1,5,4,5,5,5,5,5,5,5,5,5,5,4,5,1,1,1,1,1,1,1,0
0,1,1,1,1,1,1,1,5,4,5,5,5,5,5,5,5,5,5,5,4,5,1,1,1,1,1,1,1,0
0,1,1,1,1,1,1,1,5,4,5,5,4,5,5,5,5,4,5,5,4,5,1,1,1,1,1,1,1,0
0,1,1,1,1,1,1,1,5,4,5,4,0,4,5,5,4,0,4,5,4,5,1,1,1,1,1,1,1,0
0,1,1,1,1,1,1,1,5,4,5,5,4,5,5,5,5,4,5,5,4,5,1,1,1,1,1,1,1,0
0,1,1,1,1,1,1,1,5,4,5,5,5,5,5,5,5,5,5,5,4,5,1,1,1,1,1,1,1,0
0,1,1,1,1,1,1,1,5,4,4,4,4,4,4,4,4,4,4,4,4,5,1,1,1,1,1,1,1,0
0,1,1,1,1,1,1,1,5,5,5,5,5,5,5,5,5,5,5,5,5,5,1,1,1,1,1,1,1,0
0,1,1,1,1,1,1,1,1,1,1,1,1,1,1,1,1,1,1,1,1,1,1,1,1,1,1,1,1,0
1,1,1,1,1,1,1,1,1,1,1,1,1,1,1,1,1,1,1,1,1,1,1,1,1,1,1,1,1,1
1,1,1,1,1,1,1,1,1,1,1,1,1,1,1,1,1,1,1,1,1,1,1,1,1,1,1,1,1,1
1,1,1,1,1,1,1,1,1,1,1,1,1,1,1,1,1,1,1,1,1,1,1,1,1,1,1,1,1,1
1,1,1,1,1,1,1,1,1,1,1,1,1,1,1,1,1,1,1,1,1,1,1,1,1,1,1,1,1,1
1,1,1,1,1,1,1,1,1,1,1,1,1,1,1,1,1,1,1,1,1,1,1,1,1,1,1,1,1,1
1,1,1,1,1,1,1,1,1,1,1,1,1,1,1,1,1,1,1,1,1,1,1,1,1,1,1,1,1,1
1,1,1,1,1,1,1,0,0,0,0,0,0,0,0,0,0,0,0,0,0,0,0,1,1,1,1,1,1,1
endlayer

layer
1,1,1,1,1,1,1,1,1,1,1,1,1,1,1,1,1,1,1,1,1,1,1,1,1,1,1,1,1,1
1,1,1,1,1,1,1,1,1,1,1,1,1,1,1,1,1,1,1,1,1,1,1,1,1,1,1,1,1,1
1,1,1,1,1,1,1,1,1,1,1,1,1,1,1,1,1,1,1,1,1,1,1,1,1,1,1,1,1,1
1,1,1,1,1,1,1,1,1,1,1,1,1,1,1,1,1,1,1,1,1,1,1,1,1,1,1,1,1,1
1,1,1,1,1,1,1,1,1,1,1,1,1,1,1,1,1,1,1,1,1,1,1,1,1,1,1,1,1,1
1,1,1,1,1,1,1,1,1,1,1,1,1,1,1,1,1,1,1,1,1,1,1,1,1,1,1,1,1,1
1,1,1,1,1,1,1,1,1,1,1,1,1,1,1,1,1,1,1,1,1,1,1,1,1,1,1,1,1,1
1,1,1,1,1,1,1,1,1,1,1,1,1,1,1,1,1,1,1,1,1,1,1,1,1,1,1,1,1,1
1,1,1,1,1,1,1,1,1,1,1,1,1,1,1,1,1,1,1,1,1,1,1,1,1,1,1,1,1,1
1,1,1,1,1,1,1,1,1,4,4,4,4,4,4,4,4,4,4,4,4,1,1,1,1,1,1,1,1,1
1,1,1,1,1,1,1,1,1,4,5,5,5,5,5,5,5,5,5,5,4,1,1,1,1,1,1,1,1,1
1,1,1,1,1,1,1,1,1,4,5,5,4,5,5,5,5,4,5,5,4,1,1,1,1,1,1,1,1,1
1,1,1,1,1,1,1,1,1,4,5,4,0,4,5,5,4,0,4,5,4,1,1,1,1,1,1,1,1,1
1,1,1,1,1,1,1,1,1,4,5,5,4,5,5,5,5,4,5,5,4,1,1,1,1,1,1,1,1,1
1,1,1,1,1,1,1,1,1,4,5,5,5,5,5,5,5,5,5,5,4,1,1,1,1,1,1,1,1,1
1,1,1,1,1,1,1,1,1,4,5,5,5,5,5,5,5,5,5,5,4,1,1,1,1,1,1,1,1,1
1,1,1,1,1,1,1,1,1,4,5,5,4,5,5,5,5,4,5,5,4,1,1,1,1,1,1,1,1,1
1,1,1,1,1,1,1,1,1,4,5,4,0,4,5,5,4,0,4,5,4,1,1,1,1,1,1,1,1,1
1,1,1,1,1,1,1,1,1,4,5,5,4,5,5,5,5,4,5,5,4,1,1,1,1,1,1,1,1,1
1,1,1,1,1,1,1,1,1,4,5,5,5,5,5,5,5,5,5,5,4,1,1,1,1,1,1,1,1,1
1,1,1,1,1,1,1,1,1,4,4,4,4,4,4,4,4,4,4,4,4,1,1,1,1,1,1,1,1,1
1,1,1,1,1,1,1,1,1,1,1,1,1,1,1,1,1,1,1,1,1,1,1,1,1,1,1,1,1,1
1,1,1,1,1,1,1,1,1,1,1,1,1,1,1,1,1,1,1,1,1,1,1,1,1,1,1,1,1,1
1,1,1,1,1,1,1,1,1,1,1,1,1,1,1,1,1,1,1,1,1,1,1,1,1,1,1,1,1,1
1,1,1,1,1,1,1,1,1,1,1,1,1,1,1,1,1,1,1,1,1,1,1,1,1,1,1,1,1,1
1,1,1,1,1,1,1,1,1,1,1,1,1,1,1,1,1,1,1,1,1,1,1,1,1,1,1,1,1,1
1,1,1,1,1,1,1,1,1,1,1,1,1,1,1,1,1,1,1,1,1,1,1,1,1,1,1,1,1,1
1,1,1,1,1,1,1,1,1,1,1,1,1,1,1,1,1,1,1,1,1,1,1,1,1,1,1,1,1,1
1,1,1,1,1,1,1,1,1,1,1,1,1,1,1,1,1,1,1,1,1,1,1,1,1,1,1,1,1,1
1,1,1,1,1,1,1,1,1,1,1,1,1,1,1,1,1,1,1,1,1,1,1,1,1,1,1,1,1,1
endlayer

layer
1,1,1,1,1,1,1,1,1,1,1,1,1,1,1,1,1,1,1,1,1,1,1,1,1,1,1,1,1,1
1,1,1,1,1,1,1,1,1,1,1,1,1,1,1,1,1,1,1,1,1,1,1,1,1,1,1,1,1,1
1,1,1,1,1,1,1,1,1,1,1,1,1,1,1,1,1,1,1,1,1,1,1,1,1,1,1,1,1,1
1,1,1,1,1,1,1,1,1,1,1,1,1,1,1,1,1,1,1,1,1,1,1,1,1,1,1,1,1,1
1,1,1,1,1,1,1,1,1,1,1,1,1,1,1,1,1,1,1,1,1,1,1,1,1,1,1,1,1,1
1,1,1,1,1,1,1,1,1,1,1,1,1,1,1,1,1,1,1,1,1,1,1,1,1,1,1,1,1,1
1,1,1,1,1,1,1,1,1,1,1,1,1,1,1,1,1,1,1,1,1,1,1,1,1,1,1,1,1,1
1,1,1,1,1,1,1,1,1,1,1,1,1,1,1,1,1,1,1,1,1,1,1,1,1,1,1,1,1,1
1,1,1,1,1,1,1,1,1,1,1,1,1,1,1,1,1,1,1,1,1,1,1,1,1,1,1,1,1,1
1,1,1,1,1,1,1,1,1,1,1,1,1,1,1,1,1,1,1,1,1,1,1,1,1,1,1,1,1,1
1,1,1,1,1,1,1,1,1,1,5,5,5,5,5,5,5,5,5,5,1,1,1,1,1,1,1,1,1,1
1,1,1,1,1,1,1,1,1,1,5,4,4,4,4,4,4,4,4,5,1,1,1,1,1,1,1,1,1,1
1,1,1,1,1,1,1,1,1,1,5,4,0,4,5,5,4,0,4,5,1,1,1,1,1,1,1,1,1,1
1,1,1,1,1,1,1,1,1,1,5,4,4,5,5,5,5,4,4,5,1,1,1,1,1,1,1,1,1,1
1,1,1,1,1,1,1,1,1,1,5,4,5,5,5,5,5,5,4,5,1,1,1,1,1,1,1,1,1,1
1,1,1,1,1,1,1,1,1,1,5,4,5,5,5,5,5,5,4,5,1,1,1,1,1,1,1,1,1,1
1,1,1,1,1,1,1,1,1,1,5,4,4,5,5,5,5,4,4,5,1,1,1,1,1,1,1,1,1,1
1,1,1,1,1,1,1,1,1,1,5,4,0,4,5,5,4,0,4,5,1,1,1,1,1,1,1,1,1,1
1,1,1,1,1,1,1,1,1,1,5,4,4,4,4,4,4,4,4,5,1,1,1,1,1,1,1,1,1,1
1,1,1,1,1,1,1,1,1,1,5,5,5,5,5,5,5,5,5,5,1,1,1,1,1,1,1,1,1,1
1,1,1,1,1,1,1,1,1,1,1,1,1,1,1,1,1,1,1,1,1,1,1,1,1,1,1,1,1,1
1,1,1,1,1,1,1,1,1,1,1,1,1,1,1,1,1,1,1,1,1,1,1,1,1,1,1,1,1,1
1,1,1,1,1,1,1,1,1,1,1,1,1,1,1,1,1,1,1,1,1,1,1,1,1,1,1,1,1,1
1,1,1,1,1,1,1,1,1,1,1,1,1,1,1,1,1,1,1,1,1,1,1,1,1,1,1,1,1,1
1,1,1,1,1,1,1,1,1,1,1,1,1,1,1,1,1,1,1,1,1,1,1,1,1,1,1,1,1,1
1,1,1,1,1,1,1,1,1,1,1,1,1,1,1,1,1,1,1,1,1,1,1,1,1,1,1,1,1,1
1,1,1,1,1,1,1,1,1,1,1,1,1,1,1,1,1,1,1,1,1,1,1,1,1,1,1,1,1,1
1,1,1,1,1,1,1,1,1,1,1,1,1,1,1,1,1,1,1,1,1,1,1,1,1,1,1,1,1,1
1,1,1,1,1,1,1,1,1,1,1,1,1,1,1,1,1,1,1,1,1,1,1,1,1,1,1,1,1,1
1,1,1,1,1,1,1,1,1,1,1,1,1,1,1,1,1,1,1,1,1,1,1,1,1,1,1,1,1,1
endlayer

layer
1,1,1,1,1,1,1,1,1,1,1,1,1,1,1,1,1,1,1,1,1,1,1,1,1,1,1,1,1,1
1,1,1,1,1,1,1,1,1,1,1,1,1,1,1,1,1,1,1,1,1,1,1,1,1,1,1,1,1,1
1,1,1,1,1,1,1,1,1,1,1,1,1,1,1,1,1,1,1,1,1,1,1,1,1,1,1,1,1,1
1,1,1,1,1,1,1,1,1,1,1,1,1,1,1,1,1,1,1,1,1,1,1,1,1,1,1,1,1,1
1,1,1,1,1,1,1,1,1,1,1,1,1,1,1,1,1,1,1,1,1,1,1,1,1,1,1,1,1,1
1,1,1,1,1,1,1,1,1,1,1,1,1,1,1,1,1,1,1,1,1,1,1,1,1,1,1,1,1,1
1,1,1,1,1,1,1,1,1,1,1,1,1,1,1,1,1,1,1,1,1,1,1,1,1,1,1,1,1,1
1,1,1,1,1,1,1,1,1,1,1,1,1,1,1,1,1,1,1,1,1,1,1,1,1,1,1,1,1,1
1,1,1,1,1,1,1,1,1,1,1,1,1,1,1,1,1,1,1,1,1,1,1,1,1,1,1,1,1,1
1,1,1,1,1,1,1,1,1,1,1,1,1,1,1,1,1,1,1,1,1,1,1,1,1,1,1,1,1,1
1,1,1,1,1,1,1,1,1,1,1,1,1,1,1,1,1,1,1,1,1,1,1,1,1,1,1,1,1,1
1,1,1,1,1,1,1,1,1,1,1,5,5,5,5,5,5,5,5,1,1,1,1,1,1,1,1,1,1,1
1,1,1,1,1,1,1,1,1,1,1,5,0,4,4,4,4,0,5,1,1,1,1,1,1,1,1,1,1,1
1,1,1,1,1,1,1,1,1,1,1,5,4,5,5,5,5,4,5,1,1,1,1,1,1,1,1,1,1,1
1,1,1,1,1,1,1,1,1,1,1,5,4,5,5,5,5,4,5,1,1,1,1,1,1,1,1,1,1,1
1,1,1,1,1,1,1,1,1,1,1,5,4,5,5,5,5,4,5,1,1,1,1,1,1,1,1,1,1,1
1,1,1,1,1,1,1,1,1,1,1,5,4,5,5,5,5,4,5,1,1,1,1,1,1,1,1,1,1,1
1,1,1,1,1,1,1,1,1,1,1,5,0,4,4,4,4,0,5,1,1,1,1,1,1,1,1,1,1,1
1,1,1,1,1,1,1,1,1,1,1,5,5,5,5,5,5,5,5,1,1,1,1,1,1,1,1,1,1,1
1,1,1,1,1,1,1,1,1,1,1,1,1,1,1,1,1,1,1,1,1,1,1,1,1,1,1,1,1,1
1,1,1,1,1,1,1,1,1,1,1,1,1,1,1,1,1,1,1,1,1,1,1,1,1,1,1,1,1,1
1,1,1,1,1,1,1,1,1,1,1,1,1,1,1,1,1,1,1,1,1,1,1,1,1,1,1,1,1,1
1,1,1,1,1,1,1,1,1,1,1,1,1,1,1,1,1,1,1,1,1,1,1,1,1,1,1,1,1,1
1,1,1,1,1,1,1,1,1,1,1,1,1,1,1,1,1,1,1,1,1,1,1,1,1,1,1,1,1,1
1,1,1,1,1,1,1,1,1,1,1,1,1,1,1,1,1,1,1,1,1,1,1,1,1,1,1,1,1,1
1,1,1,1,1,1,1,1,1,1,1,1,1,1,1,1,1,1,1,1,1,1,1,1,1,1,1,1,1,1
1,1,1,1,1,1,1,1,1,1,1,1,1,1,1,1,1,1,1,1,1,1,1,1,1,1,1,1,1,1
1,1,1,1,1,1,1,1,1,1,1,1,1,1,1,1,1,1,1,1,1,1,1,1,1,1,1,1,1,1
1,1,1,1,1,1,1,1,1,1,1,1,1,1,1,1,1,1,1,1,1,1,1,1,1,1,1,1,1,1
1,1,1,1,1,1,1,1,1,1,1,1,1,1,1,1,1,1,1,1,1,1,1,1,1,1,1,1,1,1
endlayer

layer
1,1,1,1,1,1,1,1,1,1,1,1,1,1,1,1,1,1,1,1,1,1,1,1,1,1,1,1,1,1
1,1,1,1,1,1,1,1,1,1,1,1,1,1,1,1,1,1,1,1,1,1,1,1,1,1,1,1,1,1
1,1,1,1,1,1,1,1,1,1,1,1,1,1,1,1,1,1,1,1,1,1,1,1,1,1,1,1,1,1
1,1,1,1,1,1,1,1,1,1,1,1,1,1,1,1,1,1,1,1,1,1,1,1,1,1,1,1,1,1
1,1,1,1,1,1,1,1,1,1,1,1,1,1,1,1,1,1,1,1,1,1,1,1,1,1,1,1,1,1
1,1,1,1,1,1,1,1,1,1,1,1,1,1,1,1,1,1,1,1,1,1,1,1,1,1,1,1,1,1
1,1,1,1,1,1,1,1,1,1,1,1,1,1,1,1,1,1,1,1,1,1,1,1,1,1,1,1,1,1
1,1,1,1,1,1,1,1,1,1,1,1,1,1,1,1,1,1,1,1,1,1,1,1,1,1,1,1,1,1
1,1,1,1,1,1,1,1,1,1,1,1,1,1,1,1,1,1,1,1,1,1,1,1,1,1,1,1,1,1
1,1,1,1,1,1,1,1,1,1,1,1,1,1,1,1,1,1,1,1,1,1,1,1,1,1,1,1,1,1
1,1,1,1,1,1,1,1,1,1,1,1,1,1,1,1,1,1,1,1,1,1,1,1,1,1,1,1,1,1
1,1,1,1,1,1,1,1,1,1,1,1,1,1,1,1,1,1,1,1,1,1,1,1,1,1,1,1,1,1
1,1,1,1,1,1,1,1,1,1,1,1,0,4,4,4,4,0,1,1,1,1,1,1,1,1,1,1,1,1
1,1,1,1,1,1,1,1,1,1,1,1,4,5,5,5,5,4,1,1,1,1,1,1,1,1,1,1,1,1
1,1,1,1,1,1,1,1,1,1,1,1,4,5,5,5,5,4,1,1,1,1,1,1,1,1,1,1,1,1
1,1,1,1,1,1,1,1,1,1,1,1,4,5,5,5,5,4,1,1,1,1,1,1,1,1,1,1,1,1
1,1,1,1,1,1,1,1,1,1,1,1,4,5,5,5,5,4,1,1,1,1,1,1,1,1,1,1,1,1
1,1,1,1,1,1,1,1,1,1,1,1,0,4,4,4,4,0,1,1,1,1,1,1,1,1,1,1,1,1
1,1,1,1,1,1,1,1,1,1,1,1,1,1,1,1,1,1,1,1,1,1,1,1,1,1,1,1,1,1
1,1,1,1,1,1,1,1,1,1,1,1,1,1,1,1,1,1,1,1,1,1,1,1,1,1,1,1,1,1
1,1,1,1,1,1,1,1,1,1,1,1,1,1,1,1,1,1,1,1,1,1,1,1,1,1,1,1,1,1
1,1,1,1,1,1,1,1,1,1,1,1,1,1,1,1,1,1,1,1,1,1,1,1,1,1,1,1,1,1
1,1,1,1,1,1,1,1,1,1,1,1,1,1,1,1,1,1,1,1,1,1,1,1,1,1,1,1,1,1
1,1,1,1,1,1,1,1,1,1,1,1,1,1,1,1,1,1,1,1,1,1,1,1,1,1,1,1,1,1
1,1,1,1,1,1,1,1,1,1,1,1,1,1,1,1,1,1,1,1,1,1,1,1,1,1,1,1,1,1
1,1,1,1,1,1,1,1,1,1,1,1,1,1,1,1,1,1,1,1,1,1,1,1,1,1,1,1,1,1
1,1,1,1,1,1,1,1,1,1,1,1,1,1,1,1,1,1,1,1,1,1,1,1,1,1,1,1,1,1
1,1,1,1,1,1,1,1,1,1,1,1,1,1,1,1,1,1,1,1,1,1,1,1,1,1,1,1,1,1
1,1,1,1,1,1,1,1,1,1,1,1,1,1,1,1,1,1,1,1,1,1,1,1,1,1,1,1,1,1
1,1,1,1,1,1,1,1,1,1,1,1,1,1,1,1,1,1,1,1,1,1,1,1,1,1,1,1,1,1
endlayer

layer
1,1,1,1,1,1,1,1,1,1,1,1,1,1,1,1,1,1,1,1,1,1,1,1,1,1,1,1,1,1
1,1,1,1,1,1,1,1,1,1,1,1,1,1,1,1,1,1,1,1,1,1,1,1,1,1,1,1,1,1
1,1,1,1,1,1,1,1,1,1,1,1,1,1,1,1,1,1,1,1,1,1,1,1,1,1,1,1,1,1
1,1,1,1,1,1,1,1,1,1,1,1,1,1,1,1,1,1,1,1,1,1,1,1,1,1,1,1,1,1
1,1,1,1,1,1,1,1,1,1,1,1,1,1,1,1,1,1,1,1,1,1,1,1,1,1,1,1,1,1
1,1,1,1,1,1,1,1,1,1,1,1,1,1,1,1,1,1,1,1,1,1,1,1,1,1,1,1,1,1
1,1,1,1,1,1,1,1,1,1,1,1,1,1,1,1,1,1,1,1,1,1,1,1,1,1,1,1,1,1
1,1,1,1,1,1,1,1,1,1,1,1,1,1,1,1,1,1,1,1,1,1,1,1,1,1,1,1,1,1
1,1,1,1,1,1,1,1,1,1,1,1,1,1,1,1,1,1,1,1,1,1,1,1,1,1,1,1,1,1
1,1,1,1,1,1,1,1,1,1,1,1,1,1,1,1,1,1,1,1,1,1,1,1,1,1,1,1,1,1
1,1,1,1,1,1,1,1,1,1,1,1,1,1,1,1,1,1,1,1,1,1,1,1,1,1,1,1,1,1
1,1,1,1,1,1,1,1,1,1,1,1,1,1,1,1,1,1,1,1,1,1,1,1,1,1,1,1,1,1
1,1,1,1,1,1,1,1,1,1,1,1,1,1,1,1,1,1,1,1,1,1,1,1,1,1,1,1,1,1
1,1,1,1,1,1,1,1,1,1,1,1,1,5,5,5,5,1,1,1,1,1,1,1,1,1,1,1,1,1
1,1,1,1,1,1,1,1,1,1,1,1,1,5,5,5,5,1,1,1,1,1,1,1,1,1,1,1,1,1
1,1,1,1,1,1,1,1,1,1,1,1,1,5,5,5,5,1,1,1,1,1,1,1,1,1,1,1,1,1
1,1,1,1,1,1,1,1,1,1,1,1,1,5,5,5,5,1,1,1,1,1,1,1,1,1,1,1,1,1
1,1,1,1,1,1,1,1,1,1,1,1,1,1,1,1,1,1,1,1,1,1,1,1,1,1,1,1,1,1
1,1,1,1,1,1,1,1,1,1,1,1,1,1,1,1,1,1,1,1,1,1,1,1,1,1,1,1,1,1
1,1,1,1,1,1,1,1,1,1,1,1,1,1,1,1,1,1,1,1,1,1,1,1,1,1,1,1,1,1
1,1,1,1,1,1,1,1,1,1,1,1,1,1,1,1,1,1,1,1,1,1,1,1,1,1,1,1,1,1
1,1,1,1,1,1,1,1,1,1,1,1,1,1,1,1,1,1,1,1,1,1,1,1,1,1,1,1,1,1
1,1,1,1,1,1,1,1,1,1,1,1,1,1,1,1,1,1,1,1,1,1,1,1,1,1,1,1,1,1
1,1,1,1,1,1,1,1,1,1,1,1,1,1,1,1,1,1,1,1,1,1,1,1,1,1,1,1,1,1
1,1,1,1,1,1,1,1,1,1,1,1,1,1,1,1,1,1,1,1,1,1,1,1,1,1,1,1,1,1
1,1,1,1,1,1,1,1,1,1,1,1,1,1,1,1,1,1,1,1,1,1,1,1,1,1,1,1,1,1
1,1,1,1,1,1,1,1,1,1,1,1,1,1,1,1,1,1,1,1,1,1,1,1,1,1,1,1,1,1
1,1,1,1,1,1,1,1,1,1,1,1,1,1,1,1,1,1,1,1,1,1,1,1,1,1,1,1,1,1
1,1,1,1,1,1,1,1,1,1,1,1,1,1,1,1,1,1,1,1,1,1,1,1,1,1,1,1,1,1
1,1,1,1,1,1,1,1,1,1,1,1,1,1,1,1,1,1,1,1,1,1,1,1,1,1,1,1,1,1
endlayer

layer
1,1,1,1,1,1,1,1,1,1,1,1,1,1,1,1,1,1,1,1,1,1,1,1,1,1,1,1,1,1
1,1,1,1,1,1,1,1,1,1,1,1,1,1,1,1,1,1,1,1,1,1,1,1,1,1,1,1,1,1
1,1,1,1,1,1,1,1,1,1,1,1,1,1,1,1,1,1,1,1,1,1,1,1,1,1,1,1,1,1
1,1,1,1,1,1,1,1,1,1,1,1,1,1,1,1,1,1,1,1,1,1,1,1,1,1,1,1,1,1
1,1,1,1,1,1,1,1,1,1,1,1,1,1,1,1,1,1,1,1,1,1,1,1,1,1,1,1,1,1
1,1,1,1,1,1,1,1,1,1,1,1,1,1,1,1,1,1,1,1,1,1,1,1,1,1,1,1,1,1
1,1,1,1,1,1,1,1,1,1,1,1,1,1,1,1,1,1,1,1,1,1,1,1,1,1,1,1,1,1
1,1,1,1,1,1,1,1,1,1,1,1,1,1,1,1,1,1,1,1,1,1,1,1,1,1,1,1,1,1
1,1,1,1,1,1,1,1,1,1,1,1,1,1,1,1,1,1,1,1,1,1,1,1,1,1,1,1,1,1
1,1,1,1,1,1,1,1,1,1,1,1,1,1,1,1,1,1,1,1,1,1,1,1,1,1,1,1,1,1
1,1,1,1,1,1,1,1,1,1,1,1,1,1,1,1,1,1,1,1,1,1,1,1,1,1,1,1,1,1
1,1,1,1,1,1,1,1,1,1,1,1,1,1,1,1,1,1,1,1,1,1,1,1,1,1,1,1,1,1
1,1,1,1,1,1,1,1,1,1,1,1,1,1,1,1,1,1,1,1,1,1,1,1,1,1,1,1,1,1
1,1,1,1,1,1,1,1,1,1,1,1,1,1,1,1,1,1,1,1,1,1,1,1,1,1,1,1,1,1
1,1,1,1,1,1,1,1,1,1,1,1,1,1,4,4,1,1,1,1,1,1,1,1,1,1,1,1,1,1
1,1,1,1,1,1,1,1,1,1,1,1,1,1,4,4,1,1,1,1,1,1,1,1,1,1,1,1,1,1
1,1,1,1,1,1,1,1,1,1,1,1,1,1,1,1,1,1,1,1,1,1,1,1,1,1,1,1,1,1
1,1,1,1,1,1,1,1,1,1,1,1,1,1,1,1,1,1,1,1,1,1,1,1,1,1,1,1,1,1
1,1,1,1,1,1,1,1,1,1,1,1,1,1,1,1,1,1,1,1,1,1,1,1,1,1,1,1,1,1
1,1,1,1,1,1,1,1,1,1,1,1,1,1,1,1,1,1,1,1,1,1,1,1,1,1,1,1,1,1
1,1,1,1,1,1,1,1,1,1,1,1,1,1,1,1,1,1,1,1,1,1,1,1,1,1,1,1,1,1
1,1,1,1,1,1,1,1,1,1,1,1,1,1,1,1,1,1,1,1,1,1,1,1,1,1,1,1,1,1
1,1,1,1,1,1,1,1,1,1,1,1,1,1,1,1,1,1,1,1,1,1,1,1,1,1,1,1,1,1
1,1,1,1,1,1,1,1,1,1,1,1,1,1,1,1,1,1,1,1,1,1,1,1,1,1,1,1,1,1
1,1,1,1,1,1,1,1,1,1,1,1,1,1,1,1,1,1,1,1,1,1,1,1,1,1,1,1,1,1
1,1,1,1,1,1,1,1,1,1,1,1,1,1,1,1,1,1,1,1,1,1,1,1,1,1,1,1,1,1
1,1,1,1,1,1,1,1,1,1,1,1,1,1,1,1,1,1,1,1,1,1,1,1,1,1,1,1,1,1
1,1,1,1,1,1,1,1,1,1,1,1,1,1,1,1,1,1,1,1,1,1,1,1,1,1,1,1,1,1
1,1,1,1,1,1,1,1,1,1,1,1,1,1,1,1,1,1,1,1,1,1,1,1,1,1,1,1,1,1
1,1,1,1,1,1,1,1,1,1,1,1,1,1,1,1,1,1,1,1,1,1,1,1,1,1,1,1,1,1
endlayer

layer
1,1,1,1,1,1,1,1,1,1,1,1,1,1,1,1,1,1,1,1,1,1,1,1,1,1,1,1,1,1
1,1,1,1,1,1,1,1,1,1,1,1,1,1,1,1,1,1,1,1,1,1,1,1,1,1,1,1,1,1
1,1,1,1,1,1,1,1,1,1,1,1,1,1,1,1,1,1,1,1,1,1,1,1,1,1,1,1,1,1
1,1,1,1,1,1,1,1,1,1,1,1,1,1,1,1,1,1,1,1,1,1,1,1,1,1,1,1,1,1
1,1,1,1,1,1,1,1,1,1,1,1,1,1,1,1,1,1,1,1,1,1,1,1,1,1,1,1,1,1
1,1,1,1,1,1,1,1,1,1,1,1,1,1,1,1,1,1,1,1,1,1,1,1,1,1,1,1,1,1
1,1,1,1,1,1,1,1,1,1,1,1,1,1,1,1,1,1,1,1,1,1,1,1,1,1,1,1,1,1
1,1,1,1,1,1,1,1,1,1,1,1,1,1,1,1,1,1,1,1,1,1,1,1,1,1,1,1,1,1
1,1,1,1,1,1,1,1,1,1,1,1,1,1,1,1,1,1,1,1,1,1,1,1,1,1,1,1,1,1
1,1,1,1,1,1,1,1,1,1,1,1,1,1,1,1,1,1,1,1,1,1,1,1,1,1,1,1,1,1
1,1,1,1,1,1,1,1,1,1,1,1,1,1,1,1,1,1,1,1,1,1,1,1,1,1,1,1,1,1
1,1,1,1,1,1,1,1,1,1,1,1,1,1,1,1,1,1,1,1,1,1,1,1,1,1,1,1,1,1
1,1,1,1,1,1,1,1,1,1,1,1,1,1,1,1,1,1,1,1,1,1,1,1,1,1,1,1,1,1
1,1,1,1,1,1,1,1,1,1,1,1,1,1,1,1,1,1,1,1,1,1,1,1,1,1,1,1,1,1
1,1,1,1,1,1,1,1,1,1,1,1,1,1,1,1,1,1,1,1,1,1,1,1,1,1,1,1,1,1
1,1,1,1,1,1,1,1,1,1,1,1,1,1,1,1,1,1,1,1,1,1,1,1,1,1,1,1,1,1
1,1,1,1,1,1,1,1,1,1,1,1,1,1,1,1,1,1,1,1,1,1,1,1,1,1,1,1,1,1
1,1,1,1,1,1,1,1,1,1,1,1,1,1,1,1,1,1,1,1,1,1,1,1,1,1,1,1,1,1
1,1,1,1,1,1,1,1,1,1,1,1,1,1,1,1,1,1,1,1,1,1,1,1,1,1,1,1,1,1
1,1,1,1,1,1,1,1,1,1,1,1,1,1,1,1,1,1,1,1,1,1,1,1,1,1,1,1,1,1
1,1,1,1,1,1,1,1,1,1,1,1,1,1,1,1,1,1,1,1,1,1,1,1,1,1,1,1,1,1
1,1,1,1,1,1,1,1,1,1,1,1,1,1,1,1,1,1,1,1,1,1,1,1,1,1,1,1,1,1
1,1,1,1,1,1,1,1,1,1,1,1,1,1,1,1,1,1,1,1,1,1,1,1,1,1,1,1,1,1
1,1,1,1,1,1,1,1,1,1,1,1,1,1,1,1,1,1,1,1,1,1,1,1,1,1,1,1,1,1
1,1,1,1,1,1,1,1,1,1,1,1,1,1,1,1,1,1,1,1,1,1,1,1,1,1,1,1,1,1
1,1,1,1,1,1,1,1,1,1,1,1,1,1,1,1,1,1,1,1,1,1,1,1,1,1,1,1,1,1
1,1,1,1,1,1,1,1,1,1,1,1,1,1,1,1,1,1,1,1,1,1,1,1,1,1,1,1,1,1
1,1,1,1,1,1,1,1,1,1,1,1,1,1,1,1,1,1,1,1,1,1,1,1,1,1,1,1,1,1
1,1,1,1,1,1,1,1,1,1,1,1,1,1,1,1,1,1,1,1,1,1,1,1,1,1,1,1,1,1
1,1,1,1,1,1,1,1,1,1,1,1,1,1,1,1,1,1,1,1,1,1,1,1,1,1,1,1,1,1
endlayer

layer
1,1,1,1,1,1,1,1,1,1,1,1,1,1,1,1,1,1,1,1,1,1,1,1,1,1,1,1,1,1
1,1,1,1,1,1,1,1,1,1,1,1,1,1,1,1,1,1,1,1,1,1,1,1,1,1,1,1,1,1
1,1,1,1,1,1,1,1,1,1,1,1,1,1,1,1,1,1,1,1,1,1,1,1,1,1,1,1,1,1
1,1,1,1,1,1,1,1,1,1,1,1,1,1,1,1,1,1,1,1,1,1,1,1,1,1,1,1,1,1
1,1,1,1,1,1,1,1,1,1,1,1,1,1,1,1,1,1,1,1,1,1,1,1,1,1,1,1,1,1
1,1,1,1,1,1,1,1,1,1,1,1,1,1,1,1,1,1,1,1,1,1,1,1,1,1,1,1,1,1
1,1,1,1,1,1,1,1,1,1,1,1,1,1,1,1,1,1,1,1,1,1,1,1,1,1,1,1,1,1
1,1,1,1,1,1,1,1,1,1,1,1,1,1,1,1,1,1,1,1,1,1,1,1,1,1,1,1,1,1
1,1,1,1,1,1,1,1,1,1,1,1,1,1,1,1,1,1,1,1,1,1,1,1,1,1,1,1,1,1
1,1,1,1,1,1,1,1,1,1,1,1,1,1,1,1,1,1,1,1,1,1,1,1,1,1,1,1,1,1
1,1,1,1,1,1,1,1,1,1,1,1,1,1,1,1,1,1,1,1,1,1,1,1,1,1,1,1,1,1
1,1,1,1,1,1,1,1,1,1,1,1,1,1,1,1,1,1,1,1,1,1,1,1,1,1,1,1,1,1
1,1,1,1,1,1,1,1,1,1,1,1,1,1,1,1,1,1,1,1,1,1,1,1,1,1,1,1,1,1
1,1,1,1,1,1,1,1,1,1,1,1,1,1,1,1,1,1,1,1,1,1,1,1,1,1,1,1,1,1
1,1,1,1,1,1,1,1,1,1,1,1,1,1,1,1,1,1,1,1,1,1,1,1,1,1,1,1,1,1
1,1,1,1,1,1,1,1,1,1,1,1,1,1,1,1,1,1,1,1,1,1,1,1,1,1,1,1,1,1
1,1,1,1,1,1,1,1,1,1,1,1,1,1,1,1,1,1,1,1,1,1,1,1,1,1,1,1,1,1
1,1,1,1,1,1,1,1,1,1,1,1,1,1,1,1,1,1,1,1,1,1,1,1,1,1,1,1,1,1
1,1,1,1,1,1,1,1,1,1,1,1,1,1,1,1,1,1,1,1,1,1,1,1,1,1,1,1,1,1
1,1,1,1,1,1,1,1,1,1,1,1,1,1,1,1,1,1,1,1,1,1,1,1,1,1,1,1,1,1
1,1,1,1,1,1,1,1,1,1,1,1,1,1,1,1,1,1,1,1,1,1,1,1,1,1,1,1,1,1
1,1,1,1,1,1,1,1,1,1,1,1,1,1,1,1,1,1,1,1,1,1,1,1,1,1,1,1,1,1
1,1,1,1,1,1,1,1,1,1,1,1,1,1,1,1,1,1,1,1,1,1,1,1,1,1,1,1,1,1
1,1,1,1,1,1,1,1,1,1,1,1,1,1,1,1,1,1,1,1,1,1,1,1,1,1,1,1,1,1
1,1,1,1,1,1,1,1,1,1,1,1,1,1,1,1,1,1,1,1,1,1,1,1,1,1,1,1,1,1
1,1,1,1,1,1,1,1,1,1,1,1,1,1,1,1,1,1,1,1,1,1,1,1,1,1,1,1,1,1
1,1,1,1,1,1,1,1,1,1,1,1,1,1,1,1,1,1,1,1,1,1,1,1,1,1,1,1,1,1
1,1,1,1,1,1,1,1,1,1,1,1,1,1,1,1,1,1,1,1,1,1,1,1,1,1,1,1,1,1
1,1,1,1,1,1,1,1,1,1,1,1,1,1,1,1,1,1,1,1,1,1,1,1,1,1,1,1,1,1
1,1,1,1,1,1,1,1,1,1,1,1,1,1,1,1,1,1,1,1,1,1,1,1,1,1,1,1,1,1
endlayer

layer
1,1,1,1,1,1,1,1,1,1,1,1,1,1,1,1,1,1,1,1,1,1,1,1,1,1,1,1,1,1
1,1,1,1,1,1,1,1,1,1,1,1,1,1,1,1,1,1,1,1,1,1,1,1,1,1,1,1,1,1
1,1,1,1,1,1,1,1,1,1,1,1,1,1,1,1,1,1,1,1,1,1,1,1,1,1,1,1,1,1
1,1,1,1,1,1,1,1,1,1,1,1,1,1,1,1,1,1,1,1,1,1,1,1,1,1,1,1,1,1
1,1,1,1,1,1,1,1,1,1,1,1,1,1,1,1,1,1,1,1,1,1,1,1,1,1,1,1,1,1
1,1,1,1,1,1,1,1,1,1,1,1,1,1,1,1,1,1,1,1,1,1,1,1,1,1,1,1,1,1
1,1,1,1,1,1,1,1,1,1,1,1,1,1,1,1,1,1,1,1,1,1,1,1,1,1,1,1,1,1
1,1,1,1,1,1,1,1,1,1,1,1,1,1,1,1,1,1,1,1,1,1,1,1,1,1,1,1,1,1
1,1,1,1,1,1,1,1,1,1,1,1,1,1,1,1,1,1,1,1,1,1,1,1,1,1,1,1,1,1
1,1,1,1,1,1,1,1,1,1,1,1,1,1,1,1,1,1,1,1,1,1,1,1,1,1,1,1,1,1
1,1,1,1,1,1,1,1,1,1,1,1,1,1,1,1,1,1,1,1,1,1,1,1,1,1,1,1,1,1
1,1,1,1,1,1,1,1,1,1,1,1,1,1,1,1,1,1,1,1,1,1,1,1,1,1,1,1,1,1
1,1,1,1,1,1,1,1,1,1,1,1,1,1,1,1,1,1,1,1,1,1,1,1,1,1,1,1,1,1
1,1,1,1,1,1,1,1,1,1,1,1,1,1,1,1,1,1,1,1,1,1,1,1,1,1,1,1,1,1
1,1,1,1,1,1,1,1,1,1,1,1,1,1,1,1,1,1,1,1,1,1,1,1,1,1,1,1,1,1
1,1,1,1,1,1,1,1,1,1,1,1,1,1,1,1,1,1,1,1,1,1,1,1,1,1,1,1,1,1
1,1,1,1,1,1,1,1,1,1,1,1,1,1,1,1,1,1,1,1,1,1,1,1,1,1,1,1,1,1
1,1,1,1,1,1,1,1,1,1,1,1,1,1,1,1,1,1,1,1,1,1,1,1,1,1,1,1,1,1
1,1,1,1,1,1,1,1,1,1,1,1,1,1,1,1,1,1,1,1,1,1,1,1,1,1,1,1,1,1
1,1,1,1,1,1,1,1,1,1,1,1,1,1,1,1,1,1,1,1,1,1,1,1,1,1,1,1,1,1
1,1,1,1,1,1,1,1,1,1,1,1,1,1,1,1,1,1,1,1,1,1,1,1,1,1,1,1,1,1
1,1,1,1,1,1,1,1,1,1,1,1,1,1,1,1,1,1,1,1,1,1,1,1,1,1,1,1,1,1
1,1,1,1,1,1,1,1,1,1,1,1,1,1,1,1,1,1,1,1,1,1,1,1,1,1,1,1,1,1
1,1,1,1,1,1,1,1,1,1,1,1,1,1,1,1,1,1,1,1,1,1,1,1,1,1,1,1,1,1
1,1,1,1,1,1,1,1,1,1,1,1,1,1,1,1,1,1,1,1,1,1,1,1,1,1,1,1,1,1
1,1,1,1,1,1,1,1,1,1,1,1,1,1,1,1,1,1,1,1,1,1,1,1,1,1,1,1,1,1
1,1,1,1,1,1,1,1,1,1,1,1,1,1,1,1,1,1,1,1,1,1,1,1,1,1,1,1,1,1
1,1,1,1,1,1,1,1,1,1,1,1,1,1,1,1,1,1,1,1,1,1,1,1,1,1,1,1,1,1
1,1,1,1,1,1,1,1,1,1,1,1,1,1,1,1,1,1,1,1,1,1,1,1,1,1,1,1,1,1
1,1,1,1,1,1,1,1,1,1,1,1,1,1,1,1,1,1,1,1,1,1,1,1,1,1,1,1,1,1
endlayer

layer
1,1,1,1,1,1,1,1,1,1,1,1,1,1,1,1,1,1,1,1,1,1,1,1,1,1,1,1,1,1
1,1,1,1,1,1,1,1,1,1,1,1,1,1,1,1,1,1,1,1,1,1,1,1,1,1,1,1,1,1
1,1,1,1,1,1,1,1,1,1,1,1,1,1,1,1,1,1,1,1,1,1,1,1,1,1,1,1,1,1
1,1,1,1,1,1,1,1,1,1,1,1,1,1,1,1,1,1,1,1,1,1,1,1,1,1,1,1,1,1
1,1,1,1,1,1,1,1,1,1,1,1,1,1,1,1,1,1,1,1,1,1,1,1,1,1,1,1,1,1
1,1,1,1,1,1,1,1,1,1,1,1,1,1,1,1,1,1,1,1,1,1,1,1,1,1,1,1,1,1
1,1,1,1,1,1,1,1,1,1,1,1,1,1,1,1,1,1,1,1,1,1,1,1,1,1,1,1,1,1
1,1,1,1,1,1,1,1,1,1,1,1,1,1,1,1,1,1,1,1,1,1,1,1,1,1,1,1,1,1
1,1,1,1,1,1,1,1,1,1,1,1,1,1,1,1,1,1,1,1,1,1,1,1,1,1,1,1,1,1
1,1,1,1,1,1,1,1,1,1,1,1,1,1,1,1,1,1,1,1,1,1,1,1,1,1,1,1,1,1
1,1,1,1,1,1,1,1,1,1,1,1,1,1,1,1,1,1,1,1,1,1,1,1,1,1,1,1,1,1
1,1,1,1,1,1,1,1,1,1,1,1,1,1,1,1,1,1,1,1,1,1,1,1,1,1,1,1,1,1
1,1,1,1,1,1,1,1,1,1,1,1,1,1,1,1,1,1,1,1,1,1,1,1,1,1,1,1,1,1
1,1,1,1,1,1,1,1,1,1,1,1,1,1,1,1,1,1,1,1,1,1,1,1,1,1,1,1,1,1
1,1,1,1,1,1,1,1,1,1,1,1,1,1,1,1,1,1,1,1,1,1,1,1,1,1,1,1,1,1
1,1,1,1,1,1,1,1,1,1,1,1,1,1,1,1,1,1,1,1,1,1,1,1,1,1,1,1,1,1
1,1,1,1,1,1,1,1,1,1,1,1,1,1,1,1,1,1,1,1,1,1,1,1,1,1,1,1,1,1
1,1,1,1,1,1,1,1,1,1,1,1,1,1,1,1,1,1,1,1,1,1,1,1,1,1,1,1,1,1
1,1,1,1,1,1,1,1,1,1,1,1,1,1,1,1,1,1,1,1,1,1,1,1,1,1,1,1,1,1
1,1,1,1,1,1,1,1,1,1,1,1,1,1,1,1,1,1,1,1,1,1,1,1,1,1,1,1,1,1
1,1,1,1,1,1,1,1,1,1,1,1,1,1,1,1,1,1,1,1,1,1,1,1,1,1,1,1,1,1
1,1,1,1,1,1,1,1,1,1,1,1,1,1,1,1,1,1,1,1,1,1,1,1,1,1,1,1,1,1
1,1,1,1,1,1,1,1,1,1,1,1,1,1,1,1,1,1,1,1,1,1,1,1,1,1,1,1,1,1
1,1,1,1,1,1,1,1,1,1,1,1,1,1,1,1,1,1,1,1,1,1,1,1,1,1,1,1,1,1
1,1,1,1,1,1,1,1,1,1,1,1,1,1,1,1,1,1,1,1,1,1,1,1,1,1,1,1,1,1
1,1,1,1,1,1,1,1,1,1,1,1,1,1,1,1,1,1,1,1,1,1,1,1,1,1,1,1,1,1
1,1,1,1,1,1,1,1,1,1,1,1,1,1,1,1,1,1,1,1,1,1,1,1,1,1,1,1,1,1
1,1,1,1,1,1,1,1,1,1,1,1,1,1,1,1,1,1,1,1,1,1,1,1,1,1,1,1,1,1
1,1,1,1,1,1,1,1,1,1,1,1,1,1,1,1,1,1,1,1,1,1,1,1,1,1,1,1,1,1
1,1,1,1,1,1,1,1,1,1,1,1,1,1,1,1,1,1,1,1,1,1,1,1,1,1,1,1,1,1
endlayer

layer
1,1,1,1,1,1,1,1,1,1,1,1,1,1,1,1,1,1,1,1,1,1,1,1,1,1,1,1,1,1
1,1,1,1,1,1,1,1,1,1,1,1,1,1,1,1,1,1,1,1,1,1,1,1,1,1,1,1,1,1
1,1,1,1,1,1,1,1,1,1,1,1,1,1,1,1,1,1,1,1,1,1,1,1,1,1,1,1,1,1
1,1,1,1,1,1,1,1,1,1,1,1,1,1,1,1,1,1,1,1,1,1,1,1,1,1,1,1,1,1
1,1,1,1,1,1,1,1,1,1,1,1,1,1,1,1,1,1,1,1,1,1,1,1,1,1,1,1,1,1
1,1,1,1,1,1,1,1,1,1,1,1,1,1,1,1,1,1,1,1,1,1,1,1,1,1,1,1,1,1
1,1,1,1,1,1,1,1,1,1,1,1,1,1,1,1,1,1,1,1,1,1,1,1,1,1,1,1,1,1
1,1,1,1,1,1,1,1,1,1,1,1,1,1,1,1,1,1,1,1,1,1,1,1,1,1,1,1,1,1
1,1,1,1,1,1,1,1,1,1,1,1,1,1,1,1,1,1,1,1,1,1,1,1,1,1,1,1,1,1
1,1,1,1,1,1,1,1,1,1,1,1,1,1,1,1,1,1,1,1,1,1,1,1,1,1,1,1,1,1
1,1,1,1,1,1,1,1,1,1,1,1,1,1,1,1,1,1,1,1,1,1,1,1,1,1,1,1,1,1
1,1,1,1,1,1,1,1,1,1,1,1,1,1,1,1,1,1,1,1,1,1,1,1,1,1,1,1,1,1
1,1,1,1,1,1,1,1,1,1,1,1,1,1,1,1,1,1,1,1,1,1,1,1,1,1,1,1,1,1
1,1,1,1,1,1,1,1,1,1,1,1,1,1,1,1,1,1,1,1,1,1,1,1,1,1,1,1,1,1
1,1,1,1,1,1,1,1,1,1,1,1,1,1,1,1,1,1,1,1,1,1,1,1,1,1,1,1,1,1
1,1,1,1,1,1,1,1,1,1,1,1,1,1,1,1,1,1,1,1,1,1,1,1,1,1,1,1,1,1
1,1,1,1,1,1,1,1,1,1,1,1,1,1,1,1,1,1,1,1,1,1,1,1,1,1,1,1,1,1
1,1,1,1,1,1,1,1,1,1,1,1,1,1,1,1,1,1,1,1,1,1,1,1,1,1,1,1,1,1
1,1,1,1,1,1,1,1,1,1,1,1,1,1,1,1,1,1,1,1,1,1,1,1,1,1,1,1,1,1
1,1,1,1,1,1,1,1,1,1,1,1,1,1,1,1,1,1,1,1,1,1,1,1,1,1,1,1,1,1
1,1,1,1,1,1,1,1,1,1,1,1,1,1,1,1,1,1,1,1,1,1,1,1,1,1,1,1,1,1
1,1,1,1,1,1,1,1,1,1,1,1,1,1,1,1,1,1,1,1,1,1,1,1,1,1,1,1,1,1
1,1,1,1,1,1,1,1,1,1,1,1,1,1,1,1,1,1,1,1,1,1,1,1,1,1,1,1,1,1
1,1,1,1,1,1,1,1,1,1,1,1,1,1,1,1,1,1,1,1,1,1,1,1,1,1,1,1,1,1
1,1,1,1,1,1,1,1,1,1,1,1,1,1,1,1,1,1,1,1,1,1,1,1,1,1,1,1,1,1
1,1,1,1,1,1,1,1,1,1,1,1,1,1,1,1,1,1,1,1,1,1,1,1,1,1,1,1,1,1
1,1,1,1,1,1,1,1,1,1,1,1,1,1,1,1,1,1,1,1,1,1,1,1,1,1,1,1,1,1
1,1,1,1,1,1,1,1,1,1,1,1,1,1,1,1,1,1,1,1,1,1,1,1,1,1,1,1,1,1
1,1,1,1,1,1,1,1,1,1,1,1,1,1,1,1,1,1,1,1,1,1,1,1,1,1,1,1,1,1
1,1,1,1,1,1,1,1,1,1,1,1,1,1,1,1,1,1,1,1,1,1,1,1,1,1,1,1,1,1
endlayer

layer
1,1,1,1,1,1,1,1,1,1,1,1,1,1,1,1,1,1,1,1,1,1,1,1,1,1,1,1,1,1
1,1,1,1,1,1,1,1,1,1,1,1,1,1,1,1,1,1,1,1,1,1,1,1,1,1,1,1,1,1
1,1,1,1,1,1,1,1,1,1,1,1,1,1,1,1,1,1,1,1,1,1,1,1,1,1,1,1,1,1
1,1,1,1,1,1,1,1,1,1,1,1,1,1,1,1,1,1,1,1,1,1,1,1,1,1,1,1,1,1
1,1,1,1,1,1,1,1,1,1,1,1,1,1,1,1,1,1,1,1,1,1,1,1,1,1,1,1,1,1
1,1,1,1,1,1,1,1,1,1,1,1,1,1,1,1,1,1,1,1,1,1,1,1,1,1,1,1,1,1
1,1,1,1,1,1,1,1,1,1,1,1,1,1,1,1,1,1,1,1,1,1,1,1,1,1,1,1,1,1
1,1,1,1,1,1,1,1,1,1,1,1,1,1,1,1,1,1,1,1,1,1,1,1,1,1,1,1,1,1
1,1,1,1,1,1,1,1,1,1,1,1,1,1,1,1,1,1,1,1,1,1,1,1,1,1,1,1,1,1
1,1,1,1,1,1,1,1,1,1,1,1,1,1,1,1,1,1,1,1,1,1,1,1,1,1,1,1,1,1
1,1,1,1,1,1,1,1,1,1,1,1,1,1,1,1,1,1,1,1,1,1,1,1,1,1,1,1,1,1
1,1,1,1,1,1,1,1,1,1,1,1,1,1,1,1,1,1,1,1,1,1,1,1,1,1,1,1,1,1
1,1,1,1,1,1,1,1,1,1,1,1,1,1,1,1,1,1,1,1,1,1,1,1,1,1,1,1,1,1
1,1,1,1,1,1,1,1,1,1,1,1,1,1,1,1,1,1,1,1,1,1,1,1,1,1,1,1,1,1
1,1,1,1,1,1,1,1,1,1,1,1,1,1,11,11,1,1,1,1,1,1,1,1,1,1,1,1,1,1
1,1,1,1,1,1,1,1,1,1,1,1,1,1,11,11,1,1,1,1,1,1,1,1,1,1,1,1,1,1
1,1,1,1,1,1,1,1,1,1,1,1,1,1,1,1,1,1,1,1,1,1,1,1,1,1,1,1,1,1
1,1,1,1,1,1,1,1,1,1,1,1,1,1,1,1,1,1,1,1,1,1,1,1,1,1,1,1,1,1
1,1,1,1,1,1,1,1,1,1,1,1,1,1,1,1,1,1,1,1,1,1,1,1,1,1,1,1,1,1
1,1,1,1,1,1,1,1,1,1,1,1,1,1,1,1,1,1,1,1,1,1,1,1,1,1,1,1,1,1
1,1,1,1,1,1,1,1,1,1,1,1,1,1,1,1,1,1,1,1,1,1,1,1,1,1,1,1,1,1
1,1,1,1,1,1,1,1,1,1,1,1,1,1,1,1,1,1,1,1,1,1,1,1,1,1,1,1,1,1
1,1,1,1,1,1,1,1,1,1,1,1,1,1,1,1,1,1,1,1,1,1,1,1,1,1,1,1,1,1
1,1,1,1,1,1,1,1,1,1,1,1,1,1,1,1,1,1,1,1,1,1,1,1,1,1,1,1,1,1
1,1,1,1,1,1,1,1,1,1,1,1,1,1,1,1,1,1,1,1,1,1,1,1,1,1,1,1,1,1
1,1,1,1,1,1,1,1,1,1,1,1,1,1,1,1,1,1,1,1,1,1,1,1,1,1,1,1,1,1
1,1,1,1,1,1,1,1,1,1,1,1,1,1,1,1,1,1,1,1,1,1,1,1,1,1,1,1,1,1
1,1,1,1,1,1,1,1,1,1,1,1,1,1,1,1,1,1,1,1,1,1,1,1,1,1,1,1,1,1
1,1,1,1,1,1,1,1,1,1,1,1,1,1,1,1,1,1,1,1,1,1,1,1,1,1,1,1,1,1
1,1,1,1,1,1,1,1,1,1,1,1,1,1,1,1,1,1,1,1,1,1,1,1,1,1,1,1,1,1
endlayer

layer
1,1,1,1,1,1,1,1,1,1,1,1,1,1,1,1,1,1,1,1,1,1,1,1,1,1,1,1,1,1
1,1,1,1,1,1,1,1,1,1,1,1,1,1,1,1,1,1,1,1,1,1,1,1,1,1,1,1,1,1
1,1,1,1,1,1,1,1,1,1,1,1,1,1,1,1,1,1,1,1,1,1,1,1,1,1,1,1,1,1
1,1,1,1,1,1,1,1,1,1,1,1,1,1,1,1,1,1,1,1,1,1,1,1,1,1,1,1,1,1
1,1,1,1,1,1,1,1,1,1,1,1,1,1,1,1,1,1,1,1,1,1,1,1,1,1,1,1,1,1
1,1,1,1,1,1,1,1,1,1,1,1,1,1,1,1,1,1,1,1,1,1,1,1,1,1,1,1,1,1
1,1,1,1,1,1,1,1,1,1,1,1,1,1,1,1,1,1,1,1,1,1,1,1,1,1,1,1,1,1
1,1,1,1,1,1,1,1,1,1,1,1,1,1,1,1,1,1,1,1,1,1,1,1,1,1,1,1,1,1
1,1,1,1,1,1,1,1,1,1,1,1,1,1,1,1,1,1,1,1,1,1,1,1,1,1,1,1,1,1
1,1,1,1,1,1,1,1,1,1,1,1,1,1,1,1,1,1,1,1,1,1,1,1,1,1,1,1,1,1
1,1,1,1,1,1,1,1,1,1,1,1,1,1,1,1,1,1,1,1,1,1,1,1,1,1,1,1,1,1
1,1,1,1,1,1,1,1,1,1,1,1,1,1,1,1,1,1,1,1,1,1,1,1,1,1,1,1,1,1
1,1,1,1,1,1,1,1,1,1,1,1,1,1,1,1,1,1,1,1,1,1,1,1,1,1,1,1,1,1
1,1,1,1,1,1,1,1,1,1,1,1,1,1,1,1,1,1,1,1,1,1,1,1,1,1,1,1,1,1
1,1,1,1,1,1,1,1,1,1,1,1,1,1,20,20,1,1,1,1,1,1,1,1,1,1,1,1,1,1
1,1,1,1,1,1,1,1,1,1,1,1,1,1,20,20,1,1,1,1,1,1,1,1,1,1,1,1,1,1
1,1,1,1,1,1,1,1,1,1,1,1,1,1,1,1,1,1,1,1,1,1,1,1,1,1,1,1,1,1
1,1,1,1,1,1,1,1,1,1,1,1,1,1,1,1,1,1,1,1,1,1,1,1,1,1,1,1,1,1
1,1,1,1,1,1,1,1,1,1,1,1,1,1,1,1,1,1,1,1,1,1,1,1,1,1,1,1,1,1
1,1,1,1,1,1,1,1,1,1,1,1,1,1,1,1,1,1,1,1,1,1,1,1,1,1,1,1,1,1
1,1,1,1,1,1,1,1,1,1,1,1,1,1,1,1,1,1,1,1,1,1,1,1,1,1,1,1,1,1
1,1,1,1,1,1,1,1,1,1,1,1,1,1,1,1,1,1,1,1,1,1,1,1,1,1,1,1,1,1
1,1,1,1,1,1,1,1,1,1,1,1,1,1,1,1,1,1,1,1,1,1,1,1,1,1,1,1,1,1
1,1,1,1,1,1,1,1,1,1,1,1,1,1,1,1,1,1,1,1,1,1,1,1,1,1,1,1,1,1
1,1,1,1,1,1,1,1,1,1,1,1,1,1,1,1,1,1,1,1,1,1,1,1,1,1,1,1,1,1
1,1,1,1,1,1,1,1,1,1,1,1,1,1,1,1,1,1,1,1,1,1,1,1,1,1,1,1,1,1
1,1,1,1,1,1,1,1,1,1,1,1,1,1,1,1,1,1,1,1,1,1,1,1,1,1,1,1,1,1
1,1,1,1,1,1,1,1,1,1,1,1,1,1,1,1,1,1,1,1,1,1,1,1,1,1,1,1,1,1
1,1,1,1,1,1,1,1,1,1,1,1,1,1,1,1,1,1,1,1,1,1,1,1,1,1,1,1,1,1
1,1,1,1,1,1,1,1,1,1,1,1,1,1,1,1,1,1,1,1,1,1,1,1,1,1,1,1,1,1
endlayer
