# Converted from schematic
# THIS TEMPLATE USES DEFAULTS!  Please edit for corrections.
# If you need help, consult template_rules.txt
biomesToSpawnIn=desert,desert oil field,deserthills,dunes,lush desert,mountainous desert,desert_hills,desert_defiled,desert_shrubland,mutated_desert
weight=1
embed_into_distance=1
unacceptable_target_blocks=flowing_water,water,flowing_lava,lava,Natura:Cloud,red_mushroom_block,brown_mushroom_block,planks,cobblestone,end_stone,obsidian,purpur_block,iron_bars,purpur_slab,purpur_pillar,netherrack,soul_sand,quartz_ore
dimensions=7,11,10
allowable_overhang=0
max_cut_in=2
cut_in_buffer=1
max_leveling=2
leveling_buffer=-1
preserve_water=0
preserve_lava=0
preserve_plants=0


rule1=0,100,sand
rule2=0,100,sandstone
rule3=0,100,wooden_door-1
rule4=0,100,wooden_door-8
rule5=0,100,iron_bars
rule6=2,100,torch-1
rule7=2,100,torch-4
rule8=0,100,stone_slab-1


layer
2,2,2,2,2,1,1,1,1,1
2,2,2,2,2,2,2,2,2,1
2,2,2,2,2,2,2,2,2,1
2,2,2,2,2,2,2,2,2,1
2,2,2,2,2,1,1,1,1,1
2,2,2,2,2,1,1,1,1,1
2,2,2,2,2,1,1,1,1,1
2,2,2,2,2,1,1,1,1,1
2,2,2,2,2,1,1,1,1,1
2,2,2,2,2,1,1,1,1,1
2,2,2,2,2,1,1,1,1,1
endlayer

layer
2,2,2,2,2,2,2,2,2,0
2,0,0,0,0,0,0,0,2,0
2,0,0,0,0,0,0,0,3,0
2,0,0,0,0,0,0,0,2,0
2,0,0,0,2,2,2,2,2,0
2,0,0,0,2,0,0,0,0,0
2,0,0,0,2,0,0,0,0,0
2,0,0,0,2,0,0,0,0,0
2,0,0,0,2,0,0,0,0,0
2,0,0,0,2,0,0,0,0,0
2,2,2,2,2,0,0,0,0,0
endlayer

layer
2,2,2,2,2,2,2,2,2,0
2,0,0,0,0,0,0,0,2,0
5,0,0,0,0,0,0,0,4,0
5,0,0,0,0,0,0,0,2,0
2,0,0,0,2,2,2,2,2,0
2,0,0,0,2,0,0,0,0,0
2,0,0,0,2,0,0,0,0,0
5,0,0,0,2,0,0,0,0,0
5,0,0,0,2,0,0,0,0,0
2,0,0,0,2,0,0,0,0,0
2,2,2,2,2,0,0,0,0,0
endlayer

layer
2,2,5,2,2,2,2,5,2,0
2,0,0,0,0,6,0,0,2,0
2,0,0,0,0,0,0,0,2,0
2,7,0,0,0,0,0,0,2,0
2,0,0,0,2,2,2,5,2,0
2,0,0,0,2,0,0,0,0,0
2,0,0,0,2,0,0,0,0,0
2,0,0,0,2,0,0,0,0,0
2,0,0,0,5,0,0,0,0,0
2,0,0,0,2,0,0,0,0,0
2,2,2,2,2,0,0,0,0,0
endlayer

layer
2,2,2,2,2,2,2,2,2,0
2,7,0,0,0,0,0,0,2,8
2,0,0,0,0,0,0,0,2,8
2,0,0,0,0,0,0,0,2,8
2,0,0,0,2,2,2,2,2,0
2,0,0,0,2,0,0,0,0,0
2,0,0,0,2,0,0,0,0,0
2,0,0,0,2,0,0,0,0,0
2,0,0,0,2,0,0,0,0,0
2,0,0,0,2,0,0,0,0,0
2,2,2,2,2,0,0,0,0,0
endlayer

layer
2,2,2,2,2,2,2,2,2,0
2,2,2,2,2,2,2,2,2,0
2,2,2,2,2,2,2,2,2,0
2,2,2,2,2,2,2,2,2,0
2,2,2,2,2,2,2,2,2,0
2,2,2,2,2,0,0,0,0,0
2,2,2,2,2,0,0,0,0,0
2,2,2,2,2,0,0,0,0,0
2,2,2,2,2,0,0,0,0,0
2,2,2,2,2,0,0,0,0,0
2,2,2,2,2,0,0,0,0,0
endlayer

layer
8,8,8,8,8,8,8,8,8,0
8,0,0,0,0,0,0,0,8,0
8,0,0,0,0,0,0,0,8,0
8,0,0,0,0,0,0,0,8,0
8,0,0,0,8,8,8,8,8,0
8,0,0,0,8,0,0,0,0,0
8,0,0,0,8,0,0,0,0,0
8,0,0,0,8,0,0,0,0,0
8,0,0,0,8,0,0,0,0,0
8,0,0,0,8,0,0,0,0,0
8,8,8,8,8,0,0,0,0,0
endlayer

