# Author: RoofFiddler
# From: Minecraft Forums
biomesToSpawnIn=sky
weight=20
embed_into_distance=0


dimensions=7,9,15
allowable_overhang=0
max_leveling=2
leveling_buffer=0
preserve_water=0
preserve_lava=0
preserve_plants=1

rule1=0,100,air,purpur_block,quark:duskbound_block
rule2=0,100,purpur_block,quark:duskbound_block
rule3=1,80,purpur_block,quark:duskbound_block
rule4=1,75,purpur_block,quark:duskbound_block
rule5=2,75,purpur_block,quark:duskbound_block
rule6=2,50,purpur_block,quark:duskbound_block

layer
1,1,1,1,1,1,1,1,1,1,1,1,1,1,1
1,1,1,1,1,1,1,1,1,1,1,1,1,1,1
1,1,1,1,1,1,1,1,1,1,1,1,1,1,1
1,1,1,1,1,1,1,1,1,1,1,1,1,1,1
1,1,1,1,1,1,1,1,1,1,1,1,1,1,1
1,1,1,1,1,1,1,1,1,1,1,1,1,1,1
1,1,1,1,1,1,1,1,1,1,1,1,1,1,1
1,1,1,1,1,1,1,1,1,1,1,1,1,1,1
1,1,1,1,1,1,1,1,1,1,1,1,1,1,1
endlayer

layer
0,3,0,0,0,0,0,3,0,0,0,0,0,3,0
3,2,3,0,0,0,3,2,3,0,0,0,3,2,3
0,3,0,0,0,0,0,3,0,0,0,0,0,3,0
0,0,0,0,0,0,0,0,0,0,0,0,0,0,0
0,0,0,0,0,0,0,0,0,0,0,0,0,0,0
0,0,0,0,0,0,0,0,0,0,0,0,0,0,0
0,3,0,0,0,0,0,3,0,0,0,0,0,3,0
3,2,3,0,0,0,3,2,3,0,0,0,3,2,3
0,3,0,0,0,0,0,3,0,0,0,0,0,3,0
endlayer

layer
0,0,0,0,0,0,0,0,0,0,0,0,0,0,0
0,3,0,0,0,0,0,3,0,0,0,0,0,3,0
0,0,0,0,0,0,0,0,0,0,0,0,0,0,0
0,0,0,0,0,0,0,0,0,0,0,0,0,0,0
0,0,0,0,0,0,0,0,0,0,0,0,0,0,0
0,0,0,0,0,0,0,0,0,0,0,0,0,0,0
0,0,0,0,0,0,0,0,0,0,0,0,0,0,0
0,3,0,0,0,0,0,3,0,0,0,0,0,3,0
0,0,0,0,0,0,0,0,0,0,0,0,0,0,0
endlayer

layer
0,0,0,0,0,0,0,0,0,0,0,0,0,0,0
0,3,0,0,0,0,0,3,0,0,0,0,0,3,0
0,0,0,0,0,0,0,0,0,0,0,0,0,0,0
0,0,0,0,0,0,0,0,0,0,0,0,0,0,0
0,0,0,0,0,0,0,0,0,0,0,0,0,0,0
0,0,0,0,0,0,0,0,0,0,0,0,0,0,0
0,0,0,0,0,0,0,0,0,0,0,0,0,0,0
0,3,0,0,0,0,0,3,0,0,0,0,0,3,0
0,0,0,0,0,0,0,0,0,0,0,0,0,0,0
endlayer

layer
0,0,0,0,0,0,0,0,0,0,0,0,0,0,0
5,3,5,0,0,0,5,3,5,0,0,0,5,3,5
0,5,0,0,0,0,0,5,0,0,0,0,0,5,0
0,0,0,0,0,0,0,0,0,0,0,0,0,0,0
0,0,0,0,0,0,0,0,0,0,0,0,0,0,0
0,0,0,0,0,0,0,0,0,0,0,0,0,0,0
0,5,0,0,0,0,0,5,0,0,0,0,0,5,0
5,3,5,0,0,0,5,3,5,0,0,0,5,3,5
0,0,0,0,0,0,0,0,0,0,0,0,0,0,0
endlayer

layer
0,0,0,0,0,0,0,0,0,0,0,0,0,0,0
4,0,4,5,0,5,4,0,4,5,0,5,4,0,4
0,4,0,0,0,0,0,4,0,0,0,0,0,4,0
0,5,0,0,0,0,0,5,0,0,0,0,0,5,0
0,0,0,0,0,0,0,0,0,0,0,0,0,0,0
0,5,0,0,0,0,0,5,0,0,0,0,0,5,0
0,4,0,0,0,0,0,4,0,0,0,0,0,4,0
4,0,4,5,0,5,4,0,4,5,0,5,4,0,4
0,0,0,0,0,0,0,4,0,0,0,0,0,0,0
endlayer

layer
0,0,0,0,0,0,0,0,0,0,0,0,0,0,0
0,0,0,4,6,4,0,0,0,4,6,4,0,0,0
0,0,0,0,0,0,0,0,0,0,0,0,0,0,0
0,4,0,0,0,0,0,4,0,0,0,0,0,4,0
0,6,0,0,0,0,0,6,0,0,0,0,0,6,0
0,4,0,0,0,0,0,4,0,0,0,0,0,4,0
0,0,0,0,0,0,0,0,0,0,0,0,0,0,0
0,0,0,4,6,4,0,0,0,4,6,4,0,0,0
0,0,0,0,0,0,0,0,0,0,0,0,0,0,0
endlayer
