#SpiralTree
# Author: Arrrg
# From: Minecraft Forums

biomesToSpawnIn=biomesToSpawnIn=autumn woods,birch forest,boreal forest,cherry blossom grove,coniferous forest,deciduous forest,forest,forested field,forested hills,forested island,foresthills,fungi forest,lush redwoods,magical forest,maplewoods,orchard,pine forest,rainforest,redwood forest,sacred springs,seasonal forest,seasonal spruce forest,spruce woods,thinned timber,timber,wonderous woods,woodland,woodlands
weight=20
embed_into_distance=5
unacceptable_target_blocks=flowing_water,water,flowing_lava,lava,Natura:Cloud,red_mushroom_block,brown_mushroom_block,planks,cobblestone,end_stone,obsidian,purpur_block,iron_bars,purpur_slab,purpur_pillar,netherrack,soul_sand,quartz_ore
dimensions=34,17,17
allowable_overhang=150
max_cut_in=20
cut_in_buffer=0
max_leveling=5
leveling_buffer=-1
preserve_water=0
preserve_lava=0
preserve_plants=0

rule1=0,100,preserveBlock
rule2=0,100,log-2
rule3=0,100,log-1
rule4=0,100,log-0
rule5=0,100,gravel
rule6=0,100,stone
rule7=0,100,leaves
rule8=0,50,leaves
rule9=0,100,dirt
rule10=0,100,flowing_lava
rule11=0,100,sapling

layer
1,1,1,1,1,1,1,1,1,1,1,1,1,1,1,1,1
1,1,1,1,1,1,1,1,1,1,1,1,1,1,1,1,1
1,1,1,1,1,1,1,1,1,1,1,1,1,1,1,1,1
1,1,1,1,1,1,1,1,1,1,1,1,1,1,1,1,1
1,1,1,1,1,1,6,6,6,6,6,6,6,6,1,1,1
1,1,1,1,1,6,6,6,6,6,6,6,6,6,1,1,1
1,1,1,1,6,6,6,6,6,6,6,6,6,6,1,1,1
1,1,1,1,6,6,6,6,6,6,6,6,1,1,1,1,1
1,1,1,1,6,6,6,6,6,6,6,6,1,1,1,1,1
1,1,6,6,6,6,6,6,6,6,6,6,1,1,1,1,1
1,1,6,6,6,6,6,6,6,6,6,1,1,1,1,1,1
1,1,6,6,6,6,6,6,6,6,1,1,1,1,1,1,1
1,1,1,1,1,1,1,1,1,1,1,1,1,1,1,1,1
1,1,1,1,1,1,1,1,1,1,1,1,1,1,1,1,1
1,1,1,1,1,1,1,1,1,1,1,1,1,1,1,1,1
1,1,1,1,1,1,1,1,1,1,1,1,1,1,1,1,1
1,1,1,1,1,1,1,1,1,1,1,1,1,1,1,1,1
endlayer

layer
1,1,1,1,1,1,1,1,1,1,1,1,1,1,1,1,1
1,1,1,1,1,1,1,1,1,1,1,1,1,1,1,1,1
1,1,1,1,1,1,1,1,1,1,1,1,1,1,1,1,1
1,1,1,1,1,1,1,1,1,1,1,1,1,1,1,1,1
1,1,1,1,1,1,4,6,6,6,6,0,1,1,1,1,1
1,1,1,1,1,4,0,0,0,6,0,6,1,1,1,1,1
1,1,1,1,4,0,0,0,0,0,6,6,1,1,1,1,1
1,1,1,1,6,0,0,0,0,0,0,6,1,1,1,1,1
1,1,1,1,6,0,0,0,0,0,0,6,1,1,1,1,1
1,1,1,1,6,6,0,0,0,0,0,3,1,1,1,1,1
1,1,1,1,6,0,6,0,0,0,3,1,1,1,1,1,1
1,1,1,1,0,6,6,6,6,3,1,1,1,1,1,1,1
1,1,1,1,1,1,1,1,1,1,1,1,1,1,1,1,1
1,1,1,1,1,1,1,1,1,1,1,1,1,1,1,1,1
1,1,1,1,1,1,1,1,1,1,1,1,1,1,1,1,1
1,1,1,1,1,1,1,1,1,1,1,1,1,1,1,1,1
1,1,1,1,1,1,1,1,1,1,1,1,1,1,1,1,1
endlayer

layer
1,1,1,1,1,1,1,1,1,1,1,1,1,1,1,1,1
1,1,1,1,1,1,1,1,1,1,1,1,1,1,1,1,1
1,1,1,1,1,1,1,1,1,1,1,1,1,1,1,1,1
1,1,1,1,1,1,1,1,1,1,6,6,6,1,1,1,1
1,1,1,1,1,1,4,6,6,6,6,6,6,6,1,1,1
1,1,1,1,1,4,0,0,0,0,0,10,6,6,1,1,1
1,1,1,1,4,0,0,0,0,0,0,6,6,6,1,1,1
1,1,1,1,6,0,0,0,0,0,0,6,6,1,1,1,1
1,1,1,6,6,0,0,0,0,0,0,6,1,1,1,1,1
1,1,6,6,6,0,0,0,0,0,0,3,1,1,1,1,1
1,1,6,6,10,0,0,0,0,0,3,1,1,1,1,1,1
1,1,6,6,6,6,6,6,6,3,1,1,1,1,1,1,1
1,1,1,6,6,6,1,1,1,1,1,1,1,1,1,1,1
1,1,1,1,1,1,1,1,1,1,1,1,1,1,1,1,1
1,1,1,1,1,1,1,1,1,1,1,1,1,1,1,1,1
1,1,1,1,1,1,1,1,1,1,1,1,1,1,1,1,1
1,1,1,1,1,1,1,1,1,1,1,1,1,1,1,1,1
endlayer

layer
1,1,1,1,1,1,1,1,1,1,1,1,1,1,1,1,1
1,1,1,1,1,1,1,1,1,1,1,1,1,1,1,1,1
1,1,1,1,1,1,1,1,1,1,1,1,1,1,1,1,1
1,1,1,1,1,1,1,1,1,1,1,6,6,1,1,1,1
1,1,1,1,1,1,6,6,6,6,6,6,6,6,1,1,1
1,1,1,1,1,6,0,0,0,0,0,6,6,6,1,1,1
1,1,1,1,6,0,0,0,0,0,0,6,6,6,1,1,1
1,1,1,1,6,0,0,0,0,0,0,6,6,1,1,1,1
1,1,1,6,6,0,0,0,0,0,0,6,1,1,1,1,1
1,1,6,6,6,0,0,0,0,0,0,6,1,1,1,1,1
1,1,6,6,6,0,0,0,0,0,6,1,1,1,1,1,1
1,1,6,6,6,6,6,6,6,6,1,1,1,1,1,1,1
1,1,1,6,6,6,1,1,1,1,1,1,1,1,1,1,1
1,1,1,1,1,1,1,1,1,1,1,1,1,1,1,1,1
1,1,1,1,1,1,1,1,1,1,1,1,1,1,1,1,1
1,1,1,1,1,1,1,1,1,1,1,1,1,1,1,1,1
1,1,1,1,1,1,1,1,1,1,1,1,1,1,1,1,1
endlayer

layer
1,1,1,1,1,1,1,1,1,1,1,1,1,1,1,1,1
1,1,1,1,1,1,1,1,1,1,1,1,1,1,1,1,1
1,1,1,1,1,1,1,1,1,1,1,1,1,1,1,1,1
1,1,1,1,1,1,1,1,1,1,1,1,1,1,1,1,1
1,1,1,1,1,1,4,4,6,6,6,6,1,1,1,1,1
1,1,1,1,1,4,6,6,6,6,0,6,1,1,1,1,1
1,1,1,1,4,6,0,0,0,0,6,6,1,1,1,1,1
1,1,1,1,4,6,0,0,0,0,6,6,1,1,1,1,1
1,1,1,1,6,6,0,0,0,0,6,2,1,1,1,1,1
1,1,1,1,6,6,0,0,0,0,6,3,1,1,1,1,1
1,1,1,1,6,0,6,6,6,6,3,1,1,1,1,1,1
1,1,1,1,6,6,6,6,3,3,1,1,1,1,1,1,1
1,1,1,1,1,1,1,1,1,1,1,1,1,1,1,1,1
1,1,1,1,1,1,1,1,1,1,1,1,1,1,1,1,1
1,1,1,1,1,1,1,1,1,1,1,1,1,1,1,1,1
1,1,1,1,1,1,1,1,1,1,1,1,1,1,1,1,1
1,1,1,1,1,1,1,1,1,1,1,1,1,1,1,1,1
endlayer

layer
1,1,1,1,1,1,1,1,1,1,1,1,1,1,1,1,1
1,1,1,1,1,1,1,1,1,1,1,1,1,1,1,1,1
1,1,1,1,1,1,1,1,1,1,1,1,1,1,1,1,1
1,1,1,1,1,1,1,1,1,1,1,1,1,1,1,1,1
1,1,1,1,1,1,4,4,2,2,2,1,1,1,1,1,1
1,1,1,1,1,4,6,4,2,6,0,2,1,1,1,1,1
1,1,1,1,4,6,6,4,2,6,6,2,1,1,1,1,1
1,1,1,1,4,6,4,4,2,2,6,2,1,1,1,1,1
1,1,1,1,4,6,4,3,3,2,6,2,1,1,1,1,1
1,1,1,1,4,6,6,3,3,6,6,3,1,1,1,1,1
1,1,1,1,3,0,6,6,6,6,3,1,1,1,1,1,1
1,1,1,1,1,3,3,3,3,3,1,1,1,1,1,1,1
1,1,1,1,1,1,1,1,1,1,1,1,1,1,1,1,1
1,1,1,1,1,1,1,1,1,1,1,1,1,1,1,1,1
1,1,1,1,1,1,1,1,1,1,1,1,1,1,1,1,1
1,1,1,1,1,1,1,1,1,1,1,1,1,1,1,1,1
1,1,1,1,1,1,1,1,1,1,1,1,1,1,1,1,1
endlayer

layer
1,1,1,1,1,1,1,1,1,1,1,1,1,1,1,1,1
1,1,1,1,1,1,1,1,1,1,1,1,1,1,1,1,1
1,1,1,1,1,1,1,1,1,1,1,1,1,1,1,1,1
1,1,1,1,1,1,1,1,1,1,1,1,1,1,1,1,1
1,1,1,1,1,1,4,0,0,2,2,1,1,1,1,1,1
1,1,1,1,1,4,6,0,0,6,0,2,1,1,1,1,1
1,1,1,1,4,6,0,0,0,0,6,2,1,1,1,1,1
1,1,1,1,4,6,0,0,0,0,6,2,1,1,1,1,1
1,1,1,1,4,6,0,0,0,0,6,2,1,1,1,1,1
1,1,1,1,4,6,0,0,0,6,6,2,1,1,1,1,1
1,1,1,1,3,0,6,6,6,6,3,1,1,1,1,1,1
1,1,1,1,1,3,3,3,3,3,1,1,1,1,1,1,1
1,1,1,1,1,1,1,1,1,1,1,1,1,1,1,1,1
1,1,1,1,1,1,1,1,1,1,1,1,1,1,1,1,1
1,1,1,1,1,1,1,1,1,1,1,1,1,1,1,1,1
1,1,1,1,1,1,1,1,1,1,1,1,1,1,1,1,1
1,1,1,1,1,1,1,1,1,1,1,1,1,1,1,1,1
endlayer

layer
1,1,1,1,1,1,1,1,1,1,1,1,1,1,1,1,1
1,1,1,1,1,1,1,1,1,1,1,1,1,1,1,1,1
1,1,1,1,1,1,1,1,1,1,1,1,1,1,1,1,1
1,1,1,1,1,1,1,1,1,1,1,1,1,1,1,1,1
1,1,1,1,1,1,4,0,0,2,2,1,1,1,1,1,1
1,1,1,1,1,4,6,0,0,6,0,2,1,1,1,1,1
1,1,1,1,4,6,0,0,0,0,6,2,1,1,1,1,1
1,1,1,1,4,6,0,0,0,0,6,2,1,1,1,1,1
1,1,1,1,4,6,0,0,0,0,6,2,1,1,1,1,1
1,1,1,1,1,6,0,0,6,0,6,2,1,1,1,1,1
1,1,1,1,3,0,6,6,6,6,1,1,1,1,1,1,1
1,1,1,1,3,3,3,3,3,3,1,1,1,1,1,1,1
1,1,1,1,1,1,1,1,1,1,1,1,1,1,1,1,1
1,1,1,1,1,1,1,1,1,1,1,1,1,1,1,1,1
1,1,1,1,1,1,1,1,1,1,1,1,1,1,1,1,1
1,1,1,1,1,1,1,1,1,1,1,1,1,1,1,1,1
1,1,1,1,1,1,1,1,1,1,1,1,1,1,1,1,1
endlayer

layer
1,1,1,1,1,1,1,1,1,1,1,1,1,1,1,1,1
1,1,1,1,1,1,1,1,1,1,1,1,1,1,1,1,1
1,1,1,1,1,1,1,1,1,1,1,1,1,1,1,1,1
1,1,1,1,1,1,1,1,1,1,1,1,1,1,1,1,1
1,1,1,1,1,1,4,0,0,1,1,1,1,1,1,1,1
1,1,1,1,1,4,6,0,0,6,0,2,1,1,1,1,1
1,1,1,1,4,6,0,0,0,0,6,2,1,1,1,1,1
1,1,1,1,4,6,0,0,0,0,6,2,1,1,1,1,1
1,1,1,1,1,6,0,0,0,0,6,2,1,1,1,1,1
1,1,1,1,1,6,0,6,0,0,6,2,1,1,1,1,1
1,1,8,8,3,0,6,6,6,6,1,1,1,1,1,1,1
1,8,7,7,3,3,3,3,3,1,1,1,1,1,1,1,1
1,8,7,3,7,8,1,1,1,1,1,1,1,1,1,1,1
1,8,7,7,7,8,1,1,1,1,1,1,1,1,1,1,1
1,1,8,8,8,1,1,1,1,1,1,1,1,1,1,1,1
1,1,1,1,1,1,1,1,1,1,1,1,1,1,1,1,1
1,1,1,1,1,1,1,1,1,1,1,1,1,1,1,1,1
endlayer

layer
1,1,1,1,1,1,1,1,1,1,1,1,1,1,1,1,1
1,1,1,1,1,1,1,1,1,1,1,1,1,1,1,1,1
1,1,1,1,1,1,1,1,1,1,1,1,1,1,1,1,1
1,1,1,1,1,1,1,1,1,1,1,1,1,1,1,1,1
1,1,1,1,1,1,4,1,1,1,1,1,1,1,1,1,1
1,1,1,1,1,4,6,6,6,6,0,1,1,1,1,1,1
1,1,1,1,4,6,0,0,0,0,6,2,1,1,1,1,1
1,1,1,1,1,6,0,0,0,0,6,2,1,1,1,1,1
1,1,1,1,1,6,0,0,0,0,6,2,1,1,1,1,1
1,1,8,8,8,6,6,0,0,0,6,2,1,1,1,1,1
1,8,7,7,3,0,6,6,6,6,1,1,1,1,1,1,1
8,7,3,7,7,3,3,3,1,1,1,1,1,1,1,1,1
8,7,7,3,7,7,8,1,1,1,1,1,1,1,1,1,1
8,7,3,7,3,7,8,1,1,1,1,1,1,1,1,1,1
1,8,7,7,7,8,1,1,1,1,1,1,1,1,1,1,1
1,1,8,8,8,1,1,1,1,1,1,1,1,1,1,1,1
1,1,1,1,1,1,1,1,1,1,1,1,1,1,1,1,1
endlayer

layer
1,1,1,1,1,1,1,1,1,1,1,1,1,1,1,1,1
1,1,1,1,1,1,1,1,1,1,1,1,1,1,1,1,1
1,1,1,1,1,1,1,1,1,1,1,1,1,1,1,1,1
1,1,1,1,1,1,1,1,1,1,1,1,1,1,1,1,1
1,1,1,1,1,1,4,4,1,1,1,1,1,1,1,1,1
1,1,1,1,1,4,6,6,6,6,0,1,1,1,1,1,1
1,1,1,1,1,6,0,0,0,0,6,1,1,1,1,1,1
1,1,1,1,1,6,0,0,0,0,6,2,1,1,1,1,1
1,1,1,1,1,6,6,0,0,0,6,2,1,1,1,1,1
0,0,7,7,3,0,0,0,0,0,6,2,1,1,1,1,1
1,7,0,0,3,0,0,6,6,6,2,1,1,1,1,1,1
7,0,0,0,0,3,3,1,1,1,1,1,1,1,1,1,1
7,0,0,3,0,0,7,1,1,1,1,1,1,1,1,1,1
7,0,0,0,0,0,7,1,1,1,1,1,1,1,1,1,1
1,7,0,0,0,7,0,1,1,1,1,1,1,1,1,1,1
1,1,7,7,7,1,0,1,1,1,1,1,1,1,1,1,1
1,1,1,1,1,1,0,1,1,1,1,1,1,1,1,1,1
endlayer

layer
1,1,1,1,1,1,1,1,1,1,1,1,1,1,1,1,1
1,1,8,8,8,1,1,1,1,1,1,1,1,1,1,1,1
1,8,7,7,7,8,1,1,1,1,1,1,1,1,1,1,1
1,8,7,4,7,8,1,1,1,1,1,1,1,1,1,1,1
1,8,7,7,4,4,4,4,0,1,1,1,1,1,1,1,1
1,1,8,8,8,1,6,6,6,6,0,1,1,1,1,1,1
1,1,1,1,1,6,0,0,0,0,6,1,1,1,1,1,1
1,1,1,1,1,6,6,0,0,0,6,1,1,1,1,1,1
1,1,1,1,1,6,0,0,0,0,6,2,1,1,1,1,1
1,1,0,0,3,0,0,0,0,0,6,2,1,1,1,1,1
0,0,0,0,3,3,0,6,6,6,2,1,1,1,1,1,1
0,0,0,0,0,3,0,1,1,1,1,1,1,1,1,1,1
0,0,0,3,0,0,0,1,1,1,1,1,1,1,1,1,1
0,0,0,0,0,0,0,1,1,1,1,1,1,1,1,1,1
0,0,0,0,0,0,1,1,1,1,1,1,1,1,1,1,1
1,1,0,0,0,0,1,1,1,1,1,1,1,1,1,1,1
0,0,0,0,0,0,1,1,1,1,1,1,1,1,1,1,1
endlayer

layer
1,1,8,8,8,1,1,1,1,1,1,1,1,1,1,1,1
1,8,7,7,7,8,1,1,1,1,1,1,1,1,1,1,1
8,7,4,7,4,7,8,1,1,1,1,1,1,1,1,1,1
8,7,7,4,7,7,8,1,1,1,1,1,1,1,1,1,1
8,7,4,7,7,7,4,4,1,1,1,1,1,1,1,1,1
1,8,7,7,7,7,6,6,6,6,0,1,1,1,1,1,1
1,1,8,8,8,6,6,0,0,0,6,1,1,1,1,1,1
1,1,1,1,1,6,0,0,0,0,6,1,1,1,1,1,1
1,1,1,1,1,6,0,0,0,0,6,1,1,1,1,1,1
1,1,0,0,3,6,0,0,0,0,6,2,1,1,1,1,1
1,0,7,7,7,5,6,6,6,6,2,1,1,1,1,1,1
0,7,8,8,8,7,0,1,1,1,1,1,1,1,1,1,1
0,7,8,3,8,7,0,1,1,1,1,1,1,1,1,1,1
0,7,8,8,8,7,0,1,1,1,1,1,1,1,1,1,1
0,0,7,7,7,0,1,1,1,1,1,1,1,1,1,1,1
1,1,0,0,0,1,1,1,1,1,1,1,1,1,1,1,1
1,1,1,1,1,1,1,1,1,1,1,1,1,1,1,1,1
endlayer

layer
0,0,7,7,7,0,0,1,1,1,1,1,1,1,1,1,1
0,7,0,0,0,7,0,1,1,1,1,1,1,1,1,1,1
7,0,0,0,0,0,7,1,1,1,1,1,1,1,1,1,1
7,0,0,4,0,0,7,1,1,1,1,1,1,1,1,1,1
7,0,0,0,0,0,7,4,4,1,1,1,1,1,1,1,1
0,7,0,0,0,0,0,6,6,6,0,1,1,1,1,1,1
0,0,7,7,7,0,0,6,0,0,6,1,1,1,1,1,1
1,1,1,1,1,6,0,0,0,0,6,1,1,1,1,1,1
1,1,1,1,3,6,0,0,0,0,6,1,1,1,1,1,1
1,1,8,8,3,6,0,0,0,0,6,1,1,1,1,1,1
1,8,8,8,8,8,6,6,6,6,2,1,1,1,1,1,1
8,8,3,8,3,8,8,1,1,2,1,1,1,1,1,1,1
8,8,8,3,8,8,8,1,1,1,1,1,1,1,1,1,1
8,8,3,8,3,8,8,1,1,1,1,1,1,1,1,1,1
1,8,8,8,8,8,1,1,1,1,1,1,1,1,1,1,1
1,1,8,8,8,1,1,1,1,1,1,1,1,1,1,1,1
1,1,1,1,1,1,1,1,1,1,1,1,1,1,1,1,1
endlayer

layer
0,0,0,0,0,0,0,1,1,1,1,1,1,1,1,1,1
0,0,0,0,0,0,0,1,1,1,1,8,8,8,1,1,1
0,0,0,0,0,0,0,1,1,1,8,7,7,7,8,1,1
0,0,0,4,0,0,0,1,1,1,8,7,4,7,8,1,1
0,0,0,0,0,0,0,4,4,4,4,4,7,7,8,1,1
0,0,0,0,0,0,0,6,6,6,0,8,8,8,1,1,1
0,0,0,0,0,0,0,0,6,0,6,1,1,1,1,1,1
1,1,1,1,1,6,0,0,0,0,6,1,1,1,1,1,1
1,1,1,1,3,6,0,0,0,0,6,1,1,1,1,1,1
1,1,1,1,3,6,0,0,0,0,6,1,1,1,1,1,1
1,1,8,8,8,1,6,6,6,6,2,1,1,1,1,1,1
1,8,8,8,8,8,1,1,1,2,1,1,1,1,1,1,1
1,8,8,3,8,8,1,1,1,1,1,1,1,1,1,1,1
1,8,8,8,8,8,1,1,1,1,1,1,1,1,1,1,1
1,1,8,8,8,1,1,1,1,1,1,1,1,1,1,1,1
1,1,1,1,1,1,1,1,1,1,1,1,1,1,1,1,1
1,1,1,1,1,1,1,1,1,1,1,1,1,1,1,1,1
endlayer

layer
0,0,0,0,0,0,0,1,1,1,1,8,8,8,1,1,1
0,0,0,0,0,0,0,1,1,1,8,7,7,7,8,1,1
0,0,0,7,0,0,0,1,1,8,7,4,7,4,7,8,1
0,0,7,4,7,0,0,1,1,8,7,7,4,7,7,8,1
0,0,0,7,0,0,0,1,4,4,7,7,7,4,7,8,1
0,0,0,0,0,0,6,6,6,6,0,7,7,7,8,1,1
0,0,0,0,0,6,0,0,0,6,6,8,8,8,1,1,1
1,1,1,1,3,6,0,0,0,0,6,1,1,1,1,1,1
1,1,1,1,3,6,0,0,0,0,6,1,1,1,1,1,1
1,1,1,1,1,6,0,0,0,0,6,1,1,1,1,1,1
1,1,8,8,8,1,6,6,6,6,1,1,1,1,1,1,1
1,8,8,8,8,8,1,1,2,2,1,1,1,1,1,1,1
1,8,8,3,8,8,1,1,1,1,1,1,1,1,1,1,1
1,8,8,8,8,8,1,1,1,1,1,1,1,1,1,1,1
1,1,8,8,8,1,1,1,1,1,1,1,1,1,1,1,1
1,1,1,1,1,1,1,1,1,1,1,1,1,1,1,1,1
1,1,1,1,1,1,1,1,1,1,1,1,1,1,1,1,1
endlayer

layer
0,0,0,0,0,0,0,1,1,1,1,7,7,7,1,1,1
0,0,7,7,7,0,0,1,1,1,7,0,0,0,7,1,1
0,7,8,8,8,7,0,1,1,7,0,0,0,0,0,7,1
0,7,8,4,8,7,0,1,1,7,0,0,4,0,0,7,1
0,7,8,8,8,7,0,1,4,4,0,0,0,0,0,7,1
0,0,7,7,7,0,6,6,6,0,0,0,0,0,7,1,1
0,0,0,0,0,6,0,0,0,0,0,7,7,7,1,1,1
1,1,1,1,3,6,0,0,0,6,6,1,1,1,1,1,1
1,1,1,1,3,6,0,0,0,0,6,1,1,1,1,1,1
1,1,1,1,1,6,0,0,0,0,6,1,1,1,1,1,1
1,1,1,1,1,1,6,6,6,6,1,1,1,1,1,1,1
1,1,8,8,8,1,1,1,2,2,1,1,1,1,1,1,1
1,1,8,8,8,1,1,1,1,1,1,1,1,1,1,1,1
1,1,8,8,8,1,1,1,1,1,1,1,1,1,1,1,1
1,1,1,1,1,1,1,1,1,1,1,1,1,1,1,1,1
1,1,1,1,1,1,1,1,1,1,1,1,1,1,1,1,1
1,1,1,1,1,1,1,1,1,1,1,1,1,1,1,1,1
endlayer

layer
1,1,8,8,8,1,1,1,1,1,0,0,0,0,0,0,0
1,8,8,8,8,8,1,1,1,1,0,0,0,0,0,0,0
8,8,4,8,4,8,8,1,1,1,0,0,0,0,0,0,0
8,8,8,4,8,8,8,1,1,1,0,0,4,0,0,0,0
8,8,4,8,8,8,8,1,1,4,0,0,0,0,0,0,0
1,8,8,8,8,8,6,6,6,0,4,0,0,0,0,0,0
1,1,8,8,3,6,0,0,0,0,0,1,1,1,1,1,1
1,1,1,1,3,6,0,0,0,0,6,1,1,1,1,1,1
1,1,1,1,1,6,0,0,0,6,6,1,1,1,1,1,1
1,1,1,1,1,6,0,0,0,0,6,1,1,1,1,1,1
1,1,1,1,1,1,6,6,6,6,8,8,8,8,1,1,1
1,1,8,8,8,1,1,2,2,2,2,2,7,7,8,1,1
1,1,8,8,8,1,1,1,1,1,8,7,2,7,8,1,1
1,1,8,8,8,1,1,1,1,1,8,7,7,7,8,1,1
1,1,1,1,1,1,1,1,1,1,0,8,8,8,1,1,1
1,1,1,1,1,1,1,1,1,1,1,1,1,1,1,1,1
1,1,1,1,1,1,1,1,1,1,1,1,1,1,1,1,1
endlayer

layer
1,1,1,1,1,1,1,1,1,1,0,0,0,0,0,0,0
1,1,8,8,8,1,1,1,1,1,0,0,0,0,0,0,0
1,8,8,8,8,8,1,1,1,1,0,0,7,0,0,0,0
1,8,8,4,8,8,1,1,1,1,0,7,4,7,0,0,0
1,8,8,8,8,8,1,1,1,4,0,0,7,0,0,0,0
1,1,8,8,8,1,6,6,6,6,5,0,0,0,0,0,0
1,1,1,1,3,6,0,0,0,0,6,1,1,1,1,1,1
1,1,1,1,3,6,0,0,0,0,6,1,1,1,1,1,1
1,1,1,1,1,6,0,0,0,0,6,1,1,1,1,1,1
1,1,1,1,1,6,0,0,0,6,6,8,8,8,1,1,1
1,1,1,1,1,1,6,6,6,6,7,7,7,7,8,1,1
1,1,1,8,1,1,1,2,2,8,7,7,7,2,7,8,1
1,1,8,8,8,1,1,1,1,8,7,7,2,7,7,8,1
1,1,1,8,1,1,1,1,1,8,7,2,7,2,7,8,1
1,1,1,1,1,1,1,1,1,1,8,7,7,7,8,1,1
1,1,1,1,1,1,1,1,1,1,1,8,8,8,1,1,1
1,1,1,1,1,1,1,1,1,1,1,1,1,1,1,1,1
endlayer

layer
1,1,1,1,1,1,1,1,1,1,1,1,1,1,1,1,1
1,1,8,8,8,1,1,1,1,1,1,7,7,7,1,1,1
1,8,8,8,8,8,1,1,1,1,7,8,8,8,7,1,1
1,8,8,4,8,8,1,1,1,1,7,8,4,8,7,1,1
1,8,8,8,8,8,1,1,1,1,8,8,8,8,7,1,1
1,1,8,8,8,1,6,6,6,6,4,7,7,7,1,1,1
1,1,1,1,3,6,0,0,0,0,6,4,1,1,1,1,1
1,1,1,1,1,6,0,0,0,0,6,1,1,1,1,1,1
1,1,1,1,1,6,0,0,0,0,6,1,1,1,1,1,1
1,1,1,1,1,6,0,0,6,0,0,7,7,7,0,0,0
1,1,1,1,1,1,6,6,6,0,0,0,0,0,7,0,0
1,1,1,1,1,1,2,2,1,7,0,0,0,0,0,7,0
1,1,1,1,1,1,1,1,1,7,0,0,2,0,0,7,0
1,1,1,1,1,1,1,1,1,7,0,0,0,0,0,7,0
1,1,1,1,1,1,1,1,1,0,7,0,0,0,7,0,0
1,1,1,1,1,1,1,1,1,0,0,7,7,7,0,0,0
1,1,1,1,1,1,1,1,1,0,0,0,0,0,0,0,0
endlayer

layer
1,1,1,1,1,1,1,1,1,1,1,1,1,1,1,1,1
1,1,1,1,1,1,1,1,1,1,1,8,8,8,1,1,1
1,1,8,8,8,1,1,1,1,1,8,8,8,8,8,1,1
1,1,8,8,8,1,1,1,1,1,8,8,4,8,8,1,1
1,1,8,8,8,1,1,1,1,1,8,8,8,8,8,1,1
1,1,1,1,1,3,6,6,6,6,1,8,8,8,1,1,1
1,1,1,1,3,6,0,0,0,0,6,4,1,1,1,1,1
1,1,1,1,1,6,0,0,0,0,6,1,1,1,1,1,1
1,1,1,1,1,6,0,0,0,0,6,1,1,1,1,1,1
1,1,1,1,1,6,0,6,0,0,0,0,0,0,0,0,0
1,1,8,8,8,1,6,6,6,0,0,0,0,0,0,0,0
1,8,7,7,2,2,2,2,1,0,0,0,0,0,0,0,0
1,8,7,2,7,8,1,1,1,0,0,0,2,0,0,0,0
1,8,7,7,7,8,1,1,1,0,0,0,0,0,0,0,0
1,1,8,8,8,1,1,1,1,0,0,0,0,0,0,0,0
1,1,1,1,1,1,1,1,1,0,0,0,0,0,0,0,0
1,1,1,1,1,1,1,1,1,0,0,0,0,0,0,0,0
endlayer

layer
1,1,1,1,1,1,1,1,1,1,1,1,1,1,1,1,1
1,1,1,1,1,1,1,1,1,1,1,8,8,8,1,1,1
1,1,8,8,8,1,1,1,1,1,8,8,8,8,8,1,1
1,1,8,8,8,1,1,1,1,1,8,8,4,8,8,1,1
1,1,8,8,8,1,3,1,1,1,8,8,8,8,8,1,1
1,1,1,1,1,3,6,6,6,6,1,8,8,8,1,1,1
1,1,1,1,1,6,0,0,0,0,6,4,1,1,1,1,1
1,1,1,1,1,6,0,0,0,0,6,4,1,1,1,1,1
1,1,1,1,1,6,0,0,0,0,6,1,1,1,1,1,1
1,1,8,8,8,6,6,0,0,0,6,0,0,0,0,0,0
1,8,7,7,7,2,6,6,6,6,0,0,0,0,0,0,0
8,7,2,7,7,7,2,1,1,0,0,0,7,0,0,0,0
8,7,7,2,7,7,8,1,1,0,0,7,2,7,0,0,0
8,7,2,7,2,7,8,1,1,0,0,0,7,0,0,0,0
1,8,7,7,7,8,1,1,1,0,0,0,0,0,0,0,0
1,1,8,8,8,1,1,1,1,0,0,0,0,0,0,0,0
1,1,1,1,1,1,1,1,1,0,0,0,0,0,0,0,0
endlayer

layer
1,1,1,1,1,1,1,1,1,1,1,1,1,1,1,1,1
1,1,1,1,1,1,1,1,1,1,1,1,1,1,1,1,1
1,1,1,8,1,1,1,1,1,1,1,8,8,8,1,1,1
1,1,8,8,8,1,1,1,1,1,1,8,8,8,1,1,1
1,1,1,8,1,1,3,1,1,1,1,8,8,8,1,1,1
1,1,1,1,1,3,6,6,6,6,1,1,1,1,1,1,1
1,1,1,1,1,6,0,0,0,0,6,4,1,1,1,1,1
1,1,1,1,1,6,0,0,0,0,6,4,1,1,1,1,1
1,1,1,1,1,6,6,0,0,0,6,1,1,1,1,1,1
1,1,7,7,7,0,0,0,0,0,6,1,1,1,1,1,1
1,7,0,0,0,2,0,6,6,6,1,7,7,7,1,1,1
7,0,0,0,0,0,2,1,1,1,7,8,8,8,7,1,1
7,0,0,2,0,0,7,1,1,1,7,8,2,8,7,1,1
7,0,0,0,0,0,7,1,1,1,7,8,8,8,7,1,1
1,7,0,0,0,7,1,1,1,1,1,7,7,7,1,1,1
1,1,7,7,7,1,1,1,1,1,1,1,1,1,1,1,1
1,1,1,1,1,1,1,1,1,1,1,1,1,1,1,1,1
endlayer

layer
1,1,1,1,1,1,1,1,1,1,1,1,1,1,1,1,1
1,1,8,8,8,1,1,1,1,1,1,1,1,1,1,1,1
1,8,7,7,7,8,1,1,1,1,1,8,8,8,1,1,1
1,8,7,3,7,8,1,1,1,1,1,8,8,8,1,1,1
1,8,7,7,3,3,3,3,1,1,1,8,8,8,1,1,1
1,1,8,8,8,1,6,6,6,6,1,1,1,1,1,1,1
1,1,1,1,1,6,0,0,0,0,6,1,1,1,1,1,1
1,1,1,1,1,6,6,0,0,0,6,4,1,1,1,1,1
1,1,1,1,1,6,0,0,0,0,6,4,1,1,1,1,1
1,1,1,1,2,0,0,0,0,0,6,1,1,1,1,1,1
1,1,1,1,1,2,0,6,6,6,1,8,8,8,1,1,1
1,1,1,1,1,1,1,1,1,1,8,8,8,8,8,1,1
1,1,1,2,1,1,1,1,1,1,8,8,2,8,8,1,1
1,1,1,1,1,1,1,1,1,1,8,8,8,8,8,1,1
1,1,1,1,1,1,1,1,1,1,1,8,8,8,1,1,1
1,1,1,1,1,1,1,1,1,1,1,1,1,1,1,1,1
1,1,1,1,1,1,1,1,1,1,1,1,1,1,1,1,1
endlayer

layer
1,1,8,8,8,1,1,1,1,1,1,1,1,1,1,1,1
1,8,7,7,7,8,1,1,1,1,1,1,1,1,1,1,1
8,7,3,7,3,7,8,1,1,1,1,1,8,1,1,1,1
8,7,7,3,7,7,8,1,1,1,1,8,8,8,1,1,1
8,7,3,7,7,7,3,3,1,1,1,1,8,1,1,1,1
1,8,7,7,7,7,6,6,6,6,1,1,1,1,1,1,1
1,1,8,8,8,6,6,0,0,0,6,1,1,1,1,1,1
1,1,1,1,1,6,0,0,0,0,6,4,1,1,1,1,1
1,1,1,1,1,6,0,0,0,0,6,4,1,1,1,1,1
1,1,1,1,2,6,0,0,0,0,6,1,1,1,1,1,1
1,1,1,1,1,2,6,6,6,6,1,8,8,8,1,1,1
1,1,1,7,1,1,1,1,1,1,8,8,8,8,8,1,1
1,1,7,2,7,1,1,1,1,1,8,8,2,8,8,1,1
1,1,1,7,1,1,1,1,1,1,8,8,8,8,8,1,1
1,1,1,1,1,1,1,1,1,1,1,8,8,8,1,1,1
1,1,1,1,1,1,1,1,1,1,1,1,1,1,1,1,1
1,1,1,1,1,1,1,1,1,1,1,1,1,1,1,1,1
endlayer

layer
1,1,7,7,7,1,1,1,1,1,1,1,1,1,1,1,1
1,7,0,0,0,7,1,1,1,1,1,1,1,1,1,1,1
7,0,0,0,0,0,7,1,1,1,1,1,1,1,1,1,1
7,0,0,3,0,0,7,1,1,1,1,1,1,1,1,1,1
7,0,0,0,0,0,0,3,3,1,1,1,1,1,1,1,1
1,7,0,0,0,0,0,6,6,6,1,1,1,1,1,1,1
1,1,7,7,7,0,0,6,0,0,6,1,1,1,1,1,1
1,1,1,1,1,6,0,0,0,0,6,1,1,1,1,1,1
1,1,1,1,2,6,0,0,0,0,6,4,1,1,1,1,1
1,1,1,1,2,6,0,0,0,0,6,4,1,1,1,1,1
1,1,8,8,8,1,6,6,6,6,1,1,1,1,1,1,1
1,8,7,7,7,8,1,1,1,1,1,8,8,8,1,1,1
1,8,7,2,7,8,1,1,1,1,1,8,8,8,1,1,1
1,8,7,7,7,8,1,1,1,1,1,8,8,8,1,1,1
1,1,8,8,8,1,1,1,1,1,1,1,1,1,1,1,1
1,1,1,1,1,1,1,1,1,1,1,1,1,1,1,1,1
1,1,1,1,1,1,1,1,1,1,1,1,1,1,1,1,1
endlayer

layer
1,1,1,1,1,1,1,1,1,1,1,1,1,1,1,1,1
1,1,1,1,1,1,1,1,1,1,1,1,1,1,1,1,1
1,1,1,1,1,1,1,1,1,1,1,1,1,1,1,1,1
1,1,1,3,1,1,1,1,1,1,1,1,1,1,1,1,1
1,1,1,1,1,1,1,3,3,1,1,1,1,1,1,1,1
1,1,1,1,1,1,0,6,6,6,1,1,1,1,1,1,1
1,1,1,1,1,0,0,0,6,0,6,1,1,1,1,1,1
1,1,1,1,1,6,0,0,0,0,6,1,1,1,1,1,1
1,1,1,1,2,6,0,0,0,0,6,4,1,1,1,1,1
1,1,1,1,2,6,0,0,0,0,6,4,1,1,1,1,1
1,1,8,8,8,1,6,6,6,6,1,1,1,1,1,1,1
1,8,8,8,8,8,1,1,1,1,1,8,8,8,1,1,1
1,8,8,2,8,8,1,1,1,1,1,8,8,8,1,1,1
1,8,8,8,8,8,1,1,1,1,1,8,8,8,1,1,1
1,1,8,8,8,1,1,1,1,1,1,1,1,1,1,1,1
1,1,1,1,1,1,1,1,1,1,1,1,1,1,1,1,1
1,1,1,1,1,1,1,1,1,1,1,1,1,1,1,1,1
endlayer

layer
1,1,1,1,1,1,1,1,1,1,1,1,1,1,1,1,1
1,1,1,1,1,1,1,1,1,1,1,8,8,8,1,1,1
1,1,1,7,1,1,1,1,1,1,8,7,7,7,8,1,1
1,1,7,3,7,1,1,1,1,1,8,7,3,7,8,1,1
1,1,1,7,1,1,1,1,3,3,3,3,7,7,8,1,1
1,1,1,1,1,1,6,6,6,6,8,8,8,8,1,1,1
1,1,1,1,1,6,0,0,0,6,6,1,1,1,1,1,1
1,1,1,1,2,6,0,0,0,0,6,1,1,1,1,1,1
1,1,1,1,2,6,0,0,0,0,6,1,1,1,1,1,1
1,1,1,1,1,6,0,0,0,0,6,4,1,1,1,1,1
1,1,8,8,8,1,6,6,6,6,4,1,1,1,1,1,1
1,8,8,8,8,8,1,1,1,1,1,1,8,1,1,1,1
1,8,8,2,8,8,1,1,1,1,1,8,8,8,1,1,1
1,8,8,8,8,8,1,1,1,1,1,1,8,1,1,1,1
1,1,8,8,8,1,1,1,1,1,1,1,1,1,1,1,1
1,1,1,1,1,1,1,1,1,1,1,1,1,1,1,1,1
1,1,1,1,1,1,1,1,1,1,1,1,1,1,1,1,1
endlayer

layer
1,1,1,1,1,1,1,1,1,1,1,8,8,8,1,1,1
1,1,8,8,8,1,1,1,1,1,8,7,7,7,8,1,1
1,8,7,7,7,8,1,1,1,8,7,3,7,3,7,8,1
1,8,7,2,7,8,1,1,1,8,7,7,3,7,7,8,1
1,8,7,7,7,8,1,1,3,3,7,7,7,3,7,8,1
1,1,8,8,8,1,6,6,6,6,7,7,7,7,8,1,1
1,1,1,1,1,6,6,0,0,0,6,8,8,8,1,1,1
1,1,1,1,2,6,6,6,6,6,6,1,1,1,1,1,1
1,1,1,1,2,6,6,6,6,6,6,1,1,1,1,1,1
1,1,1,1,1,6,6,6,6,6,6,4,1,1,1,1,1
1,1,1,1,1,1,6,6,6,6,4,1,1,1,1,1,1
1,1,8,8,8,1,1,1,1,1,1,1,1,1,1,1,1
1,1,8,8,8,1,1,1,1,1,1,1,1,1,1,1,1
1,1,8,8,8,1,1,1,1,1,1,1,1,1,1,1,1
1,1,1,1,1,1,1,1,1,1,1,1,1,1,1,1,1
1,1,1,1,1,1,1,1,1,1,1,1,1,1,1,1,1
1,1,1,1,1,1,1,1,1,1,1,1,1,1,1,1,1
endlayer

layer
1,1,1,1,1,1,1,1,1,1,1,7,7,7,1,1,1
1,1,8,8,8,1,1,1,1,1,7,0,0,0,7,1,1
1,8,8,8,8,8,1,1,1,7,0,0,0,0,0,7,1
1,8,8,2,8,8,1,1,1,7,0,0,3,0,0,7,1
1,8,8,8,8,8,1,1,1,3,0,0,0,0,1,7,1
1,1,8,8,8,1,0,0,0,0,0,0,0,0,7,1,1
1,1,1,1,0,0,0,0,0,0,0,7,7,7,1,1,1
1,1,1,1,2,0,0,0,0,0,0,1,1,1,1,1,1
1,1,1,1,1,0,0,0,0,0,0,1,1,1,1,1,1
1,1,1,1,1,0,0,0,0,0,0,1,1,1,1,1,1
1,1,1,1,1,1,0,0,0,0,4,1,1,1,1,1,1
1,1,1,8,1,1,1,1,1,0,1,1,1,1,1,1,1
1,1,8,8,8,1,1,1,1,1,1,1,1,1,1,1,1
1,1,1,8,1,1,1,1,1,1,1,1,1,1,1,1,1
1,1,1,1,1,1,1,1,1,1,1,1,1,1,1,1,1
1,1,1,1,1,1,1,1,1,1,1,1,1,1,1,1,1
1,1,1,1,1,1,1,1,1,1,1,1,1,1,1,1,1
endlayer

layer
1,1,1,1,1,1,1,1,1,1,1,1,1,1,1,1,1
1,1,8,8,8,1,1,1,1,1,1,1,1,1,1,1,1
1,8,8,8,8,8,1,1,1,1,1,1,1,1,1,1,1
1,8,8,2,8,8,1,1,1,1,1,1,3,1,1,1,1
1,8,8,8,8,8,1,1,1,3,1,1,1,1,1,1,1
1,1,8,8,8,1,0,0,0,0,0,1,1,1,1,1,1
1,1,1,1,0,0,0,0,0,0,0,1,1,1,1,1,1
1,1,1,1,2,0,0,0,0,0,0,1,1,1,1,1,1
1,1,1,1,1,0,0,0,0,0,0,1,1,1,1,1,1
1,1,1,1,1,0,0,0,0,0,0,1,1,1,1,1,1
1,1,1,1,1,1,0,0,0,0,4,1,1,1,1,1,1
1,1,1,1,1,1,1,1,1,0,1,1,1,1,1,1,1
1,1,1,1,1,1,1,1,1,1,1,1,1,1,1,1,1
1,1,1,1,1,1,1,1,1,1,1,1,1,1,1,1,1
1,1,1,1,1,1,1,1,1,1,1,1,1,1,1,1,1
1,1,1,1,1,1,1,1,1,1,1,1,1,1,1,1,1
1,1,1,1,1,1,1,1,1,1,1,1,1,1,1,1,1
endlayer

layer
1,1,1,1,1,1,1,1,1,1,1,1,1,1,1,1,1
1,1,1,1,1,1,1,1,1,1,1,1,1,1,1,1,1
1,1,8,8,8,1,1,1,1,1,1,1,7,1,1,1,1
1,1,8,8,8,1,1,1,1,1,1,7,3,7,1,1,1
1,1,8,8,8,1,1,1,1,1,1,1,7,1,1,1,1
1,1,1,1,1,1,0,0,0,0,0,1,1,1,1,1,1
1,1,1,1,0,0,0,0,0,0,0,1,1,1,1,1,1
1,1,1,1,1,0,0,0,0,0,0,1,1,1,1,1,1
1,1,1,1,1,0,0,0,0,0,0,1,1,1,1,1,1
1,1,1,1,1,0,0,0,0,0,0,1,1,1,1,1,1
1,1,1,1,1,1,0,0,0,0,1,1,1,1,1,1,1
1,1,1,1,1,1,1,1,1,0,1,1,1,1,1,1,1
1,1,1,1,1,1,1,1,1,1,1,1,1,1,1,1,1
1,1,1,1,1,1,1,1,1,1,1,1,1,1,1,1,1
1,1,1,1,1,1,1,1,1,1,1,1,1,1,1,1,1
1,1,1,1,1,1,1,1,1,1,1,1,1,1,1,1,1
1,1,1,1,1,1,1,1,1,1,1,1,1,1,1,1,1
endlayer

layer
1,1,1,1,1,1,1,1,1,1,1,1,1,1,1,1,1
1,1,1,1,1,1,1,1,1,1,1,8,8,8,1,1,1
1,1,8,8,8,1,1,1,1,1,8,7,7,7,8,1,1
1,1,8,8,8,1,1,1,1,1,8,7,9,7,8,1,1
1,1,8,8,8,1,1,1,1,1,8,7,7,7,8,1,1
1,1,1,1,1,1,0,0,0,0,0,8,8,8,1,1,1
1,1,1,1,0,0,0,0,0,0,0,1,1,1,1,1,1
1,1,1,1,1,0,0,0,0,0,0,1,1,1,1,1,1
1,1,1,1,1,0,0,0,0,0,0,1,1,1,1,1,1
1,1,1,1,1,0,0,0,0,0,0,1,1,1,1,1,1
1,1,1,1,1,1,0,0,0,0,1,1,1,1,1,1,1
1,1,1,1,1,1,1,1,1,0,1,1,1,1,1,1,1
1,1,1,1,1,1,1,1,1,1,1,1,1,1,1,1,1
1,1,1,1,1,1,1,1,1,1,1,1,1,1,1,1,1
1,1,1,1,1,1,1,1,1,1,1,1,1,1,1,1,1
1,1,1,1,1,1,1,1,1,1,1,1,1,1,1,1,1
1,1,1,1,1,1,1,1,1,1,1,1,1,1,1,1,1
endlayer

layer
1,1,1,1,1,1,1,1,1,1,1,1,1,1,1,1,1
1,1,1,1,1,1,1,1,1,1,1,1,1,1,1,1,1
1,1,1,8,1,1,1,1,1,1,1,8,0,8,1,1,1
1,1,8,8,8,1,1,1,1,1,1,0,11,0,1,1,1
1,1,1,8,1,1,1,1,1,1,1,8,0,8,1,1,1
1,1,1,1,1,1,0,0,0,0,0,1,1,1,1,1,1
1,1,1,1,0,0,0,0,0,0,0,1,1,1,1,1,1
1,1,1,1,1,0,0,0,0,0,0,1,1,1,1,1,1
1,1,1,1,1,0,0,0,0,0,0,1,1,1,1,1,1
1,1,1,1,1,0,0,0,0,0,0,1,1,1,1,1,1
1,1,1,1,1,1,0,0,0,0,1,1,1,1,1,1,1
1,1,1,1,1,1,1,1,1,0,1,1,1,1,1,1,1
1,1,1,1,1,1,1,1,1,1,1,1,1,1,1,1,1
1,1,1,1,1,1,1,1,1,1,1,1,1,1,1,1,1
1,1,1,1,1,1,1,1,1,1,1,1,1,1,1,1,1
1,1,1,1,1,1,1,1,1,1,1,1,1,1,1,1,1
1,1,1,1,1,1,1,1,1,1,1,1,1,1,1,1,1
endlayer
