# Author: d00dv4d3r
# From: Default Template
# Updated to MC 1.9: 21 Apr 2016

biomesToSpawnIn=hell,boneyard,phantasmagoric inferno,corrupted sands,bloody heap,nether,sludgepit,undergarden
weight=1
embed_into_distance=0
unacceptable_target_blocks=bedrock,Natura:Cloud
dimensions=10,9,9
allowable_overhang=2
max_cut_in=2
cut_in_buffer=1
max_leveling=2
leveling_buffer=1
preserve_water=0
preserve_lava=0
preserve_plants=0

rule1=0,100,cobblestone,mossy_cobblestone
rule2=0,100,preserveBlock
rule3=0,25,MobSpawner:Blaze
rule4=0,100,MobSpawner:Creeper,MobSpawner:Zombie,MobSpawner:Skeleton

layer
2,1,1,1,1,1,1,1,2
1,1,1,1,1,1,1,1,1
1,1,1,1,1,1,1,1,1
1,1,1,1,1,1,1,1,1
1,1,1,1,1,1,1,1,1
1,1,1,1,1,1,1,1,1
1,1,1,1,1,1,1,1,1
1,1,1,1,1,1,1,1,1
2,1,1,1,1,1,1,1,2
endlayer

layer
0,0,1,1,1,1,1,0,0
0,0,0,0,3,0,0,0,0
1,0,0,0,0,0,0,0,1
1,0,0,0,0,0,0,0,1
1,3,0,0,4,0,0,3,1
1,0,0,0,0,0,0,0,1
1,0,0,0,0,0,0,0,1
0,0,0,0,3,0,0,0,0
0,0,1,1,1,1,1,0,0
endlayer

layer
0,0,1,1,1,1,1,0,0
0,0,0,0,0,0,0,0,0
1,0,0,0,0,0,0,0,1
1,0,0,0,0,0,0,0,1
1,0,0,0,0,0,0,0,1
1,0,0,0,0,0,0,0,1
1,0,0,0,0,0,0,0,1
0,0,0,0,0,0,0,0,0
0,0,1,1,1,1,1,0,0
endlayer

layer
0,1,1,1,1,1,1,1,0
1,0,0,0,0,0,0,0,1
1,0,0,0,0,0,0,0,1
1,0,0,0,0,0,0,0,1
1,0,0,0,0,0,0,0,1
1,0,0,0,0,0,0,0,1
1,0,0,0,0,0,0,0,1
1,0,0,0,0,0,0,0,1
0,1,1,1,1,1,1,1,0
endlayer

layer
0,1,1,1,1,1,1,1,0
1,1,1,1,1,1,1,1,1
1,1,1,1,1,1,1,1,1
1,1,1,1,1,1,1,1,1
1,1,1,1,1,1,1,1,1
1,1,1,1,1,1,1,1,1
1,1,1,1,1,1,1,1,1
1,1,1,1,1,1,1,1,1
0,1,1,1,1,1,1,1,0
endlayer

layer
0,1,1,1,1,1,1,1,0
1,0,0,0,0,0,0,0,1
1,0,0,0,0,0,0,0,1
1,0,0,0,0,0,0,0,1
1,0,0,0,0,0,0,0,1
1,0,0,0,0,0,0,0,1
1,0,0,0,0,0,0,0,1
1,0,0,0,0,0,0,0,1
0,1,1,1,1,1,1,1,0
endlayer

layer
0,1,1,0,1,0,1,1,0
1,0,0,0,0,0,0,0,1
1,0,0,0,0,0,0,0,1
0,0,0,0,0,0,0,0,0
1,0,0,0,0,0,0,0,1
0,0,0,0,0,0,0,0,0
1,0,0,0,0,0,0,0,1
1,0,0,0,0,0,0,0,1
0,1,1,0,1,0,1,1,0
endlayer

layer
0,1,0,0,1,0,0,1,0
1,0,0,0,0,0,0,0,1
0,0,0,0,0,0,0,0,0
0,0,0,0,0,0,0,0,0
1,0,0,0,0,0,0,0,1
0,0,0,0,0,0,0,0,0
0,0,0,0,0,0,0,0,0
1,0,0,0,0,0,0,0,1
0,1,0,0,1,0,0,1,0
endlayer

layer
0,1,1,1,1,1,1,1,0
1,1,1,1,1,1,1,1,1
1,1,1,1,1,1,1,1,1
1,1,1,1,1,1,1,1,1
1,1,1,1,1,1,1,1,1
1,1,1,1,1,1,1,1,1
1,1,1,1,1,1,1,1,1
1,1,1,1,1,1,1,1,1
0,1,1,1,1,1,1,1,0
endlayer

layer
0,0,0,0,0,0,0,0,0
0,0,1,1,1,1,1,0,0
0,1,1,1,1,1,1,1,0
0,1,1,1,1,1,1,1,0
0,1,1,1,1,1,1,1,0
0,1,1,1,1,1,1,1,0
0,1,1,1,1,1,1,1,0
0,0,1,1,1,1,1,0,0
0,0,0,0,0,0,0,0,0
endlayer