# Author: Arrrg
# From: Minecraft Forums

biomesToSpawnIn=alps forest,frost forest,snow forest,snowy coniferous forest,snowy dead forest,snowy rainforest,tundra,ice_plains,frozen_ocean,frozen_river,ice_mountains,ice_flats,glacier_spikes,taiga_cold,glacier,taiga_cold_hills
weight=30
embed_into_distance=1
unacceptable_target_blocks=flowing_water,water,flowing_lava,lava,Natura:Cloud,red_mushroom_block,brown_mushroom_block,planks,cobblestone,end_stone,obsidian,purpur_block,iron_bars,purpur_slab,purpur_pillar,netherrack,soul_sand,quartz_ore
dimensions=29,11,11
allowable_overhang=66
max_cut_in=0
cut_in_buffer=0
max_leveling=1
leveling_buffer=-1
preserve_water=1
preserve_lava=1
preserve_plants=1

rule1=0,100,preserveBlock
rule2=0,100,grass
rule3=0,100,log-2
rule4=0,100,ice
rule5=0,100,sand
rule6=0,50,ice
rule7=0,100,leaves
rule8=0,100,flowing_water
rule9=0,100,ladder-2
rule10=0,100,ladder-3
rule11=0,100,ladder-4
rule12=0,100,ladder-5



layer
1,1,1,1,1,1,1,1,1,1,1
1,1,1,1,1,1,1,1,1,1,1
1,1,1,1,1,1,1,1,1,1,1
1,1,1,1,1,1,1,1,1,1,1
1,1,1,1,3,1,3,1,1,1,1
1,1,1,1,1,3,1,1,1,1,1
1,1,1,1,3,1,3,1,1,1,1
1,1,1,1,1,1,1,1,1,1,1
1,1,1,1,1,1,1,1,1,1,1
1,1,1,1,1,1,1,1,1,1,1
1,1,1,1,1,1,1,1,1,1,1
endlayer

layer
1,1,1,1,1,1,1,1,1,1,1
1,1,1,1,1,1,1,1,1,1,1
1,1,1,1,1,1,1,1,1,1,1
1,1,1,1,1,1,1,1,1,1,1
1,1,1,1,3,1,3,1,1,1,1
1,1,1,1,1,3,1,1,1,1,1
1,1,1,1,3,1,3,1,1,1,1
1,1,1,1,1,1,1,1,1,1,1
1,1,1,1,1,1,1,1,1,1,1
1,1,1,1,1,1,1,1,1,1,1
1,1,1,1,1,1,1,1,1,1,1
endlayer

layer
1,1,1,1,1,1,1,1,1,1,1
1,1,1,1,1,1,1,1,1,1,1
1,1,1,1,1,1,1,1,1,1,1
1,1,1,1,1,1,1,1,1,1,1
1,1,1,1,1,1,1,1,1,1,1
1,1,1,1,1,3,1,1,1,1,1
1,1,1,1,1,1,1,1,1,1,1
1,1,1,1,1,1,1,1,1,1,1
1,1,1,1,1,1,1,1,1,1,1
1,1,1,1,1,1,1,1,1,1,1
1,1,1,1,1,1,1,1,1,1,1
endlayer

layer
1,1,1,1,1,1,1,1,1,1,1
1,1,6,1,1,1,1,1,6,1,1
1,6,1,1,1,1,1,1,1,6,1
1,1,1,1,1,1,1,1,1,1,1
1,1,1,1,1,1,1,1,1,1,1
1,1,1,1,1,3,1,1,1,1,1
1,1,1,1,1,1,1,1,1,1,1
1,1,1,1,1,1,1,1,1,1,1
1,6,1,1,1,1,1,1,1,6,1
1,1,6,1,1,1,1,1,6,1,1
1,1,1,1,1,1,1,1,1,1,1
endlayer

layer
1,1,1,1,1,1,1,1,1,1,1
1,1,6,6,1,1,1,6,6,1,1
1,6,1,1,1,1,1,1,1,6,1
1,6,1,1,1,1,1,1,1,6,1
1,1,1,1,1,11,1,1,1,1,1
1,1,1,1,10,3,9,1,1,1,1
1,1,1,1,1,12,1,1,1,1,1
1,6,1,1,1,1,1,1,1,6,1
1,6,1,1,1,1,1,1,1,6,1
1,1,6,6,1,1,1,6,6,1,1
1,1,1,1,1,1,1,1,1,1,1
endlayer

layer
1,1,1,1,6,1,6,1,1,1,1
1,1,6,6,1,7,1,6,6,1,1
1,6,7,1,1,1,1,1,7,6,1
1,6,1,1,1,11,1,1,1,6,1
6,1,1,1,10,5,11,1,1,1,6
1,7,1,10,5,5,5,9,1,7,1
6,1,1,1,12,5,9,1,1,1,6
1,6,1,1,1,12,1,1,1,6,1
1,6,7,1,1,1,1,1,7,6,1
1,1,6,6,1,7,1,6,6,1,1
1,1,1,1,6,1,6,1,1,1,1
endlayer

layer
1,1,1,1,6,6,6,1,1,1,1
1,1,6,6,1,7,1,6,6,1,1
1,6,7,1,1,7,1,1,7,6,1
1,6,1,1,10,5,9,1,1,6,1
6,1,1,11,5,5,5,11,1,1,6
6,7,7,5,5,5,5,5,7,7,6
6,1,1,12,5,5,5,12,1,1,6
1,6,1,1,10,5,9,1,1,6,1
1,6,7,1,1,7,1,1,7,6,1
1,1,6,6,1,7,1,6,6,1,1
1,1,1,1,6,6,6,1,1,1,1
endlayer

layer
1,1,1,1,6,6,6,1,1,1,1
1,1,6,6,1,7,1,6,6,1,1
1,6,7,7,11,3,11,7,7,6,1
1,6,7,10,5,5,5,11,7,6,1
6,1,10,5,5,5,5,5,9,1,6
6,7,3,5,5,5,5,5,3,7,6
6,1,10,5,5,5,5,5,9,1,6
1,6,7,12,5,5,5,9,7,6,1
1,6,7,7,12,3,12,7,7,6,1
1,1,6,6,1,7,1,6,6,1,1
1,1,1,1,6,6,6,1,1,1,1
endlayer

layer
1,1,1,1,4,4,4,1,1,1,1
1,1,4,4,7,7,7,4,4,1,1
1,4,7,7,5,5,5,7,7,4,1
1,4,7,5,5,5,5,5,7,4,1
4,7,5,5,5,5,5,5,5,7,4
4,7,5,5,5,5,5,5,5,7,4
4,7,5,5,5,5,5,5,5,7,4
1,4,7,5,5,5,5,5,7,4,1
1,4,7,7,5,5,5,7,7,4,1
1,1,4,4,7,7,7,4,4,1,1
1,1,1,1,4,4,4,1,1,1,1
endlayer

layer
1,1,1,1,4,4,4,1,1,1,1
1,1,4,4,7,7,7,4,4,1,1
1,4,1,7,5,3,5,7,1,4,1
1,4,7,5,5,5,5,5,7,4,1
4,7,5,5,5,5,5,5,5,7,4
4,7,3,5,5,5,5,5,3,7,4
4,7,5,5,5,5,5,5,5,7,4
1,4,7,5,5,5,5,5,7,4,1
1,4,1,7,5,3,5,7,1,4,1
1,1,4,4,7,7,7,4,4,1,1
1,1,1,1,4,4,4,1,1,1,1
endlayer

layer
1,1,1,1,4,4,4,1,1,1,1
1,1,4,4,7,7,7,4,4,1,1
1,4,7,7,5,3,5,7,7,4,1
1,4,7,5,5,5,5,5,7,4,1
4,7,5,5,5,5,5,5,5,7,4
4,7,3,5,5,5,5,5,3,7,4
4,7,5,5,5,5,5,5,5,7,4
1,4,7,5,5,5,5,5,7,4,1
1,4,7,7,5,3,5,7,7,4,1
1,1,4,4,7,7,7,4,4,1,1
1,1,1,1,4,4,4,1,1,1,1
endlayer

layer
1,1,1,1,6,6,6,1,1,1,1
1,1,6,4,4,4,4,4,6,1,1
1,6,4,7,7,7,7,7,4,6,1
1,4,7,5,5,5,5,5,7,4,1
6,4,7,5,5,5,5,5,7,4,6
6,4,7,5,5,5,5,5,7,4,6
6,4,7,5,5,5,5,5,7,4,6
1,4,7,5,5,5,5,5,7,4,1
1,6,4,7,7,7,7,7,4,6,1
1,1,6,4,4,4,4,4,6,1,1
1,1,1,1,6,6,6,1,1,1,1
endlayer

layer
1,1,1,1,6,6,6,1,1,1,1
1,1,6,4,4,4,4,4,6,1,1
1,6,4,7,7,7,7,7,4,6,1
1,4,7,3,5,5,5,3,7,4,1
6,4,7,5,5,5,5,5,7,4,6
6,4,7,5,5,5,5,5,7,4,6
6,4,7,5,5,5,5,5,7,4,6
1,4,7,3,5,5,5,3,7,4,1
1,6,4,7,7,7,7,7,4,6,1
1,1,6,4,4,4,4,4,6,1,1
1,1,1,1,6,6,6,1,1,1,1
endlayer

layer
1,1,1,1,6,6,6,1,1,1,1
1,1,6,6,4,4,4,6,6,1,1
1,6,6,4,7,7,7,4,6,6,1
1,6,4,7,5,5,5,7,4,6,1
6,4,7,5,5,5,5,5,7,4,6
6,4,7,5,5,5,5,5,7,4,6
6,4,7,5,5,5,5,5,7,4,6
1,6,4,7,5,5,5,7,4,6,1
1,6,6,4,7,7,7,4,6,6,1
1,1,6,6,4,4,4,6,6,1,1
1,1,1,1,6,6,6,1,1,1,1
endlayer

layer
1,1,1,1,6,6,6,1,1,1,1
1,1,6,6,4,4,4,6,6,1,1
1,6,6,4,7,7,7,4,6,6,1
1,6,4,7,5,5,5,7,4,6,1
6,4,7,5,5,5,5,5,7,4,6
6,4,7,5,5,5,5,5,7,4,6
6,4,7,5,5,5,5,5,7,4,6
1,6,4,7,5,5,5,7,4,6,1
1,6,6,4,7,7,7,4,6,6,1
1,1,6,6,4,4,4,6,6,1,1
1,1,1,1,6,6,6,1,1,1,1
endlayer

layer
1,1,1,1,1,1,1,1,1,1,1
1,1,1,1,6,6,6,1,1,1,1
1,1,1,6,4,4,4,6,6,1,1
1,1,6,4,7,7,7,4,6,1,1
1,6,4,7,3,5,3,7,4,6,1
1,6,4,7,5,5,5,7,4,6,1
1,6,4,7,3,5,3,7,4,6,1
1,1,6,4,7,7,7,4,6,1,1
1,1,1,6,4,4,4,6,1,1,1
1,1,1,1,6,6,6,1,1,1,1
1,1,1,1,1,1,1,1,1,1,1
endlayer

layer
1,1,1,1,1,1,1,1,1,1,1
1,1,1,1,6,6,6,1,1,1,1
1,1,1,6,4,4,4,6,6,1,1
1,1,6,4,7,7,7,4,6,1,1
1,6,4,7,8,5,8,7,4,6,1
1,6,4,7,5,5,5,7,4,6,1
1,6,4,7,8,5,8,7,4,6,1
1,1,6,4,7,7,7,4,6,1,1
1,1,1,6,4,4,4,6,1,1,1
1,1,1,1,6,6,6,1,1,1,1
1,1,1,1,1,1,1,1,1,1,1
endlayer

layer
1,1,1,1,1,1,1,1,1,1,1
1,1,1,1,1,1,1,1,1,1,1
1,1,1,1,6,6,6,1,1,1,1
1,1,1,6,4,4,4,6,1,1,1
1,1,6,4,7,7,7,4,6,1,1
1,1,6,4,7,5,7,4,6,1,1
1,1,6,4,7,7,7,4,6,1,1
1,1,1,6,4,4,4,6,1,1,1
1,1,1,1,6,6,6,1,1,1,1
1,1,1,1,1,1,1,1,1,1,1
1,1,1,1,1,1,1,1,1,1,1
endlayer

layer
1,1,1,1,1,1,1,1,1,1,1
1,1,1,1,1,1,1,1,1,1,1
1,1,1,1,6,6,6,1,1,1,1
1,1,1,6,4,4,4,6,1,1,1
1,1,6,4,7,7,7,4,6,1,1
1,1,6,4,7,5,7,4,6,1,1
1,1,6,4,7,7,7,4,6,1,1
1,1,1,6,4,4,4,6,1,1,1
1,1,1,1,6,6,6,1,1,1,1
1,1,1,1,1,1,1,1,1,1,1
1,1,1,1,1,1,1,1,1,1,1
endlayer

layer
1,1,1,1,1,1,1,1,1,1,1
1,1,1,1,1,1,1,1,1,1,1
1,1,1,1,6,6,6,1,1,1,1
1,1,1,6,6,4,6,6,1,1,1
1,1,6,6,4,7,4,6,6,1,1
1,1,6,4,7,7,7,4,6,1,1
1,1,6,6,4,7,4,6,6,1,1
1,1,1,6,6,4,6,6,1,1,1
1,1,1,1,6,6,6,1,1,1,1
1,1,1,1,1,1,1,1,1,1,1
1,1,1,1,1,1,1,1,1,1,1
endlayer

layer
1,1,1,1,1,1,1,1,1,1,1
1,1,1,1,1,1,1,1,1,1,1
1,1,1,1,6,6,6,1,1,1,1
1,1,1,6,6,4,6,6,1,1,1
1,1,6,6,4,7,4,6,6,1,1
1,1,6,4,7,3,7,4,6,1,1
1,1,6,6,4,7,4,6,6,1,1
1,1,1,6,6,4,6,6,1,1,1
1,1,1,1,6,6,6,1,1,1,1
1,1,1,1,1,1,1,1,1,1,1
1,1,1,1,1,1,1,1,1,1,1
endlayer

layer
1,1,1,1,1,1,1,1,1,1,1
1,1,1,1,1,1,1,1,1,1,1
1,1,1,1,1,1,1,1,1,1,1
1,1,1,1,6,6,6,1,1,1,1
1,1,1,6,6,4,6,6,1,1,1
1,1,1,6,4,7,4,6,1,1,1
1,1,1,6,6,4,6,6,1,1,1
1,1,1,1,6,6,6,1,1,1,1
1,1,1,1,1,1,1,1,1,1,1
1,1,1,1,1,1,1,1,1,1,1
1,1,1,1,1,1,1,1,1,1,1
endlayer

layer
1,1,1,1,1,1,1,1,1,1,1
1,1,1,1,1,1,1,1,1,1,1
1,1,1,1,1,1,1,1,1,1,1
1,1,1,1,6,6,6,1,1,1,1
1,1,1,6,6,4,6,6,1,1,1
1,1,1,6,4,7,4,6,1,1,1
1,1,1,6,6,4,6,6,1,1,1
1,1,1,1,6,6,6,1,1,1,1
1,1,1,1,1,1,1,1,1,1,1
1,1,1,1,1,1,1,1,1,1,1
1,1,1,1,1,1,1,1,1,1,1
endlayer

layer
1,1,1,1,1,1,1,1,1,1,1
1,1,1,1,1,1,1,1,1,1,1
1,1,1,1,1,1,1,1,1,1,1
1,1,1,1,1,1,1,1,1,1,1
1,1,1,1,6,4,6,1,1,1,1
1,1,1,1,4,8,4,1,1,1,1
1,1,1,1,6,4,6,1,1,1,1
1,1,1,1,1,1,1,1,1,1,1
1,1,1,1,1,1,1,1,1,1,1
1,1,1,1,1,1,1,1,1,1,1
1,1,1,1,1,1,1,1,1,1,1
endlayer

layer
1,1,1,1,1,1,1,1,1,1,1
1,1,1,1,1,1,1,1,1,1,1
1,1,1,1,1,1,1,1,1,1,1
1,1,1,1,1,1,1,1,1,1,1
1,1,1,1,6,6,6,1,1,1,1
1,1,1,1,6,4,6,1,1,1,1
1,1,1,1,6,6,6,1,1,1,1
1,1,1,1,1,1,1,1,1,1,1
1,1,1,1,1,1,1,1,1,1,1
1,1,1,1,1,1,1,1,1,1,1
1,1,1,1,1,1,1,1,1,1,1
endlayer

layer
1,1,1,1,1,1,1,1,1,1,1
1,1,1,1,1,1,1,1,1,1,1
1,1,1,1,1,1,1,1,1,1,1
1,1,1,1,1,1,1,1,1,1,1
1,1,1,1,1,6,1,1,1,1,1
1,1,1,1,6,6,6,1,1,1,1
1,1,1,1,1,6,1,1,1,1,1
1,1,1,1,1,1,1,1,1,1,1
1,1,1,1,1,1,1,1,1,1,1
1,1,1,1,1,1,1,1,1,1,1
1,1,1,1,1,1,1,1,1,1,1
endlayer

layer
1,1,1,1,1,1,1,1,1,1,1
1,1,1,1,1,1,1,1,1,1,1
1,1,1,1,1,1,1,1,1,1,1
1,1,1,1,1,1,1,1,1,1,1
1,1,1,1,1,6,1,1,1,1,1
1,1,1,1,6,6,6,1,1,1,1
1,1,1,1,1,6,1,1,1,1,1
1,1,1,1,1,1,1,1,1,1,1
1,1,1,1,1,1,1,1,1,1,1
1,1,1,1,1,1,1,1,1,1,1
1,1,1,1,1,1,1,1,1,1,1
endlayer

layer
1,1,1,1,1,1,1,1,1,1,1
1,1,1,1,1,1,1,1,1,1,1
1,1,1,1,1,1,1,1,1,1,1
1,1,1,1,1,1,1,1,1,1,1
1,1,1,1,1,1,1,1,1,1,1
1,1,1,1,1,6,1,1,1,1,1
1,1,1,1,1,1,1,1,1,1,1
1,1,1,1,1,1,1,1,1,1,1
1,1,1,1,1,1,1,1,1,1,1
1,1,1,1,1,1,1,1,1,1,1
1,1,1,1,1,1,1,1,1,1,1
endlayer

layer
0,0,0,0,0,0,0,0,0,0,0
0,0,0,0,0,0,0,0,0,0,0
0,0,0,0,0,0,0,0,0,0,0
0,0,0,0,0,0,0,0,0,0,0
0,0,0,0,0,0,0,0,0,0,0
0,0,0,0,0,6,0,0,0,0,0
0,0,0,0,0,0,0,0,0,0,0
0,0,0,0,0,0,0,0,0,0,0
0,0,0,0,0,0,0,0,0,0,0
0,0,0,0,0,0,0,0,0,0,0
0,0,0,0,0,0,0,0,0,0,0
endlayer
