# Monolith
# Author: Arrrg
# From: Minecraft Forums

biomesToSpawnIn=desert,desert oil field,deserthills,dunes,lush desert,mountainous desert,crag,badlands,dead forest,dead swamp,deadlands,ominous woods,canyon,canyon ravine,thick ominous woods,volcano,wasteland,desert_hills,desert_defiled,desert_shrubland,mutated_desert
weight=1
uniqueMinDistance=2000
embed_into_distance=58
unacceptable_target_blocks=flowing_water,water,flowing_lava,lava,Natura:Cloud,red_mushroom_block,brown_mushroom_block,planks,cobblestone,end_stone,obsidian,purpur_block,iron_bars,purpur_slab,purpur_pillar,netherrack,soul_sand,quartz_ore
dimensions=75,5,7
allowable_overhang=300
max_cut_in=10
cut_in_buffer=1
max_leveling=5
leveling_buffer=0
preserve_water=0
preserve_lava=0
preserve_plants=0

rule1=0,100,preserveBlock
rule2=0,100,lapis_ore,preserveBlock,preserveBlock,preserveBlock
rule3=0,100,diamond_ore,preserveBlock,preserveBlock,preserveBlock
rule4=0,100,gold_ore,preserveBlock,preserveBlock
rule5=0,100,iron_ore,preserveBlock
rule6=0,100,coal_ore,preserveBlock,preserveBlock,preserveBlock
rule7=0,100,obsidian
rule8=0,100,flowing_water
rule9=1,100,water
rule10=1,100,flowing_lava
rule11=0,100,lava
rule12=0,100,sand


layer
1,1,1,1,1,1,1
1,1,1,1,1,1,1
1,1,1,1,1,1,1
1,1,1,1,1,3,1
1,1,1,1,1,1,1
endlayer

layer
1,1,1,1,1,1,1
1,1,1,1,1,1,1
1,1,1,1,1,1,1
1,1,1,1,1,3,1
1,1,1,1,1,1,1
endlayer

layer
1,1,1,1,1,1,1
1,2,1,1,1,1,1
1,1,1,1,1,3,1
1,1,1,1,3,3,3
1,1,1,1,1,3,1
endlayer

layer
1,1,1,1,1,1,1
1,2,1,1,1,1,1
1,1,1,1,1,3,1
1,1,1,1,3,3,3
1,1,1,1,1,3,1
endlayer

layer
1,2,1,1,1,1,1
2,2,2,1,4,1,1
1,2,1,1,3,3,3
1,1,1,1,3,3,3
1,1,1,1,3,3,3
endlayer

layer
1,2,1,1,1,1,1
2,2,2,1,4,1,1
1,2,1,1,3,3,3
1,1,1,1,3,3,3
1,1,1,1,3,3,3
endlayer

layer
2,2,2,1,4,1,1
2,2,2,4,4,4,1
2,2,2,1,4,3,1
1,1,1,1,3,3,3
1,1,1,1,1,3,1
endlayer

layer
2,2,2,1,4,1,1
2,2,2,4,4,4,1
2,2,2,1,4,3,1
1,1,1,1,3,3,3
1,1,1,1,1,3,1
endlayer

layer
1,2,1,4,4,4,1
2,2,2,4,4,4,1
1,2,4,4,4,4,1
1,4,4,4,1,3,1
1,1,4,1,1,1,1
endlayer

layer
1,2,1,4,4,4,1
2,2,2,4,4,4,1
1,2,4,4,4,4,1
1,4,4,4,1,5,1
1,1,4,1,1,1,1
endlayer

layer
1,1,1,1,4,1,1
1,2,1,4,4,4,1
1,4,4,4,4,5,1
1,4,4,4,5,5,5
1,4,4,4,1,5,1
endlayer

layer
1,1,1,1,4,1,1
1,5,1,4,4,4,1
1,4,4,4,4,5,1
1,4,4,4,5,5,5
1,4,4,4,1,5,1
endlayer

layer
1,5,1,1,1,1,1
5,5,5,1,4,1,1
1,5,4,1,5,5,5
1,4,4,4,5,5,5
1,1,4,1,5,5,5
endlayer

layer
1,5,1,1,1,1,1
5,5,5,1,6,1,1
1,5,4,1,5,5,5
1,4,4,4,5,5,5
1,1,4,1,5,5,5
endlayer

layer
5,5,5,1,6,1,1
5,5,5,6,6,6,1
5,5,5,1,6,5,1
1,1,4,1,5,5,5
1,1,1,1,1,5,1
endlayer

layer
5,5,5,1,6,1,1
5,5,5,6,6,6,1
5,5,5,1,6,5,1
1,1,6,1,5,5,5
1,1,1,1,1,5,1
endlayer

layer
1,5,1,6,6,6,1
5,5,5,6,6,6,1
1,5,6,6,6,6,1
1,6,6,6,1,5,1
1,1,6,1,1,1,1
endlayer

layer
1,5,1,6,6,6,1
5,5,5,6,6,6,1
1,5,6,6,6,6,1
1,6,6,6,1,5,1
1,1,6,1,1,1,1
endlayer

layer
1,1,1,1,6,1,1
1,5,1,6,6,6,1
1,1,1,1,6,1,1
1,1,6,1,1,1,1
1,1,1,1,1,1,1
endlayer

layer
1,1,1,1,6,1,1
1,5,1,6,6,6,1
1,1,1,1,6,1,1
1,1,6,1,1,1,1
1,1,1,1,1,1,1
endlayer

layer
1,1,1,1,1,1,1
1,1,1,1,6,1,1
1,1,1,1,1,1,1
1,1,1,1,1,1,1
1,1,1,1,1,1,1
endlayer

layer
1,1,1,1,1,1,1
1,1,1,1,6,1,1
1,1,1,1,1,1,1
1,1,1,1,1,1,1
1,1,1,1,1,1,1
endlayer

layer
1,1,1,1,1,1,1
1,1,1,1,1,1,1
1,1,1,1,1,1,1
1,1,1,1,1,1,1
1,1,1,1,1,1,1
endlayer

layer
1,1,1,1,1,1,1
1,1,1,1,1,1,1
1,1,1,1,1,1,1
1,1,1,1,1,1,1
1,1,1,1,1,1,1
endlayer

layer
1,1,1,1,1,1,1
1,1,1,1,1,1,1
1,1,1,1,1,1,1
1,1,1,1,1,1,1
1,1,1,1,1,1,1
endlayer

layer
1,1,1,1,1,1,1
1,1,1,1,1,1,1
1,1,1,1,1,1,1
1,1,1,1,1,1,1
1,1,1,1,1,1,1
endlayer

layer
1,1,1,1,1,1,1
1,1,1,1,1,1,1
1,1,1,1,1,1,1
1,1,1,1,1,1,1
1,1,1,1,1,1,1
endlayer

layer
1,1,1,1,1,1,1
1,1,1,1,1,1,1
1,1,1,1,1,1,1
1,1,1,1,1,1,1
1,1,1,1,1,1,1
endlayer

layer
1,1,1,1,1,1,1
1,1,1,1,1,1,1
1,1,1,1,1,1,1
1,1,1,1,1,1,1
1,1,1,1,1,1,1
endlayer

layer
1,1,1,1,1,1,1
1,1,1,1,1,1,1
1,1,1,1,1,1,1
1,1,1,1,1,1,1
1,1,1,1,1,1,1
endlayer

layer
1,1,1,1,1,1,1
1,1,1,1,1,1,1
1,1,1,1,1,1,1
1,1,1,1,1,1,1
1,1,1,1,1,1,1
endlayer

layer
1,1,1,1,1,1,1
1,1,1,1,1,1,1
1,1,1,1,1,1,1
1,1,1,1,1,1,1
1,1,1,1,1,1,1
endlayer

layer
1,1,1,1,1,1,1
1,1,1,1,1,1,1
1,1,1,1,1,1,1
1,1,1,1,1,1,1
1,1,1,1,1,1,1
endlayer

layer
1,1,1,1,1,1,1
1,1,1,1,1,1,1
1,1,1,1,1,1,1
1,1,1,1,1,1,1
1,1,1,1,1,1,1
endlayer

layer
1,1,1,1,1,1,1
1,1,1,1,1,1,1
1,1,1,1,1,1,1
1,1,1,1,1,1,1
1,1,1,1,1,1,1
endlayer

layer
1,1,1,1,1,1,1
1,1,1,1,1,1,1
1,1,1,1,1,1,1
1,1,1,1,1,1,1
1,1,1,1,1,1,1
endlayer

layer
1,1,1,1,1,1,1
1,1,1,1,1,1,1
1,1,1,1,1,1,1
1,1,1,1,1,1,1
1,1,1,1,1,1,1
endlayer

layer
1,1,1,1,1,1,1
1,1,1,1,1,1,1
1,1,1,1,1,1,1
1,1,1,1,1,1,1
1,1,1,1,1,1,1
endlayer

layer
1,1,1,1,1,1,1
1,1,1,1,1,1,1
1,1,1,1,1,1,1
1,1,1,1,1,1,1
1,1,1,1,1,1,1
endlayer

layer
1,1,1,1,1,1,1
1,1,1,1,1,1,1
1,1,1,1,1,1,1
1,1,1,1,1,1,1
1,1,1,1,1,1,1
endlayer

layer
1,1,1,1,1,1,1
1,1,1,1,1,1,1
1,1,1,1,1,1,1
1,1,1,1,1,1,1
1,1,1,1,1,1,1
endlayer

layer
1,1,1,1,1,1,1
1,1,1,1,1,1,1
1,1,1,1,1,1,1
1,1,1,1,1,1,1
1,1,1,1,1,1,1
endlayer

layer
1,1,1,1,1,1,1
1,1,1,1,1,1,1
1,1,1,1,1,1,1
1,1,1,1,1,1,1
1,1,1,1,1,1,1
endlayer

layer
1,1,1,1,1,1,1
1,1,1,1,1,1,1
1,1,1,1,1,1,1
1,1,1,1,1,1,1
1,1,1,1,1,1,1
endlayer

layer
1,1,1,1,1,1,1
1,1,1,1,1,1,1
1,1,1,1,1,1,1
1,1,1,1,1,1,1
1,1,1,1,1,1,1
endlayer

layer
1,1,1,1,1,1,1
1,1,1,1,1,1,1
1,1,1,1,1,1,1
1,1,1,1,1,1,1
1,1,1,1,1,1,1
endlayer

layer
1,1,1,1,1,1,1
1,1,1,1,1,1,1
1,1,1,1,1,1,1
1,1,1,1,1,1,1
1,1,1,1,1,1,1
endlayer

layer
1,1,1,1,1,1,1
1,1,1,1,1,1,1
1,1,1,1,1,1,1
1,1,1,1,1,1,1
1,1,1,1,1,1,1
endlayer

layer
1,1,1,1,1,1,1
1,1,1,1,1,1,1
1,1,1,1,1,1,1
1,1,1,1,1,1,1
1,1,1,1,1,1,1
endlayer

layer
1,1,1,1,1,1,1
1,1,1,1,1,1,1
1,1,1,1,1,1,1
1,1,1,1,1,1,1
1,1,1,1,1,1,1
endlayer

layer
1,1,1,1,1,1,1
1,1,1,1,1,1,1
1,1,1,1,1,1,1
1,1,1,1,1,1,1
1,1,1,1,1,1,1
endlayer

layer
1,1,1,1,1,1,1
1,1,1,1,1,1,1
1,1,1,1,1,1,1
1,1,1,1,1,1,1
1,1,1,1,1,1,1
endlayer

layer
1,1,1,1,1,1,1
1,1,1,1,1,1,1
1,1,1,1,1,1,1
1,1,1,1,1,1,1
1,1,1,1,1,1,1
endlayer

layer
1,1,1,1,1,1,1
1,1,1,1,1,1,1
1,1,1,1,1,1,1
1,1,1,1,1,1,1
1,1,1,1,1,1,1
endlayer

layer
1,1,1,1,1,1,1
1,1,1,1,1,1,1
1,1,1,1,1,1,1
1,1,1,1,1,1,1
1,1,1,1,1,1,1
endlayer

layer
1,1,1,1,1,1,1
1,1,1,1,1,1,1
1,1,1,1,1,1,1
1,1,1,1,1,1,1
1,1,1,1,1,1,1
endlayer

layer
1,1,1,1,1,1,1
1,1,1,1,1,1,1
1,1,1,1,1,1,1
1,1,1,1,1,1,1
1,1,1,1,1,1,1
endlayer

layer
1,1,1,1,1,1,1
1,1,1,1,1,1,1
1,1,1,1,1,1,1
1,1,1,1,1,1,1
1,1,1,1,1,1,1
endlayer

layer
1,1,1,1,1,1,1
1,1,1,1,1,1,1
1,1,1,1,1,1,1
1,1,1,1,1,1,1
1,1,1,1,1,1,1
endlayer

layer
1,1,1,1,1,1,1
1,1,1,1,1,1,1
1,1,1,1,1,1,1
1,1,1,1,1,1,1
1,1,1,1,1,1,1
endlayer

layer
1,1,1,1,1,1,1
1,1,1,1,1,1,1
1,1,1,1,1,1,1
1,1,1,1,1,1,1
1,1,1,1,1,1,1
endlayer

layer
1,1,1,1,1,1,1
1,1,1,1,1,1,1
1,1,1,1,1,1,1
1,1,1,1,1,1,1
1,1,1,1,1,1,1
endlayer

layer
1,1,1,1,1,1,1
1,7,7,7,7,7,1
1,7,7,7,7,7,1
1,7,7,7,7,7,1
1,1,1,1,1,1,1
endlayer

layer
1,1,1,1,1,1,1
1,7,7,7,7,7,1
1,7,0,0,0,7,1
1,7,7,7,7,7,1
1,1,1,1,1,1,1
endlayer

layer
1,1,1,1,1,1,1
1,7,7,7,7,7,1
1,7,0,0,0,7,1
1,7,7,7,7,7,1
1,1,1,1,1,1,1
endlayer

layer
1,1,1,1,1,1,1
1,7,7,7,7,7,1
1,7,0,0,0,7,1
1,7,7,7,7,7,1
1,1,1,1,1,1,1
endlayer

layer
1,1,1,1,1,1,1
1,7,7,7,7,7,1
1,7,0,0,0,7,1
1,7,7,7,7,7,1
1,1,1,1,1,1,1
endlayer

layer
1,1,1,1,1,1,1
1,7,7,7,7,7,1
1,7,0,0,0,7,1
1,7,7,7,7,7,1
1,1,1,1,1,1,1
endlayer

layer
1,1,1,1,1,1,1
1,7,7,7,7,7,1
1,7,0,0,0,7,1
1,7,7,7,7,7,1
1,1,1,1,1,1,1
endlayer

layer
1,1,1,1,1,1,1
1,7,7,7,7,7,1
1,7,0,0,0,7,1
1,7,7,7,7,7,1
1,1,1,1,1,1,1
endlayer

layer
1,1,1,1,1,1,1
1,7,7,7,7,7,1
1,7,0,0,0,7,1
1,7,7,7,7,7,1
1,1,1,1,1,1,1
endlayer

layer
1,1,1,1,1,1,1
1,7,7,7,7,7,1
1,7,0,0,0,7,1
1,7,7,7,7,7,1
1,1,1,1,1,1,1
endlayer

layer
1,1,1,1,1,1,1
1,7,7,7,7,7,1
1,7,0,0,0,7,1
1,7,7,7,7,7,1
1,1,1,1,1,1,1
endlayer

layer
1,1,1,1,1,1,1
1,7,7,7,7,7,1
1,7,10,10,10,7,1
1,7,7,7,7,7,1
1,1,1,1,1,1,1
endlayer

layer
1,1,1,1,1,1,1
1,7,7,7,7,7,1
1,7,7,7,7,7,1
1,7,7,7,7,7,1
1,1,1,1,1,1,1
endlayer
