
biomesToSpawnIn=crag,badlands,dead forest,dead swamp,deadlands,ominous woods,canyon,canyon ravine,thick ominous woods,volcano,wasteland
weight=1
embed_into_distance=9
unacceptable_target_blocks=flowing_water,water,flowing_lava,lava,Natura:Cloud,red_mushroom_block,brown_mushroom_block,planks,cobblestone,end_stone,obsidian,purpur_block,iron_bars,purpur_slab,purpur_pillar,netherrack,soul_sand,quartz_ore
dimensions=9,27,27
cut_in_buffer=0
max_leveling=1
leveling_buffer=1
preserve_water=0
preserve_lava=0
preserve_plants=0
max_cut_in=10


rule1=0,100,preserveBlock
rule2=0,100,cobblestone,cobblestone,cobblestone,cobblestone,mossy_cobblestone
rule3=0,100,gravel
rule4=0,100,air,air,air,air,air,air,air,air,air,air,air,air,air,air,air,air,air,air,air,air,air,air,air,air,air,air,air,air,air,MediumMobSpawn
rule5=0,100,cobblestone
rule6=0,100,stone_stairs-3
rule7=0,100,stone_slab-3
rule8=0,100,stone_stairs-1
rule9=0,100,stone_stairs
rule10=2,100,torch-4
rule11=2,100,torch-2
rule12=2,100,torch-1
rule13=2,100,torch-3
rule14=0,100,stone_stairs-2
rule15=0,10,cobblestone,mossy_cobblestone


layer
1,1,1,1,1,1,1,1,1,1,1,1,1,1,1,1,1,1,1,1,1,1,1,1,1,1,1
1,1,1,1,1,1,1,1,1,1,1,1,1,1,1,1,1,1,1,1,1,1,1,1,1,1,1
1,1,1,1,1,1,1,1,1,1,2,2,2,2,2,2,2,1,1,1,1,1,1,1,1,1,1
1,1,1,1,1,1,1,1,1,1,2,2,2,2,2,2,2,1,1,1,1,1,1,1,1,1,1
1,1,1,1,1,1,1,1,2,2,2,2,2,2,2,2,2,2,2,1,1,1,1,1,1,1,1
1,1,1,1,1,1,1,2,2,2,2,2,2,2,2,2,2,2,2,2,1,1,1,1,1,1,1
1,1,1,1,1,1,2,2,2,2,2,2,2,2,2,2,2,2,2,2,2,1,1,1,1,1,1
1,1,1,1,1,2,2,2,2,2,2,2,2,2,2,2,2,2,2,2,2,2,1,1,1,1,1
1,1,1,1,2,2,2,2,2,2,2,2,2,2,2,2,2,2,2,2,2,2,2,1,1,1,1
1,1,1,1,2,2,2,2,2,2,2,2,2,2,2,2,2,2,2,2,2,2,2,1,1,1,1
1,1,2,2,2,2,2,2,2,2,2,2,2,2,2,2,2,2,2,2,2,2,2,2,2,1,1
1,1,2,2,2,2,2,2,2,2,2,2,2,2,2,2,2,2,2,2,2,2,2,2,2,1,1
1,1,2,2,2,2,2,2,2,2,2,2,2,2,2,2,2,2,2,2,2,2,2,2,2,1,1
1,1,2,2,2,2,2,2,2,2,2,2,2,2,2,2,2,2,2,2,2,2,2,2,2,1,1
1,1,2,2,2,2,2,2,2,2,2,2,2,2,2,2,2,2,2,2,2,2,2,2,2,1,1
1,1,2,2,2,2,2,2,2,2,2,2,2,2,2,2,2,2,2,2,2,2,2,2,2,1,1
1,1,2,2,2,2,2,2,2,2,2,2,2,2,2,2,2,2,2,2,2,2,2,2,2,1,1
1,1,1,1,2,2,2,2,2,2,2,2,2,2,2,2,2,2,2,2,2,2,2,1,1,1,1
1,1,1,1,2,2,2,2,2,2,2,2,2,2,2,2,2,2,2,2,2,2,2,1,1,1,1
1,1,1,1,1,2,2,2,2,2,2,2,2,2,2,2,2,2,2,2,2,2,1,1,1,1,1
1,1,1,1,1,1,2,2,2,2,2,2,2,2,2,2,2,2,2,2,2,1,1,1,1,1,1
1,1,1,1,1,1,1,2,2,2,2,2,2,2,2,2,2,2,2,2,1,1,1,1,1,1,1
1,1,1,1,1,1,1,1,2,2,2,2,2,2,2,2,2,2,2,1,1,1,1,1,1,1,1
1,1,1,1,1,1,1,1,1,1,2,2,2,2,2,2,2,1,1,1,1,1,1,1,1,1,1
1,1,1,1,1,1,1,1,1,1,2,2,2,2,2,2,2,1,1,1,1,1,1,1,1,1,1
1,1,1,1,1,1,1,1,1,1,1,1,1,1,1,1,1,1,1,1,1,1,1,1,1,1,1
1,1,1,1,1,1,1,1,1,1,1,1,1,1,1,1,1,1,1,1,1,1,1,1,1,1,1
endlayer


layer
1,1,1,1,1,1,1,1,1,1,1,1,1,1,1,1,1,1,1,1,1,1,1,1,1,1,1
1,1,1,1,1,1,1,1,1,1,1,1,1,1,1,1,1,1,1,1,1,1,1,1,1,1,1
1,1,1,1,1,1,1,1,1,1,2,2,2,2,2,2,2,1,1,1,1,1,1,1,1,1,1
1,1,1,1,1,1,1,1,1,1,2,2,2,2,2,2,2,1,1,1,1,1,1,1,1,1,1
1,1,1,1,1,1,1,1,2,2,3,3,3,3,3,3,3,2,2,1,1,1,1,1,1,1,1
1,1,1,1,1,1,1,2,3,3,3,3,3,3,3,3,3,3,3,2,1,1,1,1,1,1,1
1,1,1,1,1,1,2,3,3,3,3,3,3,3,3,3,3,3,3,3,2,1,1,1,1,1,1
1,1,1,1,1,2,3,3,3,3,3,3,3,3,3,3,3,3,3,3,3,2,1,1,1,1,1
1,1,1,1,2,3,3,3,3,3,3,3,3,3,3,3,3,3,3,3,3,3,2,1,1,1,1
1,1,1,1,2,3,3,3,3,3,3,3,3,3,3,3,3,3,3,3,3,3,2,1,1,1,1
1,1,2,2,3,3,3,3,3,3,3,3,3,3,3,3,3,3,3,3,3,3,3,2,2,1,1
1,1,2,2,3,3,3,3,3,3,3,3,3,3,3,3,3,3,3,3,3,3,3,2,2,1,1
1,1,2,2,3,3,3,3,3,3,3,3,3,3,3,3,3,3,3,3,3,3,3,2,2,1,1
1,1,2,2,3,3,3,3,3,3,3,3,3,3,3,3,3,3,3,3,3,3,3,2,2,1,1
1,1,2,2,3,3,3,3,3,3,3,3,3,3,3,3,3,3,3,3,3,3,3,2,2,1,1
1,1,2,2,3,3,3,3,3,3,3,3,3,3,3,3,3,3,3,3,3,3,3,2,2,1,1
1,1,2,2,3,3,3,3,3,3,3,3,3,3,3,3,3,3,3,3,3,3,3,2,2,1,1
1,1,1,1,2,3,3,3,3,3,3,3,3,3,3,3,3,3,3,3,3,3,2,1,1,1,1
1,1,1,1,2,3,3,3,3,3,3,3,3,3,3,3,3,3,3,3,3,3,2,1,1,1,1
1,1,1,1,1,2,3,3,3,3,3,3,3,3,3,3,3,3,3,3,3,2,1,1,1,1,1
1,1,1,1,1,1,2,3,3,3,3,3,3,3,3,3,3,3,3,3,2,1,1,1,1,1,1
1,1,1,1,1,1,1,2,3,3,3,3,3,3,3,3,3,3,3,2,1,1,1,1,1,1,1
1,1,1,1,1,1,1,1,2,2,3,3,3,3,3,3,3,2,2,1,1,1,1,1,1,1,1
1,1,1,1,1,1,1,1,1,1,2,2,2,2,2,2,2,1,1,1,1,1,1,1,1,1,1
1,1,1,1,1,1,1,1,1,1,2,2,2,2,2,2,2,1,1,1,1,1,1,1,1,1,1
1,1,1,1,1,1,1,1,1,1,1,1,1,1,1,1,1,1,1,1,1,1,1,1,1,1,1
1,1,1,1,1,1,1,1,1,1,1,1,1,1,1,1,1,1,1,1,1,1,1,1,1,1,1
endlayer

layer
1,1,1,1,1,1,1,1,1,1,1,1,1,1,1,1,1,1,1,1,1,1,1,1,1,1,1
1,1,1,1,1,1,1,1,1,1,1,1,1,1,1,1,1,1,1,1,1,1,1,1,1,1,1
1,1,1,1,1,1,1,1,1,1,2,2,2,2,2,2,2,1,1,1,1,1,1,1,1,1,1
1,1,1,1,1,1,1,1,1,1,2,2,2,2,2,2,2,1,1,1,1,1,1,1,1,1,1
1,1,1,1,1,1,1,1,2,2,4,4,4,4,4,4,4,2,2,1,1,1,1,1,1,1,1
1,1,1,1,1,1,1,2,4,4,4,4,4,4,4,4,4,4,4,2,1,1,1,1,1,1,1
1,1,1,1,1,1,2,4,4,4,4,4,4,4,4,4,4,4,4,4,2,1,1,1,1,1,1
1,1,1,1,1,2,4,4,4,4,4,4,4,4,4,4,4,4,4,4,4,2,1,1,1,1,1
1,1,1,1,2,4,4,4,4,4,4,4,4,4,4,4,4,4,4,4,4,4,2,1,1,1,1
1,1,1,1,2,4,4,4,4,4,4,4,4,4,4,4,4,4,4,4,4,4,2,1,1,1,1
1,1,2,2,4,4,4,4,4,4,4,4,4,4,4,4,4,4,4,4,4,4,4,2,2,1,1
1,1,2,2,4,4,4,4,4,4,4,4,4,4,4,4,4,4,4,4,4,4,4,2,2,1,1
1,1,2,2,4,4,4,4,4,4,4,4,4,4,4,4,4,4,4,4,4,4,4,2,2,1,1
1,1,2,2,4,4,4,4,4,4,4,4,4,5,4,4,4,4,4,4,4,4,4,2,2,1,1
1,1,2,2,4,4,4,4,4,4,4,4,4,4,4,4,4,4,4,4,4,4,4,2,2,1,1
1,1,2,2,4,4,4,4,4,4,4,4,4,4,4,4,4,4,4,4,4,4,4,2,2,1,1
1,1,2,2,4,4,4,4,4,4,4,4,4,4,4,4,4,4,4,4,4,4,4,2,2,1,1
1,1,1,1,2,4,4,4,4,4,4,4,4,4,4,4,4,4,4,4,4,4,2,1,1,1,1
1,1,1,1,2,4,4,4,4,4,4,4,4,4,4,4,4,4,4,4,4,4,2,1,1,1,1
1,1,1,1,1,2,4,4,4,4,4,4,4,4,4,4,4,4,4,4,4,2,1,1,1,1,1
1,1,1,1,1,1,2,4,4,4,4,4,4,4,4,4,4,4,4,4,2,1,1,1,1,1,1
1,1,1,1,1,1,1,2,4,4,4,4,4,4,4,4,4,4,4,2,1,1,1,1,1,1,1
1,1,1,1,1,1,1,1,2,2,4,4,4,4,4,4,4,2,2,1,1,1,1,1,1,1,1
1,1,1,1,1,1,1,1,1,1,2,2,2,2,2,2,2,1,1,1,1,1,1,1,1,1,1
1,1,1,1,1,1,1,1,1,1,2,2,2,2,2,2,2,1,1,1,1,1,1,1,1,1,1
1,1,1,1,1,1,1,1,1,1,1,1,1,1,1,1,1,1,1,1,1,1,1,1,1,1,1
1,1,1,1,1,1,1,1,1,1,1,1,1,1,1,1,1,1,1,1,1,1,1,1,1,1,1
endlayer

layer
1,1,1,1,1,1,1,1,1,1,1,1,1,1,1,1,1,1,1,1,1,1,1,1,1,1,1
1,1,1,1,1,1,1,1,1,1,1,1,1,1,1,1,1,1,1,1,1,1,1,1,1,1,1
1,1,1,1,1,1,1,1,1,1,2,2,2,2,2,2,2,1,1,1,1,1,1,1,1,1,1
1,1,1,1,1,1,1,1,1,1,2,0,0,0,0,0,2,1,1,1,1,1,1,1,1,1,1
1,1,1,1,1,1,1,1,2,2,0,0,0,0,0,0,0,2,2,1,1,1,1,1,1,1,1
1,1,1,1,1,1,1,2,0,0,0,0,0,0,0,0,0,0,0,2,1,1,1,1,1,1,1
1,1,1,1,1,1,2,0,0,0,0,0,0,0,0,0,0,0,0,0,2,1,1,1,1,1,1
1,1,1,1,1,2,0,0,0,0,0,0,0,0,0,0,0,0,0,0,0,2,1,1,1,1,1
1,1,1,1,2,0,0,0,0,0,0,0,0,0,0,0,0,0,0,0,0,0,2,1,1,1,1
1,1,1,1,2,0,0,0,0,0,0,0,0,0,0,0,0,0,0,0,0,0,2,1,1,1,1
1,1,2,2,0,0,0,0,0,0,0,0,0,0,0,0,0,0,0,0,0,0,0,2,2,1,1
1,1,2,0,0,0,0,0,0,0,0,0,0,0,0,0,0,0,0,0,0,0,0,0,2,1,1
1,1,2,0,0,0,0,0,0,0,0,0,0,0,0,0,0,0,0,0,0,0,0,0,2,1,1
1,1,2,0,0,0,0,0,0,0,0,0,0,5,0,0,0,0,0,0,0,0,0,0,2,1,1
1,1,2,0,0,0,0,0,0,0,0,0,0,0,0,0,0,0,0,0,0,0,0,0,2,1,1
1,1,2,0,0,0,0,0,0,0,0,0,0,0,0,0,0,0,0,0,0,0,0,0,2,1,1
1,1,2,2,0,0,0,0,0,0,0,0,0,0,0,0,0,0,0,0,0,0,0,2,2,1,1
1,1,1,1,2,0,0,0,0,0,0,0,0,0,0,0,0,0,0,0,0,0,2,1,1,1,1
1,1,1,1,2,0,0,0,0,0,0,0,0,0,0,0,0,0,0,0,0,0,2,1,1,1,1
1,1,1,1,1,2,0,0,0,0,0,0,0,0,0,0,0,0,0,0,0,2,1,1,1,1,1
1,1,1,1,1,1,2,0,0,0,0,0,0,0,0,0,0,0,0,0,2,1,1,1,1,1,1
1,1,1,1,1,1,1,2,0,0,0,0,0,0,0,0,0,0,0,2,1,1,1,1,1,1,1
1,1,1,1,1,1,1,1,2,2,0,0,0,0,0,0,0,2,2,1,1,1,1,1,1,1,1
1,1,1,1,1,1,1,1,1,1,2,0,0,0,0,0,2,1,1,1,1,1,1,1,1,1,1
1,1,1,1,1,1,1,1,1,1,2,2,2,2,2,2,2,1,1,1,1,1,1,1,1,1,1
1,1,1,1,1,1,1,1,1,1,1,1,1,1,1,1,1,1,1,1,1,1,1,1,1,1,1
1,1,1,1,1,1,1,1,1,1,1,1,1,1,1,1,1,1,1,1,1,1,1,1,1,1,1
endlayer

layer
1,1,1,1,1,1,1,1,1,1,1,1,1,1,1,1,1,1,1,1,1,1,1,1,1,1,1
1,1,1,1,1,1,1,1,1,1,1,1,1,1,1,1,1,1,1,1,1,1,1,1,1,1,1
1,1,1,1,1,1,1,1,1,1,2,2,2,2,2,2,2,1,1,1,1,1,1,1,1,1,1
1,1,1,1,1,1,1,1,1,1,2,0,0,0,0,0,2,1,1,1,1,1,1,1,1,1,1
1,1,1,1,1,1,1,1,2,2,0,0,0,0,0,0,0,2,2,1,1,1,1,1,1,1,1
1,1,1,1,1,1,1,2,0,0,0,0,0,0,0,0,0,0,0,2,1,1,1,1,1,1,1
1,1,1,1,1,1,2,0,0,0,0,0,0,0,0,0,0,0,0,0,2,1,1,1,1,1,1
1,1,1,1,1,2,0,0,0,0,0,0,0,0,0,0,0,0,0,0,0,2,1,1,1,1,1
1,1,1,1,2,0,0,0,0,0,0,0,0,0,0,0,0,0,0,0,0,0,2,1,1,1,1
1,1,1,1,2,0,0,0,0,0,0,0,0,0,0,0,0,0,0,0,0,0,2,1,1,1,1
1,1,2,2,0,0,0,0,0,0,0,0,0,0,0,0,0,0,0,0,0,0,0,2,2,1,1
1,1,2,0,0,0,0,0,0,0,0,0,0,0,0,0,0,0,0,0,0,0,0,0,2,1,1
1,1,2,0,0,0,0,0,0,0,0,0,0,0,0,0,0,0,0,0,0,0,0,0,2,1,1
1,1,2,0,0,0,0,0,0,0,0,0,0,5,0,0,0,0,0,0,0,0,0,0,2,1,1
1,1,2,0,0,0,0,0,0,0,0,0,0,0,0,0,0,0,0,0,0,0,0,0,2,1,1
1,1,2,0,0,0,0,0,0,0,0,0,0,0,0,0,0,0,0,0,0,0,0,0,2,1,1
1,1,2,2,0,0,0,0,0,0,0,0,0,0,0,0,0,0,0,0,0,0,0,2,2,1,1
1,1,1,1,2,0,0,0,0,0,0,0,0,0,0,0,0,0,0,0,0,0,2,1,1,1,1
1,1,1,1,2,0,0,0,0,0,0,0,0,0,0,0,0,0,0,0,0,0,2,1,1,1,1
1,1,1,1,1,2,0,0,0,0,0,0,0,0,0,0,0,0,0,0,0,2,1,1,1,1,1
1,1,1,1,1,1,2,0,0,0,0,0,0,0,0,0,0,0,0,0,2,1,1,1,1,1,1
1,1,1,1,1,1,1,2,0,0,0,0,0,0,0,0,0,0,0,2,1,1,1,1,1,1,1
1,1,1,1,1,1,1,1,2,2,0,0,0,0,0,0,0,2,2,1,1,1,1,1,1,1,1
1,1,1,1,1,1,1,1,1,1,2,0,0,0,0,0,2,1,1,1,1,1,1,1,1,1,1
1,1,1,1,1,1,1,1,1,1,2,2,2,2,2,2,2,1,1,1,1,1,1,1,1,1,1
1,1,1,1,1,1,1,1,1,1,1,1,1,1,1,1,1,1,1,1,1,1,1,1,1,1,1
1,1,1,1,1,1,1,1,1,1,1,1,1,1,1,1,1,1,1,1,1,1,1,1,1,1,1
endlayer

layer
1,1,1,1,1,1,1,1,1,1,1,1,1,1,1,1,1,1,1,1,1,1,1,1,1,1,1
1,1,1,1,1,1,1,1,1,1,1,1,1,1,1,1,1,1,1,1,1,1,1,1,1,1,1
1,1,1,1,1,1,1,1,1,1,2,2,2,2,2,2,2,1,1,1,1,1,1,1,1,1,1
1,1,1,1,1,1,1,1,1,1,2,2,2,2,2,2,2,1,1,1,1,1,1,1,1,1,1
1,1,1,1,1,1,1,1,2,2,0,0,0,0,0,0,0,2,2,1,1,1,1,1,1,1,1
1,1,1,1,1,1,1,2,0,0,0,0,0,0,0,0,0,0,0,2,1,1,1,1,1,1,1
1,1,1,1,1,1,2,0,0,0,0,0,0,0,0,0,0,0,0,0,2,1,1,1,1,1,1
1,1,1,1,1,2,0,0,0,0,0,0,0,0,0,0,0,0,0,0,0,2,1,1,1,1,1
1,1,1,1,2,0,0,0,0,0,0,0,0,0,0,0,0,0,0,0,0,0,2,1,1,1,1
1,1,1,1,2,0,0,0,0,0,0,0,0,0,0,0,0,0,0,0,0,0,2,1,1,1,1
1,1,2,2,0,0,0,0,0,0,0,0,0,0,0,0,0,0,0,0,0,0,0,2,2,1,1
1,1,2,2,0,0,0,0,0,0,0,0,0,0,0,0,0,0,0,0,0,0,0,2,2,1,1
1,1,2,2,0,0,0,0,0,0,0,0,0,0,0,0,0,0,0,0,0,0,0,2,2,1,1
1,1,2,2,0,0,0,0,0,0,0,0,0,5,0,0,0,0,0,0,0,0,0,2,2,1,1
1,1,2,2,0,0,0,0,0,0,0,0,0,0,0,0,0,0,0,0,0,0,0,2,2,1,1
1,1,2,2,0,0,0,0,0,0,0,0,0,0,0,0,0,0,0,0,0,0,0,2,2,1,1
1,1,2,2,0,0,0,0,0,0,0,0,0,0,0,0,0,0,0,0,0,0,0,2,2,1,1
1,1,1,1,2,0,0,0,0,0,0,0,0,0,0,0,0,0,0,0,0,0,2,1,1,1,1
1,1,1,1,2,0,0,0,0,0,0,0,0,0,0,0,0,0,0,0,0,0,2,1,1,1,1
1,1,1,1,1,2,0,0,0,0,0,0,0,0,0,0,0,0,0,0,0,2,1,1,1,1,1
1,1,1,1,1,1,2,0,0,0,0,0,0,0,0,0,0,0,0,0,2,1,1,1,1,1,1
1,1,1,1,1,1,1,2,0,0,0,0,0,0,0,0,0,0,0,2,1,1,1,1,1,1,1
1,1,1,1,1,1,1,1,2,2,0,0,0,0,0,0,0,2,2,1,1,1,1,1,1,1,1
1,1,1,1,1,1,1,1,1,1,2,2,2,2,2,2,2,1,1,1,1,1,1,1,1,1,1
1,1,1,1,1,1,1,1,1,1,2,2,2,2,2,2,2,1,1,1,1,1,1,1,1,1,1
1,1,1,1,1,1,1,1,1,1,1,1,1,1,1,1,1,1,1,1,1,1,1,1,1,1,1
1,1,1,1,1,1,1,1,1,1,1,1,1,1,1,1,1,1,1,1,1,1,1,1,1,1,1
endlayer

layer
1,1,1,1,1,1,1,1,1,1,1,1,1,1,1,1,1,1,1,1,1,1,1,1,1,1,1
1,1,1,1,1,1,1,1,1,1,1,1,1,1,1,1,1,1,1,1,1,1,1,1,1,1,1
1,1,1,1,1,1,1,1,1,1,2,2,2,2,2,2,2,1,1,1,1,1,1,1,1,1,1
1,1,1,1,1,1,1,2,2,2,2,2,2,2,2,2,2,2,2,2,1,1,1,1,1,1,1
1,1,1,1,1,1,2,2,2,2,8,8,8,8,8,8,8,2,2,2,2,1,1,1,1,1,1
1,1,1,1,1,2,2,2,8,8,0,0,0,0,0,0,0,8,8,2,2,2,1,1,1,1,1
1,1,1,1,2,2,2,7,0,0,0,0,0,0,0,0,0,0,0,7,2,2,2,1,1,1,1
1,1,1,2,2,2,7,0,0,0,0,0,0,0,0,0,0,0,0,0,7,2,2,2,1,1,1
1,1,1,2,2,14,0,0,0,0,0,0,0,0,0,0,0,0,0,0,0,6,2,2,1,1,1
1,1,1,2,2,14,0,0,0,0,0,0,0,0,0,0,0,0,0,0,0,6,2,2,1,1,1
1,1,2,2,14,0,0,0,0,0,0,0,0,0,0,0,0,0,0,0,0,0,6,2,2,1,1
1,1,2,2,14,0,0,0,0,0,0,0,0,0,0,0,0,0,0,0,0,0,6,2,2,1,1
1,1,2,2,14,0,0,0,0,0,0,0,0,11,0,0,0,0,0,0,0,0,6,2,2,1,1
1,1,2,2,14,0,0,0,0,0,0,0,13,5,10,0,0,0,0,0,0,0,6,2,2,1,1
1,1,2,2,14,0,0,0,0,0,0,0,0,12,0,0,0,0,0,0,0,0,6,2,2,1,1
1,1,2,2,14,0,0,0,0,0,0,0,0,0,0,0,0,0,0,0,0,0,6,2,2,1,1
1,1,2,2,14,0,0,0,0,0,0,0,0,0,0,0,0,0,0,0,0,0,6,2,2,1,1
1,1,1,2,2,14,0,0,0,0,0,0,0,0,0,0,0,0,0,0,0,6,2,2,1,1,1
1,1,1,2,2,14,0,0,0,0,0,0,0,0,0,0,0,0,0,0,0,6,2,2,1,1,1
1,1,1,2,2,2,7,0,0,0,0,0,0,0,0,0,0,0,0,0,7,2,2,2,1,1,1
1,1,1,1,2,2,2,7,0,0,0,0,0,0,0,0,0,0,0,7,2,2,2,1,1,1,1
1,1,1,1,1,2,2,2,9,9,0,0,0,0,0,0,0,9,7,2,2,2,1,1,1,1,1
1,1,1,1,1,1,2,2,2,2,9,9,9,9,9,9,9,2,2,2,2,1,1,1,1,1,1
1,1,1,1,1,1,1,2,2,2,2,2,2,2,2,2,2,2,2,2,1,1,1,1,1,1,1
1,1,1,1,1,1,1,1,1,1,2,2,2,2,2,2,2,1,1,1,1,1,1,1,1,1,1
1,1,1,1,1,1,1,1,1,1,1,1,1,1,1,1,1,1,1,1,1,1,1,1,1,1,1
1,1,1,1,1,1,1,1,1,1,1,1,1,1,1,1,1,1,1,1,1,1,1,1,1,1,1
endlayer

layer
1,1,1,1,1,1,2,2,2,2,2,2,2,2,2,2,2,2,2,2,2,1,1,1,1,1,1
1,1,1,1,1,2,2,2,2,2,2,2,2,2,2,2,2,2,2,2,2,2,1,1,1,1,1
1,1,1,1,2,2,2,2,2,8,8,8,8,8,8,8,8,8,2,2,2,2,2,1,1,1,1
1,1,1,2,2,2,2,8,8,0,0,0,0,0,0,0,0,0,8,8,2,2,2,2,1,1,1
1,1,2,2,2,2,7,0,0,0,0,0,0,0,0,0,0,0,0,0,7,2,2,2,2,1,1
1,2,2,2,2,7,0,0,0,0,0,0,0,0,0,0,0,0,0,0,0,7,2,2,2,2,1
2,2,2,2,7,0,0,0,0,0,0,0,0,0,0,0,0,0,0,0,0,0,7,2,2,2,2
2,2,2,14,0,0,0,0,0,0,0,0,0,0,0,0,0,0,0,0,0,0,0,6,2,2,2
2,2,2,14,0,0,0,0,0,0,0,0,0,0,0,0,0,0,0,0,0,0,0,6,2,2,2
2,2,14,0,0,0,0,0,0,0,0,0,0,0,0,0,0,0,0,0,0,0,0,0,6,2,2
2,2,14,0,0,0,0,0,0,0,0,0,0,0,0,0,0,0,0,0,0,0,0,0,6,2,2
2,2,14,0,0,0,0,0,0,0,0,0,0,0,0,0,0,0,0,0,0,0,0,0,6,2,2
2,2,14,0,0,0,0,0,0,0,0,0,0,0,0,0,0,0,0,0,0,0,0,0,6,2,2
2,2,14,0,0,0,0,0,0,0,0,0,0,0,0,0,0,0,0,0,0,0,0,0,6,2,2
2,2,14,0,0,0,0,0,0,0,0,0,0,0,0,0,0,0,0,0,0,0,0,0,6,2,2
2,2,14,0,0,0,0,0,0,0,0,0,0,0,0,0,0,0,0,0,0,0,0,0,6,2,2
2,2,14,0,0,0,0,0,0,0,0,0,0,0,0,0,0,0,0,0,0,0,0,0,6,2,2
2,2,14,0,0,0,0,0,0,0,0,0,0,0,0,0,0,0,0,0,0,0,0,0,6,2,2
2,2,2,14,0,0,0,0,0,0,0,0,0,0,0,0,0,0,0,0,0,0,0,6,2,2,2
2,2,2,14,0,0,0,0,0,0,0,0,0,0,0,0,0,0,0,0,0,0,0,6,2,2,2
2,2,2,2,7,0,0,0,0,0,0,0,0,0,0,0,0,0,0,0,0,0,7,2,2,2,2
1,2,2,2,2,7,0,0,0,0,0,0,0,0,0,0,0,0,0,0,0,7,2,2,2,2,1
1,1,2,2,2,2,7,0,0,0,0,0,0,0,0,0,0,0,0,0,7,2,2,2,2,1,1
1,1,1,2,2,2,2,9,9,0,0,0,0,0,0,0,0,0,9,9,2,2,2,2,1,1,1
1,1,1,1,2,2,2,2,2,9,9,9,9,9,9,9,9,9,2,2,2,2,2,1,1,1,1
1,1,1,1,1,2,2,2,2,2,2,2,2,2,2,2,2,2,2,2,2,2,1,1,1,1,1
1,1,1,1,1,1,2,2,2,2,2,2,2,2,2,2,2,2,2,2,2,1,1,1,1,1,1
endlayer

layer
1,1,1,15,15,15,2,2,8,8,8,8,8,8,8,8,8,8,8,2,2,15,15,15,1,1,1
1,1,15,15,15,2,8,8,0,0,0,0,0,0,0,0,0,0,0,8,8,2,15,15,15,1,1
1,15,15,15,2,7,0,0,0,0,0,0,0,0,0,0,0,0,0,0,0,7,2,15,15,15,1
15,15,15,2,7,0,0,0,0,0,0,0,0,0,0,0,0,0,0,0,0,0,7,2,15,15,15
15,15,2,7,0,0,0,0,0,0,0,0,0,0,0,0,0,0,0,0,0,0,0,7,2,15,15
15,2,7,0,0,0,0,0,0,0,0,0,0,0,0,0,0,0,0,0,0,0,0,0,7,2,15
2,14,0,0,0,0,0,0,0,0,0,0,0,0,0,0,0,0,0,0,0,0,0,0,0,6,2
2,14,0,0,0,0,0,0,0,0,0,0,0,0,0,0,0,0,0,0,0,0,0,0,0,6,2
14,0,0,0,0,0,0,0,0,0,0,0,0,0,0,0,0,0,0,0,0,0,0,0,0,0,6
14,0,0,0,0,0,0,0,0,0,0,0,0,0,0,0,0,0,0,0,0,0,0,0,0,0,6
14,0,0,0,0,0,0,0,0,0,0,0,0,0,0,0,0,0,0,0,0,0,0,0,0,0,6
14,0,0,0,0,0,0,0,0,0,0,0,0,0,0,0,0,0,0,0,0,0,0,0,0,0,6
14,0,0,0,0,0,0,0,0,0,0,0,0,0,0,0,0,0,0,0,0,0,0,0,0,0,6
14,0,0,0,0,0,0,0,0,0,0,0,0,0,0,0,0,0,0,0,0,0,0,0,0,0,6
14,0,0,0,0,0,0,0,0,0,0,0,0,0,0,0,0,0,0,0,0,0,0,0,0,0,6
14,0,0,0,0,0,0,0,0,0,0,0,0,0,0,0,0,0,0,0,0,0,0,0,0,0,6
14,0,0,0,0,0,0,0,0,0,0,0,0,0,0,0,0,0,0,0,0,0,0,0,0,0,6
14,0,0,0,0,0,0,0,0,0,0,0,0,0,0,0,0,0,0,0,0,0,0,0,0,0,6
14,0,0,0,0,0,0,0,0,0,0,0,0,0,0,0,0,0,0,0,0,0,0,0,0,0,6
2,14,0,0,0,0,0,0,0,0,0,0,0,0,0,0,0,0,0,0,0,0,0,0,0,6,2
2,14,0,0,0,0,0,0,0,0,0,0,0,0,0,0,0,0,0,0,0,0,0,0,0,6,2
15,2,7,0,0,0,0,0,0,0,0,0,0,0,0,0,0,0,0,0,0,0,0,0,7,2,15
15,15,2,7,0,0,0,0,0,0,0,0,0,0,0,0,0,0,0,0,0,0,0,7,2,15,15
15,15,15,2,7,0,0,0,0,0,0,0,0,0,0,0,0,0,0,0,0,0,7,2,15,15,15
1,15,15,15,2,7,0,0,0,0,0,0,0,0,0,0,0,0,0,0,0,7,2,15,15,15,1
1,1,15,15,15,2,9,9,0,0,0,0,0,0,0,0,0,0,0,9,9,2,15,15,15,1,1
1,1,1,15,15,15,2,2,9,9,9,9,9,9,9,9,9,9,9,2,2,15,15,15,1,1,1
endlayer
