# Converted from schematic
# THIS TEMPLATE USES DEFAULTS!  Please edit for corrections.
# If you need help, consult template_rules.txt
biomesToSpawnIn=desert,desert oil field,deserthills,dunes,lush desert,mountainous desert,desert_hills,desert_defiled,desert_shrubland,mutated_desert
weight=2
embed_into_distance=1
unacceptable_target_blocks=flowing_water,water,flowing_lava,lava,Natura:Cloud,red_mushroom_block,brown_mushroom_block,planks,cobblestone,end_stone,obsidian,purpur_block,iron_bars,purpur_slab,purpur_pillar,netherrack,soul_sand,quartz_ore
dimensions=10,14,8
allowable_overhang=0
max_cut_in=2
cut_in_buffer=1
max_leveling=2
leveling_buffer=-1
preserve_water=0
preserve_lava=0
preserve_plants=0


rule1=0,100,sand
rule2=0,100,planks
rule3=0,100,sandstone-1
rule4=0,100,sandstone
rule5=0,100,stone_slab-1
rule6=0,100,double_stone_slab-1
rule7=0,100,iron_bars
rule8=0,100,stone_slab-2
rule9=0,100,stone_slab-10


layer
1,1,1,1,1,1,1,1
0,0,0,0,0,1,1,1
0,0,0,0,0,0,1,1
0,0,0,0,0,0,1,1
0,0,0,0,0,0,1,1
2,2,0,2,2,2,1,1
2,2,0,2,2,2,1,1
2,2,2,2,2,2,1,1
2,2,2,2,2,2,1,1
2,2,2,2,2,2,1,1
2,2,2,2,2,2,1,1
2,2,2,2,2,2,1,1
2,2,2,2,2,2,1,1
1,1,1,1,1,1,1,1
endlayer

layer
0,0,0,0,0,0,0,0
0,0,0,0,0,0,3,0
0,0,0,0,0,0,0,0
0,0,0,0,0,0,0,0
0,0,0,0,0,0,0,0
0,0,0,0,0,0,0,0
4,0,0,0,0,0,4,0
4,0,0,0,0,0,4,0
4,0,0,0,0,0,4,0
4,0,0,0,0,0,4,0
4,0,0,0,0,5,4,0
4,0,0,0,0,6,4,0
4,4,4,4,6,6,4,0
3,4,4,4,4,4,3,0
endlayer

layer
0,0,0,0,0,0,0,0
0,0,0,0,0,4,3,0
0,0,0,0,0,0,0,0
0,0,0,0,0,0,0,0
0,0,0,0,0,0,0,0
0,0,0,0,0,0,0,0
4,0,0,0,0,0,0,0
0,0,0,0,0,0,0,0
0,0,0,0,0,0,4,0
0,0,0,0,0,0,0,0
4,0,0,0,0,0,4,0
0,0,0,0,0,0,7,0
4,4,4,4,6,5,4,0
3,4,4,4,0,4,3,0
endlayer

layer
0,0,0,0,0,0,0,0
0,0,0,0,0,4,3,0
0,0,0,0,0,0,4,0
0,0,0,0,0,0,0,8
0,0,0,0,0,0,0,0
0,0,0,0,0,0,4,8
4,0,0,0,0,0,4,0
4,0,0,0,0,0,4,8
4,0,0,0,0,0,4,0
4,0,0,0,0,0,4,8
4,0,0,0,0,0,4,0
4,0,0,0,0,0,4,8
4,4,4,5,0,0,4,0
3,4,4,4,0,4,3,0
endlayer

layer
0,0,0,0,0,0,0,0
0,0,0,0,0,3,3,0
0,0,0,0,0,9,3,0
0,0,0,0,0,0,0,0
0,0,0,0,0,0,0,0
0,0,0,0,0,0,0,0
0,0,0,0,0,0,0,0
0,0,0,0,0,0,0,0
3,9,0,0,0,9,3,0
3,9,9,9,9,9,3,0
3,9,9,9,9,9,3,0
3,9,9,9,9,9,3,0
3,5,0,0,0,0,3,0
3,3,3,3,0,3,3,0
endlayer

layer
0,0,0,0,0,0,0,0
0,0,0,0,0,0,0,0
0,0,0,0,0,0,0,0
0,0,0,0,0,0,0,0
0,0,0,0,0,0,0,0
0,0,0,0,0,0,0,0
0,0,0,0,0,0,0,0
0,0,0,0,0,0,0,0
4,0,0,0,0,0,4,0
4,0,0,0,0,0,4,0
0,0,0,0,0,0,4,0
4,0,0,0,0,0,4,0
4,0,0,0,0,0,4,0
3,4,0,4,0,4,3,0
endlayer

layer
0,0,0,0,0,0,0,0
0,0,0,0,0,0,0,0
0,0,0,0,0,0,0,0
0,0,0,0,0,0,0,0
0,0,0,0,0,0,0,0
0,0,0,0,0,0,0,0
0,0,0,0,0,0,0,0
0,0,0,0,0,0,0,0
4,0,0,0,0,0,4,0
0,0,0,0,0,0,0,0
0,0,0,0,0,0,4,0
0,0,0,0,0,0,0,0
4,0,0,0,0,0,4,0
3,4,7,4,0,4,3,0
endlayer

layer
0,0,0,0,0,0,0,0
0,0,0,0,0,0,0,0
0,0,0,0,0,0,0,0
0,0,0,0,0,0,0,0
0,0,0,0,0,0,0,0
0,0,0,0,0,0,0,0
0,0,0,0,0,0,0,0
0,0,0,0,0,0,0,0
4,0,0,0,0,0,4,0
4,0,0,0,0,0,4,8
0,0,0,0,0,0,4,0
4,0,0,0,0,0,0,8
4,0,0,0,0,0,0,0
3,4,4,0,0,0,0,0
endlayer

layer
0,0,0,0,0,0,0,0
0,0,0,0,0,0,0,0
0,0,0,0,0,0,0,0
0,0,0,0,0,0,0,0
0,0,0,0,0,0,0,0
0,0,0,0,0,0,0,0
0,0,0,0,0,0,0,0
0,0,3,0,0,3,0,0
3,9,9,9,9,9,3,0
3,0,0,9,0,0,3,0
0,0,0,0,0,0,0,0
3,9,0,0,0,0,0,0
3,9,9,0,0,0,0,0
3,3,0,0,0,0,0,0
endlayer

layer
0,0,0,0,0,0,0,0
0,0,0,0,0,0,0,0
0,0,0,0,0,0,0,0
0,0,0,0,0,0,0,0
0,0,0,0,0,0,0,0
0,0,0,0,0,0,0,0
0,0,0,0,0,0,0,0
3,5,0,6,0,5,3,0
5,0,0,0,0,0,5,0
0,0,0,0,0,0,0,0
0,0,0,0,0,0,0,0
0,0,0,0,0,0,0,0
5,0,0,0,0,0,0,0
3,0,0,0,0,0,0,0
endlayer

