# Converted from schematic
# THIS TEMPLATE USES DEFAULTS!  Please edit for corrections.
# If you need help, consult template_rules.txt
biomesToSpawnIn=desert,desert oil field,deserthills,dunes,lush desert,mountainous desert,desert_hills,desert_defiled,desert_shrubland,mutated_desert
weight=2
embed_into_distance=1
unacceptable_target_blocks=flowing_water,water,flowing_lava,lava,Natura:Cloud,red_mushroom_block,brown_mushroom_block,planks,cobblestone,end_stone,obsidian,purpur_block,iron_bars,purpur_slab,purpur_pillar,netherrack,soul_sand,quartz_ore
dimensions=6,9,8
allowable_overhang=0
max_cut_in=2
cut_in_buffer=1
max_leveling=2
leveling_buffer=-1
preserve_water=0
preserve_lava=0
preserve_plants=0


rule1=0,100,sandstone
rule2=0,100,dirt
rule3=0,100,sandstone-2
rule4=0,100,stone_slab-1


layer
1,1,1,1,1,1,1,1
1,2,2,2,2,2,1,1
1,1,1,1,1,1,2,1
1,1,1,1,1,1,2,1
1,1,1,1,1,1,2,1
2,1,1,1,1,1,2,1
2,1,1,1,1,1,2,1
1,2,2,2,2,2,1,1
1,1,1,1,1,1,1,1
endlayer

layer
0,0,0,0,0,0,0,0
0,1,1,1,1,1,0,0
1,0,0,0,0,0,1,0
3,0,0,0,0,0,1,0
0,0,0,0,0,0,1,0
3,0,0,0,0,0,1,0
1,0,0,0,0,0,1,0
0,1,1,1,1,1,0,0
0,0,0,0,0,0,0,0
endlayer

layer
0,0,0,0,0,0,0,0
0,1,0,0,0,1,0,0
0,0,0,0,0,0,1,0
0,0,0,0,0,0,0,0
0,0,0,0,0,0,0,0
0,0,0,0,0,0,0,0
1,0,0,0,0,0,1,0
0,1,0,0,0,1,0,0
0,0,0,0,0,0,0,0
endlayer

layer
0,0,0,0,0,0,0,0
0,0,0,0,0,1,0,0
0,0,0,0,0,0,1,0
0,0,0,0,0,0,0,0
0,0,0,0,0,0,0,0
3,0,0,0,0,0,0,0
1,0,0,0,0,0,1,0
0,1,0,0,0,1,0,0
0,0,0,0,0,0,0,0
endlayer

layer
0,0,0,0,4,4,0,0
0,0,0,0,0,1,4,0
0,0,0,0,1,1,1,4
0,0,0,0,0,1,1,4
0,0,0,0,0,1,1,4
1,1,0,0,0,1,1,4
1,1,1,1,1,1,1,4
4,1,1,1,1,1,4,0
0,4,4,4,4,4,0,0
endlayer

layer
0,0,0,0,0,0,0,0
0,0,0,0,0,0,0,0
0,0,0,4,4,4,0,0
0,0,0,0,1,4,0,0
0,4,0,0,1,4,0,0
0,4,1,1,1,4,0,0
0,4,4,4,4,4,0,0
0,0,0,0,0,0,0,0
0,0,0,0,0,0,0,0
endlayer

