biomesToSpawnIn=desert,desert oil field,deserthills,dunes,lush desert,mountainous desert,desert_hills,desert_defiled,desert_shrubland,mutated_desert
weight=8
embed_into_distance=3
unacceptable_target_blocks=flowing_water,water,flowing_lava,lava,Natura:Cloud,red_mushroom_block,brown_mushroom_block,planks,cobblestone,end_stone,obsidian,purpur_block,iron_bars,purpur_slab,purpur_pillar,netherrack,soul_sand,quartz_ore
dimensions=43,8,8
allowable_overhang=32
max_cut_in=0
cut_in_buffer=0
max_leveling=4
leveling_buffer=0
preserve_water=0
preserve_lava=0
preserve_plants=0


rule1=0,100,preserveBlock
rule2=0,100,grass
rule3=0,100,glowstone
rule4=0,100,mossy_cobblestone
rule5=0,100,sand
rule6=0,100,redstone_torch
rule7=0,100,glass
rule8=0,100,flowing_water
rule9=2,100,ladder-2
rule10=2,100,ladder-3
rule11=2,100,ladder-4
rule12=2,100,ladder-5
rule13=0,100,sand
rule14=0,100,soul_sand
rule15=0,100,redstone_torch-1
rule16=0,100,redstone_torch-2
rule17=0,100,redstone_torch-3
rule18=0,100,redstone_torch-4
rule19=0,100,snow_layer

layer
4,4,4,4,4,4,4,4
4,4,4,4,4,4,4,4
4,4,4,4,4,4,4,4
4,4,4,4,4,4,4,4
4,4,4,4,4,4,4,4
4,4,4,4,4,4,4,4
4,4,4,4,4,4,4,4
4,4,4,4,4,4,4,4
endlayer

layer
4,5,14,14,14,14,5,4
5,19,19,0,0,19,19,5
14,0,0,0,0,0,0,14
14,0,0,0,0,0,0,14
14,0,0,0,0,0,0,14
14,0,0,0,0,0,0,14
5,19,19,0,0,19,19,5
4,5,14,14,14,14,5,4
endlayer

layer
4,5,14,14,14,14,5,4
5,5,5,0,0,5,5,5
14,0,0,0,0,0,0,14
14,0,0,0,0,0,0,14
14,0,0,0,0,0,0,14
14,0,0,0,0,0,0,14
5,5,5,0,0,5,5,5
4,5,14,14,14,14,5,4
endlayer

layer
1,5,14,14,14,14,5,1
5,5,5,4,4,5,5,5
14,4,4,4,4,4,4,14
14,0,4,4,4,4,4,14
14,4,4,4,4,4,0,14
14,4,4,4,4,4,4,14
5,5,5,4,4,5,5,5
1,5,14,14,14,14,5,1
endlayer

layer
1,5,14,0,0,14,5,1
5,5,5,0,0,5,5,5
14,5,0,0,0,0,0,14
14,19,0,0,0,0,0,14
14,0,0,0,0,0,19,14
14,0,0,0,0,0,5,14
5,5,5,0,0,5,5,5
1,5,14,0,0,14,5,1
endlayer

layer
1,1,14,0,0,14,1,1
1,5,5,0,0,5,5,1
14,0,0,0,0,0,0,14
14,5,0,0,0,0,11,14
14,12,0,0,0,0,5,14
14,0,0,0,0,0,0,14
1,5,5,0,0,5,5,1
1,1,14,0,0,14,1,1
endlayer

layer
1,1,14,0,0,14,1,1
1,5,5,0,0,5,5,1
14,0,0,0,0,0,11,14
14,0,0,0,0,0,5,14
14,5,0,0,0,0,0,14
14,12,0,0,0,0,0,14
1,5,5,0,0,5,5,1
1,1,14,0,0,14,1,1
endlayer

layer
1,1,14,14,14,14,1,1
1,5,5,9,10,5,5,1
14,0,0,0,0,10,5,14
14,0,0,0,0,0,0,14
14,0,0,0,0,0,0,14
14,5,9,0,0,0,0,14
1,5,5,9,10,5,5,1
1,1,14,14,14,14,1,1
endlayer

layer
1,1,14,14,14,14,1,1
1,5,5,5,5,5,5,1
14,12,0,0,10,5,0,14
14,0,0,0,0,0,0,14
14,0,0,0,0,0,0,14
14,0,5,9,0,0,11,14
1,5,5,5,5,5,5,1
1,1,14,14,14,14,1,1
endlayer

layer
1,1,14,14,14,1,1,1
1,5,5,5,5,5,5,1
1,5,0,10,5,0,0,14
14,12,0,0,0,0,0,14
14,0,0,0,0,0,11,14
14,0,0,5,9,0,5,1
1,5,5,5,5,5,5,1
1,1,1,14,14,14,1,1
endlayer

layer
1,1,14,14,1,1,1,1
1,5,5,5,5,5,5,1
1,5,10,5,0,0,0,14
1,5,0,0,0,0,11,14
14,12,0,0,0,0,5,1
14,0,0,0,5,9,5,1
1,5,5,5,5,5,5,1
1,1,1,1,14,14,1,1
endlayer

layer
1,1,14,14,1,1,1,1
1,5,5,5,5,5,5,1
1,5,5,0,0,0,11,14
1,5,12,0,0,0,5,14
14,5,0,0,0,11,5,1
14,12,0,0,0,5,5,1
1,5,5,5,5,5,5,1
1,1,1,1,14,14,1,1
endlayer

layer
1,1,14,1,1,1,1,1
1,5,5,5,5,5,5,1
1,0,0,0,0,0,5,14
1,5,5,0,0,11,5,1
1,5,12,0,0,5,5,1
14,5,0,0,0,0,0,1
1,5,5,5,5,5,5,1
1,1,1,1,1,14,1,1
endlayer

layer
1,1,14,1,1,1,1,1
1,5,5,5,5,5,5,1
1,0,0,0,0,11,5,14
1,0,0,0,0,5,5,1
1,5,5,0,0,0,0,1
14,5,12,0,0,0,0,1
1,5,5,5,5,5,5,1
1,1,1,1,1,14,1,1
endlayer

layer
1,1,1,1,1,1,1,1
1,5,5,5,5,5,5,1
1,0,0,0,10,5,5,1
1,0,0,0,0,0,0,1
1,0,0,0,0,0,0,1
1,5,5,9,0,0,0,1
1,5,5,5,5,5,5,1
1,1,1,1,1,1,1,1
endlayer

layer
1,1,1,1,1,1,1,1
1,5,5,5,5,5,5,1
1,0,0,10,5,0,0,1
1,0,0,0,0,0,0,1
1,0,0,0,0,0,0,1
1,0,0,5,9,0,0,1
1,5,5,5,5,5,5,1
1,1,1,1,1,1,1,1
endlayer

layer
1,1,1,1,1,1,1,1
1,5,5,5,5,5,5,1
1,12,10,5,0,0,0,1
1,0,0,0,0,0,0,1
1,0,0,0,0,0,0,1
1,0,0,0,5,9,11,1
1,5,5,5,5,5,5,1
1,1,1,1,1,1,1,1
endlayer

layer
1,1,1,1,1,1,1,1
1,5,5,5,5,5,5,1
1,5,5,0,0,0,0,1
1,12,12,0,0,0,0,1
1,0,0,0,0,11,11,1
1,0,0,0,0,5,5,1
1,5,5,5,5,5,5,1
1,1,1,1,1,1,1,1
endlayer

layer
1,1,1,1,1,1,1,1
1,5,5,5,5,5,5,1
1,5,0,0,0,0,0,1
1,5,5,0,0,11,11,1
1,12,12,0,0,5,5,1
1,0,0,0,0,0,5,1
1,5,5,5,5,5,5,1
1,1,1,1,1,1,1,1
endlayer

layer
1,1,1,1,1,1,1,1
1,5,5,5,5,5,5,1
1,5,0,0,0,11,11,1
1,5,0,0,0,5,5,1
1,5,5,0,0,0,5,1
1,12,12,0,0,0,5,1
1,5,5,5,5,5,5,1
1,1,1,1,1,1,1,1
endlayer

layer
1,1,1,1,1,1,1,1
1,1,5,5,5,5,5,1
1,5,12,12,12,5,5,1
1,5,0,0,0,0,5,1
1,5,0,0,0,0,5,1
1,5,5,11,11,11,5,1
1,5,5,5,5,5,1,1
1,1,1,1,1,1,1,1
endlayer
layer
1,1,1,1,1,1,1,1
1,1,5,5,5,5,5,1
1,5,5,5,5,5,5,1
1,5,12,12,12,12,5,1
1,5,11,11,11,11,5,1
1,5,5,5,5,5,5,1
1,5,5,5,5,5,1,1
1,1,1,1,1,1,1,1
endlayer

layer
1,1,1,1,1,1,1,1
1,1,5,5,5,5,5,1
1,5,5,5,5,5,5,1
1,5,5,5,5,5,5,1
1,5,5,5,5,5,5,1
1,5,5,5,5,5,5,1
1,5,5,5,5,5,1,1
1,1,1,1,1,1,1,1
endlayer

layer
1,1,1,1,1,1,1,1
1,1,5,5,5,5,1,1
1,5,8,8,8,8,5,1
1,5,8,8,8,8,5,1
1,5,8,8,8,8,5,1
1,5,8,8,8,8,5,1
1,1,5,5,5,5,1,1
1,1,1,1,1,1,1,1
endlayer

layer
1,1,1,1,1,1,1,1
1,1,5,5,5,5,1,1
1,5,4,4,4,4,5,1
1,5,4,4,4,4,5,1
1,5,4,4,4,4,5,1
1,5,4,4,4,4,5,1
1,1,5,5,5,5,1,1
1,1,1,1,1,1,1,1
endlayer

layer
1,1,1,1,1,1,1,1
1,1,5,5,5,5,1,1
1,5,0,0,0,0,5,1
1,5,0,0,0,0,5,1
1,5,0,0,0,0,5,1
1,5,0,0,0,0,5,1
1,1,5,5,5,5,1,1
1,1,1,1,1,1,1,1
endlayer

layer
1,1,1,1,1,1,1,1
1,1,5,5,5,5,1,1
1,5,0,0,0,0,5,1
1,5,0,0,0,0,5,1
1,5,0,0,0,0,5,1
1,5,0,0,0,0,5,1
1,1,5,5,5,5,1,1
1,1,1,1,1,1,1,1
endlayer

layer
1,1,1,1,1,1,1,1
1,1,5,5,5,5,1,1
1,5,0,0,0,0,5,1
1,5,0,0,0,0,5,1
1,5,0,0,0,0,5,1
1,5,0,0,0,0,5,1
1,1,5,5,5,5,1,1
1,1,1,1,1,1,1,1
endlayer

layer
1,1,1,1,1,1,1,1
1,1,5,5,5,5,1,1
1,5,0,0,0,0,5,1
1,5,0,0,0,0,5,1
1,5,0,0,0,0,5,1
1,5,0,0,0,0,5,1
1,1,5,5,5,5,1,1
1,1,1,1,1,1,1,1
endlayer

layer
1,1,1,1,1,1,1,1
1,1,5,5,5,5,1,1
1,5,0,0,0,0,5,1
1,5,0,0,0,0,5,1
1,5,0,0,0,0,5,1
1,5,0,0,0,0,5,1
1,1,5,5,5,5,1,1
1,1,1,1,1,1,1,1
endlayer

layer
1,1,1,1,1,1,1,1
1,1,5,5,5,13,1,1
1,5,0,0,0,0,5,1
1,5,0,0,0,0,5,1
1,5,0,0,0,0,5,1
1,5,0,0,0,0,5,1
1,1,13,5,5,5,1,1
1,1,1,1,1,1,1,1
endlayer

layer
1,1,1,1,1,1,1,1
1,1,5,5,5,0,1,1
1,5,0,0,0,0,5,1
1,5,0,0,0,0,5,1
1,5,0,0,0,0,5,1
1,5,0,0,0,0,5,1
1,1,0,5,5,5,1,1
1,1,1,1,1,1,1,1
endlayer

layer
1,1,1,1,1,1,1,1
1,1,5,5,13,0,1,1
1,5,0,0,0,0,5,1
1,5,0,0,0,0,5,1
1,5,0,0,0,0,5,1
1,5,0,0,0,0,5,1
1,1,0,13,5,5,1,1
1,1,1,1,1,1,1,1
endlayer

layer
1,1,1,1,1,1,1,1
1,1,5,5,0,0,1,1
1,5,0,0,0,0,5,1
1,5,0,0,0,0,5,1
1,5,0,0,0,0,5,1
1,5,0,0,0,0,5,1
1,1,0,0,5,5,1,1
1,1,1,1,1,1,1,1
endlayer

layer
1,1,1,1,1,1,1,1
1,1,5,13,0,0,1,1
1,5,0,0,0,0,5,1
1,5,0,0,0,0,5,1
1,5,0,0,0,0,5,1
1,5,0,0,0,0,5,1
1,1,0,0,13,5,1,1
1,1,1,1,1,1,1,1
endlayer

layer
1,1,1,1,1,1,1,1
1,1,5,0,0,0,1,1
1,5,0,0,0,0,5,1
1,5,0,0,0,0,5,1
1,5,0,0,0,0,5,1
1,5,0,0,0,0,5,1
1,1,0,0,0,5,1,1
1,1,1,1,1,1,1,1
endlayer

layer
1,1,1,1,1,1,1,1
1,1,13,0,0,0,1,1
1,13,0,0,0,0,5,1
1,5,0,0,0,0,5,1
1,5,0,0,0,0,5,1
1,5,0,0,0,0,13,1
1,1,0,0,0,13,1,1
1,1,1,1,1,1,1,1
endlayer

layer
1,1,1,1,1,1,1,1
1,1,0,0,0,0,1,1
1,1,0,0,0,0,5,1
1,5,0,0,0,0,5,1
1,5,0,0,0,0,5,1
1,5,0,0,0,0,1,1
1,1,0,0,0,0,1,1
1,1,1,1,1,1,1,1
endlayer

layer
1,1,1,1,1,1,1,1
1,1,0,0,0,0,1,1
1,1,0,0,0,0,5,1
1,5,0,0,0,0,5,1
1,5,0,0,0,0,13,1
1,13,0,0,0,0,1,1
1,1,0,0,0,0,1,1
1,1,1,1,1,1,1,1
endlayer

layer
1,1,1,1,1,1,1,1
1,1,0,0,0,0,1,1
1,0,0,0,0,0,5,1
1,0,0,0,0,0,5,1
1,5,0,0,0,0,1,1
1,5,0,0,0,0,0,1
1,1,0,0,0,0,1,1
1,1,1,1,1,1,1,1
endlayer

layer
1,1,1,1,1,1,1,1
1,1,0,0,0,0,1,1
1,0,0,0,0,0,5,1
1,0,0,0,0,0,13,1
1,5,0,0,0,0,0,1
1,13,0,0,0,0,0,1
1,1,0,0,0,0,1,1
1,1,1,1,1,1,1,1
endlayer

layer
1,1,1,1,1,1,1,1
1,1,0,0,0,0,1,1
1,0,0,0,0,0,5,1
1,0,0,0,0,0,0,1
1,0,0,0,0,0,0,1
1,5,0,0,0,0,0,1
1,1,0,0,0,0,1,1
1,1,1,1,1,1,1,1
endlayer

layer
1,1,1,1,1,1,1,1
1,1,0,0,0,0,1,1
1,0,0,0,0,0,13,1
1,0,0,0,0,0,0,1
1,0,0,0,0,0,0,1
1,13,0,0,0,0,0,1
1,1,0,0,0,0,1,1
1,1,1,1,1,1,1,1
endlayer
