# Author: Arrrg
# From: Minecraft Forums

biomesToSpawnIn=alpine,alps,alps forest,alps mountainside,arctic,frost forest,frozenocean,glacier,ice montains,ice plains,ice wasteland,icy hills,snow forest,snowy coniferous forest,snowy dead forest,snowy rainforest,tundra,polar,ice_plains,frozen_ocean,frozen_river,ice_mountains,ice_flats,glacier_spikes,taiga_cold,glacier,taiga_cold_hills
weight=3
embed_into_distance=7
unacceptable_target_blocks=flowing_water,water,flowing_lava,lava,Natura:Cloud,red_mushroom_block,brown_mushroom_block,planks,cobblestone,end_stone,obsidian,purpur_block,iron_bars,purpur_slab,purpur_pillar,netherrack,soul_sand,quartz_ore
dimensions=14,12,12
allowable_overhang=300
max_cut_in=0
cut_in_buffer=0
max_leveling=14
leveling_buffer=-1
preserve_water=0
preserve_lava=0
preserve_plants=0

rule1=0,100,preserveBlock
rule2=0,100,glowstone
rule3=0,100,snow
rule4=0,100,cobblestone
rule5=0,100,snow_layer
rule6=0,100,ice
rule7=0,100,glass
rule8=0,100,flowing_water
rule9=0,100,HardMobSpawn,iron_block,jukebox
rule10=0,100,MobSpawner:Skeleton





layer
1,1,1,1,1,1,1,1,1,1,1,1
1,1,1,1,1,1,1,1,1,1,1,1
1,1,1,1,1,1,1,1,1,1,1,1
1,1,1,1,1,1,1,1,1,1,1,1
1,1,1,1,1,1,1,1,1,1,1,1
1,1,1,1,1,1,1,1,1,1,1,1
1,1,1,1,1,1,1,1,1,1,1,1
1,1,1,1,1,1,1,1,1,1,1,1
1,1,1,1,1,1,1,1,1,1,1,1
1,1,1,1,1,1,1,1,1,1,1,1
1,1,1,1,1,1,1,1,1,1,1,1
1,1,1,1,1,1,1,1,1,1,1,1
endlayer

layer
1,1,1,1,1,1,1,1,1,1,1,1
1,1,1,0,0,0,0,0,1,1,1,1
1,1,0,0,0,0,0,0,0,1,1,1
1,0,0,0,0,0,0,0,0,0,1,1
1,0,0,0,0,0,0,0,0,0,1,1
1,0,0,0,0,10,0,0,0,0,1,1
1,0,0,0,0,0,0,0,0,0,1,1
1,0,0,0,0,0,0,0,0,0,1,1
1,1,0,0,0,0,0,0,0,1,1,1
1,1,1,0,0,0,0,0,1,1,1,1
1,1,1,1,1,1,1,1,1,1,1,1
1,1,1,1,1,1,1,1,1,1,1,1
endlayer

layer
1,1,1,1,1,1,1,1,1,1,1,1
1,1,1,0,0,0,0,0,1,1,1,1
1,1,0,0,0,0,0,0,0,1,1,1
1,0,0,0,0,0,0,0,0,0,1,1
1,0,0,0,0,0,0,0,0,0,1,1
1,0,0,0,0,0,0,0,0,0,1,1
1,0,0,0,0,0,0,0,0,0,1,1
1,0,0,0,0,0,0,0,0,0,1,1
1,1,0,0,0,0,0,0,0,1,1,1
1,1,1,0,0,0,0,0,1,1,1,1
1,1,1,1,1,1,1,1,1,1,1,1
1,1,1,1,1,1,1,1,1,1,1,1
endlayer

layer
1,1,1,1,1,1,1,1,1,1,1,1
1,1,1,0,0,0,0,0,1,1,1,1
1,1,0,0,0,0,0,0,0,1,1,1
1,0,0,0,0,0,0,0,0,0,1,1
1,0,0,0,0,0,0,0,0,0,1,1
1,0,0,0,0,0,0,0,0,0,1,1
1,0,0,0,0,0,0,0,0,0,1,1
1,0,0,0,0,0,0,0,0,0,1,1
1,1,0,0,0,0,0,0,0,1,1,1
1,1,1,0,0,0,0,0,1,1,1,1
1,1,1,1,1,1,1,1,1,1,1,1
1,1,1,1,1,1,1,1,1,1,1,1
endlayer

layer
1,1,1,1,1,1,1,1,1,1,1,1
1,1,1,0,0,0,0,0,1,1,1,1
1,1,0,0,0,0,0,0,0,1,1,1
1,0,0,0,0,0,0,0,0,0,1,1
1,0,0,0,0,0,0,0,0,0,1,1
1,0,0,0,0,0,0,0,0,0,1,1
1,0,0,0,0,0,0,0,0,0,1,1
1,0,0,0,0,0,0,0,0,0,1,1
1,1,0,0,0,0,0,0,0,1,1,1
1,1,1,0,0,0,0,0,1,1,1,1
1,1,1,1,1,1,1,1,1,1,1,1
1,1,1,1,1,1,1,1,1,1,1,1
endlayer

layer
1,1,1,3,3,3,3,3,1,1,1,1
1,1,3,0,0,0,0,0,3,1,1,1
1,3,0,0,0,0,0,0,0,3,1,1
3,0,0,0,0,0,0,0,0,0,3,1
3,0,0,0,0,0,0,0,0,0,3,1
3,0,0,0,0,0,0,0,0,0,3,1
3,0,0,0,0,0,0,0,0,0,3,1
3,0,0,0,0,0,0,0,0,0,3,1
0,3,0,0,0,0,0,0,0,3,1,1
1,1,3,0,0,0,0,0,3,1,1,1
1,1,1,3,3,3,3,3,1,1,1,1
1,1,1,1,1,1,1,1,1,1,1,1
endlayer

layer
1,1,1,3,3,3,3,3,1,1,1,1
1,1,3,0,0,3,0,0,3,1,1,1
1,3,0,0,0,3,0,0,0,3,1,1
3,0,0,0,0,3,0,0,0,0,3,1
3,0,0,0,0,3,0,0,0,0,3,1
3,0,0,0,0,3,0,0,0,0,3,1
3,0,0,0,0,3,0,0,0,0,3,1
3,0,0,0,0,3,0,0,0,0,3,1
1,3,0,0,0,3,0,0,0,3,1,1
1,1,3,0,0,3,0,0,3,1,1,1
1,1,1,3,3,3,3,3,1,1,1,1
1,1,1,1,4,4,4,1,1,1,1,1
endlayer

layer
1,1,1,3,3,3,3,3,1,1,1,1
1,1,3,5,5,9,5,5,3,1,1,1
1,3,5,5,5,5,5,5,5,3,1,1
3,5,5,5,5,5,5,5,5,5,3,1
3,5,5,5,5,5,5,5,5,5,3,1
3,5,5,5,5,5,5,5,5,5,3,1
3,5,5,5,5,5,5,5,5,5,3,1
3,5,5,5,5,5,5,5,5,5,3,1
1,3,5,5,5,5,5,5,5,3,1,1
1,1,3,5,5,5,5,5,3,1,1,1
1,1,1,3,3,5,3,3,1,1,1,1
1,1,1,1,4,5,4,1,1,1,1,1
endlayer

layer
0,0,0,3,3,3,3,3,0,0,0,0
0,0,3,0,0,5,0,0,3,0,0,0
0,3,0,0,0,0,0,0,0,3,0,0
3,0,0,0,0,0,0,0,0,0,3,0
3,0,0,0,0,0,0,0,0,0,3,0
3,0,0,0,0,0,0,0,0,0,3,0
3,0,0,0,0,0,0,0,0,0,3,0
3,0,0,0,0,0,0,0,0,0,3,0
0,3,0,0,0,0,0,0,0,3,0,0
0,0,3,0,0,0,0,0,3,0,0,0
0,0,0,3,3,0,3,3,0,0,0,0
0,0,0,0,4,0,4,0,0,0,0,0
endlayer

layer
0,0,0,3,3,3,3,3,0,0,0,0
0,0,3,0,0,0,0,0,3,0,0,0
0,3,0,0,0,0,0,0,0,3,0,0
3,0,0,0,0,0,0,0,0,0,3,0
3,0,0,0,0,0,0,0,0,0,3,0
3,0,0,0,0,0,0,0,0,0,3,0
3,0,0,0,0,0,0,0,0,0,3,0
3,0,0,0,0,0,0,0,0,0,3,0
0,3,0,0,0,0,0,0,0,3,0,0
0,0,3,0,0,0,0,0,3,0,0,0
0,0,0,3,3,3,3,3,0,0,0,0
0,0,0,0,4,4,4,0,0,0,0,0
endlayer

layer
0,0,0,0,3,3,3,0,0,0,0,0
0,0,3,3,0,0,0,3,3,0,0,0
0,3,0,0,0,0,0,0,0,3,0,0
0,3,0,0,0,0,0,0,0,3,0,0
3,0,0,0,0,0,0,0,0,0,3,0
3,0,0,0,0,0,0,0,0,0,3,0
3,0,0,0,0,0,0,0,0,0,3,0
0,3,0,0,0,0,0,0,0,3,0,0
0,3,0,0,0,0,0,0,0,3,0,0
0,0,3,3,0,0,0,3,3,0,0,0
0,0,0,0,3,3,3,0,0,0,0,0
0,0,0,0,0,0,0,0,0,0,0,0
endlayer

layer
0,0,0,0,0,0,0,0,0,0,0,0
0,0,0,3,3,3,3,3,0,0,0,0
0,0,3,0,0,0,0,0,3,0,0,0
0,3,0,0,0,0,0,0,0,3,0,0
0,3,0,0,0,0,0,0,0,3,0,0
0,3,0,0,0,0,0,0,0,3,0,0
0,3,0,0,0,0,0,0,0,3,0,0
0,3,0,0,0,0,0,0,0,3,0,0
0,0,3,0,0,0,0,0,3,0,0,0
0,0,0,3,3,3,3,3,0,0,0,0
0,0,0,0,0,0,0,0,0,0,0,0
0,0,0,0,0,0,0,0,0,0,0,0
endlayer

layer
0,0,0,0,0,0,0,0,0,0,0,0
0,0,0,0,0,0,0,0,0,0,0,0
0,0,0,3,3,3,3,3,0,0,0,0
0,0,3,3,0,0,0,3,3,0,0,0
0,0,3,0,0,0,0,0,3,0,0,0
0,0,3,0,0,0,0,0,3,0,0,0
0,0,3,0,0,0,0,0,3,0,0,0
0,0,3,3,0,0,0,3,3,0,0,0
0,0,0,3,3,3,3,3,0,0,0,0
0,0,0,0,0,0,0,0,0,0,0,0
0,0,0,0,0,0,0,0,0,0,0,0
0,0,0,0,0,0,0,0,0,0,0,0
endlayer

layer
0,0,0,0,0,0,0,0,0,0,0,0
0,0,0,0,0,0,0,0,0,0,0,0
0,0,0,0,0,0,0,0,0,0,0,0
0,0,0,0,3,3,3,0,0,0,0,0
0,0,0,3,6,6,6,3,0,0,0,0
0,0,0,3,6,6,6,3,0,0,0,0
0,0,0,3,6,6,6,3,0,0,0,0
0,0,0,0,3,3,3,0,0,0,0,0
0,0,0,0,0,0,0,0,0,0,0,0
0,0,0,0,0,0,0,0,0,0,0,0
0,0,0,0,0,0,0,0,0,0,0,0
0,0,0,0,0,0,0,0,0,0,0,0
endlayer
