# Author: d00dv4d3r
# From: Default Template
biomesToSpawnIn=sky
weight=10
embed_into_distance=0


dimensions=14,8,8
allowable_overhang=0
max_leveling=2
leveling_buffer=1
preserve_water=0
preserve_lava=0
preserve_plants=1


rule1=0,100,purpur_block,quark:duskbound_block
rule2=0,100,purpur_block
rule3=0,100,purpur_stairs-0
rule4=0,100,preserveBlock
rule5=0,100,air,wool-4


layer
4,4,1,1,1,1,4,4
4,1,2,2,2,2,1,4
1,2,2,2,2,2,2,1
1,2,2,2,2,2,2,1
1,2,2,2,2,2,2,1
1,2,2,2,2,2,2,1
4,1,2,2,2,2,1,4
4,4,1,1,1,1,4,4
endlayer

layer
0,0,0,0,0,0,0,0
0,0,2,2,2,2,0,0
0,2,2,2,2,2,2,0
0,2,2,2,2,2,2,0
0,2,2,2,2,2,2,0
0,2,2,2,2,2,2,0
0,0,2,2,2,2,0,0
0,0,0,0,0,0,0,0
endlayer

layer
0,0,0,0,0,0,0,0
0,0,0,0,0,0,0,0
0,2,2,2,2,2,2,0
0,2,2,2,2,2,2,0
0,2,2,2,2,2,2,0
0,2,2,2,2,2,2,0
0,0,2,2,2,2,0,0
0,0,0,0,0,0,0,0
endlayer

layer
0,0,0,0,0,0,0,0
0,0,3,3,3,3,0,0
0,0,2,2,2,2,0,0
0,0,2,2,2,2,0,0
0,0,2,2,2,2,0,0
0,0,2,2,2,2,0,0
0,0,0,2,2,0,0,0
0,0,0,0,0,0,0,0
endlayer

layer
0,0,0,0,0,0,0,0
0,0,0,0,0,0,0,0
0,2,2,2,2,2,2,0
0,2,2,2,2,2,2,0
0,2,2,2,2,2,2,0
0,0,2,2,2,2,0,0
0,0,2,2,2,2,0,0
0,0,0,0,0,0,0,0
endlayer

layer
0,0,0,0,0,0,0,0
0,0,0,3,3,0,0,0
0,2,2,2,2,2,2,0
0,2,2,2,2,2,2,0
0,2,2,2,2,2,2,0
0,2,2,2,2,2,2,0
0,0,2,2,2,2,0,0
0,0,0,0,0,0,0,0
endlayer

layer
0,0,0,0,0,0,0,0
0,0,0,0,0,0,0,0
0,2,2,2,2,2,2,0
0,2,2,2,2,2,2,0
0,0,2,2,2,2,0,0
0,2,2,2,2,2,2,0
0,0,2,2,2,2,0,0
0,0,0,0,0,0,0,0
endlayer

layer
0,0,0,0,0,0,0,0
0,0,0,2,2,0,0,0
0,2,2,2,2,2,2,0
0,2,2,2,2,2,2,0
0,0,2,2,2,2,0,0
0,2,2,2,2,2,2,0
0,0,2,2,2,2,0,0
0,0,0,0,0,0,0,0
endlayer

layer
0,0,0,0,0,0,0,0
0,0,0,2,2,0,0,0
0,2,2,2,2,2,2,0
0,2,2,2,2,2,2,0
0,0,2,2,2,2,0,0
0,2,2,2,2,2,2,0
0,0,2,2,2,2,0,0
0,0,0,0,0,0,0,0
endlayer

layer
0,0,0,0,0,0,0,0
0,0,0,2,2,0,0,0
0,2,2,2,2,2,2,0
0,2,2,2,2,2,2,0
0,0,2,2,2,2,0,0
0,2,2,2,2,2,2,0
0,0,2,2,2,2,0,0
0,0,0,0,0,0,0,0
endlayer

layer
0,0,0,0,0,0,0,0
0,0,0,3,3,0,0,0
0,2,5,2,2,5,2,0
0,2,2,2,2,2,2,0
0,0,2,2,2,2,0,0
0,2,2,2,2,2,2,0
0,0,2,2,2,2,0,0
0,0,0,0,0,0,0,0
endlayer

layer
0,0,0,0,0,0,0,0
0,2,2,2,2,2,2,0
0,2,2,2,2,2,2,0
0,2,2,2,2,2,2,0
0,0,2,2,2,2,0,0
0,2,2,2,2,2,2,0
0,0,2,2,2,2,0,0
0,0,0,0,0,0,0,0
endlayer

layer
0,0,0,0,0,0,0,0
0,0,2,2,2,2,0,0
0,2,2,2,2,2,2,0
0,2,2,2,2,2,2,0
0,0,2,2,2,2,0,0
0,2,2,2,2,2,2,0
0,0,2,2,2,2,0,0
0,0,0,0,0,0,0,0
endlayer

layer
0,0,0,0,0,0,0,0
0,0,0,0,0,0,0,0
0,0,2,2,2,2,0,0
0,0,2,2,2,2,0,0
0,0,2,2,2,2,0,0
0,0,2,2,2,2,0,0
0,0,0,2,2,0,0,0
0,0,0,0,0,0,0,0
endlayer
