# Converted from schematic
# THIS TEMPLATE USES DEFAULTS!  Please edit for corrections.
# If you need help, consult template_rules.txt
biomesToSpawnIn=autumn hills,autumn woods,bamboo forest,birch forest,bog,boneyard,boreal forest,brushland,chaparral,cherry blossom grove,coniferous forest,deciduous forest,extreme hills,extreme hills edge,fen,field,forest,forested field,forested hills,forested island,foresthills,fungi forest,garden,grassland,green hills,green swamplands,grove,heathland,highland,hot springs,jade cliffs,jungle,junglehills,lavender fields,lush redwoods,lush swamp,magical forest,majestic meadow,mangrove,maplewoods,marsh,meadow,meadow forest,mesa,mini jungle,mountain, mountain ridge,mountain taiga,mystic grove,orchard,outback,overgrown beach,overgrown greens,pasture,pasture meadow,pine forest,plains,prarie,quagmire,rainforest,redwood forest,sacred springs,savanna,savanna plateau,scrubland,seasonal forest,seasonal spruce forest,shield,spruce woods,steppe,sublime shrubland,swampland,taiga,taigahills,temperate rainforest,thick shrubland,thicket,thinned mystic grove,thinned pasture,thinned timber,timber,tropical rainforest,tropics mountain,tundra,wonderous woods,woodland,woodlands,wyvern biome,wetland
unacceptable_target_blocks=flowing_water,water,flowing_lava,lava,Natura:Cloud,red_mushroom_block,brown_mushroom_block,planks,cobblestone,end_stone,obsidian,purpur_block,iron_bars,purpur_slab,purpur_pillar,netherrack,soul_sand,quartz_ore
weight=1
uniqueMinDistance=2000
embed_into_distance=0
dimensions=42,18,26
allowable_overhang=0
max_cut_in=2
cut_in_buffer=1
max_leveling=2
leveling_buffer=1
preserve_water=1
preserve_lava=0
preserve_plants=0


rule1=0,100,mossy_cobblestone
rule2=0,100,cobblestone
rule3=0,100,obsidian
rule4=0,100,stone_slab-11
rule5=0,100,glass
rule6=0,100,lava


layer
0,0,0,0,0,0,0,0,0,0,0,0,0,0,0,0,0,0,0,0,0,0,0,0,0,0
0,0,0,0,0,0,0,0,0,0,0,1,3,3,1,0,0,0,0,0,0,0,0,0,0,0
0,0,0,0,0,0,0,0,0,0,0,0,0,0,0,0,0,0,0,0,0,0,0,0,0,0
0,0,0,0,0,0,0,0,0,0,0,0,0,0,0,0,0,0,0,0,0,0,0,0,0,0
0,0,0,0,0,0,0,0,0,0,0,0,0,0,0,0,0,0,0,0,0,0,0,0,0,0
0,0,0,1,1,2,0,0,0,0,0,0,0,0,0,0,0,0,0,0,2,1,1,0,0,0
0,0,2,1,1,1,3,3,3,3,3,3,3,3,3,3,3,3,3,3,1,1,1,1,0,0
0,0,2,1,1,1,2,2,2,2,2,2,2,1,1,2,1,2,2,1,2,2,2,1,0,0
0,0,2,1,1,2,1,1,2,1,2,1,1,1,1,1,1,2,2,2,1,1,1,2,0,0
0,0,2,1,1,1,2,2,2,1,1,1,1,1,1,2,1,2,1,1,2,1,1,2,0,0
0,0,1,2,2,2,1,2,2,1,2,1,1,1,2,2,2,2,2,2,1,1,1,2,0,0
0,0,1,1,1,1,3,3,3,3,3,3,3,3,3,3,3,3,3,3,1,1,1,2,0,0
0,0,0,1,1,2,0,0,0,0,0,0,0,0,0,0,0,0,0,0,2,1,1,0,0,0
0,0,0,0,0,0,0,0,0,0,0,0,0,0,0,0,0,0,0,0,0,0,0,0,0,0
0,0,0,0,0,0,0,0,0,0,0,0,0,0,0,0,0,0,0,0,0,0,0,0,0,0
0,0,0,0,0,0,0,0,0,0,0,0,0,0,0,0,0,0,0,0,0,0,0,0,0,0
0,0,0,0,0,0,0,0,0,0,0,1,3,3,1,0,0,0,0,0,0,0,0,0,0,0
0,0,0,0,0,0,0,0,0,0,0,0,0,0,0,0,0,0,0,0,0,0,0,0,0,0
endlayer

layer
0,0,0,0,0,0,0,0,0,0,0,0,0,0,0,0,0,0,0,0,0,0,0,0,0,0
0,0,0,0,0,0,0,0,0,0,0,2,3,3,1,0,0,0,0,0,0,0,0,0,0,0
0,0,0,0,0,0,0,0,0,0,0,0,0,0,0,0,0,0,0,0,0,0,0,0,0,0
0,0,0,0,0,0,0,0,0,0,0,0,0,0,0,0,0,0,0,0,0,0,0,0,0,0
0,0,0,0,0,0,0,0,0,0,0,0,0,0,0,0,0,0,0,0,0,0,0,0,0,0
0,0,0,1,1,1,0,0,0,0,0,0,0,0,0,0,0,0,0,0,2,1,2,0,0,0
0,0,1,1,2,1,3,3,3,3,3,3,3,3,3,3,3,3,3,3,2,1,1,1,0,0
0,0,1,1,1,2,2,1,1,1,1,1,1,1,2,1,1,1,1,1,2,1,1,2,0,0
0,0,2,1,2,1,1,2,2,1,2,1,1,1,1,1,2,2,1,2,1,1,1,2,0,0
0,0,2,1,1,1,2,1,2,2,1,1,1,1,1,2,1,2,2,1,1,2,1,2,0,0
0,0,2,1,1,2,1,1,1,1,1,2,1,1,1,1,1,1,1,2,2,1,1,1,0,0
0,0,1,1,1,2,3,3,3,3,3,3,3,3,3,3,3,3,3,3,1,2,1,1,0,0
0,0,0,2,1,2,0,0,0,0,0,0,0,0,0,0,0,0,0,0,1,1,1,0,0,0
0,0,0,0,0,0,0,0,0,0,0,0,0,0,0,0,0,0,0,0,0,0,0,0,0,0
0,0,0,0,0,0,0,0,0,0,0,0,0,0,0,0,0,0,0,0,0,0,0,0,0,0
0,0,0,0,0,0,0,0,0,0,0,0,0,0,0,0,0,0,0,0,0,0,0,0,0,0
0,0,0,0,0,0,0,0,0,0,0,1,3,3,1,0,0,0,0,0,0,0,0,0,0,0
0,0,0,0,0,0,0,0,0,0,0,0,0,0,0,0,0,0,0,0,0,0,0,0,0,0
endlayer

layer
0,0,0,0,0,0,0,0,0,0,0,0,0,0,0,0,0,0,0,0,0,0,0,0,0,0
0,0,0,0,0,0,0,0,0,0,0,1,3,3,1,0,0,0,0,0,0,0,0,0,0,0
0,0,0,0,0,0,0,0,0,0,0,0,0,0,0,0,0,0,0,0,0,0,0,0,0,0
0,0,0,0,0,0,0,0,0,0,0,0,0,0,0,0,0,0,0,0,0,0,0,0,0,0
0,0,0,0,0,0,0,0,0,0,0,0,0,0,0,0,0,0,0,0,0,0,0,0,0,0
0,0,0,1,1,1,0,0,0,0,0,0,0,0,0,0,0,0,0,0,1,2,1,0,0,0
0,0,1,2,2,1,3,3,3,3,3,3,3,3,3,3,3,3,3,3,1,1,1,2,0,0
0,0,1,1,1,2,2,1,1,1,1,1,1,1,2,2,1,2,2,1,2,1,1,2,0,0
0,0,1,1,1,1,1,1,1,1,2,2,1,2,1,1,1,1,2,1,1,1,1,1,0,0
0,0,1,1,1,1,1,1,1,1,1,1,2,1,2,2,1,1,1,1,1,1,1,2,0,0
0,0,2,1,1,2,1,2,2,1,2,2,1,1,1,1,1,1,1,2,2,1,1,1,0,0
0,0,2,1,1,1,3,3,3,3,3,3,3,3,3,3,3,3,3,3,1,2,2,1,0,0
0,0,0,1,2,1,0,0,0,0,0,0,0,0,0,0,0,0,0,0,1,1,1,0,0,0
0,0,0,0,0,0,0,0,0,0,0,0,0,0,0,0,0,0,0,0,0,0,0,0,0,0
0,0,0,0,0,0,0,0,0,0,0,0,0,0,0,0,0,0,0,0,0,0,0,0,0,0
0,0,0,0,0,0,0,0,0,0,0,0,0,0,0,0,0,0,0,0,0,0,0,0,0,0
0,0,0,0,0,0,0,0,0,0,0,1,3,3,1,0,0,0,0,0,0,0,0,0,0,0
0,0,0,0,0,0,0,0,0,0,0,0,0,0,0,0,0,0,0,0,0,0,0,0,0,0
endlayer

layer
0,0,0,0,0,0,0,0,0,0,0,0,0,0,0,0,0,0,0,0,0,0,0,0,0,0
0,0,0,0,0,0,0,0,0,0,0,1,3,3,2,0,0,0,0,0,0,0,0,0,0,0
0,0,0,0,0,0,0,0,0,0,0,0,0,0,0,0,0,0,0,0,0,0,0,0,0,0
0,0,0,0,0,0,0,0,0,0,0,0,0,0,0,0,0,0,0,0,0,0,0,0,0,0
0,0,0,0,0,0,0,0,0,0,0,0,0,0,0,0,0,0,0,0,0,0,0,0,0,0
0,0,0,1,1,2,0,0,0,0,0,0,0,0,0,0,0,0,0,0,2,1,1,0,0,0
0,0,2,1,1,1,3,3,3,3,3,3,3,3,3,3,3,3,3,3,1,2,2,1,0,0
0,0,2,2,1,2,1,1,1,1,2,1,1,2,2,1,2,2,1,1,2,1,1,1,0,0
0,0,1,1,1,1,1,1,1,2,1,1,1,1,1,2,1,1,1,2,2,2,1,1,0,0
0,0,1,1,1,1,1,1,1,1,2,1,1,1,1,1,2,1,1,1,2,1,1,1,0,0
0,0,1,1,1,2,1,1,2,2,1,2,1,1,1,2,1,1,1,1,2,1,2,2,0,0
0,0,1,2,2,1,3,3,3,3,3,3,3,3,3,3,3,3,3,3,1,1,1,2,0,0
0,0,0,1,1,2,0,0,0,0,0,0,0,0,0,0,0,0,0,0,2,1,1,0,0,0
0,0,0,0,0,0,0,0,0,0,0,0,0,0,0,0,0,0,0,0,0,0,0,0,0,0
0,0,0,0,0,0,0,0,0,0,0,0,0,0,0,0,0,0,0,0,0,0,0,0,0,0
0,0,0,0,0,0,0,0,0,0,0,0,0,0,0,0,0,0,0,0,0,0,0,0,0,0
0,0,0,0,0,0,0,0,0,0,0,1,3,3,1,0,0,0,0,0,0,0,0,0,0,0
0,0,0,0,0,0,0,0,0,0,0,0,0,0,0,0,0,0,0,0,0,0,0,0,0,0
endlayer

layer
0,0,0,0,0,0,0,0,0,0,0,0,0,0,0,0,0,0,0,0,0,0,0,0,0,0
0,0,0,0,0,0,0,0,0,0,0,1,3,3,1,0,0,0,0,0,0,0,0,0,0,0
0,0,0,0,0,0,0,0,0,0,0,0,0,0,0,0,0,0,0,0,0,0,0,0,0,0
0,0,0,0,0,0,0,0,0,0,0,0,0,0,0,0,0,0,0,0,0,0,0,0,0,0
0,0,0,0,0,0,0,0,0,0,0,0,0,0,0,0,0,0,0,0,0,0,0,0,0,0
0,0,0,2,2,1,0,0,0,0,0,0,0,0,0,0,0,0,0,0,1,1,1,0,0,0
0,0,1,2,2,1,3,3,3,3,3,3,3,3,3,3,3,3,3,3,1,1,1,1,0,0
0,0,1,1,1,2,1,1,1,1,1,1,1,1,1,1,1,1,1,1,1,1,2,1,0,0
0,0,1,1,2,2,1,1,1,1,2,1,2,1,2,1,2,1,1,2,1,1,1,1,0,0
0,0,1,1,1,1,2,1,1,2,1,2,1,2,1,2,1,1,1,1,2,2,1,1,0,0
0,0,1,2,1,1,1,1,1,1,1,1,1,1,1,1,1,1,1,1,2,1,1,1,0,0
0,0,1,1,1,1,3,3,3,3,3,3,3,3,3,3,3,3,3,3,1,2,2,1,0,0
0,0,0,1,1,1,0,0,0,0,0,0,0,0,0,0,0,0,0,0,1,2,2,0,0,0
0,0,0,0,0,0,0,0,0,0,0,0,0,0,0,0,0,0,0,0,0,0,0,0,0,0
0,0,0,0,0,0,0,0,0,0,0,0,0,0,0,0,0,0,0,0,0,0,0,0,0,0
0,0,0,0,0,0,0,0,0,0,0,0,0,0,0,0,0,0,0,0,0,0,0,0,0,0
0,0,0,0,0,0,0,0,0,0,0,1,3,3,1,0,0,0,0,0,0,0,0,0,0,0
0,0,0,0,0,0,0,0,0,0,0,0,0,0,0,0,0,0,0,0,0,0,0,0,0,0
endlayer

layer
0,0,0,0,0,0,0,0,0,0,0,0,0,0,0,0,0,0,0,0,0,0,0,0,0,0
0,0,0,0,0,0,0,0,0,0,0,1,3,3,2,0,0,0,0,0,0,0,0,0,0,0
0,0,0,0,0,0,0,0,0,0,0,0,0,0,0,0,0,0,0,0,0,0,0,0,0,0
0,0,0,0,0,0,0,0,0,0,0,0,0,0,0,0,0,0,0,0,0,0,0,0,0,0
0,0,0,0,0,0,0,0,0,0,0,0,0,0,0,0,0,0,0,0,0,0,0,0,0,0
0,0,0,1,1,2,0,0,0,0,0,0,0,0,0,0,0,0,0,0,1,2,2,0,0,0
0,0,2,1,1,2,3,3,3,3,3,3,3,3,3,3,3,3,3,3,1,1,1,1,0,0
0,0,1,1,2,2,1,2,2,1,1,1,1,2,1,1,2,1,2,1,1,1,2,1,0,0
0,0,1,1,2,1,2,2,2,1,1,1,2,1,1,1,1,1,1,1,1,2,1,1,0,0
0,0,1,1,2,1,1,1,1,1,1,1,1,2,1,1,1,2,2,2,1,2,1,1,0,0
0,0,1,2,1,1,1,2,1,2,1,1,1,1,1,1,1,2,2,1,2,2,1,1,0,0
0,0,1,1,1,1,3,3,3,3,3,3,3,3,3,3,3,3,3,3,2,1,1,2,0,0
0,0,0,2,2,1,0,0,0,0,0,0,0,0,0,0,0,0,0,0,2,1,1,0,0,0
0,0,0,0,0,0,0,0,0,0,0,0,0,0,0,0,0,0,0,0,0,0,0,0,0,0
0,0,0,0,0,0,0,0,0,0,0,0,0,0,0,0,0,0,0,0,0,0,0,0,0,0
0,0,0,0,0,0,0,0,0,0,0,0,0,0,0,0,0,0,0,0,0,0,0,0,0,0
0,0,0,0,0,0,0,0,0,0,0,1,3,3,1,0,0,0,0,0,0,0,0,0,0,0
0,0,0,0,0,0,0,0,0,0,0,0,0,0,0,0,0,0,0,0,0,0,0,0,0,0
endlayer

layer
0,0,0,0,0,0,0,0,0,0,0,0,0,0,0,0,0,0,0,0,0,0,0,0,0,0
0,0,0,0,0,0,0,0,0,0,0,1,3,3,1,0,0,0,0,0,0,0,0,0,0,0
0,0,0,0,0,0,0,0,0,0,0,0,0,0,0,0,0,0,0,0,0,0,0,0,0,0
0,0,0,0,0,0,0,0,0,0,0,0,0,0,0,0,0,0,0,0,0,0,0,0,0,0
0,0,0,0,0,0,0,0,0,0,0,0,0,0,0,0,0,0,0,0,0,0,0,0,0,0
0,0,0,1,1,1,0,0,0,0,0,0,0,0,0,0,0,0,0,0,2,1,1,0,0,0
0,0,1,2,2,1,3,3,3,3,3,3,3,3,3,3,3,3,3,3,1,1,2,2,0,0
0,0,1,1,1,1,1,1,2,1,1,2,2,1,1,1,1,1,1,2,1,1,1,1,0,0
0,0,1,1,1,2,1,2,1,1,2,1,1,2,2,2,1,2,1,1,1,1,1,2,0,0
0,0,2,1,1,1,1,1,2,1,2,2,2,1,1,2,1,1,2,1,2,1,1,1,0,0
0,0,1,1,1,1,2,1,1,1,1,1,1,2,2,1,1,2,1,1,1,1,1,1,0,0
0,0,2,2,1,1,3,3,3,3,3,3,3,3,3,3,3,3,3,3,1,2,2,1,0,0
0,0,0,1,1,2,0,0,0,0,0,0,0,0,0,0,0,0,0,0,1,1,1,0,0,0
0,0,0,0,0,0,0,0,0,0,0,0,0,0,0,0,0,0,0,0,0,0,0,0,0,0
0,0,0,0,0,0,0,0,0,0,0,0,0,0,0,0,0,0,0,0,0,0,0,0,0,0
0,0,0,0,0,0,0,0,0,0,0,0,0,0,0,0,0,0,0,0,0,0,0,0,0,0
0,0,0,0,0,0,0,0,0,0,0,1,3,3,1,0,0,0,0,0,0,0,0,0,0,0
0,0,0,0,0,0,0,0,0,0,0,0,0,0,0,0,0,0,0,0,0,0,0,0,0,0
endlayer

layer
0,0,0,0,0,0,0,0,0,0,0,0,0,0,0,0,0,0,0,0,0,0,0,0,0,0
0,0,0,0,0,0,0,0,0,0,0,1,3,3,1,0,0,0,0,0,0,0,0,0,0,0
0,0,0,0,0,0,0,0,0,0,0,0,0,0,0,0,0,0,0,0,0,0,0,0,0,0
0,0,0,0,0,0,0,0,0,0,0,0,0,0,0,0,0,0,0,0,0,0,0,0,0,0
0,0,0,0,0,0,0,0,0,0,0,0,0,0,0,0,0,0,0,0,0,0,0,0,0,0
0,0,0,1,1,1,0,0,0,0,0,0,0,0,0,0,0,0,0,0,2,1,1,0,0,0
0,0,1,2,2,1,3,3,3,3,3,3,3,3,3,3,3,3,3,3,2,1,1,1,0,0
0,0,1,1,1,2,1,2,1,1,2,1,1,2,1,1,1,1,2,1,2,2,1,1,0,0
0,0,1,1,1,1,1,1,1,1,1,2,1,1,2,1,1,1,1,2,2,1,1,1,0,0
0,0,1,1,1,2,2,1,1,1,1,2,1,1,2,1,1,1,1,1,1,1,1,1,0,0
0,0,1,1,2,2,1,2,1,1,1,1,2,1,1,2,1,1,2,1,2,1,1,1,0,0
0,0,1,1,1,2,3,3,3,3,3,3,3,3,3,3,3,3,3,3,1,2,2,1,0,0
0,0,0,1,1,2,0,0,0,0,0,0,0,0,0,0,0,0,0,0,1,1,1,0,0,0
0,0,0,0,0,0,0,0,0,0,0,0,0,0,0,0,0,0,0,0,0,0,0,0,0,0
0,0,0,0,0,0,0,0,0,0,0,0,0,0,0,0,0,0,0,0,0,0,0,0,0,0
0,0,0,0,0,0,0,0,0,0,0,0,0,0,0,0,0,0,0,0,0,0,0,0,0,0
0,0,0,0,0,0,0,0,0,0,0,1,3,3,1,0,0,0,0,0,0,0,0,0,0,0
0,0,0,0,0,0,0,0,0,0,0,0,0,0,0,0,0,0,0,0,0,0,0,0,0,0
endlayer

layer
0,0,0,0,0,0,0,0,0,0,0,0,0,0,0,0,0,0,0,0,0,0,0,0,0,0
0,0,0,0,0,0,0,0,0,0,0,2,3,3,1,0,0,0,0,0,0,0,0,0,0,0
0,0,0,0,0,0,0,0,0,0,0,0,0,0,0,0,0,0,0,0,0,0,0,0,0,0
0,0,0,0,0,0,0,0,0,0,0,0,0,0,0,0,0,0,0,0,0,0,0,0,0,0
0,0,0,0,0,0,0,0,0,0,0,0,0,0,0,0,0,0,0,0,0,0,0,0,0,0
0,0,0,1,1,2,0,0,0,0,0,0,0,0,0,0,0,0,0,0,1,1,1,0,0,0
0,0,1,1,2,1,3,3,3,3,3,3,3,3,3,3,3,3,3,3,1,1,1,2,0,0
0,0,1,2,2,2,1,1,2,1,1,2,1,1,1,1,2,1,2,1,2,1,1,1,0,0
0,0,1,1,1,1,1,2,1,1,1,1,1,2,1,1,1,1,1,2,1,1,1,1,0,0
0,0,1,1,1,1,2,1,1,1,1,1,2,1,1,1,1,1,2,1,1,1,1,1,0,0
0,0,1,1,1,2,1,2,1,2,1,1,1,1,2,1,1,2,1,1,2,2,2,1,0,0
0,0,2,1,1,1,3,3,3,3,3,3,3,3,3,3,3,3,3,3,1,2,1,1,0,0
0,0,0,1,1,1,0,0,0,0,0,0,0,0,0,0,0,0,0,0,2,1,1,0,0,0
0,0,0,0,0,0,0,0,0,0,0,0,0,0,0,0,0,0,0,0,0,0,0,0,0,0
0,0,0,0,0,0,0,0,0,0,0,0,0,0,0,0,0,0,0,0,0,0,0,0,0,0
0,0,0,0,0,0,0,0,0,0,0,0,0,0,0,0,0,0,0,0,0,0,0,0,0,0
0,0,0,0,0,0,0,0,0,0,0,1,3,3,1,0,0,0,0,0,0,0,0,0,0,0
0,0,0,0,0,0,0,0,0,0,0,0,0,0,0,0,0,0,0,0,0,0,0,0,0,0
endlayer

layer
0,0,0,0,0,0,0,0,0,0,0,0,0,0,0,0,0,0,0,0,0,0,0,0,0,0
0,0,0,0,0,0,0,0,0,0,0,2,3,3,2,0,0,0,0,0,0,0,0,0,0,0
0,0,0,0,0,0,0,0,0,0,0,0,0,0,0,0,0,0,0,0,0,0,0,0,0,0
0,0,0,0,0,0,0,0,0,0,0,0,0,0,0,0,0,0,0,0,0,0,0,0,0,0
0,0,0,0,0,0,0,0,0,0,0,0,0,0,0,0,0,0,0,0,0,0,0,0,0,0
0,0,0,1,2,1,0,0,0,0,0,0,0,0,0,0,0,0,0,0,2,2,1,0,0,0
0,0,1,1,1,2,3,3,3,3,3,3,3,3,3,3,3,3,3,3,1,1,1,1,0,0
0,0,1,2,1,1,1,2,1,2,1,2,2,2,1,2,1,1,1,1,2,1,1,1,0,0
0,0,1,1,2,2,1,1,1,1,1,1,2,2,1,1,1,1,1,1,2,2,2,1,0,0
0,0,1,2,2,2,1,1,1,1,1,1,2,2,1,1,1,1,1,1,2,2,1,1,0,0
0,0,1,1,1,2,1,1,1,1,2,1,2,2,2,1,2,1,2,1,1,1,2,1,0,0
0,0,1,1,1,1,3,3,3,3,3,3,3,3,3,3,3,3,3,3,2,1,1,1,0,0
0,0,0,1,2,2,0,0,0,0,0,0,0,0,0,0,0,0,0,0,1,2,1,0,0,0
0,0,0,0,0,0,0,0,0,0,0,0,0,0,0,0,0,0,0,0,0,0,0,0,0,0
0,0,0,0,0,0,0,0,0,0,0,0,0,0,0,0,0,0,0,0,0,0,0,0,0,0
0,0,0,0,0,0,0,0,0,0,0,0,0,0,0,0,0,0,0,0,0,0,0,0,0,0
0,0,0,0,0,0,0,0,0,0,0,2,3,3,2,0,0,0,0,0,0,0,0,0,0,0
0,0,0,0,0,0,0,0,0,0,0,0,0,0,0,0,0,0,0,0,0,0,0,0,0,0
endlayer

layer
0,0,0,0,0,0,0,0,0,0,0,0,0,0,0,0,0,0,0,0,0,0,0,0,0,0
0,0,0,0,0,0,0,0,0,0,0,1,3,3,1,0,0,0,0,0,0,0,0,0,0,0
0,0,0,0,0,0,0,0,0,0,0,0,0,0,0,0,0,0,0,0,0,0,0,0,0,0
0,0,0,0,0,0,0,0,0,0,0,0,0,0,0,0,0,0,0,0,0,0,0,0,0,0
0,0,0,0,0,0,0,0,0,0,0,0,0,0,0,0,0,0,0,0,0,0,0,0,0,0
0,0,0,1,2,1,0,0,0,0,0,0,1,1,0,0,0,0,0,0,1,1,1,0,0,0
0,0,2,1,2,1,3,3,3,3,3,3,2,1,3,3,3,3,3,3,1,1,1,1,0,0
0,0,1,2,1,1,2,1,1,1,2,1,1,1,1,1,1,2,1,2,1,1,2,2,0,0
0,0,1,1,1,2,2,1,1,1,1,1,2,1,1,2,1,2,2,1,2,2,1,2,0,0
0,0,2,1,2,2,1,2,2,1,2,1,1,2,1,1,1,1,1,2,2,1,1,1,0,0
0,0,2,2,1,1,2,1,2,1,1,1,1,1,1,2,1,1,1,2,1,1,2,1,0,0
0,0,1,1,1,1,3,3,3,3,3,3,1,2,3,3,3,3,3,3,1,2,1,2,0,0
0,0,0,1,1,1,0,0,0,0,0,0,1,1,0,0,0,0,0,0,1,2,1,0,0,0
0,0,0,0,0,0,0,0,0,0,0,0,0,0,0,0,0,0,0,0,0,0,0,0,0,0
0,0,0,0,0,0,0,0,0,0,0,0,0,0,0,0,0,0,0,0,0,0,0,0,0,0
0,0,0,0,0,0,0,0,0,0,0,0,0,0,0,0,0,0,0,0,0,0,0,0,0,0
0,0,0,0,0,0,0,0,0,0,0,1,3,3,1,0,0,0,0,0,0,0,0,0,0,0
0,0,0,0,0,0,0,0,0,0,0,0,0,0,0,0,0,0,0,0,0,0,0,0,0,0
endlayer

layer
0,0,0,0,0,0,0,0,0,0,0,0,0,0,0,0,0,0,0,0,0,0,0,0,0,0
0,0,0,0,0,0,0,0,0,0,0,2,3,3,1,0,0,0,0,0,0,0,0,0,0,0
0,0,0,0,0,0,0,0,0,0,0,0,0,0,0,0,0,0,0,0,0,0,0,0,0,0
0,0,0,0,0,0,0,0,0,0,0,0,0,0,0,0,0,0,0,0,0,0,0,0,0,0
0,0,0,0,0,0,0,0,0,0,0,0,0,0,0,0,0,0,0,0,0,0,0,0,0,0
0,0,0,1,2,2,0,1,1,2,1,1,2,1,2,2,2,1,1,0,1,1,2,0,0,0
0,0,1,1,1,1,3,2,1,1,2,1,1,2,1,1,1,1,1,3,2,1,1,2,0,0
0,0,1,1,1,2,1,1,1,1,1,2,1,1,1,1,1,1,2,1,2,2,1,1,0,0
0,0,2,2,2,1,1,1,1,2,2,2,1,1,1,1,2,1,2,1,1,2,1,2,0,0
0,0,2,1,2,1,1,2,1,2,1,1,1,1,2,2,2,1,1,1,1,2,2,2,0,0
0,0,1,1,2,2,1,2,1,1,1,1,1,1,2,1,1,1,1,1,2,1,1,1,0,0
0,0,2,1,1,2,3,1,1,1,1,1,2,1,1,2,1,1,2,3,1,1,1,1,0,0
0,0,0,2,1,1,0,1,1,2,2,2,1,2,1,1,2,1,1,0,2,2,1,0,0,0
0,0,0,0,0,0,0,0,0,0,0,0,0,0,0,0,0,0,0,0,0,0,0,0,0,0
0,0,0,0,0,0,0,0,0,0,0,0,0,0,0,0,0,0,0,0,0,0,0,0,0,0
0,0,0,0,0,0,0,0,0,0,0,0,0,0,0,0,0,0,0,0,0,0,0,0,0,0
0,0,0,0,0,0,0,0,0,0,0,1,3,3,2,0,0,0,0,0,0,0,0,0,0,0
0,0,0,0,0,0,0,0,0,0,0,0,0,0,0,0,0,0,0,0,0,0,0,0,0,0
endlayer

layer
0,0,0,0,0,0,0,0,0,0,0,0,0,0,0,0,0,0,0,0,0,0,0,0,0,0
0,0,0,0,0,0,0,0,0,0,0,2,3,3,1,0,0,0,0,0,0,0,0,0,0,0
0,0,0,0,0,0,0,0,0,0,0,0,0,0,0,0,0,0,0,0,0,0,0,0,0,0
0,0,0,0,0,0,0,0,0,0,0,0,0,0,0,0,0,0,0,0,0,0,0,0,0,0
0,0,0,0,0,0,0,0,0,0,0,0,0,0,0,0,0,0,0,0,0,0,0,0,0,0
0,0,0,1,2,0,0,0,0,0,0,0,2,1,0,0,0,0,0,0,0,2,1,0,0,0
0,0,1,1,1,0,0,3,3,3,3,3,2,1,3,3,3,3,3,0,0,1,2,2,0,0
0,0,1,1,1,3,3,1,2,1,1,1,1,1,2,1,1,1,2,3,3,1,1,2,0,0
0,0,1,2,1,2,1,2,1,1,1,1,2,1,1,1,1,2,2,1,2,1,1,1,0,0
0,0,1,1,1,2,1,2,2,1,1,1,1,2,1,1,1,1,2,1,2,1,2,1,0,0
0,0,2,1,1,3,3,2,1,1,1,2,1,1,1,1,1,2,1,3,3,1,1,1,0,0
0,0,2,2,1,0,0,3,3,3,3,3,1,2,3,3,3,3,3,0,0,1,1,1,0,0
0,0,0,1,2,0,0,0,0,0,0,0,1,2,0,0,0,0,0,0,0,2,1,0,0,0
0,0,0,0,0,0,0,0,0,0,0,0,0,0,0,0,0,0,0,0,0,0,0,0,0,0
0,0,0,0,0,0,0,0,0,0,0,0,0,0,0,0,0,0,0,0,0,0,0,0,0,0
0,0,0,0,0,0,0,0,0,0,0,0,0,0,0,0,0,0,0,0,0,0,0,0,0,0
0,0,0,0,0,0,0,0,0,0,0,1,3,3,2,0,0,0,0,0,0,0,0,0,0,0
0,0,0,0,0,0,0,0,0,0,0,0,0,0,0,0,0,0,0,0,0,0,0,0,0,0
endlayer

layer
0,0,0,0,0,0,0,0,0,0,0,0,0,0,0,0,0,0,0,0,0,0,0,0,0,0
0,0,0,0,0,0,0,0,0,0,0,1,3,3,2,0,0,0,0,0,0,0,0,0,0,0
0,0,0,0,0,0,0,0,0,0,0,0,0,0,0,0,0,0,0,0,0,0,0,0,0,0
0,0,0,0,0,0,0,0,0,0,0,0,0,0,0,0,0,0,0,0,0,0,0,0,0,0
0,0,0,0,0,0,0,0,0,0,0,0,0,0,0,0,0,0,0,0,0,0,0,0,0,0
0,0,0,1,1,0,0,0,0,0,0,0,0,0,0,0,0,0,0,0,0,2,2,0,0,0
0,0,1,2,1,0,0,3,3,3,3,3,3,3,3,3,3,3,3,0,0,1,1,1,0,0
0,0,1,2,1,3,3,1,2,1,1,1,2,1,1,1,2,1,1,3,3,2,1,1,0,0
0,0,1,1,1,2,2,1,1,1,1,1,2,2,2,1,1,1,1,1,1,1,1,2,0,0
0,0,2,1,1,1,1,1,1,1,1,2,2,2,1,1,1,1,1,2,2,1,1,1,0,0
0,0,1,1,2,3,3,1,1,2,1,1,1,2,1,1,1,2,1,3,3,1,2,1,0,0
0,0,1,1,1,0,0,3,3,3,3,3,3,3,3,3,3,3,3,0,0,1,2,1,0,0
0,0,0,2,2,0,0,0,0,0,0,0,0,0,0,0,0,0,0,0,0,1,1,0,0,0
0,0,0,0,0,0,0,0,0,0,0,0,0,0,0,0,0,0,0,0,0,0,0,0,0,0
0,0,0,0,0,0,0,0,0,0,0,0,0,0,0,0,0,0,0,0,0,0,0,0,0,0
0,0,0,0,0,0,0,0,0,0,0,0,0,0,0,0,0,0,0,0,0,0,0,0,0,0
0,0,0,0,0,0,0,0,0,0,0,1,3,3,1,0,0,0,0,0,0,0,0,0,0,0
0,0,0,0,0,0,0,0,0,0,0,0,0,0,0,0,0,0,0,0,0,0,0,0,0,0
endlayer

layer
0,0,0,0,0,0,0,0,0,0,0,0,0,0,0,0,0,0,0,0,0,0,0,0,0,0
0,0,0,0,0,0,0,0,0,1,0,0,3,3,0,0,1,0,0,0,0,0,0,0,0,0
0,0,0,0,0,0,0,0,0,0,0,0,0,0,0,0,0,0,0,0,0,0,0,0,0,0
0,0,0,0,0,0,0,0,0,0,0,0,0,0,0,0,0,0,0,0,0,0,0,0,0,0
0,0,0,0,0,0,0,0,0,0,0,0,0,0,0,0,0,0,0,0,0,0,0,0,0,0
0,0,0,1,1,0,0,0,0,0,0,0,0,0,0,0,0,0,0,0,0,1,1,0,0,0
0,0,1,1,2,0,3,3,3,3,3,3,3,3,3,3,3,3,3,3,0,1,1,1,0,0
0,0,2,1,1,3,1,2,1,1,2,1,1,1,1,1,1,1,1,2,3,1,1,1,0,0
0,0,1,2,1,2,1,1,1,1,1,1,2,1,2,1,1,1,1,2,1,2,2,2,0,0
0,0,2,2,2,1,2,1,1,1,1,2,1,2,1,1,1,1,1,1,2,1,2,1,0,0
0,0,1,1,1,3,2,1,1,1,1,1,1,1,1,2,1,1,2,1,3,1,1,2,0,0
0,0,1,1,1,0,3,3,3,3,3,3,3,3,3,3,3,3,3,3,0,2,1,1,0,0
0,0,0,1,1,0,0,0,0,0,0,0,0,0,0,0,0,0,0,0,0,1,1,0,0,0
0,0,0,0,0,0,0,0,0,0,0,0,0,0,0,0,0,0,0,0,0,0,0,0,0,0
0,0,0,0,0,0,0,0,0,0,0,0,0,0,0,0,0,0,0,0,0,0,0,0,0,0
0,0,0,0,0,0,0,0,0,0,0,0,0,0,0,0,0,0,0,0,0,0,0,0,0,0
0,0,0,0,0,0,0,0,0,1,0,0,3,3,0,0,1,0,0,0,0,0,0,0,0,0
0,0,0,0,0,0,0,0,0,0,0,0,0,0,0,0,0,0,0,0,0,0,0,0,0,0
endlayer

layer
0,0,0,0,0,0,0,0,0,0,0,0,2,2,0,0,0,0,0,0,0,0,0,0,0,0
0,0,0,0,0,0,0,0,0,2,1,3,1,2,3,1,2,0,0,0,0,0,0,0,0,0
0,0,0,0,0,0,0,0,0,0,0,0,1,1,0,0,0,0,0,0,0,0,0,0,0,0
0,0,0,0,0,0,0,0,0,0,0,0,0,0,0,0,0,0,0,0,0,0,0,0,0,0
0,0,0,0,0,0,0,0,0,0,0,0,0,0,0,0,0,0,0,0,0,0,0,0,0,0
0,0,0,1,1,0,2,2,0,0,0,0,0,0,0,0,0,0,1,1,0,1,1,0,0,0
0,0,1,2,1,3,1,1,3,3,3,3,3,3,3,3,3,3,2,1,3,1,1,1,0,0
0,0,2,1,1,2,2,1,1,1,2,1,1,2,1,1,1,2,1,1,1,1,2,1,0,0
0,0,1,2,1,1,1,1,1,1,1,2,1,2,2,1,1,1,1,1,1,2,2,1,0,0
0,0,1,2,2,1,1,1,1,1,1,2,2,1,2,1,1,1,1,1,1,1,2,1,0,0
0,0,1,2,1,1,1,1,2,1,1,1,2,1,1,2,1,1,1,2,2,1,1,2,0,0
0,0,1,1,1,3,1,2,3,3,3,3,3,3,3,3,3,3,1,1,3,1,2,1,0,0
0,0,0,1,1,0,1,1,0,0,0,0,0,0,0,0,0,0,2,2,0,1,1,0,0,0
0,0,0,0,0,0,0,0,0,0,0,0,0,0,0,0,0,0,0,0,0,0,0,0,0,0
0,0,0,0,0,0,0,0,0,0,0,0,0,0,0,0,0,0,0,0,0,0,0,0,0,0
0,0,0,0,0,0,0,0,0,0,0,0,1,1,0,0,0,0,0,0,0,0,0,0,0,0
0,0,0,0,0,0,0,0,0,2,1,3,2,1,3,1,2,0,0,0,0,0,0,0,0,0
0,0,0,0,0,0,0,0,0,0,0,0,2,2,0,0,0,0,0,0,0,0,0,0,0,0
endlayer

layer
0,0,0,0,0,0,0,0,0,0,0,1,1,2,1,0,0,0,0,0,0,0,0,0,0,0
0,0,0,0,0,0,0,0,0,2,1,2,1,1,1,1,1,0,0,0,0,0,0,0,0,0
0,0,0,0,0,0,0,0,0,0,0,2,1,1,2,0,0,0,0,0,0,0,0,0,0,0
0,0,0,0,0,0,0,0,0,0,0,0,0,0,0,0,0,0,0,0,0,0,0,0,0,0
0,0,0,0,0,0,0,2,1,0,0,0,0,0,0,0,0,2,2,0,0,0,0,0,0,0
0,0,0,2,1,0,1,1,1,1,0,0,0,0,0,0,1,1,1,1,0,1,1,0,0,0
0,0,2,1,1,3,2,1,1,1,3,3,3,3,3,3,2,2,1,1,3,1,2,2,0,0
0,0,1,2,1,1,1,1,2,1,2,1,1,1,2,2,1,1,1,1,2,2,1,1,0,0
0,0,1,1,2,1,1,2,1,1,1,1,1,1,1,1,2,2,2,2,1,2,2,2,0,0
0,0,2,2,2,1,2,2,2,2,1,1,1,1,1,1,1,1,2,1,1,2,1,1,0,0
0,0,1,1,2,2,1,1,1,1,2,2,1,1,1,2,1,2,1,1,1,1,2,1,0,0
0,0,2,2,1,3,1,1,2,2,3,3,3,3,3,3,1,1,1,2,3,1,1,2,0,0
0,0,0,1,1,0,1,1,1,1,0,0,0,0,0,0,1,1,1,1,0,1,2,0,0,0
0,0,0,0,0,0,0,2,2,0,0,0,0,0,0,0,0,1,2,0,0,0,0,0,0,0
0,0,0,0,0,0,0,0,0,0,0,0,0,0,0,0,0,0,0,0,0,0,0,0,0,0
0,0,0,0,0,0,0,0,0,0,0,2,1,1,2,0,0,0,0,0,0,0,0,0,0,0
0,0,0,0,0,0,0,0,0,1,1,1,1,1,2,1,2,0,0,0,0,0,0,0,0,0
0,0,0,0,0,0,0,0,0,0,0,1,2,1,1,0,0,0,0,0,0,0,0,0,0,0
endlayer

layer
0,0,0,0,0,0,0,0,0,0,0,0,1,2,0,0,0,0,0,0,0,0,0,0,0,0
0,0,0,0,0,0,0,0,0,0,1,3,2,1,3,2,0,0,0,0,0,0,0,0,0,0
0,0,0,0,0,0,0,0,0,0,0,0,2,2,0,0,0,0,0,0,0,0,0,0,0,0
0,0,0,0,0,0,0,0,1,2,0,0,0,0,0,0,1,1,0,0,0,0,0,0,0,0
0,0,0,0,0,0,2,1,1,1,0,0,0,0,0,0,1,1,1,2,0,0,0,0,0,0
0,0,0,2,1,0,1,1,2,1,1,0,0,0,0,2,1,1,1,1,0,1,2,0,0,0
0,0,2,2,1,3,1,1,2,2,2,3,3,3,3,2,1,1,2,1,3,1,1,1,0,0
0,0,2,1,1,1,2,1,2,1,1,1,1,1,2,1,1,2,1,2,1,1,1,1,0,0
0,0,1,1,1,1,1,1,1,1,1,2,1,1,1,2,1,2,1,2,2,1,2,1,0,0
0,0,1,2,1,2,2,1,2,1,2,1,1,1,2,1,1,1,1,1,1,1,1,1,0,0
0,0,1,1,1,1,2,1,2,1,1,2,1,1,1,1,1,2,1,2,1,1,1,2,0,0
0,0,1,1,1,3,1,2,1,1,2,3,3,3,3,2,2,2,1,1,3,1,2,2,0,0
0,0,0,2,1,0,1,1,1,1,2,0,0,0,0,1,1,2,1,1,0,1,2,0,0,0
0,0,0,0,0,0,2,1,1,1,0,0,0,0,0,0,1,1,1,2,0,0,0,0,0,0
0,0,0,0,0,0,0,0,1,1,0,0,0,0,0,0,2,1,0,0,0,0,0,0,0,0
0,0,0,0,0,0,0,0,0,0,0,0,2,2,0,0,0,0,0,0,0,0,0,0,0,0
0,0,0,0,0,0,0,0,0,0,2,3,1,2,3,1,0,0,0,0,0,0,0,0,0,0
0,0,0,0,0,0,0,0,0,0,0,0,2,1,0,0,0,0,0,0,0,0,0,0,0,0
endlayer

layer
0,0,0,0,0,0,0,0,0,0,0,0,1,1,0,0,0,0,0,0,0,0,0,0,0,0
0,0,0,0,0,0,0,0,0,0,0,3,1,1,3,0,0,0,0,0,0,0,0,0,0,0
0,0,0,0,0,0,0,0,0,1,1,2,1,1,1,1,1,0,0,0,0,0,0,0,0,0
0,0,0,0,0,0,0,1,1,1,1,0,0,0,0,1,2,1,1,0,0,0,0,0,0,0
0,0,0,0,0,0,2,1,0,1,1,0,0,0,0,1,1,0,1,1,0,0,0,0,0,0
0,0,0,1,1,0,1,2,1,1,1,1,0,0,1,2,2,1,1,1,0,1,2,0,0,0
0,0,1,1,2,3,1,1,2,2,1,1,3,3,2,1,2,1,1,1,3,1,1,2,0,0
0,0,2,1,1,2,2,1,1,2,1,1,1,1,1,1,1,2,1,2,1,2,1,2,0,0
0,0,1,1,2,1,1,1,1,1,1,2,2,2,2,1,1,2,2,2,2,1,1,2,0,0
0,0,2,1,1,2,2,2,2,1,1,2,2,2,2,1,1,1,1,1,1,2,1,1,0,0
0,0,2,1,2,1,2,1,2,1,1,1,1,1,1,1,2,1,1,2,2,1,1,2,0,0
0,0,2,1,1,3,1,1,1,2,1,2,3,3,1,1,2,2,1,1,3,2,1,1,0,0
0,0,0,2,1,0,1,1,1,2,2,1,0,0,1,1,1,1,2,1,0,1,1,0,0,0
0,0,0,0,0,0,1,1,0,1,1,0,0,0,0,1,1,0,1,2,0,0,0,0,0,0
0,0,0,0,0,0,0,1,1,2,1,0,0,0,0,1,1,1,1,0,0,0,0,0,0,0
0,0,0,0,0,0,0,0,0,1,1,1,1,1,2,1,1,0,0,0,0,0,0,0,0,0
0,0,0,0,0,0,0,0,0,0,0,3,1,1,3,0,0,0,0,0,0,0,0,0,0,0
0,0,0,0,0,0,0,0,0,0,0,0,1,1,0,0,0,0,0,0,0,0,0,0,0,0
endlayer

layer
0,0,0,0,0,0,0,0,0,0,0,1,2,1,1,0,0,0,0,0,0,0,0,0,0,0
0,0,0,0,0,0,0,0,0,0,1,1,2,2,2,1,0,0,0,0,0,0,0,0,0,0
0,0,0,0,0,0,0,0,1,1,1,2,1,1,1,1,1,1,0,0,0,0,0,0,0,0
0,0,0,0,0,0,0,2,1,1,1,1,0,0,1,2,1,2,2,0,0,0,0,0,0,0
0,0,0,0,0,0,0,2,1,1,1,0,0,0,0,2,1,1,2,0,0,0,0,0,0,0
0,0,0,1,1,2,0,1,2,1,1,0,0,0,0,1,1,1,2,0,1,1,2,0,0,0
0,0,1,1,1,1,3,1,2,1,1,3,3,3,3,1,1,2,1,3,1,2,2,2,0,0
0,0,1,1,2,1,1,2,1,1,1,2,1,1,2,1,1,1,1,2,1,1,1,2,0,0
0,0,1,1,2,2,1,2,2,1,1,2,1,1,1,2,1,2,1,1,1,2,2,2,0,0
0,0,2,2,2,1,1,1,2,1,2,1,1,1,2,1,1,2,2,1,2,2,1,1,0,0
0,0,2,1,1,1,2,1,1,1,1,2,1,1,2,1,1,1,2,1,1,2,1,1,0,0
0,0,2,2,2,1,3,1,2,1,1,3,3,3,3,1,1,2,1,3,1,1,1,1,0,0
0,0,0,2,1,1,0,2,1,1,1,0,0,0,0,1,1,2,1,0,2,1,1,0,0,0
0,0,0,0,0,0,0,2,1,1,2,0,0,0,0,1,1,1,2,0,0,0,0,0,0,0
0,0,0,0,0,0,0,2,2,1,2,1,0,0,1,1,1,1,2,0,0,0,0,0,0,0
0,0,0,0,0,0,0,0,1,1,1,1,1,1,2,1,1,1,0,0,0,0,0,0,0,0
0,0,0,0,0,0,0,0,0,0,1,2,2,2,1,1,0,0,0,0,0,0,0,0,0,0
0,0,0,0,0,0,0,0,0,0,0,1,1,2,1,0,0,0,0,0,0,0,0,0,0,0
endlayer

layer
0,0,0,0,0,0,0,0,0,0,0,1,1,1,1,0,0,0,0,0,0,0,0,0,0,0
0,0,0,0,0,0,0,0,0,0,1,1,1,1,1,2,0,0,0,0,0,0,0,0,0,0
0,0,0,0,0,0,0,0,2,2,1,1,1,1,1,1,2,2,0,0,0,0,0,0,0,0
0,0,0,0,0,0,0,0,1,2,1,1,1,2,1,1,2,1,0,0,0,0,0,0,0,0
0,0,0,0,0,0,0,0,0,1,2,1,0,0,2,1,1,0,0,0,0,0,0,0,0,0
0,0,0,2,1,1,1,0,0,0,0,0,0,0,0,0,0,0,0,1,1,1,2,0,0,0
0,0,1,1,1,2,1,3,3,3,3,3,3,3,3,3,3,3,3,2,1,1,2,1,0,0
0,0,2,1,1,1,2,2,2,1,1,1,1,1,1,1,1,1,1,1,2,1,1,2,0,0
0,0,1,2,1,1,1,1,1,1,1,1,1,1,1,1,1,1,1,1,1,1,1,1,0,0
0,0,1,1,1,1,1,1,1,1,1,1,1,1,1,1,1,1,1,1,1,1,2,1,0,0
0,0,2,1,1,2,1,1,1,1,1,1,1,1,1,1,1,2,2,2,1,1,1,2,0,0
0,0,1,2,1,1,2,3,3,3,3,3,3,3,3,3,3,3,3,1,2,1,1,1,0,0
0,0,0,2,1,1,1,0,0,0,0,0,0,0,0,0,0,0,0,1,1,1,2,0,0,0
0,0,0,0,0,0,0,0,0,1,1,2,0,0,1,2,1,0,0,0,0,0,0,0,0,0
0,0,0,0,0,0,0,0,1,2,1,1,2,1,1,1,2,1,0,0,0,0,0,0,0,0
0,0,0,0,0,0,0,0,2,2,1,1,1,1,1,1,2,2,0,0,0,0,0,0,0,0
0,0,0,0,0,0,0,0,0,0,2,1,1,1,1,1,0,0,0,0,0,0,0,0,0,0
0,0,0,0,0,0,0,0,0,0,0,1,1,1,1,0,0,0,0,0,0,0,0,0,0,0
endlayer

layer
0,0,0,0,0,0,0,0,0,0,0,1,1,1,1,0,0,0,0,0,0,0,0,0,0,0
0,0,0,0,0,0,0,0,0,0,1,2,1,1,1,1,0,0,0,0,0,0,0,0,0,0
0,0,0,0,0,0,0,0,0,2,1,1,2,1,1,2,1,0,0,0,0,0,0,0,0,0
0,0,0,0,0,0,0,0,0,0,1,1,1,1,1,1,0,0,0,0,0,0,0,0,0,0
0,0,0,0,0,0,0,0,0,0,0,2,0,0,2,0,0,0,0,0,0,0,0,0,0,0
0,0,0,1,1,1,1,1,0,0,0,0,0,0,0,0,0,0,1,1,2,1,2,0,0,0
0,0,1,1,1,2,1,1,3,3,3,3,3,3,3,3,3,3,2,2,1,2,2,1,0,0
0,0,2,2,1,2,1,2,1,1,2,1,1,1,2,2,1,1,2,1,1,2,1,1,0,0
0,0,1,2,1,2,1,1,1,1,1,1,1,2,1,1,1,1,1,1,1,1,1,1,0,0
0,0,1,1,1,1,1,1,1,1,1,1,2,1,1,1,1,1,1,1,2,1,2,1,0,0
0,0,1,1,2,1,1,2,1,1,2,2,1,1,1,2,1,1,2,1,2,1,2,2,0,0
0,0,1,2,2,1,2,2,3,3,3,3,3,3,3,3,3,3,1,1,2,1,1,1,0,0
0,0,0,2,1,2,1,1,0,0,0,0,0,0,0,0,0,0,1,1,1,1,1,0,0,0
0,0,0,0,0,0,0,0,0,0,0,2,0,0,2,0,0,0,0,0,0,0,0,0,0,0
0,0,0,0,0,0,0,0,0,0,1,1,1,1,1,1,0,0,0,0,0,0,0,0,0,0
0,0,0,0,0,0,0,0,0,1,2,1,1,2,1,1,2,0,0,0,0,0,0,0,0,0
0,0,0,0,0,0,0,0,0,0,1,1,1,1,2,1,0,0,0,0,0,0,0,0,0,0
0,0,0,0,0,0,0,0,0,0,0,1,1,1,1,0,0,0,0,0,0,0,0,0,0,0
endlayer

layer
0,0,0,0,0,0,0,0,0,0,0,0,2,1,0,0,0,0,0,0,0,0,0,0,0,0
0,0,0,0,0,0,0,0,0,0,0,1,1,1,2,0,0,0,0,0,0,0,0,0,0,0
0,0,0,0,0,0,0,0,0,0,0,1,1,1,1,0,0,0,0,0,0,0,0,0,0,0
0,0,0,0,0,0,0,0,0,0,0,2,2,1,2,0,0,0,0,0,0,0,0,0,0,0
0,0,0,0,0,0,0,0,0,0,0,0,0,0,0,0,0,0,0,0,0,0,0,0,0,0
0,0,0,2,1,1,3,1,2,0,0,0,0,0,0,0,0,1,1,3,1,1,2,0,0,0
0,0,1,2,1,1,1,2,1,3,3,3,3,3,3,3,3,1,1,1,1,2,1,1,0,0
0,0,1,1,2,2,1,2,2,1,1,1,1,1,1,1,1,1,1,1,2,1,1,1,0,0
0,0,2,1,2,1,1,1,1,1,1,1,1,1,1,1,1,1,1,1,2,1,2,1,0,0
0,0,1,2,1,2,1,1,1,1,1,1,1,1,1,1,1,1,1,1,1,2,1,2,0,0
0,0,1,1,1,2,1,1,1,1,1,1,1,1,1,1,1,2,2,1,2,2,1,1,0,0
0,0,1,1,2,1,1,1,1,3,3,3,3,3,3,3,3,1,2,1,1,1,2,1,0,0
0,0,0,2,1,1,3,1,1,0,0,0,0,0,0,0,0,2,1,3,1,1,2,0,0,0
0,0,0,0,0,0,0,0,0,0,0,0,0,0,0,0,0,0,0,0,0,0,0,0,0,0
0,0,0,0,0,0,0,0,0,0,0,2,1,2,2,0,0,0,0,0,0,0,0,0,0,0
0,0,0,0,0,0,0,0,0,0,0,1,1,1,1,0,0,0,0,0,0,0,0,0,0,0
0,0,0,0,0,0,0,0,0,0,0,2,1,1,1,0,0,0,0,0,0,0,0,0,0,0
0,0,0,0,0,0,0,0,0,0,0,0,1,2,0,0,0,0,0,0,0,0,0,0,0,0
endlayer

layer
0,0,0,0,0,0,0,0,0,0,0,0,0,0,0,0,0,0,0,0,0,0,0,0,0,0
0,0,0,0,0,0,0,0,0,0,0,0,1,2,0,0,0,0,0,0,0,0,0,0,0,0
0,0,0,0,0,0,0,0,0,0,0,0,0,0,0,0,0,0,0,0,0,0,0,0,0,0
0,0,0,0,0,0,0,0,0,0,0,0,0,0,0,0,0,0,0,0,0,0,0,0,0,0
0,0,0,0,0,0,0,0,0,0,0,0,0,0,0,0,0,0,0,0,0,0,0,0,0,0
0,0,0,1,1,2,3,3,1,2,0,0,0,0,0,0,1,2,3,3,2,1,1,0,0,0
0,0,1,1,1,1,1,1,1,1,3,3,3,3,3,3,1,2,1,1,1,2,2,1,0,0
0,0,1,2,1,1,1,1,1,2,1,1,2,1,2,1,1,2,1,1,1,1,1,1,0,0
0,0,2,2,1,1,1,2,1,2,1,1,1,2,1,1,1,1,1,1,2,2,1,1,0,0
0,0,1,1,2,2,1,1,1,1,1,1,2,1,1,1,2,1,2,1,1,1,2,2,0,0
0,0,1,1,1,1,1,1,2,1,1,2,1,2,1,1,2,1,1,1,1,1,2,1,0,0
0,0,1,2,2,1,1,1,2,1,3,3,3,3,3,3,1,1,1,1,1,1,1,1,0,0
0,0,0,1,1,2,3,3,2,1,0,0,0,0,0,0,2,1,3,3,2,1,1,0,0,0
0,0,0,0,0,0,0,0,0,0,0,0,0,0,0,0,0,0,0,0,0,0,0,0,0,0
0,0,0,0,0,0,0,0,0,0,0,0,0,0,0,0,0,0,0,0,0,0,0,0,0,0
0,0,0,0,0,0,0,0,0,0,0,0,0,0,0,0,0,0,0,0,0,0,0,0,0,0
0,0,0,0,0,0,0,0,0,0,0,0,2,1,0,0,0,0,0,0,0,0,0,0,0,0
0,0,0,0,0,0,0,0,0,0,0,0,0,0,0,0,0,0,0,0,0,0,0,0,0,0
endlayer

layer
0,0,0,0,0,0,0,0,0,0,0,0,0,0,0,0,0,0,0,0,0,0,0,0,0,0
0,0,0,0,0,0,0,0,0,0,0,0,1,1,0,0,0,0,0,0,0,0,0,0,0,0
0,0,0,0,0,0,0,0,0,0,0,0,0,0,0,0,0,0,0,0,0,0,0,0,0,0
0,0,0,0,0,0,0,0,0,0,0,0,0,0,0,0,0,0,0,0,0,0,0,0,0,0
0,0,0,0,0,0,0,0,0,0,0,0,0,0,0,0,0,0,0,0,0,0,0,0,0,0
0,0,0,1,1,2,3,3,2,1,1,0,0,0,0,1,1,2,3,3,1,2,1,0,0,0
0,0,1,1,1,1,2,1,1,1,1,3,3,3,3,2,1,1,1,2,1,1,1,2,0,0
0,0,1,1,1,1,1,1,1,2,2,1,1,2,1,2,1,1,2,2,2,1,2,1,0,0
0,0,1,1,2,1,1,1,2,1,1,2,1,1,1,2,2,1,2,2,2,2,1,2,0,0
0,0,2,1,2,2,2,2,1,2,2,1,1,1,2,1,1,2,1,1,1,2,1,1,0,0
0,0,1,2,1,2,2,2,1,1,2,1,2,1,1,2,2,1,1,1,1,1,1,1,0,0
0,0,2,1,1,1,2,1,1,1,2,3,3,3,3,1,1,1,1,2,1,1,1,1,0,0
0,0,0,1,2,1,3,3,2,1,1,0,0,0,0,1,1,2,3,3,2,1,1,0,0,0
0,0,0,0,0,0,0,0,0,0,0,0,0,0,0,0,0,0,0,0,0,0,0,0,0,0
0,0,0,0,0,0,0,0,0,0,0,0,0,0,0,0,0,0,0,0,0,0,0,0,0,0
0,0,0,0,0,0,0,0,0,0,0,0,0,0,0,0,0,0,0,0,0,0,0,0,0,0
0,0,0,0,0,0,0,0,0,0,0,0,1,1,0,0,0,0,0,0,0,0,0,0,0,0
0,0,0,0,0,0,0,0,0,0,0,0,0,0,0,0,0,0,0,0,0,0,0,0,0,0
endlayer

layer
0,0,0,0,0,0,0,0,0,0,0,0,0,0,0,0,0,0,0,0,0,0,0,0,0,0
0,0,0,0,0,0,0,0,0,0,0,0,2,2,0,0,0,0,0,0,0,0,0,0,0,0
0,0,0,0,0,0,0,0,0,0,0,0,0,0,0,0,0,0,0,0,0,0,0,0,0,0
0,0,0,0,0,0,0,0,0,0,0,0,0,0,0,0,0,0,0,0,0,0,0,0,0,0
0,0,0,0,0,0,0,0,0,0,0,0,0,0,0,0,0,0,0,0,0,0,0,0,0,0
0,0,0,0,1,1,3,3,1,2,1,0,0,0,0,1,2,1,3,3,1,1,0,0,0,0
0,0,0,1,1,1,1,1,1,1,2,3,3,3,3,1,2,1,2,1,2,1,2,0,0,0
0,0,1,2,2,1,1,1,1,2,1,1,2,1,1,1,2,2,1,1,1,2,2,2,0,0
0,0,1,2,1,1,1,2,1,2,1,1,1,2,2,1,2,1,1,1,1,1,2,1,0,0
0,0,1,2,1,1,1,1,1,2,1,2,2,1,1,1,2,1,2,1,1,1,2,1,0,0
0,0,2,2,2,1,1,1,2,2,1,1,1,2,1,1,2,1,1,1,1,2,2,1,0,0
0,0,0,2,1,2,1,2,1,2,1,3,3,3,3,2,1,1,1,1,1,1,1,0,0,0
0,0,0,0,1,1,3,3,1,2,1,0,0,0,0,1,2,1,3,3,1,1,0,0,0,0
0,0,0,0,0,0,0,0,0,0,0,0,0,0,0,0,0,0,0,0,0,0,0,0,0,0
0,0,0,0,0,0,0,0,0,0,0,0,0,0,0,0,0,0,0,0,0,0,0,0,0,0
0,0,0,0,0,0,0,0,0,0,0,0,0,0,0,0,0,0,0,0,0,0,0,0,0,0
0,0,0,0,0,0,0,0,0,0,0,0,2,2,0,0,0,0,0,0,0,0,0,0,0,0
0,0,0,0,0,0,0,0,0,0,0,0,0,0,0,0,0,0,0,0,0,0,0,0,0,0
endlayer

layer
0,0,0,0,0,0,0,0,0,0,0,0,0,0,0,0,0,0,0,0,0,0,0,0,0,0
0,0,0,0,0,0,0,0,0,0,0,0,0,0,0,0,0,0,0,0,0,0,0,0,0,0
0,0,0,0,0,0,0,0,0,0,0,0,0,0,0,0,0,0,0,0,0,0,0,0,0,0
0,0,0,0,0,0,0,0,0,0,0,0,0,0,0,0,0,0,0,0,0,0,0,0,0,0
0,0,0,0,0,0,0,0,0,0,0,0,0,0,0,0,0,0,0,0,0,0,0,0,0,0
0,0,0,0,2,2,3,3,1,2,1,0,0,0,0,1,1,1,3,3,2,1,0,0,0,0
0,0,0,2,1,1,2,1,2,1,1,3,3,3,3,1,1,1,1,2,2,1,1,0,0,0
0,0,1,1,1,1,2,2,1,1,2,1,2,2,1,1,1,2,1,2,1,2,2,1,0,0
0,0,2,1,1,1,1,1,1,1,2,1,1,2,1,1,2,1,1,2,1,1,1,2,0,0
0,0,2,1,1,1,2,1,1,2,1,1,2,1,1,2,1,1,1,1,1,1,1,2,0,0
0,0,1,2,2,1,2,1,2,1,1,1,2,2,1,2,1,1,2,2,1,1,1,1,0,0
0,0,0,1,1,2,2,1,1,1,1,3,3,3,3,1,1,2,1,2,1,1,1,0,0,0
0,0,0,0,1,2,3,3,1,1,1,0,0,0,0,1,2,1,3,3,2,2,0,0,0,0
0,0,0,0,0,0,0,0,0,0,0,0,0,0,0,0,0,0,0,0,0,0,0,0,0,0
0,0,0,0,0,0,0,0,0,0,0,0,0,0,0,0,0,0,0,0,0,0,0,0,0,0
0,0,0,0,0,0,0,0,0,0,0,0,0,0,0,0,0,0,0,0,0,0,0,0,0,0
0,0,0,0,0,0,0,0,0,0,0,0,0,0,0,0,0,0,0,0,0,0,0,0,0,0
0,0,0,0,0,0,0,0,0,0,0,0,0,0,0,0,0,0,0,0,0,0,0,0,0,0
endlayer

layer
0,0,0,0,0,0,0,0,0,0,0,0,0,0,0,0,0,0,0,0,0,0,0,0,0,0
0,0,0,0,0,0,0,0,0,0,0,0,0,0,0,0,0,0,0,0,0,0,0,0,0,0
0,0,0,0,0,0,0,0,0,0,0,0,0,0,0,0,0,0,0,0,0,0,0,0,0,0
0,0,0,0,0,0,0,0,0,0,0,0,0,0,0,0,0,0,0,0,0,0,0,0,0,0
0,0,0,0,0,0,0,0,0,0,0,0,0,0,0,0,0,0,0,0,0,0,0,0,0,0
0,0,0,0,2,1,3,3,1,1,1,1,0,0,1,1,1,1,3,3,2,1,0,0,0,0
0,0,0,2,2,1,1,1,2,2,2,1,3,3,1,1,2,1,1,1,1,1,2,0,0,0
0,0,2,1,1,2,1,1,2,1,1,1,1,1,2,1,1,2,2,1,2,2,1,1,0,0
0,0,1,1,1,1,1,2,1,1,1,1,1,1,1,1,2,1,1,1,1,1,1,1,0,0
0,0,1,1,1,1,1,1,1,2,1,1,1,1,1,1,1,1,2,1,1,1,1,1,0,0
0,0,1,1,2,2,1,2,2,1,1,2,1,1,1,1,1,2,1,1,2,1,1,1,0,0
0,0,0,2,1,1,1,1,1,2,1,1,3,3,1,2,2,2,1,1,1,2,1,0,0,0
0,0,0,0,1,2,3,3,1,1,1,1,0,0,1,1,1,1,3,3,1,2,0,0,0,0
0,0,0,0,0,0,0,0,0,0,0,0,0,0,0,0,0,0,0,0,0,0,0,0,0,0
0,0,0,0,0,0,0,0,0,0,0,0,0,0,0,0,0,0,0,0,0,0,0,0,0,0
0,0,0,0,0,0,0,0,0,0,0,0,0,0,0,0,0,0,0,0,0,0,0,0,0,0
0,0,0,0,0,0,0,0,0,0,0,0,0,0,0,0,0,0,0,0,0,0,0,0,0,0
0,0,0,0,0,0,0,0,0,0,0,0,0,0,0,0,0,0,0,0,0,0,0,0,0,0
endlayer

layer
0,0,0,0,0,0,0,0,0,0,0,0,0,0,0,0,0,0,0,0,0,0,0,0,0,0
0,0,0,0,0,0,0,0,0,0,0,0,0,0,0,0,0,0,0,0,0,0,0,0,0,0
0,0,0,0,0,0,0,0,0,0,0,0,0,0,0,0,0,0,0,0,0,0,0,0,0,0
0,0,0,0,0,0,0,0,0,0,0,0,0,0,0,0,0,0,0,0,0,0,0,0,0,0
0,0,0,0,0,0,1,1,0,0,0,0,0,0,0,0,0,0,1,1,0,0,0,0,0,0
0,0,0,0,0,2,1,1,0,0,1,2,0,0,1,1,0,0,1,1,1,0,0,0,0,0
0,0,0,1,1,1,1,1,3,3,1,1,3,3,1,2,3,3,2,1,1,2,2,0,0,0
0,0,0,1,1,1,2,2,2,1,2,1,1,1,1,1,1,1,1,1,1,1,1,0,0,0
0,0,0,2,1,1,1,2,2,1,2,2,1,1,2,1,1,1,1,2,2,1,2,0,0,0
0,0,0,2,1,2,2,1,1,1,1,2,1,1,2,2,1,2,2,1,1,1,2,0,0,0
0,0,0,1,1,1,1,1,1,1,1,1,1,1,1,2,1,2,2,2,1,1,1,0,0,0
0,0,0,2,2,1,1,2,3,3,2,1,3,3,1,1,3,3,1,1,1,1,1,0,0,0
0,0,0,0,0,1,1,1,0,0,1,1,0,0,2,1,0,0,1,1,2,0,0,0,0,0
0,0,0,0,0,0,1,1,0,0,0,0,0,0,0,0,0,0,1,1,0,0,0,0,0,0
0,0,0,0,0,0,0,0,0,0,0,0,0,0,0,0,0,0,0,0,0,0,0,0,0,0
0,0,0,0,0,0,0,0,0,0,0,0,0,0,0,0,0,0,0,0,0,0,0,0,0,0
0,0,0,0,0,0,0,0,0,0,0,0,0,0,0,0,0,0,0,0,0,0,0,0,0,0
0,0,0,0,0,0,0,0,0,0,0,0,0,0,0,0,0,0,0,0,0,0,0,0,0,0
endlayer

layer
0,0,0,0,0,0,0,0,0,0,0,0,0,0,0,0,0,0,0,0,0,0,0,0,0,0
0,0,0,0,0,0,0,0,0,0,0,0,0,0,0,0,0,0,0,0,0,0,0,0,0,0
0,0,0,0,0,0,0,0,0,0,0,0,0,0,0,0,0,0,0,0,0,0,0,0,0,0
0,0,0,0,0,0,0,0,0,0,0,0,0,0,0,0,0,0,0,0,0,0,0,0,0,0
0,0,0,0,0,0,2,1,0,0,0,0,0,0,0,0,0,0,1,2,0,0,0,0,0,0
0,0,0,0,2,1,1,1,1,1,2,1,1,2,1,1,1,1,1,2,1,1,0,0,0,0
0,0,1,1,2,2,1,2,1,2,1,2,1,1,1,2,1,1,1,1,1,1,2,1,0,0
0,1,1,1,1,1,1,2,2,1,1,1,1,1,1,2,1,1,1,1,1,1,1,1,2,0
1,1,2,1,2,1,2,2,2,2,1,1,1,1,1,1,1,1,1,1,1,2,2,2,1,2
2,1,2,2,2,1,1,1,1,1,1,1,1,1,1,1,2,2,2,2,1,2,1,2,1,1
0,2,1,1,1,1,1,1,1,1,2,1,1,1,1,1,1,2,2,1,1,1,1,1,1,0
0,0,1,2,1,1,1,1,1,1,2,1,1,1,2,1,2,1,2,1,2,2,1,1,0,0
0,0,0,0,1,1,2,1,1,1,1,1,2,1,1,2,1,1,1,1,1,2,0,0,0,0
0,0,0,0,0,0,2,1,0,0,0,0,0,0,0,0,0,0,1,2,0,0,0,0,0,0
0,0,0,0,0,0,0,0,0,0,0,0,0,0,0,0,0,0,0,0,0,0,0,0,0,0
0,0,0,0,0,0,0,0,0,0,0,0,0,0,0,0,0,0,0,0,0,0,0,0,0,0
0,0,0,0,0,0,0,0,0,0,0,0,0,0,0,0,0,0,0,0,0,0,0,0,0,0
0,0,0,0,0,0,0,0,0,0,0,0,0,0,0,0,0,0,0,0,0,0,0,0,0,0
endlayer

layer
0,0,0,0,0,0,0,0,0,0,0,0,0,0,0,0,0,0,0,0,0,0,0,0,0,0
0,0,0,0,0,0,0,0,0,0,0,0,0,0,0,0,0,0,0,0,0,0,0,0,0,0
0,0,0,0,0,0,0,0,0,0,0,0,0,0,0,0,0,0,0,0,0,0,0,0,0,0
0,0,0,0,0,0,0,0,0,0,0,0,0,0,0,0,0,0,0,0,0,0,0,0,0,0
0,0,0,0,0,0,0,0,0,0,0,0,0,0,0,0,0,0,0,0,0,0,0,0,0,0
0,0,0,2,2,1,2,1,2,2,1,1,0,0,1,2,1,1,1,2,2,2,2,0,0,0
0,0,2,1,1,1,1,2,2,1,2,1,3,3,2,1,1,1,1,1,1,2,1,1,0,0
0,1,2,2,1,1,1,2,1,2,2,2,1,1,1,2,2,1,1,1,1,2,1,1,1,0
2,1,1,2,1,1,2,1,1,2,1,1,1,1,1,1,1,1,2,1,1,1,2,1,2,1
1,2,1,2,1,1,1,2,1,1,1,1,1,1,1,1,2,1,1,2,1,1,2,1,1,2
0,1,1,1,2,1,1,1,1,2,2,1,1,1,2,2,2,1,2,1,1,1,2,2,1,0
0,0,1,1,2,1,1,1,1,1,1,2,3,3,1,2,1,2,2,1,1,1,1,2,0,0
0,0,0,2,2,2,2,1,1,1,2,1,0,0,1,1,2,2,1,2,1,2,2,0,0,0
0,0,0,0,0,0,0,0,0,0,0,0,0,0,0,0,0,0,0,0,0,0,0,0,0,0
0,0,0,0,0,0,0,0,0,0,0,0,0,0,0,0,0,0,0,0,0,0,0,0,0,0
0,0,0,0,0,0,0,0,0,0,0,0,0,0,0,0,0,0,0,0,0,0,0,0,0,0
0,0,0,0,0,0,0,0,0,0,0,0,0,0,0,0,0,0,0,0,0,0,0,0,0,0
0,0,0,0,0,0,0,0,0,0,0,0,0,0,0,0,0,0,0,0,0,0,0,0,0,0
endlayer

layer
0,0,0,0,0,0,0,0,0,0,0,0,0,0,0,0,0,0,0,0,0,0,0,0,0,0
0,0,0,0,0,0,0,0,0,0,0,0,0,0,0,0,0,0,0,0,0,0,0,0,0,0
0,0,0,0,0,0,0,0,0,0,0,0,0,0,0,0,0,0,0,0,0,0,0,0,0,0
0,0,0,0,0,0,0,0,0,0,0,0,0,0,0,0,0,0,0,0,0,0,0,0,0,0
0,0,0,0,0,0,0,0,0,0,0,0,0,0,0,0,0,0,0,0,0,0,0,0,0,0
0,0,0,1,1,1,1,1,1,1,0,0,0,0,0,0,1,1,2,1,2,1,1,0,0,0
0,0,2,2,2,1,2,1,2,1,3,3,0,0,3,3,2,1,1,1,2,2,1,1,0,0
0,2,2,1,2,1,1,1,1,1,1,2,3,3,1,2,1,2,1,1,1,1,2,1,1,0
0,1,1,1,1,1,1,1,1,1,2,1,1,1,2,1,1,1,1,1,1,1,1,2,2,0
0,2,2,1,1,1,1,1,1,1,1,2,1,1,1,2,1,1,1,1,1,1,1,1,1,0
0,1,1,2,1,1,1,1,2,1,2,1,3,3,2,1,1,1,1,1,1,2,1,2,2,0
0,0,1,1,2,2,1,1,1,2,3,3,0,0,3,3,1,2,1,2,1,2,2,2,0,0
0,0,0,1,1,2,1,2,1,1,0,0,0,0,0,0,1,1,1,1,1,1,1,0,0,0
0,0,0,0,0,0,0,0,0,0,0,0,0,0,0,0,0,0,0,0,0,0,0,0,0,0
0,0,0,0,0,0,0,0,0,0,0,0,0,0,0,0,0,0,0,0,0,0,0,0,0,0
0,0,0,0,0,0,0,0,0,0,0,0,0,0,0,0,0,0,0,0,0,0,0,0,0,0
0,0,0,0,0,0,0,0,0,0,0,0,0,0,0,0,0,0,0,0,0,0,0,0,0,0
0,0,0,0,0,0,0,0,0,0,0,0,0,0,0,0,0,0,0,0,0,0,0,0,0,0
endlayer

layer
0,0,0,0,0,0,0,0,0,0,0,0,0,0,0,0,0,0,0,0,0,0,0,0,0,0
0,0,0,0,0,0,0,0,0,0,0,0,0,0,0,0,0,0,0,0,0,0,0,0,0,0
0,0,0,0,0,0,0,0,0,0,0,0,0,0,0,0,0,0,0,0,0,0,0,0,0,0
0,0,0,0,0,0,0,0,0,0,0,0,0,0,0,0,0,0,0,0,0,0,0,0,0,0
0,0,0,0,0,0,0,0,0,0,0,0,0,0,0,0,0,0,0,0,0,0,0,0,0,0
0,0,0,0,0,1,1,1,0,0,1,1,0,0,1,1,0,0,2,1,2,0,0,0,0,0
0,0,0,1,2,2,1,1,2,0,1,0,3,3,0,1,0,1,1,1,2,1,2,0,0,0
0,0,1,2,1,2,1,2,1,2,1,1,2,1,1,1,1,1,1,1,1,1,1,2,0,0
0,0,2,2,2,2,1,1,1,1,1,1,1,1,1,1,1,1,1,1,2,2,1,1,0,0
0,0,1,1,2,2,1,1,1,1,1,1,1,1,1,1,1,1,1,1,2,2,2,2,0,0
0,0,2,1,1,1,1,1,1,1,1,1,1,2,1,1,2,1,2,1,2,1,2,1,0,0
0,0,0,2,1,2,1,1,1,0,1,0,3,3,0,1,0,2,1,1,2,2,1,0,0,0
0,0,0,0,0,2,1,2,0,0,1,1,0,0,1,1,0,0,1,1,1,0,0,0,0,0
0,0,0,0,0,0,0,0,0,0,0,0,0,0,0,0,0,0,0,0,0,0,0,0,0,0
0,0,0,0,0,0,0,0,0,0,0,0,0,0,0,0,0,0,0,0,0,0,0,0,0,0
0,0,0,0,0,0,0,0,0,0,0,0,0,0,0,0,0,0,0,0,0,0,0,0,0,0
0,0,0,0,0,0,0,0,0,0,0,0,0,0,0,0,0,0,0,0,0,0,0,0,0,0
0,0,0,0,0,0,0,0,0,0,0,0,0,0,0,0,0,0,0,0,0,0,0,0,0,0
endlayer

layer
0,0,0,0,0,0,0,0,0,0,0,0,0,0,0,0,0,0,0,0,0,0,0,0,0,0
0,0,0,0,0,0,0,0,0,0,0,0,0,0,0,0,0,0,0,0,0,0,0,0,0,0
0,0,0,0,0,0,0,0,0,0,0,0,0,0,0,0,0,0,0,0,0,0,0,0,0,0
0,0,0,0,0,0,0,0,0,0,0,0,0,0,0,0,0,0,0,0,0,0,0,0,0,0
0,0,0,0,0,0,0,0,0,0,0,0,0,0,0,0,0,0,0,0,0,0,0,0,0,0
0,0,0,0,0,0,0,0,0,0,2,1,0,0,1,1,0,0,0,0,0,0,0,0,0,0
0,0,0,0,0,1,1,2,0,0,1,1,3,3,2,2,0,0,1,1,1,0,0,0,0,0
0,0,0,0,0,1,1,1,1,0,1,1,2,2,1,2,0,1,1,1,2,0,0,0,0,0
0,0,0,0,1,1,2,2,1,0,1,1,1,2,2,2,0,1,2,1,1,1,0,0,0,0
0,0,0,0,1,1,1,2,1,0,2,2,2,1,1,1,0,1,2,2,1,1,0,0,0,0
0,0,0,0,0,2,1,1,1,0,2,1,2,2,1,1,0,1,1,1,1,0,0,0,0,0
0,0,0,0,0,1,1,1,0,0,2,2,3,3,1,1,0,0,2,1,1,0,0,0,0,0
0,0,0,0,0,0,0,0,0,0,1,1,0,0,1,2,0,0,0,0,0,0,0,0,0,0
0,0,0,0,0,0,0,0,0,0,0,0,0,0,0,0,0,0,0,0,0,0,0,0,0,0
0,0,0,0,0,0,0,0,0,0,0,0,0,0,0,0,0,0,0,0,0,0,0,0,0,0
0,0,0,0,0,0,0,0,0,0,0,0,0,0,0,0,0,0,0,0,0,0,0,0,0,0
0,0,0,0,0,0,0,0,0,0,0,0,0,0,0,0,0,0,0,0,0,0,0,0,0,0
0,0,0,0,0,0,0,0,0,0,0,0,0,0,0,0,0,0,0,0,0,0,0,0,0,0
endlayer

layer
0,0,0,0,0,0,0,0,0,0,0,0,0,0,0,0,0,0,0,0,0,0,0,0,0,0
0,0,0,0,0,0,0,0,0,0,0,0,0,0,0,0,0,0,0,0,0,0,0,0,0,0
0,0,0,0,0,0,0,0,0,0,0,0,0,0,0,0,0,0,0,0,0,0,0,0,0,0
0,0,0,0,0,0,0,0,0,0,0,0,0,0,0,0,0,0,0,0,0,0,0,0,0,0
0,0,0,0,0,0,0,0,0,0,0,0,0,0,0,0,0,0,0,0,0,0,0,0,0,0
0,0,0,0,0,0,0,0,0,0,2,1,0,0,1,2,0,0,0,0,0,0,0,0,0,0
0,0,0,0,0,0,0,0,0,1,1,1,3,3,1,1,2,0,0,0,0,0,0,0,0,0
0,0,0,0,0,0,0,0,0,0,1,1,1,1,1,1,0,0,0,0,0,0,0,0,0,0
0,0,0,0,0,0,0,0,0,0,1,1,2,1,1,1,0,0,0,0,0,0,0,0,0,0
0,0,0,0,0,0,0,0,0,0,1,1,1,2,1,1,0,0,0,0,0,0,0,0,0,0
0,0,0,0,0,0,0,0,0,0,1,1,1,1,1,1,0,0,0,0,0,0,0,0,0,0
0,0,0,0,0,0,0,0,0,2,1,1,3,3,1,1,1,0,0,0,0,0,0,0,0,0
0,0,0,0,0,0,0,0,0,0,1,1,0,0,1,1,0,0,0,0,0,0,0,0,0,0
0,0,0,0,0,0,0,0,0,0,0,0,0,0,0,0,0,0,0,0,0,0,0,0,0,0
0,0,0,0,0,0,0,0,0,0,0,0,0,0,0,0,0,0,0,0,0,0,0,0,0,0
0,0,0,0,0,0,0,0,0,0,0,0,0,0,0,0,0,0,0,0,0,0,0,0,0,0
0,0,0,0,0,0,0,0,0,0,0,0,0,0,0,0,0,0,0,0,0,0,0,0,0,0
0,0,0,0,0,0,0,0,0,0,0,0,0,0,0,0,0,0,0,0,0,0,0,0,0,0
endlayer

layer
0,0,0,0,0,0,0,0,0,0,0,0,0,0,0,0,0,0,0,0,0,0,0,0,0,0
0,0,0,0,0,0,0,0,0,0,0,0,0,0,0,0,0,0,0,0,0,0,0,0,0,0
0,0,0,0,0,0,0,0,0,0,0,0,0,0,0,0,0,0,0,0,0,0,0,0,0,0
0,0,0,0,0,0,0,0,0,0,0,0,0,0,0,0,0,0,0,0,0,0,0,0,0,0
0,0,0,0,0,0,0,0,0,0,0,0,0,0,0,0,0,0,0,0,0,0,0,0,0,0
0,0,0,0,0,0,0,0,0,0,2,1,0,0,1,2,0,0,0,0,0,0,0,0,0,0
0,0,0,0,0,0,0,0,0,1,1,1,3,3,2,1,2,0,0,0,0,0,0,0,0,0
0,0,0,0,0,0,0,0,0,1,1,1,1,2,2,1,1,0,0,0,0,0,0,0,0,0
0,0,0,0,0,0,0,0,0,0,2,1,2,1,1,2,0,0,0,0,0,0,0,0,0,0
0,0,0,0,0,0,0,0,0,0,2,1,1,2,1,2,0,0,0,0,0,0,0,0,0,0
0,0,0,0,0,0,0,0,0,1,1,2,2,1,1,1,1,0,0,0,0,0,0,0,0,0
0,0,0,0,0,0,0,0,0,2,1,2,3,3,1,1,1,0,0,0,0,0,0,0,0,0
0,0,0,0,0,0,0,0,0,0,1,1,0,0,1,1,0,0,0,0,0,0,0,0,0,0
0,0,0,0,0,0,0,0,0,0,0,0,0,0,0,0,0,0,0,0,0,0,0,0,0,0
0,0,0,0,0,0,0,0,0,0,0,0,0,0,0,0,0,0,0,0,0,0,0,0,0,0
0,0,0,0,0,0,0,0,0,0,0,0,0,0,0,0,0,0,0,0,0,0,0,0,0,0
0,0,0,0,0,0,0,0,0,0,0,0,0,0,0,0,0,0,0,0,0,0,0,0,0,0
0,0,0,0,0,0,0,0,0,0,0,0,0,0,0,0,0,0,0,0,0,0,0,0,0,0
endlayer

layer
0,0,0,0,0,0,0,0,0,0,0,0,0,0,0,0,0,0,0,0,0,0,0,0,0,0
0,0,0,0,0,0,0,0,0,0,0,0,0,0,0,0,0,0,0,0,0,0,0,0,0,0
0,0,0,0,0,0,0,0,0,0,0,0,0,0,0,0,0,0,0,0,0,0,0,0,0,0
0,0,0,0,0,0,0,0,0,0,0,0,0,0,0,0,0,0,0,0,0,0,0,0,0,0
0,0,0,0,0,0,0,0,0,0,0,0,0,0,0,0,0,0,0,0,0,0,0,0,0,0
0,0,0,0,0,0,0,0,0,0,1,0,0,0,0,1,0,0,0,0,0,0,0,0,0,0
0,0,0,0,0,0,0,0,0,1,1,3,3,3,3,1,2,0,0,0,0,0,0,0,0,0
0,0,0,0,0,0,0,0,0,1,1,2,2,1,1,1,2,0,0,0,0,0,0,0,0,0
0,0,0,0,0,0,0,0,0,1,1,2,2,1,1,1,1,0,0,0,0,0,0,0,0,0
0,0,0,0,0,0,0,0,0,1,1,1,1,2,2,1,1,0,0,0,0,0,0,0,0,0
0,0,0,0,0,0,0,0,0,2,1,1,1,2,1,1,1,0,0,0,0,0,0,0,0,0
0,0,0,0,0,0,0,0,0,2,1,3,3,3,3,1,1,0,0,0,0,0,0,0,0,0
0,0,0,0,0,0,0,0,0,0,1,0,0,0,0,1,0,0,0,0,0,0,0,0,0,0
0,0,0,0,0,0,0,0,0,0,0,0,0,0,0,0,0,0,0,0,0,0,0,0,0,0
0,0,0,0,0,0,0,0,0,0,0,0,0,0,0,0,0,0,0,0,0,0,0,0,0,0
0,0,0,0,0,0,0,0,0,0,0,0,0,0,0,0,0,0,0,0,0,0,0,0,0,0
0,0,0,0,0,0,0,0,0,0,0,0,0,0,0,0,0,0,0,0,0,0,0,0,0,0
0,0,0,0,0,0,0,0,0,0,0,0,0,0,0,0,0,0,0,0,0,0,0,0,0,0
endlayer

layer
0,0,0,0,0,0,0,0,0,0,0,0,0,0,0,0,0,0,0,0,0,0,0,0,0,0
0,0,0,0,0,0,0,0,0,0,0,0,0,0,0,0,0,0,0,0,0,0,0,0,0,0
0,0,0,0,0,0,0,0,0,0,0,0,0,0,0,0,0,0,0,0,0,0,0,0,0,0
0,0,0,0,0,0,0,0,0,0,0,0,0,0,0,0,0,0,0,0,0,0,0,0,0,0
0,0,0,0,0,0,0,0,0,0,0,0,1,1,0,0,0,0,0,0,0,0,0,0,0,0
0,0,0,0,0,0,0,0,0,0,0,4,0,0,4,0,0,0,0,0,0,0,0,0,0,0
0,0,0,0,0,0,0,0,0,1,3,5,3,3,5,3,2,0,0,0,0,0,0,0,0,0
0,0,0,0,0,0,0,0,0,2,1,6,1,1,6,1,1,0,0,0,0,0,0,0,0,0
0,0,0,0,0,0,0,0,0,1,1,1,2,2,1,2,1,0,0,0,0,0,0,0,0,0
0,0,0,0,0,0,0,0,0,1,2,1,2,2,1,1,1,0,0,0,0,0,0,0,0,0
0,0,0,0,0,0,0,0,0,1,1,6,1,1,6,1,2,0,0,0,0,0,0,0,0,0
0,0,0,0,0,0,0,0,0,2,3,5,3,3,5,3,1,0,0,0,0,0,0,0,0,0
0,0,0,0,0,0,0,0,0,0,0,4,0,0,4,0,0,0,0,0,0,0,0,0,0,0
0,0,0,0,0,0,0,0,0,0,0,0,1,1,0,0,0,0,0,0,0,0,0,0,0,0
0,0,0,0,0,0,0,0,0,0,0,0,0,0,0,0,0,0,0,0,0,0,0,0,0,0
0,0,0,0,0,0,0,0,0,0,0,0,0,0,0,0,0,0,0,0,0,0,0,0,0,0
0,0,0,0,0,0,0,0,0,0,0,0,0,0,0,0,0,0,0,0,0,0,0,0,0,0
0,0,0,0,0,0,0,0,0,0,0,0,0,0,0,0,0,0,0,0,0,0,0,0,0,0
endlayer

layer
0,0,0,0,0,0,0,0,0,0,0,0,0,0,0,0,0,0,0,0,0,0,0,0,0,0
0,0,0,0,0,0,0,0,0,0,0,0,0,0,0,0,0,0,0,0,0,0,0,0,0,0
0,0,0,0,0,0,0,0,0,0,0,0,0,0,0,0,0,0,0,0,0,0,0,0,0,0
0,0,0,0,0,0,0,0,0,0,0,0,0,0,0,0,0,0,0,0,0,0,0,0,0,0
0,0,0,0,0,0,0,0,0,0,0,0,1,1,0,0,0,0,0,0,0,0,0,0,0,0
0,0,0,0,0,0,0,0,0,0,1,1,1,2,2,2,0,0,0,0,0,0,0,0,0,0
0,0,0,0,0,0,0,0,0,1,1,1,1,1,2,1,1,0,0,0,0,0,0,0,0,0
0,0,0,0,0,0,0,0,0,1,1,1,1,2,1,1,1,0,0,0,0,0,0,0,0,0
0,0,0,0,0,0,0,0,0,1,1,1,2,2,1,1,1,0,0,0,0,0,0,0,0,0
0,0,0,0,0,0,0,0,0,1,1,1,2,2,1,1,1,0,0,0,0,0,0,0,0,0
0,0,0,0,0,0,0,0,0,1,1,1,2,1,1,1,1,0,0,0,0,0,0,0,0,0
0,0,0,0,0,0,0,0,0,1,1,2,1,1,1,1,1,0,0,0,0,0,0,0,0,0
0,0,0,0,0,0,0,0,0,0,2,1,2,1,1,1,0,0,0,0,0,0,0,0,0,0
0,0,0,0,0,0,0,0,0,0,0,0,1,1,0,0,0,0,0,0,0,0,0,0,0,0
0,0,0,0,0,0,0,0,0,0,0,0,0,0,0,0,0,0,0,0,0,0,0,0,0,0
0,0,0,0,0,0,0,0,0,0,0,0,0,0,0,0,0,0,0,0,0,0,0,0,0,0
0,0,0,0,0,0,0,0,0,0,0,0,0,0,0,0,0,0,0,0,0,0,0,0,0,0
0,0,0,0,0,0,0,0,0,0,0,0,0,0,0,0,0,0,0,0,0,0,0,0,0,0
endlayer

layer
0,0,0,0,0,0,0,0,0,0,0,0,0,0,0,0,0,0,0,0,0,0,0,0,0,0
0,0,0,0,0,0,0,0,0,0,0,0,0,0,0,0,0,0,0,0,0,0,0,0,0,0
0,0,0,0,0,0,0,0,0,0,0,0,0,0,0,0,0,0,0,0,0,0,0,0,0,0
0,0,0,0,0,0,0,0,0,0,0,0,0,0,0,0,0,0,0,0,0,0,0,0,0,0
0,0,0,0,0,0,0,0,0,0,0,0,1,2,0,0,0,0,0,0,0,0,0,0,0,0
0,0,0,0,0,0,0,0,0,0,1,1,1,1,1,2,0,0,0,0,0,0,0,0,0,0
0,0,0,0,0,0,0,0,0,0,1,1,2,1,2,2,0,0,0,0,0,0,0,0,0,0
0,0,0,0,0,0,0,0,0,1,2,2,1,2,1,1,1,0,0,0,0,0,0,0,0,0
0,0,0,0,0,0,0,0,0,2,1,1,2,1,2,1,2,0,0,0,0,0,0,0,0,0
0,0,0,0,0,0,0,0,0,2,1,2,1,2,1,1,2,0,0,0,0,0,0,0,0,0
0,0,0,0,0,0,0,0,0,1,1,1,2,1,2,2,1,0,0,0,0,0,0,0,0,0
0,0,0,0,0,0,0,0,0,0,2,2,1,2,1,1,0,0,0,0,0,0,0,0,0,0
0,0,0,0,0,0,0,0,0,0,2,1,1,1,1,1,0,0,0,0,0,0,0,0,0,0
0,0,0,0,0,0,0,0,0,0,0,0,2,1,0,0,0,0,0,0,0,0,0,0,0,0
0,0,0,0,0,0,0,0,0,0,0,0,0,0,0,0,0,0,0,0,0,0,0,0,0,0
0,0,0,0,0,0,0,0,0,0,0,0,0,0,0,0,0,0,0,0,0,0,0,0,0,0
0,0,0,0,0,0,0,0,0,0,0,0,0,0,0,0,0,0,0,0,0,0,0,0,0,0
0,0,0,0,0,0,0,0,0,0,0,0,0,0,0,0,0,0,0,0,0,0,0,0,0,0
endlayer

layer
0,0,0,0,0,0,0,0,0,0,0,0,0,0,0,0,0,0,0,0,0,0,0,0,0,0
0,0,0,0,0,0,0,0,0,0,0,0,0,0,0,0,0,0,0,0,0,0,0,0,0,0
0,0,0,0,0,0,0,0,0,0,0,0,0,0,0,0,0,0,0,0,0,0,0,0,0,0
0,0,0,0,0,0,0,0,0,0,0,0,0,0,0,0,0,0,0,0,0,0,0,0,0,0
0,0,0,0,0,0,0,0,0,0,0,0,0,0,0,0,0,0,0,0,0,0,0,0,0,0
0,0,0,0,0,0,0,0,0,0,0,1,1,2,1,0,0,0,0,0,0,0,0,0,0,0
0,0,0,0,0,0,0,0,0,0,0,2,1,1,2,0,0,0,0,0,0,0,0,0,0,0
0,0,0,0,0,0,0,0,0,0,1,1,1,1,1,1,0,0,0,0,0,0,0,0,0,0
0,0,0,0,0,0,0,0,0,0,1,1,1,1,1,1,0,0,0,0,0,0,0,0,0,0
0,0,0,0,0,0,0,0,0,0,1,1,1,1,1,1,0,0,0,0,0,0,0,0,0,0
0,0,0,0,0,0,0,0,0,0,1,1,1,1,1,1,0,0,0,0,0,0,0,0,0,0
0,0,0,0,0,0,0,0,0,0,0,2,1,1,2,0,0,0,0,0,0,0,0,0,0,0
0,0,0,0,0,0,0,0,0,0,0,1,2,1,1,0,0,0,0,0,0,0,0,0,0,0
0,0,0,0,0,0,0,0,0,0,0,0,0,0,0,0,0,0,0,0,0,0,0,0,0,0
0,0,0,0,0,0,0,0,0,0,0,0,0,0,0,0,0,0,0,0,0,0,0,0,0,0
0,0,0,0,0,0,0,0,0,0,0,0,0,0,0,0,0,0,0,0,0,0,0,0,0,0
0,0,0,0,0,0,0,0,0,0,0,0,0,0,0,0,0,0,0,0,0,0,0,0,0,0
0,0,0,0,0,0,0,0,0,0,0,0,0,0,0,0,0,0,0,0,0,0,0,0,0,0
endlayer

layer
0,0,0,0,0,0,0,0,0,0,0,0,0,0,0,0,0,0,0,0,0,0,0,0,0,0
0,0,0,0,0,0,0,0,0,0,0,0,0,0,0,0,0,0,0,0,0,0,0,0,0,0
0,0,0,0,0,0,0,0,0,0,0,0,0,0,0,0,0,0,0,0,0,0,0,0,0,0
0,0,0,0,0,0,0,0,0,0,0,0,0,0,0,0,0,0,0,0,0,0,0,0,0,0
0,0,0,0,0,0,0,0,0,0,0,0,0,0,0,0,0,0,0,0,0,0,0,0,0,0
0,0,0,0,0,0,0,0,0,0,0,0,1,2,0,0,0,0,0,0,0,0,0,0,0,0
0,0,0,0,0,0,0,0,0,0,0,0,0,0,0,0,0,0,0,0,0,0,0,0,0,0
0,0,0,0,0,0,0,0,0,0,0,2,1,2,1,0,0,0,0,0,0,0,0,0,0,0
0,0,0,0,0,0,0,0,0,0,0,1,1,1,2,0,0,0,0,0,0,0,0,0,0,0
0,0,0,0,0,0,0,0,0,0,0,2,1,1,1,0,0,0,0,0,0,0,0,0,0,0
0,0,0,0,0,0,0,0,0,0,0,1,2,1,2,0,0,0,0,0,0,0,0,0,0,0
0,0,0,0,0,0,0,0,0,0,0,0,0,0,0,0,0,0,0,0,0,0,0,0,0,0
0,0,0,0,0,0,0,0,0,0,0,0,2,1,0,0,0,0,0,0,0,0,0,0,0,0
0,0,0,0,0,0,0,0,0,0,0,0,0,0,0,0,0,0,0,0,0,0,0,0,0,0
0,0,0,0,0,0,0,0,0,0,0,0,0,0,0,0,0,0,0,0,0,0,0,0,0,0
0,0,0,0,0,0,0,0,0,0,0,0,0,0,0,0,0,0,0,0,0,0,0,0,0,0
0,0,0,0,0,0,0,0,0,0,0,0,0,0,0,0,0,0,0,0,0,0,0,0,0,0
0,0,0,0,0,0,0,0,0,0,0,0,0,0,0,0,0,0,0,0,0,0,0,0,0,0
endlayer

