# Author: BlinkyZero
# From: Minecraft Forums

biomesToSpawnIn=autumn hills,autumn woods,bamboo forest,birch forest,bog,boneyard,boreal forest,brushland,chaparral,cherry blossom grove,coniferous forest,deciduous forest,extreme hills,extreme hills edge,fen,field,forest,forested field,forested hills,forested island,foresthills,fungi forest,garden,grassland,green hills,green swamplands,grove,heathland,highland,hot springs,jade cliffs,jungle,junglehills,lavender fields,lush redwoods,lush swamp,magical forest,majestic meadow,mangrove,maplewoods,marsh,meadow,meadow forest,mesa,mini jungle,mountain, mountain ridge,mountain taiga,mystic grove,orchard,outback,overgrown beach,overgrown greens,pasture,pasture meadow,pine forest,plains,prarie,quagmire,rainforest,redwood forest,sacred springs,savanna,savanna plateau,scrubland,seasonal forest,seasonal spruce forest,shield,spruce woods,steppe,sublime shrubland,swampland,taiga,taigahills,temperate rainforest,thick shrubland,thicket,thinned mystic grove,thinned pasture,thinned timber,timber,tropical rainforest,tropics mountain,tundra,wonderous woods,woodland,woodlands,wyvern biome,wetland
weight=2
embed_into_distance=1
unacceptable_target_blocks=flowing_water,water,flowing_lava,lava,Natura:Cloud,red_mushroom_block,brown_mushroom_block,planks,cobblestone,end_stone,obsidian,purpur_block,iron_bars,purpur_slab,purpur_pillar,netherrack,soul_sand,quartz_ore
dimensions=9,10,9
allowable_overhang=2
max_cut_in=2
cut_in_buffer=1
max_leveling=2
leveling_buffer=-1
preserve_water=0
preserve_lava=0
preserve_plants=0

rule1=0,100,cobblestone
rule2=0,100,planks
rule3=0,100,preserveBlock
rule4=2,100,torch-3
rule5=2,100,torch-5

layer
3,3,3,3,3,3,3,3,3
3,1,1,1,1,1,1,1,3
3,1,1,1,1,1,1,1,3
3,1,1,1,1,1,1,1,3
3,1,1,1,1,1,1,1,3
3,1,1,1,1,1,1,1,3
3,1,1,1,1,1,1,1,3
3,1,1,1,1,1,1,1,3
3,3,3,3,1,3,3,3,3
3,3,3,3,3,3,3,3,3
endlayer

layer
0,0,2,0,0,0,2,0,0
0,1,1,1,1,1,1,1,0
2,1,2,0,0,0,2,1,2
0,1,0,0,0,0,0,1,0
0,1,0,0,1,0,0,1,0
0,1,0,0,0,0,0,1,0
2,1,2,0,0,0,2,1,2
0,1,1,1,0,1,1,1,0
0,0,2,1,0,1,2,0,0
0,0,2,0,0,0,2,0,0
endlayer

layer
0,0,2,0,0,0,2,0,0
0,1,1,1,1,1,1,1,0
2,1,2,0,0,0,2,1,2
0,1,0,0,0,0,0,1,0
0,1,0,0,5,0,0,1,0
0,1,0,0,0,0,0,1,0
2,1,2,0,0,0,2,1,2
0,1,1,1,0,1,1,1,0
0,0,2,1,0,1,2,0,0
0,0,2,4,0,4,2,0,0
endlayer

layer
0,0,2,0,0,0,2,0,0
0,1,1,1,1,1,1,1,0
2,1,2,0,0,0,2,1,2
0,1,0,0,0,0,0,1,0
0,1,0,0,0,0,0,1,0
0,1,0,0,0,0,0,1,0
2,1,2,0,0,0,2,1,2
0,1,1,1,1,1,1,1,0
0,0,2,1,1,1,2,0,0
0,0,2,0,0,0,2,0,0
endlayer

layer
2,2,2,2,2,2,2,2,2
2,1,1,1,1,1,1,1,2
2,1,2,2,2,2,2,1,2
2,1,2,0,0,0,2,1,2
2,1,2,0,0,0,2,1,2
2,1,2,0,0,0,2,1,2
2,1,2,2,2,2,2,1,2
2,1,1,1,1,1,1,1,2
2,2,2,2,2,2,2,2,2
0,0,2,2,2,2,2,0,0
endlayer

layer
2,0,0,0,0,0,0,0,2
0,1,1,1,1,1,1,1,0
0,1,1,1,1,1,1,1,0
0,1,1,1,1,1,1,1,0
0,1,1,1,1,1,1,1,0
0,1,1,1,1,1,1,1,0
0,1,1,1,1,1,1,1,0
0,1,1,1,1,1,1,1,0
2,0,0,0,0,0,0,0,2
0,0,0,0,0,0,0,0,0
endlayer

layer
2,2,2,2,2,2,2,2,2
2,1,1,1,1,1,1,1,2
2,1,1,1,1,1,1,1,2
2,1,1,1,1,1,1,1,2
2,1,1,1,1,1,1,1,2
2,1,1,1,1,1,1,1,2
2,1,1,1,1,1,1,1,2
2,1,1,1,1,1,1,1,2
2,2,2,2,2,2,2,2,2
0,0,0,0,0,0,0,0,0
endlayer

layer
0,0,0,0,0,0,0,0,0
0,1,0,0,0,0,0,1,0
0,0,0,0,0,0,0,0,0
0,0,0,0,0,0,0,0,0
0,0,0,0,0,0,0,0,0
0,0,0,0,0,0,0,0,0
0,0,0,0,0,0,0,0,0
0,1,0,0,0,0,0,1,0
0,0,0,0,0,0,0,0,0
0,0,0,0,0,0,0,0,0
endlayer

layer
0,0,0,0,0,0,0,0,0
0,5,0,0,0,0,0,5,0
0,0,0,0,0,0,0,0,0
0,0,0,0,0,0,0,0,0
0,0,0,0,0,0,0,0,0
0,0,0,0,0,0,0,0,0
0,0,0,0,0,0,0,0,0
0,5,0,0,0,0,0,5,0
0,0,0,0,0,0,0,0,0
0,0,0,0,0,0,0,0,0
endlayer