# Author: Arrrg
# From: Minecraft Forums

uniqueMinDistance=1000

biomesToSpawnIn=kelp forest,ocean,ocean oil field,oceanic abyss,coral reef
weight=4
embed_into_distance=0
dimensions=22,12,12
allowable_overhang=150
max_cut_in=0
cut_in_buffer=0
max_leveling=1
leveling_buffer=0
preserve_water=0
preserve_lava=1
preserve_plants=1

rule1=0,100,preserveBlock
rule2=0,100,grass
rule3=0,100,sandstone
rule4=0,100,ice
rule5=0,100,planks
rule6=0,50,ice
rule7=0,100,leaves
rule8=0,100,fence
rule9=0,100,wool-0
rule10=0,100,wool-3
rule11=0,100,wool-9
rule12=0,100,wool-10
rule13=2,100,torch
rule14=2,100,rail

layer
1,1,1,1,1,1,1,1,1,1,1,1
1,1,1,1,1,1,1,1,1,1,1,1
1,1,1,1,1,1,1,1,1,1,1,1
1,1,1,1,1,1,1,1,1,1,1,1
1,1,1,1,1,1,1,1,1,1,1,1
1,1,1,1,1,5,5,1,1,1,1,1
1,1,1,1,1,5,5,1,1,1,1,1
1,1,1,1,1,1,1,1,1,1,1,1
1,1,1,1,1,1,1,1,1,1,1,1
1,1,1,1,1,1,1,1,1,1,1,1
1,1,1,1,1,1,1,1,1,1,1,1
1,1,1,1,1,1,1,1,1,1,1,1
endlayer

layer
1,1,1,1,1,1,1,1,1,1,1,1
1,1,1,1,1,1,1,1,1,1,1,1
1,1,1,1,1,1,1,1,1,1,1,1
1,1,1,1,1,1,1,1,1,1,1,1
1,1,1,1,8,1,1,8,1,1,1,1
1,1,1,1,1,0,0,1,1,1,1,1
1,1,1,1,1,0,0,1,1,1,1,1
1,1,1,1,8,1,1,8,1,1,1,1
1,1,1,1,1,1,1,1,1,1,1,1
1,1,1,1,1,1,1,1,1,1,1,1
1,1,1,1,1,1,1,1,1,1,1,1
1,1,1,1,1,1,1,1,1,1,1,1
endlayer

layer
1,1,1,1,1,1,1,1,1,1,1,1
1,1,1,1,1,1,1,1,1,1,1,1
1,1,1,1,1,1,1,1,1,1,1,1
1,1,1,1,1,1,1,1,1,1,1,1
1,1,1,1,8,0,0,8,1,1,1,1
1,1,1,1,0,0,0,0,1,1,1,1
1,1,1,1,0,0,0,0,1,1,1,1
1,1,1,1,8,0,0,8,1,1,1,1
1,1,1,1,1,1,1,1,1,1,1,1
1,1,1,1,1,1,1,1,1,1,1,1
1,1,1,1,1,1,1,1,1,1,1,1
1,1,1,1,1,1,1,1,1,1,1,1
endlayer

layer
1,1,1,1,1,1,1,1,1,1,1,1
1,1,1,1,1,1,1,1,1,1,1,1
1,1,1,1,1,1,1,1,1,1,1,1
1,1,1,1,1,1,1,1,1,1,1,1
1,1,1,1,8,0,0,8,1,1,1,1
1,1,1,1,0,0,0,0,1,1,1,1
1,1,1,1,0,0,0,0,1,1,1,1
1,1,1,1,8,0,0,8,1,1,1,1
1,1,1,1,1,1,1,1,1,1,1,1
1,1,1,1,1,1,1,1,1,1,1,1
1,1,1,1,1,1,1,1,1,1,1,1
1,1,1,1,1,1,1,1,1,1,1,1
endlayer

layer
1,1,1,1,1,1,1,1,1,1,1,1
1,1,1,1,1,1,1,1,1,1,1,1
1,1,1,1,1,1,1,1,1,1,1,1
1,1,1,1,1,1,1,1,1,1,1,1
1,1,1,1,8,9,9,8,1,1,1,1
1,1,1,1,12,0,0,10,1,1,1,1
1,1,1,1,12,0,0,10,1,1,1,1
1,1,1,1,8,11,11,8,1,1,1,1
1,1,1,1,1,1,1,1,1,1,1,1
1,1,1,1,1,1,1,1,1,1,1,1
1,1,1,1,1,1,1,1,1,1,1,1
1,1,1,1,1,1,1,1,1,1,1,1
endlayer

layer
1,1,1,1,1,1,1,1,1,1,1,1
1,1,1,1,1,1,1,1,1,1,1,1
1,1,1,1,1,1,1,1,1,1,1,1
1,1,1,8,1,1,1,1,8,1,1,1
1,1,1,1,1,9,9,1,1,1,1,1
1,1,1,1,12,0,0,10,1,1,1,1
1,1,1,1,12,0,0,10,1,1,1,1
1,1,1,1,1,11,11,1,1,1,1,1
1,1,1,8,1,1,1,1,8,1,1,1
1,1,1,1,1,1,1,1,1,1,1,1
1,1,1,1,1,1,1,1,1,1,1,1
1,1,1,1,1,1,1,1,1,1,1,1
endlayer

layer
1,1,1,1,1,1,1,1,1,1,1,1
1,1,1,1,1,1,1,1,1,1,1,1
1,1,1,1,1,1,1,1,1,1,1,1
1,1,1,8,1,9,9,1,8,1,1,1
1,1,1,1,12,0,0,9,1,1,1,1
1,1,1,12,0,0,0,0,10,1,1,1
1,1,1,12,0,0,0,0,10,1,1,1
1,1,1,1,11,0,0,10,1,1,1,1
1,1,1,8,1,11,11,1,8,1,1,1
1,1,1,1,1,1,1,1,1,1,1,1
1,1,1,1,1,1,1,1,1,1,1,1
1,1,1,1,1,1,1,1,1,1,1,1
endlayer

layer
1,1,1,1,1,1,1,1,1,1,1,1
1,1,1,1,1,1,1,1,1,1,1,1
1,1,1,1,1,1,1,1,1,1,1,1
1,1,1,8,1,9,9,1,8,1,1,1
1,1,1,1,12,0,0,9,1,1,1,1
1,1,1,12,0,0,0,0,10,1,1,1
1,1,1,12,0,0,0,0,10,1,1,1
1,1,1,1,11,0,0,10,1,1,1,1
1,1,1,8,1,11,11,1,8,1,1,1
1,1,1,1,1,1,1,1,1,1,1,1
1,1,1,1,1,1,1,1,1,1,1,1
1,1,1,1,1,1,1,1,1,1,1,1
endlayer

layer
1,1,1,1,1,1,1,1,1,1,1,1
1,1,1,1,1,1,1,1,1,1,1,1
1,1,1,1,1,1,1,1,1,1,1,1
1,1,1,8,12,9,9,9,8,1,1,1
1,1,1,12,0,0,0,0,9,1,1,1
1,1,1,12,0,0,0,0,10,1,1,1
1,1,1,12,0,0,0,0,10,1,1,1
1,1,1,11,0,0,0,0,10,1,1,1
1,1,1,8,11,11,11,10,8,1,1,1
1,1,1,1,1,1,1,1,1,1,1,1
1,1,1,1,1,1,1,1,1,1,1,1
1,1,1,1,1,1,1,1,1,1,1,1
endlayer

layer
1,1,1,1,1,1,1,1,1,1,1,1
1,1,1,1,1,1,1,1,1,1,1,1
1,1,1,1,1,1,1,1,1,1,1,1
1,1,1,8,12,9,9,9,8,1,1,1
1,1,1,12,0,0,0,0,9,1,1,1
1,1,1,12,0,0,0,0,10,1,1,1
1,1,1,12,0,0,0,0,10,1,1,1
1,1,1,11,0,0,0,0,10,1,1,1
1,1,1,8,11,11,11,10,8,1,1,1
1,1,1,1,1,1,1,1,1,1,1,1
1,1,1,1,1,1,1,1,1,1,1,1
1,1,1,1,1,1,1,1,1,1,1,1
endlayer

layer
1,1,1,1,1,1,1,1,1,1,1,1
1,1,1,1,1,1,1,1,1,1,1,1
1,1,1,1,12,12,9,9,1,1,1,1
1,1,1,12,0,0,0,0,9,1,1,1
1,1,12,0,0,0,0,0,0,9,1,1
1,1,12,0,0,0,0,0,0,9,1,1
1,1,11,0,0,0,0,0,0,10,1,1
1,1,11,0,0,0,0,0,0,10,1,1
1,1,1,11,0,0,0,10,10,1,1,1
1,1,1,1,11,11,10,10,1,1,1,1
1,1,1,1,1,1,1,1,1,1,1,1
1,1,1,1,1,1,1,1,1,1,1,1
endlayer

layer
1,1,1,1,1,1,1,1,1,1,1,1
1,1,1,1,1,1,1,1,1,1,1,1
1,1,1,1,12,12,9,9,1,1,1,1
1,1,1,12,0,0,0,0,9,1,1,1
1,1,12,0,0,0,0,0,0,9,1,1
1,1,12,0,0,0,0,0,0,9,1,1
1,1,11,0,0,0,0,0,0,10,1,1
1,1,11,0,0,0,0,0,0,10,1,1
1,1,1,11,0,0,0,10,10,1,1,1
1,1,1,1,11,11,10,10,1,1,1,1
1,1,1,1,1,1,1,1,1,1,1,1
1,1,1,1,1,1,1,1,1,1,1,1
endlayer

layer
1,1,1,1,1,1,1,1,1,1,1,1
1,1,1,1,12,12,12,9,1,1,1,1
1,1,1,12,0,0,0,0,9,1,1,1
1,1,12,0,0,0,0,0,0,9,1,1
1,12,0,0,0,0,0,0,0,0,9,1
1,11,0,0,0,0,0,0,0,0,9,1
1,11,0,0,0,0,0,0,0,0,9,1
1,11,0,0,0,0,0,0,0,0,10,1
1,1,11,0,0,0,0,0,0,10,1,1
1,1,1,11,0,0,0,0,10,1,1,1
1,1,1,1,11,10,10,10,1,1,1,1
1,1,1,1,1,1,1,1,1,1,1,1
endlayer

layer
1,1,1,1,1,1,1,1,1,1,1,1
1,1,1,1,12,12,12,9,1,1,1,1
1,1,1,12,0,0,0,0,9,1,1,1
1,1,12,0,0,0,0,0,0,9,1,1
1,12,0,0,0,0,0,0,0,0,9,1
1,11,0,0,0,0,0,0,0,0,9,1
1,11,0,0,0,0,0,0,0,0,9,1
1,11,0,0,0,0,0,0,0,0,10,1
1,1,11,0,0,0,0,0,0,10,1,1
1,1,1,11,0,0,0,0,10,1,1,1
1,1,1,1,11,10,10,10,1,1,1,1
1,1,1,1,1,1,1,1,1,1,1,1
endlayer

layer
1,1,1,1,12,12,12,12,1,1,1,1
1,1,1,12,0,0,0,0,9,1,1,1
1,1,12,0,0,0,0,0,0,9,1,1
1,12,0,0,0,0,0,0,0,0,9,1
11,0,0,0,0,0,0,0,0,0,0,9
11,0,0,0,0,0,0,0,0,0,0,9
11,0,0,0,0,0,0,0,0,0,0,9
11,0,0,0,0,0,0,0,0,0,0,9
1,11,0,0,0,0,0,0,0,0,10,1
1,1,11,0,0,0,0,0,0,10,1,1
1,1,1,11,0,0,0,0,10,1,1,1
1,1,1,1,10,10,10,10,1,1,1,1
endlayer

layer
1,1,1,1,12,12,12,12,1,1,1,1
1,1,1,12,0,0,0,0,9,1,1,1
1,1,12,0,0,0,0,0,0,9,1,1
1,12,0,0,0,0,0,0,0,0,9,1
11,0,0,0,0,0,0,0,0,0,0,9
11,0,0,0,0,0,0,0,0,0,0,9
11,0,0,0,0,0,0,0,0,0,0,9
11,0,0,0,0,0,0,0,0,0,0,9
1,11,0,0,0,0,0,0,0,0,10,1
1,1,11,0,0,0,0,0,0,10,1,1
1,1,1,11,0,0,0,0,10,1,1,1
1,1,1,1,10,10,10,10,1,1,1,1
endlayer

layer
1,1,1,1,12,12,12,12,1,1,1,1
1,1,1,12,0,0,0,0,12,1,1,1
1,1,12,0,0,0,0,0,0,9,1,1
1,11,0,0,0,0,0,0,0,0,9,1
11,0,0,0,0,0,0,0,0,0,0,9
11,0,0,0,0,0,0,0,0,0,0,9
11,0,0,0,0,0,0,0,0,0,0,9
11,0,0,0,0,0,0,0,0,0,0,9
1,11,0,0,0,0,0,0,0,0,9,1
1,1,11,0,0,0,0,0,0,10,1,1
1,1,1,10,0,0,0,0,10,1,1,1
1,1,1,1,10,10,10,10,1,1,1,1
endlayer

layer
1,1,1,1,12,12,12,12,1,1,1,1
1,1,1,12,0,0,0,0,12,1,1,1
1,1,12,0,0,0,0,0,0,9,1,1
1,11,0,0,0,0,0,0,0,0,9,1
11,0,0,0,0,0,0,0,0,0,0,9
11,0,0,0,0,0,0,0,0,0,0,9
11,0,0,0,0,0,0,0,0,0,0,9
11,0,0,0,0,0,0,0,0,0,0,9
1,11,0,0,0,0,0,0,0,0,9,1
1,1,11,0,0,0,0,0,0,10,1,1
1,1,1,10,0,0,0,0,10,1,1,1
1,1,1,1,10,10,10,10,1,1,1,1
endlayer

layer
1,1,1,1,1,1,1,1,1,1,1,1
1,1,1,1,12,12,12,12,1,1,1,1
1,1,1,12,0,0,0,0,12,1,1,1
1,1,11,0,0,0,0,0,0,9,1,1
1,11,0,0,0,0,0,0,0,0,9,1
1,11,0,0,0,0,0,0,0,0,9,1
1,11,0,0,0,0,0,0,0,0,9,1
1,11,0,0,0,0,0,0,0,0,9,1
1,1,11,0,0,0,0,0,0,9,1,1
1,1,1,10,0,0,0,0,10,1,1,1
1,1,1,1,10,10,10,10,1,1,1,1
1,1,1,1,1,1,1,1,1,1,1,1
endlayer

layer
1,1,1,1,1,1,1,1,1,1,1,1
1,1,1,1,12,12,12,12,1,1,1,1
1,1,1,12,0,0,0,0,12,1,1,1
1,1,11,0,0,0,0,0,0,9,1,1
1,11,0,0,0,0,0,0,0,0,9,1
1,11,0,0,0,0,0,0,0,0,9,1
1,11,0,0,0,0,0,0,0,0,9,1
1,11,0,0,0,0,0,0,0,0,9,1
1,1,11,0,0,0,0,0,0,9,1,1
1,1,1,10,0,0,0,0,10,1,1,1
1,1,1,1,10,10,10,10,1,1,1,1
1,1,1,1,1,1,1,1,1,1,1,1
endlayer

layer
1,1,1,1,1,1,1,1,1,1,1,1
1,1,1,1,1,1,1,1,1,1,1,1
1,1,1,1,12,12,12,12,1,1,1,1
1,1,1,11,0,0,0,0,12,1,1,1
1,1,11,0,0,0,0,0,0,9,1,1
1,1,11,0,0,0,0,0,0,9,1,1
1,1,11,0,0,0,0,0,0,9,1,1
1,1,11,0,0,0,0,0,0,9,1,1
1,1,1,10,0,0,0,0,9,1,1,1
1,1,1,1,10,10,10,10,1,1,1,1
1,1,1,1,1,1,1,1,1,1,1,1
1,1,1,1,1,1,1,1,1,1,1,1
endlayer

layer
1,1,1,1,1,1,1,1,1,1,1,1
1,1,1,1,1,1,1,1,1,1,1,1
1,1,1,1,1,1,1,1,1,1,1,1
1,1,1,1,11,11,12,12,1,1,1,1
1,1,1,11,11,11,12,12,12,1,1,1
1,1,1,11,11,11,12,12,12,1,1,1
1,1,1,11,10,10,9,9,9,1,1,1
1,1,1,10,10,10,9,9,9,1,1,1
1,1,1,1,10,10,9,9,1,1,1,1
1,1,1,1,1,1,1,1,1,1,1,1
1,1,1,1,1,1,1,1,1,1,1,1
1,1,1,1,1,1,1,1,1,1,1,1
endlayer
