biomesToSpawnIn=shore,river,bayou,beach,blessed bog
weight=2
embed_into_distance=5
dimensions=9,7,7
cut_in_buffer=0
max_leveling=1
leveling_buffer=0
preserve_water=1
preserve_lava=0
preserve_plants=0
max_cut_in=1


rule1=0,100,stonebrick-1,stonebrick-1,stonebrick-2,stonebrick
rule2=0,70,stonebrick-1,stonebrick-1,stonebrick-2,stonebrick
rule3=2,50,stone_brick_stairs-6
rule4=2,50,stone_brick_stairs-4
rule5=1,80,stonebrick-1,stonebrick-1,stonebrick-2,stonebrick
rule6=2,50,stone_brick_stairs-5
rule7=2,50,stone_brick_stairs-7
rule8=2,50,stonebrick-1,stonebrick-1,stonebrick-2,stonebrick
rule9=0,100,preserveBlock


layer
9,9,9,9,9,9,9
9,1,9,9,9,1,9
9,9,9,9,9,9,9
9,9,9,9,9,9,9
9,9,9,9,9,9,9
9,1,9,9,9,1,9
9,9,9,9,9,9,9
endlayer

layer
9,9,9,9,9,9,9
9,1,9,9,9,1,9
9,9,9,9,9,9,9
9,9,9,9,9,9,9
9,9,9,9,9,9,9
9,1,9,9,9,1,9
9,9,9,9,9,9,9
endlayer

layer
9,9,9,9,9,9,9
9,1,9,9,9,1,9
9,9,9,9,9,9,9
9,9,9,9,9,9,9
9,9,9,9,9,9,9
9,1,9,9,9,1,9
9,9,9,9,9,9,9
endlayer

layer
9,9,9,9,9,9,9
9,1,9,9,9,1,9
9,9,9,9,9,9,9
9,9,9,9,9,9,9
9,9,9,9,9,9,9
9,1,9,9,9,1,9
9,9,9,9,9,9,9
endlayer

layer
9,9,9,9,9,9,9
9,1,9,9,9,1,9
9,9,9,9,9,9,9
9,9,9,9,9,9,9
9,9,9,9,9,9,9
9,1,9,9,9,1,9
9,9,9,9,9,9,9
endlayer

layer
9,9,9,9,9,9,9
9,1,9,9,9,1,9
9,9,9,9,9,9,9
9,9,9,9,9,9,9
9,9,9,9,9,9,9
9,1,9,9,9,1,9
9,9,9,9,9,9,9
endlayer

layer
9,9,9,9,9,9,9
9,2,9,9,9,2,9
9,9,9,9,9,9,9
9,9,9,9,9,9,9
9,9,9,9,9,9,9
9,2,9,9,9,2,9
9,9,9,9,9,9,9
endlayer

layer
9,4,9,9,9,4,9
7,5,3,9,7,5,3
9,6,9,9,9,6,9
9,9,9,9,9,9,9
9,4,9,9,9,4,9
7,5,3,9,7,5,3
9,6,9,9,9,6,9
endlayer

layer
9,8,9,9,9,8,9
8,5,8,9,8,5,8
9,8,9,9,9,8,9
9,9,9,9,9,9,9
9,8,9,9,9,8,9
8,5,8,9,8,5,8
9,8,9,9,9,8,9
endlayer

