biomesToSpawnIn=autumn hills,autumn woods,bamboo forest,birch forest,bog,boneyard,boreal forest,brushland,chaparral,cherry blossom grove,coniferous forest,deciduous forest,extreme hills,extreme hills edge,fen,field,forest,forested field,forested hills,forested island,foresthills,fungi forest,garden,grassland,green hills,green swamplands,grove,heathland,hell,highland,hot springs,jade cliffs,jungle,junglehills,lavender fields,lush redwoods,lush swamp,magical forest,majestic meadow,mangrove,maplewoods,marsh,meadow,meadow forest,mesa,mini jungle,mountain, mountain ridge,mountain taiga,mystic grove,orchard,outback,overgrown beach,overgrown greens,pasture,pasture meadow,pine forest,plains,prarie,quagmire,rainforest,redwood forest,sacred springs,savanna,savanna plateau,scrubland,seasonal forest,seasonal spruce forest,shield,spruce woods,steppe,sublime shrubland,swampland,taiga,taigahills,temperate rainforest,thick shrubland,thicket,thinned mystic grove,thinned pasture,thinned timber,timber,tropical rainforest,tropics mountain,tundra,wonderous woods,woodland,woodlands,wyvern biome,wetland
weight=1
embed_into_distance=1
unacceptable_target_blocks=flowing_water,water,flowing_lava,lava,Natura:Cloud,red_mushroom_block,brown_mushroom_block,planks,cobblestone,end_stone,obsidian,purpur_block,iron_bars,purpur_slab,purpur_pillar,netherrack,soul_sand,quartz_ore
dimensions=9,8,9
cut_in_buffer=1
max_leveling=2
leveling_buffer=-1
preserve_water=0
preserve_lava=0
preserve_plants=0
max_cut_in=10


rule1=0,100,preserveBlock
rule2=0,100,cobblestone
rule3=0,100,gravel
rule4=0,100,planks
rule5=0,100,oak_stairs-3
rule6=0,100,crafting_table
rule7=0,100,oak_stairs-1
rule8=0,100,fence
rule9=0,100,wooden_door
rule10=0,100,glass_pane
rule11=0,100,wooden_pressure_plate
rule12=0,100,wooden_door-8
rule13=0,100,bookshelf
rule14=0,100,oak_stairs


layer
1,1,1,1,1,1,1,1,1
2,2,2,2,2,2,2,2,2
2,2,2,2,2,2,2,2,2
2,2,2,2,2,2,2,2,2
2,2,2,2,2,2,2,2,2
2,2,2,2,2,2,2,2,2
2,2,2,2,2,2,2,2,2
3,3,3,3,3,3,3,3,3
endlayer

layer
0,0,0,0,0,0,0,0,0
2,2,2,2,2,2,2,2,2
2,0,0,7,7,7,7,4,2
2,0,0,0,8,0,8,5,2
2,0,0,0,0,0,0,0,2
2,0,0,0,0,0,0,6,2
2,9,2,2,2,2,2,2,2
0,0,0,0,0,0,0,0,0
endlayer

layer
0,0,0,0,0,0,0,0,0
2,4,10,10,4,10,10,4,2
4,0,0,0,0,0,0,0,4
10,0,0,0,11,0,11,0,10
10,0,0,0,0,0,0,0,10
4,0,0,0,0,0,0,0,4
2,12,4,4,10,10,10,4,2
0,0,0,0,0,0,0,0,0
endlayer

layer
0,0,0,0,0,0,0,0,0
2,4,4,4,4,4,4,4,2
4,13,13,13,13,13,13,13,4
10,0,0,0,0,0,0,0,10
10,0,0,0,0,0,0,0,10
4,0,0,0,0,0,0,0,4
2,4,4,4,10,10,10,4,2
0,0,0,0,0,0,0,0,0
endlayer

layer
0,0,0,0,0,0,0,0,0
2,4,4,4,4,4,4,4,2
4,4,4,4,4,4,4,4,4
4,0,0,0,0,0,0,0,4
4,0,0,0,0,0,0,0,4
4,4,4,4,4,4,4,4,4
2,4,4,4,4,4,4,4,2
0,0,0,0,0,0,0,0,0
endlayer

layer
14,14,14,14,14,14,14,14,14
2,2,2,2,2,2,2,2,2
2,2,2,2,2,2,2,2,2
2,2,2,2,2,2,2,2,2
2,2,2,2,2,2,2,2,2
2,2,2,2,2,2,2,2,2
2,2,2,2,2,2,2,2,2
7,7,7,7,7,7,7,7,7
endlayer

layer
0,0,0,0,0,0,0,0,0
14,14,14,14,14,14,14,14,14
2,2,2,2,2,2,2,2,2
2,2,2,2,2,2,2,2,2
2,2,2,2,2,2,2,2,2
2,2,2,2,2,2,2,2,2
7,7,7,7,7,7,7,7,7
0,0,0,0,0,0,0,0,0
endlayer

layer
0,0,0,0,0,0,0,0,0
0,0,0,0,0,0,0,0,0
14,14,14,14,14,14,14,14,14
2,2,2,2,2,2,2,2,2
2,2,2,2,2,2,2,2,2
7,7,7,7,7,7,7,7,7
0,0,0,0,0,0,0,0,0
0,0,0,0,0,0,0,0,0
endlayer

layer
0,0,0,0,0,0,0,0,0
0,0,0,0,0,0,0,0,0
0,0,0,0,0,0,0,0,0
14,14,14,14,14,14,14,14,14
7,7,7,7,7,7,7,7,7
0,0,0,0,0,0,0,0,0
0,0,0,0,0,0,0,0,0
0,0,0,0,0,0,0,0,0
endlayer

