# Converted from schematic
# THIS TEMPLATE USES DEFAULTS!  Please edit for corrections.
# If you need help, consult template_rules.txt
biomesToSpawnIn=desert,desert oil field,deserthills,dunes,lush desert,mountainous desert,desert_hills,desert_defiled,desert_shrubland,mutated_desert
weight=1
embed_into_distance=1
unacceptable_target_blocks=flowing_water,water,flowing_lava,lava,Natura:Cloud,red_mushroom_block,brown_mushroom_block,planks,cobblestone,end_stone,obsidian,purpur_block,iron_bars,purpur_slab,purpur_pillar,netherrack,soul_sand,quartz_ore
dimensions=6,7,9
allowable_overhang=0
max_cut_in=2
cut_in_buffer=1
max_leveling=2
leveling_buffer=-1
preserve_water=0
preserve_lava=0
preserve_plants=0


rule1=0,100,sand
rule2=0,100,sandstone
rule3=0,100,stone_slab-1
rule4=0,100,double_stone_slab-1
rule5=0,100,wooden_door-3
rule6=0,100,wooden_door-1
rule7=0,100,wooden_door-11
rule8=0,100,wooden_door-9
rule9=2,100,torch-2
rule10=2,100,torch-3
rule11=2,100,torch-1
rule12=2,100,torch-4


layer
1,1,1,1,1,1,1,1,1
1,1,1,1,1,1,1,1,1
1,1,2,2,1,2,2,1,1
2,2,2,2,1,2,2,2,2
1,1,2,2,1,2,2,2,2
1,1,1,1,1,1,1,1,1
1,1,1,1,1,1,1,1,1
endlayer

layer
3,2,3,2,3,2,3,2,3
3,2,2,2,2,2,2,2,3
2,2,3,3,2,3,3,2,4
0,6,0,0,2,0,0,5,0
2,2,3,3,2,3,3,2,4
3,2,4,2,2,2,2,2,3
3,2,3,2,3,2,3,2,3
endlayer

layer
0,2,0,2,0,2,0,2,0
0,2,2,2,2,2,2,2,0
2,2,3,3,2,3,3,2,2
0,8,0,0,2,0,0,7,0
2,2,3,3,2,3,3,2,2
0,2,2,2,2,2,2,2,0
0,2,0,2,0,2,0,2,0
endlayer

layer
0,2,9,2,9,2,9,2,0
0,2,2,2,2,2,2,2,0
3,2,3,3,2,3,3,2,3
3,2,12,0,2,0,10,2,3
3,2,3,3,2,3,3,2,3
0,2,2,2,2,2,2,2,0
0,2,11,2,11,2,11,2,0
endlayer

layer
3,2,2,2,2,2,2,2,3
3,4,4,2,2,2,4,4,3
3,4,2,2,2,2,2,4,3
3,4,2,2,2,2,2,4,3
3,4,2,2,2,2,2,4,3
3,4,4,2,2,2,4,4,3
3,2,2,2,2,2,2,2,3
endlayer

layer
0,0,3,2,2,2,3,0,0
0,0,3,4,4,4,3,0,0
0,0,3,4,4,4,3,0,0
0,0,3,4,4,4,3,0,0
0,0,3,4,4,4,3,0,0
0,0,3,4,4,4,3,0,0
0,0,3,2,2,2,3,0,0
endlayer

