# Underwater Base
# Updated to MC 1.9

biomesToSpawnIn=deep ocean

weight=1

uniqueMinDistance=1000

embed_into_distance=14
acceptable_target_blocks=water
dimensions=11,35,34
allowable_overhang=9001
max_leveling=0
leveling_buffer=0
preserve_water=0
preserve_lava=0
preserve_plants=0


rule1=0,100,sandstone
rule2=0,100,double_stone_slab-1
rule3=0,100,stone_slab-1
rule4=0,100,sandstone_stairs-0
rule5=0,100,sandstone_stairs-1
rule6=0,100,sandstone
rule7=0,100,sandstone_stairs-3
rule8=0,100,grass
rule9=0,100,water
rule10=0,100,sandstone_stairs-2
rule11=0,100,farmland-7
rule12=0,100,water-2
rule13=0,100,water-1
rule14=0,100,water-9
rule15=0,100,water-8
rule16=0,100,sandstone-2
rule17=0,100,bed-3
rule18=0,100,bed-11
rule19=0,100,stone_slab-9
rule20=0,100,ChestGenHook:chests/spawn_bonus_chest:3-3
rule21=0,100,ChestGenHook:chests/simple_dungeon:4-3
rule22=0,100,crafting_table
rule23=0,100,lit_furnace-2
rule24=0,100,sandstone_stairs-5
rule25=0,100,sandstone_stairs-4
rule26=0,100,wall_sign-3
rule27=0,100,enchanting_table-1
rule28=0,100,tallgrass-1
rule29=0,100,trapdoor-6
rule30=0,100,trapdoor-5
rule31=0,100,wall_sign-2
rule32=0,100,sandstone-1
rule33=0,100,trapdoor-4
rule34=0,100,wheat-7
rule35=0,100,wheat-7
rule36=0,100,lit_furnace-3
rule37=0,100,sandstone_stairs-6
rule38=0,100,ladder-4
rule39=0,100,red_flower
rule40=0,100,yellow_flower
rule41=0,100,quark:blaze_lantern
rule42=0,100,sandstone_stairs-7
rule43=0,100,glass
rule44=0,100,ChestGenHook:chests/stronghold_corridor:2-5
rule45=0,100,farmland-7
rule46=0,100,ChestGenHook:chests/spawn_bonus_chest:3-2
rule47=0,100,ChestGenHook:chests/stronghold_library:2-3
rule48=0,100,ChestGenHook:gameplay/fishing/treasure:1-3


layer
1,1,1,1,1,1,1,1,1,1,1,1,1,1,1,1,1,1,1,1,1,1,1,1,1,1,1,1,1,1,1,1,1,1
1,1,1,1,1,1,1,1,1,1,1,1,1,1,1,1,1,1,1,1,1,1,1,1,1,1,1,1,1,1,1,1,1,1
1,1,1,1,1,1,1,1,1,1,1,1,1,1,1,1,1,1,1,1,1,1,1,1,1,1,1,1,1,1,1,1,1,1
1,1,1,1,1,1,1,1,1,1,1,1,1,1,1,1,1,1,1,1,1,1,1,1,1,1,1,1,1,1,1,1,1,1
1,1,1,1,1,1,1,1,1,1,1,1,1,1,1,1,1,1,1,1,1,1,1,1,1,1,1,1,1,1,1,1,1,1
1,1,1,1,1,1,1,1,1,1,1,1,1,1,1,1,1,1,1,1,1,1,1,1,1,1,1,1,1,1,1,1,1,1
1,1,1,1,1,1,1,1,1,1,1,1,1,1,1,1,1,1,1,1,1,1,1,1,1,1,1,1,1,1,1,1,1,1
1,1,1,1,1,1,1,1,1,1,1,1,1,1,1,1,1,1,1,1,1,1,1,1,1,1,1,1,1,1,1,1,1,1
1,1,1,1,1,1,1,1,1,1,1,1,1,1,1,1,1,1,1,1,1,1,1,1,1,1,1,1,1,1,1,1,1,1
1,1,1,1,1,1,1,1,1,1,1,1,1,1,1,1,1,1,1,1,1,1,1,1,1,1,1,1,1,1,1,1,1,1
1,1,1,1,1,1,1,1,1,1,1,1,1,1,1,1,1,1,1,1,1,1,1,1,1,1,1,1,1,1,1,1,1,1
1,1,1,1,1,1,1,1,1,1,1,1,1,1,1,1,1,1,1,1,1,1,1,1,1,1,1,1,1,1,1,1,1,1
1,1,1,1,1,1,1,1,1,1,1,1,1,1,1,1,1,1,1,1,1,1,1,1,1,1,1,1,1,1,1,1,1,1
1,1,1,1,1,1,1,1,1,1,1,1,1,1,1,1,1,1,1,1,1,1,1,1,1,1,1,1,1,1,1,1,1,1
1,1,1,1,1,1,1,1,1,1,1,1,1,1,1,1,1,1,1,1,1,1,1,1,1,1,1,1,1,1,1,1,1,1
1,1,1,1,1,1,1,1,1,1,1,1,1,1,1,1,1,1,1,1,1,1,1,1,1,1,1,1,1,1,1,1,1,1
1,1,1,1,1,1,1,1,1,1,1,1,1,1,1,1,1,1,1,1,1,1,1,1,1,1,1,1,1,1,1,1,1,1
1,1,1,1,1,1,1,1,1,1,1,1,1,1,1,1,1,1,1,1,1,1,1,1,1,1,1,1,1,1,1,1,1,1
1,1,1,1,1,1,1,1,1,1,1,1,1,1,1,1,1,1,1,1,1,1,1,1,1,1,1,1,1,1,1,1,1,1
1,1,1,1,1,1,1,1,1,1,1,1,1,1,1,1,1,1,1,1,1,1,1,1,1,1,1,1,1,1,1,1,1,1
1,1,1,1,1,1,1,1,1,1,1,1,1,1,1,1,1,1,1,1,1,1,1,1,1,1,1,1,1,1,1,1,1,1
1,1,1,1,1,1,1,1,1,1,1,1,1,1,1,1,1,1,1,1,1,1,1,1,1,1,1,1,1,1,1,1,1,1
1,1,1,1,1,1,1,1,1,1,1,1,1,1,1,1,1,1,1,1,1,1,1,1,1,1,1,1,1,1,1,1,1,1
1,1,1,1,1,1,1,1,1,1,1,1,1,1,1,1,1,1,1,1,1,1,1,1,1,1,1,1,1,1,1,1,1,1
1,1,1,1,1,1,1,1,1,1,1,1,1,1,1,1,1,1,1,1,1,1,1,1,1,1,1,1,1,1,1,1,1,1
1,1,1,1,1,1,1,1,1,1,1,1,1,1,1,1,1,1,1,1,1,1,1,1,1,1,1,1,1,1,1,1,1,1
1,1,1,1,1,1,1,1,1,1,1,1,1,1,1,1,1,1,1,1,1,1,1,1,1,1,1,1,1,1,1,1,1,1
1,1,1,1,1,1,1,1,1,1,1,1,1,1,1,1,1,1,1,1,1,1,1,1,1,1,1,1,1,1,1,1,1,1
1,1,1,1,1,1,1,1,1,1,1,1,1,1,1,1,1,1,1,1,1,1,1,1,1,1,1,1,1,1,1,1,1,1
1,1,1,1,1,1,1,1,1,1,1,1,1,1,1,1,1,1,1,1,1,1,1,1,1,1,1,1,1,1,1,1,1,1
1,1,1,1,1,1,1,1,1,1,1,1,1,1,1,1,1,1,1,1,1,1,1,1,1,1,1,1,1,1,1,1,1,1
1,1,1,1,1,1,1,1,1,1,1,1,1,1,1,1,1,1,1,1,1,1,1,1,1,1,1,1,1,1,1,1,1,1
1,1,1,1,1,1,1,1,1,1,1,1,1,1,1,1,1,1,1,1,1,1,1,1,1,1,1,1,1,1,1,1,1,1
1,1,1,1,1,1,1,1,1,1,1,1,1,1,1,1,1,1,1,1,1,1,1,1,1,1,1,1,1,1,1,1,1,1
1,1,1,1,1,1,1,1,1,1,1,1,1,1,1,1,1,1,1,1,1,1,1,1,1,1,1,1,1,1,1,1,1,1
endlayer

layer
1,1,1,1,1,1,1,1,1,1,1,1,1,1,1,1,1,1,1,1,1,1,1,1,1,1,1,1,1,1,1,1,1,1
1,1,1,1,1,1,1,1,1,1,1,1,1,1,1,1,1,1,1,1,1,1,1,1,1,1,1,1,1,1,1,1,1,1
1,2,2,2,2,2,2,2,2,2,2,2,2,2,2,2,2,2,2,2,2,2,2,2,2,2,2,2,2,2,2,2,2,1
1,2,3,3,2,2,2,2,2,2,2,2,2,2,2,2,2,2,2,2,2,2,2,2,2,2,2,2,2,2,2,2,2,1
1,2,3,3,2,2,2,2,2,2,2,2,45,9,11,2,3,3,2,8,8,2,2,2,2,2,2,2,2,2,3,2,2,1
1,2,3,3,2,3,3,3,3,3,3,2,45,9,11,2,3,3,2,8,8,2,2,3,3,3,3,3,2,2,3,2,2,1
1,2,3,3,3,3,3,3,3,10,3,2,45,9,11,2,3,3,2,2,2,2,2,3,3,3,3,3,2,2,3,2,2,1
1,2,3,3,2,3,3,3,3,3,3,2,45,9,11,2,3,3,3,3,3,3,3,3,3,3,3,3,2,2,3,2,2,1
1,2,3,3,2,2,2,2,2,2,2,2,45,9,11,2,3,3,2,2,2,2,2,3,3,3,3,3,2,2,3,2,2,1
1,2,3,3,2,2,2,2,2,2,2,2,45,9,11,2,3,3,2,8,8,2,2,3,3,3,3,3,2,2,3,2,2,1
1,2,3,3,3,3,3,3,3,3,3,2,45,9,11,2,4,3,2,8,8,2,2,2,2,2,2,2,2,2,3,2,2,1
1,2,3,3,3,3,3,3,3,3,3,2,2,2,2,2,10,3,2,8,8,2,2,3,3,3,3,3,2,2,3,2,2,1
1,2,3,3,3,3,3,3,3,3,3,3,3,3,7,5,5,3,2,2,2,2,2,3,3,5,3,4,2,2,3,2,2,1
1,2,3,3,3,3,3,3,3,3,3,3,3,3,3,3,3,3,3,3,3,3,3,3,3,3,7,2,2,2,3,2,2,1
1,2,3,3,2,2,2,2,2,2,2,2,2,2,2,2,3,3,2,2,2,2,2,3,3,4,3,5,2,2,3,2,2,1
1,2,3,3,2,2,2,2,2,2,2,2,2,2,2,2,3,3,2,8,8,2,2,3,3,3,3,3,2,2,3,2,2,1
1,2,3,3,2,2,3,7,4,4,10,3,3,3,2,2,3,3,2,8,8,2,2,2,2,2,2,2,2,2,3,2,2,1
1,2,3,3,2,2,4,4,2,2,10,3,3,3,2,2,3,3,2,8,8,2,2,2,2,2,2,6,2,2,3,2,2,1
1,2,3,3,2,2,2,2,2,2,10,3,3,3,2,2,3,3,2,2,2,2,2,2,2,2,2,2,2,2,3,2,2,1
1,2,3,3,2,2,2,2,2,2,10,3,3,3,2,2,3,3,3,3,3,3,3,3,3,2,2,2,2,2,3,2,2,1
1,2,3,3,2,2,5,7,2,2,10,3,3,3,2,2,3,3,2,2,2,2,2,2,2,2,2,2,2,2,3,2,2,1
1,2,3,3,2,2,3,7,5,5,10,3,3,3,2,2,3,3,2,8,8,2,2,2,2,2,2,6,2,2,3,2,2,1
1,2,3,3,2,2,2,2,2,2,2,2,2,2,2,2,3,3,2,8,8,2,2,2,2,2,2,2,2,2,3,2,2,1
1,2,3,3,2,2,2,2,2,2,2,2,2,2,2,2,3,3,2,2,2,2,2,2,2,2,2,2,2,2,3,2,2,1
1,2,3,3,3,3,3,3,3,3,3,3,3,3,3,3,3,3,3,3,3,3,3,3,3,3,3,3,3,3,3,2,2,1
1,2,3,3,3,3,3,3,3,3,3,3,3,3,3,3,3,3,3,3,3,3,3,3,3,3,3,3,3,3,3,2,2,1
1,2,2,2,3,2,2,2,2,2,3,2,2,2,2,2,3,3,2,2,2,2,2,3,2,2,2,2,2,3,2,2,1,1
1,2,2,2,3,2,2,2,2,2,3,2,2,2,1,2,3,3,2,1,2,2,2,3,2,2,2,2,2,3,2,2,2,1
1,2,3,3,3,3,3,2,3,3,3,3,3,2,1,2,3,3,2,1,2,3,3,3,3,3,2,3,3,3,3,3,2,1
1,2,3,3,3,3,3,2,3,3,3,3,3,2,1,2,3,3,2,1,2,3,3,3,3,3,2,3,3,3,3,3,2,1
1,2,3,3,3,3,2,2,3,3,3,3,2,2,1,2,3,3,2,1,2,2,3,3,3,3,2,2,3,3,3,3,2,1
1,2,2,3,3,3,2,2,2,3,3,3,2,2,1,2,3,3,2,1,2,2,3,3,3,2,2,2,3,3,3,2,2,1
1,2,2,3,3,3,2,2,2,3,3,3,2,2,1,2,3,3,2,1,2,2,3,3,3,2,2,2,3,3,3,2,2,1
1,2,2,2,2,2,2,2,2,2,2,2,2,2,1,2,3,3,2,1,2,2,2,2,2,2,2,2,2,2,2,2,2,1
1,1,1,1,1,1,1,1,1,1,1,1,1,1,1,1,9,9,1,1,1,1,1,1,1,1,1,1,1,1,1,1,1,1
endlayer

layer
13,13,13,13,13,13,13,13,13,13,13,13,13,13,13,13,13,13,14,13,13,13,13,13,13,14,13,13,13,13,13,13,13,12
14,14,14,14,14,14,14,14,14,14,14,14,14,14,14,14,14,14,15,14,14,14,14,14,14,15,14,14,14,14,14,14,14,13
15,16,16,16,16,16,16,16,16,16,16,16,16,16,16,16,16,16,16,16,16,16,16,16,16,16,16,16,16,16,16,16,16,14
15,16,0,0,0,0,0,0,0,0,0,0,0,0,0,0,0,0,0,0,0,0,0,0,0,0,0,0,0,0,0,0,16,14
15,16,0,0,32,32,32,32,32,32,32,32,35,0,34,0,0,0,0,28,28,0,16,16,16,16,16,16,16,0,0,0,16,14
15,16,0,0,32,0,0,0,0,0,0,32,35,0,34,0,0,0,0,28,28,0,16,19,19,19,19,19,16,0,0,0,16,14
15,16,0,0,0,0,0,0,0,37,0,32,35,0,34,0,0,0,0,0,0,0,16,0,0,0,0,19,16,0,0,0,16,14
15,16,0,0,32,0,38,0,0,0,0,32,35,0,34,0,0,0,0,0,0,0,0,0,0,0,0,19,16,0,0,0,16,14
15,16,0,0,32,32,32,32,32,32,32,32,35,0,34,0,0,0,0,0,0,0,16,0,0,0,0,19,16,0,0,0,16,14
15,16,0,0,0,0,0,0,0,0,0,0,35,0,34,0,0,0,0,28,28,0,16,19,19,19,19,19,16,0,0,0,16,14
15,16,0,0,0,0,0,0,0,0,0,0,35,0,34,0,0,0,0,28,28,0,16,16,16,16,16,16,16,0,0,0,16,14
14,16,0,0,0,0,0,0,0,0,0,0,0,0,0,32,0,0,0,28,28,0,16,0,26,19,0,0,16,0,0,0,16,14
14,16,0,0,0,0,0,0,0,0,0,0,0,0,0,0,0,0,0,0,0,0,16,0,26,24,0,0,16,0,0,0,16,14
14,16,0,0,0,0,0,0,0,0,0,0,0,0,0,0,0,0,0,0,0,0,0,0,26,19,0,48,16,0,0,0,16,14
14,16,0,0,0,0,0,0,0,0,0,0,0,0,0,0,0,0,0,0,0,0,16,0,26,25,0,0,16,0,0,0,16,14
14,16,0,0,0,16,16,16,16,16,16,16,16,16,16,0,0,0,0,28,28,0,16,0,26,19,0,0,16,0,0,0,16,15
14,16,0,0,0,16,0,0,0,0,0,0,0,0,16,0,0,0,0,28,28,0,16,16,16,16,16,16,16,0,0,0,16,14
14,16,0,0,0,16,0,0,5,7,0,0,0,0,16,0,0,0,0,28,28,0,16,3,3,3,3,6,16,0,0,0,16,14
14,16,0,0,0,16,0,21,10,7,0,0,0,0,0,0,0,0,0,0,0,27,16,0,0,0,3,6,16,0,0,0,16,14
14,16,0,0,0,16,0,21,10,7,0,0,0,0,0,0,0,0,0,0,0,0,0,0,0,0,3,6,16,0,0,0,16,14
14,16,0,0,0,16,0,0,10,4,0,0,0,0,16,0,0,0,0,0,0,27,16,0,0,0,3,6,16,0,0,0,16,14
14,16,0,0,0,16,0,0,0,0,0,0,0,0,16,0,0,0,0,28,28,0,16,3,3,3,3,6,16,0,0,0,16,14
14,16,0,0,0,16,16,16,16,16,16,16,16,16,16,0,0,0,0,28,28,0,16,16,16,16,16,16,16,0,0,0,16,14
14,16,0,0,0,0,0,0,0,0,0,0,0,0,0,0,0,0,0,0,0,0,0,0,0,0,0,0,0,0,0,0,16,14
14,16,0,0,0,0,0,0,0,0,0,0,0,0,0,0,0,0,0,0,0,0,0,0,0,0,0,0,0,0,0,0,16,14
14,16,0,0,0,0,0,0,0,0,0,0,0,0,0,0,0,0,0,0,0,0,0,0,0,0,0,0,0,0,0,0,16,14
14,16,0,0,0,0,0,0,0,0,0,0,0,0,29,0,0,0,0,29,0,0,0,0,0,0,0,0,0,0,0,0,16,14
14,16,16,16,0,16,16,16,16,16,0,16,16,16,8,33,0,0,30,8,16,16,16,0,16,16,16,16,16,0,16,16,16,14
14,16,0,0,0,0,0,16,0,0,0,0,0,16,8,33,0,0,30,8,16,0,0,0,0,0,16,0,0,0,0,0,16,14
14,16,0,0,0,0,0,16,0,0,0,0,0,16,8,33,0,0,30,8,16,0,0,0,0,0,16,0,0,0,0,0,16,14
14,16,0,0,0,0,20,16,0,0,0,0,20,16,8,33,0,0,30,8,16,46,0,0,0,0,16,46,0,0,0,0,16,14
14,16,17,0,0,0,22,16,17,0,0,0,22,16,8,33,0,0,30,8,16,22,0,0,0,17,16,22,0,0,0,17,16,14
14,16,18,0,0,0,36,16,18,0,0,0,36,16,8,33,0,0,30,8,16,23,0,0,0,18,16,23,0,0,0,18,16,14
14,16,16,16,16,16,16,16,16,16,16,16,16,16,16,16,31,26,16,16,16,16,16,16,16,16,16,16,16,16,16,16,16,14
13,14,14,14,14,14,14,14,14,14,14,14,15,9,9,9,9,9,9,9,9,9,9,14,14,14,14,14,14,14,14,14,14,13
endlayer

layer
13,13,13,13,13,13,13,13,13,13,13,13,13,13,13,13,13,13,14,13,13,13,13,13,13,14,13,13,13,13,13,13,13,13
14,14,14,14,14,14,14,14,14,14,14,14,14,14,14,14,14,14,15,14,14,14,14,14,14,15,14,14,14,14,14,14,14,13
15,16,16,16,16,16,16,16,16,16,16,16,16,16,16,16,16,16,16,16,16,16,16,16,16,16,16,16,16,16,16,16,16,14
15,16,0,0,0,0,0,0,0,0,0,0,0,0,0,0,0,0,0,0,0,0,0,0,0,0,0,0,0,0,0,0,16,14
15,16,0,0,16,16,16,16,16,16,16,16,0,0,0,0,0,0,0,0,0,0,16,16,16,16,16,16,16,0,0,0,16,14
15,16,0,0,32,0,0,0,0,0,0,16,0,0,0,0,0,0,0,0,0,0,16,0,0,0,0,0,16,0,0,0,16,14
15,16,0,0,0,0,0,0,0,41,0,16,0,0,0,0,0,0,0,0,0,0,16,0,0,0,0,0,16,0,0,0,16,14
15,16,0,0,32,0,38,0,0,0,0,16,0,0,0,0,0,0,0,0,0,0,0,0,0,0,0,0,16,0,0,0,16,14
15,16,0,0,16,16,16,16,16,16,16,16,0,0,0,0,0,0,0,0,0,0,16,0,0,0,0,0,16,0,0,0,16,14
15,16,0,0,0,0,0,0,0,0,0,0,0,0,0,0,0,0,0,0,0,0,16,0,0,0,0,0,16,0,0,0,16,14
15,16,0,0,0,0,0,0,0,0,0,0,0,0,0,0,0,0,0,0,0,0,16,16,16,16,16,16,16,0,0,0,16,14
14,16,0,0,0,0,0,0,0,0,0,0,0,0,0,41,0,0,0,0,0,0,16,0,0,0,0,0,16,0,0,0,16,14
14,16,0,0,0,0,0,0,0,0,0,0,0,0,0,0,0,0,0,0,0,0,16,0,0,0,0,0,16,0,0,0,16,14
14,16,0,0,0,0,0,0,0,0,0,0,0,0,0,0,0,0,0,0,0,0,0,0,0,0,0,0,16,0,0,0,16,14
14,16,0,0,0,0,0,0,0,0,0,0,0,0,0,0,0,0,0,0,0,0,16,0,0,0,0,0,16,0,0,0,16,14
14,16,0,0,0,16,16,16,16,16,16,16,16,16,16,0,0,0,0,0,0,0,16,0,0,0,0,0,16,0,0,0,16,15
14,16,0,0,0,16,0,0,0,0,0,0,0,0,16,0,0,0,0,0,0,0,16,16,16,16,16,16,16,0,0,0,16,14
14,16,0,0,0,16,0,0,37,0,0,0,0,0,16,0,0,0,0,0,0,0,16,0,0,0,0,0,16,0,0,0,16,14
14,16,0,0,0,16,0,0,37,0,0,0,0,0,0,0,0,0,0,0,0,0,16,0,0,0,0,0,16,0,0,0,16,14
14,16,0,0,0,16,0,0,37,0,0,0,0,0,0,0,0,0,0,0,0,0,0,0,0,0,0,47,16,0,0,0,16,14
14,16,0,0,0,16,0,0,37,0,0,0,0,0,16,0,0,0,0,0,0,0,16,0,0,0,0,0,16,0,0,0,16,14
14,16,0,0,0,16,0,0,0,0,0,0,0,0,16,0,0,0,0,0,0,0,16,0,0,0,0,0,16,0,0,0,16,14
14,16,0,0,0,16,16,16,16,16,16,16,16,16,16,0,0,0,0,0,0,0,16,16,16,16,16,16,16,0,0,0,16,14
14,16,0,0,0,0,0,0,0,0,0,0,0,0,0,0,0,0,0,0,0,0,0,0,0,0,0,0,0,0,0,0,16,14
14,16,0,0,0,0,0,0,0,0,0,0,0,0,0,0,0,0,0,0,0,0,0,0,0,0,0,0,0,0,0,0,16,14
14,16,0,0,0,0,0,0,0,0,0,0,0,0,0,0,0,0,0,0,0,0,0,0,0,0,0,0,0,0,0,0,16,14
14,16,0,0,0,0,0,0,0,0,0,0,0,0,0,0,0,0,0,0,0,0,0,0,0,0,0,0,0,0,0,0,16,14
14,16,16,16,0,16,16,16,16,16,0,16,16,16,39,0,0,0,0,39,16,16,16,0,16,16,16,16,16,0,16,16,16,14
14,16,0,0,0,0,0,16,0,0,0,0,0,16,40,0,0,0,0,40,16,0,0,0,0,0,16,0,0,0,0,0,16,14
14,16,0,0,0,0,0,16,0,0,0,0,0,16,39,0,0,0,0,39,16,0,0,0,0,0,16,0,0,0,0,0,16,14
14,16,0,0,0,0,0,16,0,0,0,0,0,16,40,0,0,0,0,40,16,0,0,0,0,0,16,0,0,0,0,0,16,14
14,16,0,0,0,0,0,16,0,0,0,0,0,16,39,0,0,0,0,39,16,0,0,0,0,0,16,0,0,0,0,0,16,14
14,16,0,0,0,0,0,16,0,0,0,0,0,16,40,0,0,0,0,40,16,0,0,0,0,0,16,0,0,0,0,0,16,14
14,16,16,16,16,16,16,16,16,16,16,16,16,16,16,16,31,26,16,16,16,16,16,16,16,16,16,16,16,16,16,16,16,14
13,14,14,14,14,14,14,14,14,14,14,14,9,9,9,9,14,15,9,9,14,14,14,14,14,14,14,14,14,14,14,14,14,13
endlayer

layer
13,13,13,13,13,13,13,13,13,13,13,13,13,13,13,13,13,13,14,13,13,13,13,13,13,14,13,13,13,13,13,13,13,13
14,14,14,14,14,14,14,14,14,14,14,14,14,14,14,14,14,14,15,14,14,14,14,14,14,15,14,14,14,14,14,14,14,13
15,6,6,6,6,6,6,6,6,6,6,6,6,6,6,6,6,6,6,6,6,6,6,6,6,6,6,6,6,6,6,6,6,14
15,6,41,0,0,0,0,0,0,0,0,0,0,0,0,41,0,0,0,0,0,0,0,0,0,0,0,0,0,0,0,41,6,14
15,6,0,0,32,32,32,32,32,32,32,32,0,0,0,0,0,0,0,0,0,0,6,6,6,6,6,6,6,0,0,0,6,14
15,6,0,0,32,32,32,32,24,24,42,32,0,0,0,0,0,0,0,0,0,0,6,0,0,0,0,0,6,0,0,0,6,14
15,6,0,0,32,32,32,32,37,0,42,32,41,0,0,0,0,0,0,0,0,0,16,0,0,0,0,0,6,0,0,0,6,14
15,6,0,0,32,32,38,32,25,25,42,32,0,0,0,0,0,0,0,0,0,41,16,0,0,0,0,0,6,0,0,0,6,14
15,6,0,0,32,32,32,32,32,32,32,32,0,0,0,0,0,0,0,0,0,0,16,0,0,0,0,0,6,0,0,0,6,14
15,6,0,0,0,0,0,41,0,0,0,41,0,0,0,0,0,0,0,0,0,0,6,0,0,0,0,0,6,0,0,0,6,14
15,6,0,0,0,0,0,0,0,0,0,0,0,0,0,0,0,0,0,0,0,0,6,6,6,6,6,6,6,0,0,0,6,14
14,6,0,0,0,0,0,0,0,0,0,0,0,0,0,32,0,0,0,0,0,0,6,0,0,0,0,0,6,0,0,0,6,14
14,6,0,0,0,0,0,0,0,0,0,0,0,0,0,0,0,0,0,0,0,0,16,0,0,0,0,0,6,0,0,0,6,14
14,6,0,0,0,0,0,0,0,0,0,0,0,0,0,0,0,0,0,0,0,41,16,0,0,0,0,0,6,0,0,0,6,14
14,6,0,0,0,41,0,0,0,0,0,0,0,0,41,0,0,0,0,0,0,0,16,0,0,0,0,0,6,0,0,0,6,14
14,6,0,0,0,6,6,6,6,6,6,6,6,6,6,0,0,0,0,0,0,0,6,0,0,0,0,0,6,0,0,0,6,15
14,6,0,0,0,6,41,0,0,0,0,0,0,41,6,0,0,0,0,0,0,0,6,6,6,6,6,6,6,0,0,0,6,14
14,6,41,0,0,6,0,0,0,0,0,0,0,0,16,0,0,0,0,0,0,0,6,0,0,0,0,0,6,0,0,0,6,14
14,6,0,0,0,6,0,0,0,0,0,0,0,0,16,41,0,0,0,0,0,0,16,0,0,0,0,0,6,0,0,0,6,14
14,6,0,0,0,6,0,0,0,0,0,0,0,0,16,41,0,0,0,0,0,41,16,0,0,0,0,0,6,0,0,0,6,14
14,6,0,0,0,6,0,0,0,0,0,0,0,0,16,0,0,0,0,0,0,0,16,0,0,0,0,0,6,0,0,0,6,14
14,6,0,0,0,6,41,0,0,0,0,0,0,41,6,0,0,0,0,0,0,0,6,0,0,0,0,0,6,0,0,0,6,14
14,6,0,0,0,6,6,6,6,6,6,6,6,6,6,0,0,0,0,0,0,0,6,6,6,6,6,6,6,0,0,0,6,14
14,6,0,0,0,41,0,0,0,0,0,0,0,0,41,0,0,0,0,0,0,0,0,0,0,0,0,0,0,0,0,0,6,14
14,6,0,0,0,0,0,0,0,0,0,0,0,0,0,0,0,0,0,0,0,0,0,0,0,0,0,0,0,0,0,0,6,14
14,6,0,0,0,0,0,0,0,0,0,0,0,0,0,0,0,0,0,0,0,0,0,0,0,0,0,0,0,0,0,0,6,14
14,6,0,0,41,0,0,0,0,0,41,0,0,0,0,0,0,0,0,0,0,0,0,41,0,0,0,0,0,41,0,0,6,14
14,6,6,16,16,16,6,6,6,16,16,16,6,6,0,41,0,0,41,0,6,6,16,16,16,6,6,6,16,16,16,6,6,14
14,6,0,0,0,0,0,6,0,0,0,0,0,6,0,0,0,0,0,0,6,0,0,0,0,0,6,0,0,0,0,0,6,14
14,6,0,0,0,0,0,6,0,0,0,0,0,6,0,0,0,0,0,0,6,0,0,0,0,0,6,0,0,0,0,0,6,14
14,6,0,0,0,0,0,6,0,0,0,0,0,6,0,0,0,0,0,0,6,0,0,0,0,0,6,0,0,0,0,0,6,14
14,6,0,0,0,0,0,6,0,0,0,0,0,6,0,0,0,0,0,0,6,0,0,0,0,0,6,0,0,0,0,0,6,14
14,6,0,0,0,0,0,6,0,0,0,0,0,6,0,41,0,0,41,0,6,0,0,0,0,0,6,0,0,0,0,0,6,14
14,6,6,6,6,6,6,6,6,6,6,6,6,6,6,16,31,26,16,6,6,6,6,6,6,6,6,6,6,6,6,6,6,14
13,14,14,14,14,14,14,14,14,14,14,14,14,9,9,41,14,9,41,14,14,14,14,14,14,14,14,14,14,14,14,14,14,13
endlayer

layer
13,13,13,13,13,13,13,13,13,13,13,13,13,13,13,13,13,13,13,13,13,13,13,13,13,13,13,13,13,13,13,13,13,13
14,14,14,14,14,14,14,14,14,14,14,14,14,14,14,14,14,14,9,14,14,14,14,14,14,9,14,14,14,14,14,14,14,13
15,6,6,6,6,6,6,6,6,6,6,6,6,6,6,6,6,6,6,6,6,6,6,6,6,6,6,6,6,6,6,6,6,14
15,6,0,0,0,0,0,0,0,42,24,24,24,24,24,24,24,24,24,24,24,37,19,19,19,19,19,19,19,19,19,42,6,14
9,6,0,0,32,32,32,32,43,43,43,43,0,0,0,0,0,0,0,0,41,25,6,6,6,6,6,6,6,25,0,42,6,14
15,6,0,0,32,44,0,32,43,43,43,43,0,0,0,0,0,0,0,0,0,42,6,41,24,24,24,41,6,37,0,42,6,14
15,6,0,0,32,0,0,32,43,43,43,43,0,0,0,0,0,0,0,0,0,42,6,37,0,0,0,42,6,37,0,42,6,14
15,6,0,0,32,0,38,32,43,43,43,43,0,0,0,0,0,0,0,0,0,42,6,37,0,0,0,42,6,37,0,42,6,14
15,6,0,0,32,32,32,32,43,43,43,43,0,0,0,0,0,0,0,0,0,42,6,37,0,0,0,42,6,37,0,42,6,14
15,6,0,0,41,0,0,0,0,0,0,0,0,0,0,0,0,0,0,0,0,42,6,41,25,25,25,41,6,37,0,42,6,14
15,6,25,0,0,0,0,0,0,0,0,0,0,0,42,25,25,0,0,0,0,42,6,6,6,6,6,6,6,37,0,42,6,14
14,6,37,0,0,0,0,0,0,0,0,0,0,0,42,6,37,0,0,0,0,42,6,41,24,24,24,41,6,37,0,42,6,14
14,6,37,0,0,0,0,0,0,0,0,0,0,0,24,24,24,0,0,0,0,42,6,37,0,0,0,42,6,37,0,42,6,14
14,6,37,0,0,0,0,0,0,0,0,0,0,0,0,0,0,0,0,0,0,42,6,37,0,0,0,42,6,37,0,42,6,14
14,6,37,0,42,25,25,25,25,25,25,25,25,25,25,25,0,0,0,0,0,42,6,37,0,0,0,42,6,37,0,42,6,14
14,6,37,0,42,6,6,6,6,6,6,6,6,6,6,37,0,0,0,0,0,42,6,41,25,25,25,41,6,37,0,42,6,9
14,6,37,0,42,6,41,24,24,24,24,24,24,41,6,37,0,0,0,0,0,42,6,6,6,6,6,6,6,37,0,42,6,14
14,6,37,0,42,6,37,0,0,0,0,0,0,42,6,37,0,0,0,0,0,42,6,41,24,24,24,41,6,37,0,42,6,14
14,6,37,0,42,6,37,0,0,0,0,0,0,42,6,37,0,0,0,0,0,42,6,37,0,0,0,42,6,37,0,42,6,14
14,6,37,0,42,6,37,0,0,0,0,0,0,42,6,37,0,0,0,0,0,42,6,37,0,0,0,42,6,37,0,42,6,14
14,6,37,0,42,6,37,0,0,0,0,0,0,42,6,37,0,0,0,0,0,42,6,37,0,0,0,42,6,37,0,42,6,14
14,6,37,0,42,6,41,25,25,25,25,25,25,41,6,37,0,0,0,0,0,42,6,41,25,25,25,41,6,37,0,42,6,14
14,6,37,0,42,6,6,6,6,6,6,6,6,6,6,37,0,0,0,0,0,42,6,6,6,6,6,6,6,37,0,42,6,14
14,6,37,0,42,24,24,24,24,24,24,24,24,24,24,24,0,0,0,0,0,24,24,24,24,24,24,24,24,37,0,42,6,14
14,6,37,0,0,0,0,0,0,0,0,0,0,0,0,0,0,0,0,0,0,0,0,0,0,0,0,0,0,0,0,42,6,14
14,6,37,0,0,0,0,0,0,0,0,0,0,0,0,0,0,0,0,0,0,0,0,0,0,0,0,0,0,0,0,42,6,14
14,6,25,25,25,25,25,25,25,25,25,25,25,37,19,19,19,19,19,19,42,25,25,25,25,25,25,25,25,25,25,42,6,14
14,6,6,6,6,6,6,6,6,6,6,6,6,6,19,2,19,19,2,19,6,6,6,6,6,6,6,6,6,6,6,6,6,14
14,6,41,24,24,24,41,6,41,24,24,24,41,6,19,19,19,19,19,19,6,41,24,24,24,41,6,41,24,24,24,41,6,14
14,6,37,0,0,0,42,6,37,0,0,0,42,6,19,19,19,19,19,19,6,37,0,0,0,42,6,37,0,0,0,42,6,14
14,6,37,0,0,0,42,6,37,0,0,0,42,6,19,19,19,19,19,19,6,37,0,0,0,42,6,37,0,0,0,42,6,14
14,6,37,0,0,0,42,6,37,0,0,0,42,6,19,19,19,19,19,19,6,37,0,0,0,42,6,37,0,0,0,42,6,14
14,6,41,25,25,25,41,6,41,25,25,25,41,6,19,2,19,19,2,19,6,41,25,25,25,41,6,41,25,25,25,41,6,14
14,6,6,6,6,6,6,6,6,6,6,6,6,6,6,16,16,16,16,6,6,6,6,6,6,6,6,6,6,6,6,6,6,14
13,14,14,14,14,14,14,14,14,14,14,14,14,14,14,2,14,9,2,14,14,14,14,14,14,14,14,14,14,14,14,14,14,13
endlayer

layer
13,13,13,13,13,13,13,13,13,13,13,13,13,13,13,13,13,13,13,13,13,13,13,13,13,13,13,13,13,13,13,13,13,13
13,14,14,14,14,14,14,14,14,14,14,14,14,14,14,14,14,14,14,14,14,14,14,14,14,14,14,14,14,14,14,14,13,13
9,43,43,43,43,43,43,43,43,43,9,9,9,9,9,9,9,9,9,9,9,9,9,9,9,9,9,9,9,9,9,9,9,13
9,43,43,42,25,25,25,25,25,43,43,43,43,43,43,43,43,43,43,43,43,9,9,9,9,9,9,9,9,9,43,9,9,13
9,43,43,42,5,5,5,7,37,43,43,43,43,43,43,43,43,43,43,43,43,43,9,9,9,9,9,9,9,43,43,43,9,13
9,43,43,42,10,0,0,7,37,43,9,43,43,43,43,43,43,43,43,43,43,43,9,9,43,43,43,9,9,43,43,43,14,13
9,43,43,42,10,0,0,7,37,43,9,43,43,43,43,43,43,43,43,43,43,43,14,43,43,43,43,43,9,43,43,43,14,13
9,43,43,42,10,0,0,7,37,43,9,43,43,43,43,43,43,43,43,43,43,43,14,43,43,43,43,43,14,43,43,43,14,13
9,43,43,42,10,4,4,7,37,43,43,43,43,43,43,43,43,43,43,43,43,43,14,43,43,43,43,43,14,43,43,43,9,13
9,43,43,42,24,24,24,24,24,43,43,43,43,43,43,43,43,43,43,43,43,43,9,9,43,43,43,9,14,43,43,43,9,13
9,43,43,43,43,43,43,43,43,43,43,43,43,43,43,43,43,43,43,43,43,43,9,9,9,9,9,9,14,43,43,43,9,13
14,9,43,43,43,43,43,43,43,43,43,43,43,43,43,43,43,43,43,43,43,43,9,9,43,43,43,14,14,43,43,43,9,13
14,9,43,43,43,43,43,43,43,43,43,43,43,43,43,43,43,43,43,43,43,43,9,43,43,43,43,43,14,43,43,43,9,13
14,9,43,43,43,43,43,43,43,43,43,43,43,43,43,43,43,43,43,43,43,43,9,43,43,43,43,43,14,43,43,43,9,13
14,9,43,43,43,43,43,43,43,43,43,43,43,43,43,43,43,43,43,43,43,43,9,43,43,43,43,43,9,43,43,43,9,13
14,9,43,43,43,14,14,14,14,14,14,14,14,14,14,43,43,43,43,43,43,43,9,9,43,43,43,9,9,43,43,43,9,13
14,9,43,43,43,14,9,43,43,43,43,43,43,9,14,43,43,43,43,43,43,43,9,9,14,14,9,9,9,43,43,43,9,13
14,9,43,43,43,14,43,43,43,43,43,43,43,43,14,43,43,43,43,43,43,43,9,9,43,43,43,9,9,43,43,43,9,13
14,9,43,43,43,14,43,43,43,43,43,43,43,43,14,43,43,43,43,43,43,43,14,43,43,43,43,43,9,43,43,43,9,13
14,9,43,43,43,14,43,43,43,43,43,43,43,43,14,43,43,43,43,43,43,43,14,43,43,43,43,43,14,43,43,43,9,13
14,9,43,43,43,9,43,43,43,43,43,43,43,43,14,43,43,43,43,43,43,43,14,43,43,43,43,43,14,43,43,43,9,13
14,9,43,43,43,9,9,43,43,43,43,43,43,14,14,43,43,43,43,43,43,43,14,14,43,43,43,9,14,43,43,43,9,13
14,9,43,43,43,9,9,14,14,14,9,14,14,14,14,43,43,43,43,43,43,43,14,14,14,14,9,9,14,43,43,43,9,13
14,9,43,43,43,43,43,43,43,43,43,43,43,43,43,43,43,43,43,43,43,43,43,43,43,43,43,43,43,43,43,43,9,13
14,9,43,43,43,43,43,43,43,43,43,43,43,43,43,43,43,43,43,43,43,43,43,43,43,43,43,43,43,43,43,43,9,13
14,9,43,43,43,43,43,43,43,43,43,43,43,43,43,43,43,43,43,43,43,43,43,43,43,43,43,43,43,43,43,43,9,13
14,9,43,43,43,43,43,43,43,43,43,43,43,43,43,43,43,43,43,43,43,43,43,43,43,43,43,43,43,43,43,9,9,13
14,9,9,9,9,9,9,9,9,9,9,9,9,9,9,9,9,9,9,9,9,9,9,9,9,9,9,9,9,9,9,9,9,13
14,9,9,43,43,43,9,9,9,43,43,43,9,9,9,9,9,9,9,9,9,9,43,43,43,9,9,9,43,43,43,9,9,13
14,9,43,43,43,43,43,9,43,43,43,43,43,9,9,9,9,9,9,9,9,43,43,43,43,43,14,43,43,43,43,43,9,13
14,9,43,43,43,43,43,9,43,43,43,43,43,9,9,9,9,9,9,9,9,43,43,43,43,43,14,43,43,43,43,43,9,13
14,9,43,43,43,43,43,9,43,43,43,43,43,9,9,9,9,9,9,9,9,43,43,43,43,43,14,43,43,43,43,43,9,13
14,9,9,43,43,43,9,9,9,43,43,43,9,9,9,9,9,9,9,9,9,9,43,43,43,9,9,9,43,43,43,9,9,13
13,9,9,9,9,9,9,9,9,14,14,14,9,9,9,9,9,9,9,9,9,9,9,9,9,9,9,9,9,9,9,9,9,13
13,13,13,13,13,13,13,13,13,13,13,13,13,13,13,13,13,13,13,13,13,13,13,13,13,13,13,13,13,13,13,13,13,13
endlayer

layer
13,13,13,13,13,13,13,13,13,13,13,13,13,13,13,13,13,13,13,13,13,13,13,13,13,13,13,13,13,13,13,13,13,13
13,13,14,14,14,14,14,14,14,13,13,13,13,13,13,13,13,13,13,13,13,13,13,13,13,13,13,13,13,13,13,13,13,13
13,9,9,9,9,9,9,9,9,9,9,9,9,9,9,9,9,9,9,9,9,9,9,9,9,9,9,9,9,9,9,9,13,13
13,9,9,32,43,43,43,43,32,9,9,9,9,9,9,9,9,9,9,9,9,9,9,9,9,9,9,9,9,9,9,9,13,13
13,9,9,43,0,0,0,0,43,9,9,9,9,9,9,9,9,9,9,9,9,9,9,9,9,9,9,9,9,9,9,9,13,13
13,9,9,43,0,0,0,0,43,9,9,9,9,9,9,9,9,9,9,9,9,9,9,9,9,9,9,9,9,9,9,9,13,13
13,9,9,43,0,0,0,0,43,9,9,9,9,9,9,9,9,9,9,9,9,9,13,9,9,9,9,9,9,9,9,9,13,13
13,9,9,43,0,0,0,0,43,9,9,9,9,9,9,9,9,9,9,9,9,9,13,9,9,9,9,9,13,9,9,9,13,13
13,9,9,43,0,0,0,0,43,9,9,9,9,9,9,9,9,9,9,9,9,9,13,9,9,9,9,9,13,9,9,9,13,13
13,9,9,32,43,43,43,43,32,9,9,9,9,9,9,9,9,9,9,9,9,9,9,9,9,9,9,9,13,9,9,9,13,13
13,9,9,9,9,9,9,9,9,9,9,9,9,9,9,9,9,9,9,9,9,9,9,9,9,9,9,9,13,9,9,9,13,13
13,9,9,9,9,9,9,9,9,9,9,9,9,9,9,9,9,9,9,9,9,9,9,9,9,9,9,13,13,9,9,9,13,13
13,9,9,9,9,9,9,9,9,9,9,9,9,9,9,9,9,9,9,9,9,9,9,9,9,9,9,9,13,9,9,9,13,13
13,9,9,9,9,9,9,9,9,9,9,9,9,9,9,9,9,9,9,9,9,9,9,9,9,9,9,9,13,9,9,9,13,13
13,9,9,9,9,9,9,9,9,9,9,9,9,9,9,9,9,9,9,9,9,9,9,9,9,9,9,9,9,9,9,9,13,13
13,9,9,9,9,13,13,13,13,13,13,13,13,13,13,9,9,9,9,9,9,9,9,9,9,9,9,9,9,9,9,9,13,13
13,9,9,9,9,13,9,9,9,9,9,9,9,9,13,9,9,9,9,9,9,9,9,9,13,13,9,9,9,9,9,9,13,13
13,9,9,9,9,13,9,9,9,9,9,9,9,9,13,9,9,9,9,9,9,9,9,9,9,9,9,9,9,9,9,9,13,13
13,9,9,9,9,13,9,9,9,9,9,9,9,9,13,9,9,9,9,9,9,9,13,9,9,9,9,9,9,9,9,9,13,13
13,9,9,9,9,13,9,9,9,9,9,9,9,9,13,9,9,9,9,9,9,9,13,9,9,9,9,9,13,9,9,9,13,13
13,9,9,9,9,9,9,9,9,9,9,9,9,9,13,9,9,9,9,9,9,9,13,9,9,9,9,9,13,9,9,9,13,13
13,9,9,9,9,9,9,9,9,9,9,9,9,13,13,9,9,9,9,9,9,9,13,13,9,9,9,9,13,9,9,9,13,13
13,9,9,9,9,9,9,13,13,13,9,13,13,13,13,9,9,9,9,9,9,9,13,13,13,13,9,9,13,9,9,9,13,13
13,9,9,9,9,9,9,9,9,9,9,9,9,9,9,9,9,9,9,9,9,9,9,9,9,9,9,9,9,9,9,9,13,13
13,9,9,9,9,9,9,9,9,9,9,9,9,9,9,9,9,9,9,9,9,9,9,9,9,9,9,9,9,9,9,9,13,13
13,9,9,9,9,9,9,9,9,9,9,9,9,9,9,9,9,9,9,9,9,9,9,9,9,9,9,9,9,9,9,9,13,13
13,9,9,9,9,9,9,9,9,9,9,9,9,9,9,9,9,9,9,9,9,9,9,9,9,9,9,9,9,9,9,9,13,13
13,9,9,9,9,9,9,9,9,9,9,9,9,9,9,9,9,9,9,9,9,9,9,9,9,9,9,9,9,9,9,9,13,13
13,9,9,9,9,9,9,9,9,9,9,9,9,9,9,9,9,9,9,9,9,9,9,9,9,9,9,9,9,9,9,9,13,13
13,9,9,9,9,9,9,9,9,9,9,9,9,9,9,9,9,9,9,9,9,9,9,9,9,9,13,9,9,9,9,9,13,13
13,9,9,9,9,9,9,9,9,9,9,9,9,9,9,9,9,9,9,9,9,9,9,9,9,9,13,9,9,9,9,9,13,13
13,9,9,9,9,9,9,9,9,9,9,9,9,9,9,9,9,9,9,9,9,9,9,9,9,9,13,9,9,9,9,9,13,13
13,9,9,9,9,9,9,9,9,9,9,9,9,9,9,9,9,9,9,9,9,9,9,9,9,9,9,9,9,9,9,9,13,13
13,13,13,13,13,13,13,13,13,13,13,13,13,13,13,13,13,13,13,13,13,13,13,13,13,13,13,13,13,13,13,13,13,13
13,13,13,13,13,13,13,13,13,13,13,13,13,13,13,13,13,13,13,13,13,13,13,13,13,13,13,13,13,13,13,13,13,13
endlayer

layer
9,9,9,9,9,9,9,9,9,9,9,9,9,9,9,9,9,9,9,9,9,9,9,9,9,9,9,9,9,9,9,9,9,9
9,9,13,13,13,13,13,14,14,9,9,9,9,9,9,9,9,9,9,9,9,9,9,9,9,9,9,9,9,9,9,9,9,9
9,13,9,9,9,9,9,9,9,14,9,9,9,9,9,9,9,9,9,9,9,9,9,9,9,9,9,9,9,9,9,9,9,9
9,14,9,32,24,24,24,24,32,14,9,9,9,9,9,9,9,9,9,9,9,9,9,9,9,9,9,9,9,9,9,9,9,9
9,14,9,37,41,0,0,41,42,9,14,9,9,9,9,9,9,9,9,9,9,9,9,9,9,9,9,9,9,9,9,9,9,9
9,14,9,37,0,0,0,0,42,9,14,9,9,9,9,9,9,9,9,9,9,9,9,9,9,9,9,9,9,9,9,9,9,9
9,14,9,37,0,0,0,0,42,9,14,9,9,9,9,9,9,9,9,9,9,9,9,9,9,9,9,9,9,9,9,9,9,9
9,14,9,37,0,0,0,0,42,9,14,9,9,9,9,9,9,9,9,9,9,9,9,9,9,9,9,9,9,9,9,9,9,9
9,14,9,37,41,0,0,41,42,9,14,9,9,9,9,9,9,9,9,9,9,9,9,9,9,9,9,9,9,9,9,9,9,9
9,14,9,32,25,25,25,25,32,9,14,9,9,9,9,9,9,9,9,9,9,9,9,9,9,9,9,9,9,9,9,9,9,9
9,14,9,9,9,9,9,9,9,9,14,9,9,9,9,9,9,9,9,9,9,9,9,9,9,9,9,9,9,9,9,9,9,9
9,9,14,14,14,14,14,14,14,14,9,9,9,9,9,9,9,9,9,9,9,9,9,9,9,9,9,9,9,9,9,9,9,9
9,9,9,9,9,9,9,9,9,9,9,9,9,9,9,9,9,9,9,9,9,9,9,9,9,9,9,9,9,9,9,9,9,9
9,9,9,9,9,9,9,9,9,9,9,9,9,9,9,9,9,9,9,9,9,9,9,9,9,9,9,9,9,9,9,9,9,9
9,9,9,9,9,9,9,9,9,9,9,9,9,9,9,9,9,9,9,9,9,9,9,9,9,9,9,9,9,9,9,9,9,9
9,9,9,9,9,9,9,9,9,9,9,9,9,9,9,9,9,9,9,9,9,9,9,9,9,9,9,9,9,9,9,9,9,9
9,9,9,9,9,9,9,9,9,9,9,9,9,9,9,9,9,9,9,9,9,9,9,9,9,9,9,9,9,9,9,9,9,9
9,9,9,9,9,9,9,9,9,9,9,9,9,9,9,9,9,9,9,9,9,9,9,9,9,9,9,9,9,9,9,9,9,9
9,9,9,9,9,9,9,9,9,9,9,9,9,9,9,9,9,9,9,9,9,9,9,9,9,9,9,9,9,9,9,9,9,9
9,9,9,9,9,9,9,9,9,9,9,9,9,9,9,9,9,9,9,9,9,9,9,9,9,9,9,9,9,9,9,9,9,9
9,9,9,9,9,9,9,9,9,9,9,9,9,9,9,9,9,9,9,9,9,9,9,9,9,9,9,9,9,9,9,9,9,9
9,9,9,9,9,9,9,9,9,9,9,9,9,9,9,9,9,9,9,9,9,9,9,9,9,9,9,9,9,9,9,9,9,9
9,9,9,9,9,9,9,9,9,9,9,9,9,9,9,9,9,9,9,9,9,9,9,9,9,9,9,9,9,9,9,9,9,9
9,9,9,9,9,9,9,9,9,9,9,9,9,9,9,9,9,9,9,9,9,9,9,9,9,9,9,9,9,9,9,9,9,9
9,9,9,9,9,9,9,9,9,9,9,9,9,9,9,9,9,9,9,9,9,9,9,9,9,9,9,9,9,9,9,9,9,9
9,9,9,9,9,9,9,9,9,9,9,9,9,9,9,9,9,9,9,9,9,9,9,9,9,9,9,9,9,9,9,9,9,9
9,9,9,9,9,9,9,9,9,9,9,9,9,9,9,9,9,9,9,9,9,9,9,9,9,9,9,9,9,9,9,9,9,9
9,9,9,9,9,9,9,9,9,9,9,9,9,9,9,9,9,9,9,9,9,9,9,9,9,9,9,9,9,9,9,9,9,9
9,9,9,9,9,9,9,9,9,9,9,9,9,9,9,9,9,9,9,9,9,9,9,9,9,9,9,9,9,9,9,9,9,9
9,9,9,9,9,9,9,9,9,9,9,9,9,9,9,9,9,9,9,9,9,9,9,9,9,9,9,9,9,9,9,9,9,9
9,9,9,9,9,9,9,9,9,9,9,9,9,9,9,9,9,9,9,9,9,9,9,9,9,9,9,9,9,9,9,9,9,9
9,9,9,9,9,9,9,9,9,9,9,9,9,9,9,9,9,9,9,9,9,9,9,9,9,9,9,9,9,9,9,9,9,9
9,9,9,9,9,9,9,9,9,9,9,9,9,9,9,9,9,9,9,9,9,9,9,9,9,9,9,9,9,9,9,9,9,9
9,9,9,9,9,9,9,9,9,9,9,9,9,9,9,9,9,9,9,9,9,9,9,9,9,9,9,9,9,9,9,9,9,9
9,9,9,9,9,9,9,9,9,9,9,9,9,9,9,9,9,9,9,9,9,9,9,9,9,9,9,9,9,9,9,9,9,9
endlayer

layer
9,9,9,9,9,9,9,9,9,9,9,9,9,9,9,9,9,9,9,9,9,9,9,9,9,9,9,9,9,9,9,9,9,9
9,9,9,9,9,9,9,13,13,9,9,9,9,9,9,9,9,9,9,9,9,9,9,9,9,9,9,9,9,9,9,9,9,9
9,9,13,14,14,14,14,9,9,13,9,9,9,9,9,9,9,9,9,9,9,9,9,9,9,9,9,9,9,9,9,9,9,9
9,13,9,9,43,43,43,43,9,14,9,9,9,9,9,9,9,9,9,9,9,9,9,9,9,9,9,9,9,9,9,9,9,9
9,13,9,43,43,43,43,43,43,9,13,9,9,9,9,9,9,9,9,9,9,9,9,9,9,9,9,9,9,9,9,9,9,9
9,13,9,43,43,43,43,43,43,9,13,9,9,9,9,9,9,9,9,9,9,9,9,9,9,9,9,9,9,9,9,9,9,9
9,13,9,43,43,43,43,43,43,9,13,9,9,9,9,9,9,9,9,9,9,9,9,9,9,9,9,9,9,9,9,9,9,9
9,13,9,43,43,43,43,43,43,9,13,9,9,9,9,9,9,9,9,9,9,9,9,9,9,9,9,9,9,9,9,9,9,9
9,13,9,43,43,43,43,43,43,9,13,9,9,9,9,9,9,9,9,9,9,9,9,9,9,9,9,9,9,9,9,9,9,9
9,13,9,9,43,43,43,43,9,9,13,9,9,9,9,9,9,9,9,9,9,9,9,9,9,9,9,9,9,9,9,9,9,9
9,13,9,9,9,9,9,9,9,9,13,9,9,9,9,9,9,9,9,9,9,9,9,9,9,9,9,9,9,9,9,9,9,9
9,9,13,13,13,13,13,13,13,13,9,9,9,9,9,9,9,9,9,9,9,9,9,9,9,9,9,9,9,9,9,9,9,9
9,9,9,9,9,9,9,9,9,9,9,9,9,9,9,9,9,9,9,9,9,9,9,9,9,9,9,9,9,9,9,9,9,9
9,9,9,9,9,9,9,9,9,9,9,9,9,9,9,9,9,9,9,9,9,9,9,9,9,9,9,9,9,9,9,9,9,9
9,9,9,9,9,9,9,9,9,9,9,9,9,9,9,9,9,9,9,9,9,9,9,9,9,9,9,9,9,9,9,9,9,9
9,9,9,9,9,9,9,9,9,9,9,9,9,9,9,9,9,9,9,9,9,9,9,9,9,9,9,9,9,9,9,9,9,9
9,9,9,9,9,9,9,9,9,9,9,9,9,9,9,9,9,9,9,9,9,9,9,9,9,9,9,9,9,9,9,9,9,9
9,9,9,9,9,9,9,9,9,9,9,9,9,9,9,9,9,9,9,9,9,9,9,9,9,9,9,9,9,9,9,9,9,9
9,9,9,9,9,9,9,9,9,9,9,9,9,9,9,9,9,9,9,9,9,9,9,9,9,9,9,9,9,9,9,9,9,9
9,9,9,9,9,9,9,9,9,9,9,9,9,9,9,9,9,9,9,9,9,9,9,9,9,9,9,9,9,9,9,9,9,9
9,9,9,9,9,9,9,9,9,9,9,9,9,9,9,9,9,9,9,9,9,9,9,9,9,9,9,9,9,9,9,9,9,9
9,9,9,9,9,9,9,9,9,9,9,9,9,9,9,9,9,9,9,9,9,9,9,9,9,9,9,9,9,9,9,9,9,9
9,9,9,9,9,9,9,9,9,9,9,9,9,9,9,9,9,9,9,9,9,9,9,9,9,9,9,9,9,9,9,9,9,9
9,9,9,9,9,9,9,9,9,9,9,9,9,9,9,9,9,9,9,9,9,9,9,9,9,9,9,9,9,9,9,9,9,9
9,9,9,9,9,9,9,9,9,9,9,9,9,9,9,9,9,9,9,9,9,9,9,9,9,9,9,9,9,9,9,9,9,9
9,9,9,9,9,9,9,9,9,9,9,9,9,9,9,9,9,9,9,9,9,9,9,9,9,9,9,9,9,9,9,9,9,9
9,9,9,9,9,9,9,9,9,9,9,9,9,9,9,9,9,9,9,9,9,9,9,9,9,9,9,9,9,9,9,9,9,9
9,9,9,9,9,9,9,9,9,9,9,9,9,9,9,9,9,9,9,9,9,9,9,9,9,9,9,9,9,9,9,9,9,9
9,9,9,9,9,9,9,9,9,9,9,9,9,9,9,9,9,9,9,9,9,9,9,9,9,9,9,9,9,9,9,9,9,9
9,9,9,9,9,9,9,9,9,9,9,9,9,9,9,9,9,9,9,9,9,9,9,9,9,9,9,9,9,9,9,9,9,9
9,9,9,9,9,9,9,9,9,9,9,9,9,9,9,9,9,9,9,9,9,9,9,9,9,9,9,9,9,9,9,9,9,9
9,9,9,9,9,9,9,9,9,9,9,9,9,9,9,9,9,9,9,9,9,9,9,9,9,9,9,9,9,9,9,9,9,9
9,9,9,9,9,9,9,9,9,9,9,9,9,9,9,9,9,9,9,9,9,9,9,9,9,9,9,9,9,9,9,9,9,9
9,9,9,9,9,9,9,9,9,9,9,9,9,9,9,9,9,9,9,9,9,9,9,9,9,9,9,9,9,9,9,9,9,9
9,9,9,9,9,9,9,9,9,9,9,9,9,9,9,9,9,9,9,9,9,9,9,9,9,9,9,9,9,9,9,9,9,9
endlayer

layer
9,9,9,9,9,9,9,9,9,9,9,9,9,9,9,9,9,9,9,9,9,9,9,9,9,9,9,9,9,9,9,9,9,9
9,9,9,9,9,9,9,9,9,9,9,9,9,9,9,9,9,9,9,9,9,9,9,9,9,9,9,9,9,9,9,9,9,9
9,9,9,13,13,13,13,13,13,9,9,9,9,9,9,9,9,9,9,9,9,9,9,9,9,9,9,9,9,9,9,9,9,9
9,9,13,9,9,9,9,9,9,13,9,9,9,9,9,9,9,9,9,9,9,9,9,9,9,9,9,9,9,9,9,9,9,9
9,9,13,9,9,9,9,9,9,13,9,9,9,9,9,9,9,9,9,9,9,9,9,9,9,9,9,9,9,9,9,9,9,9
9,9,13,9,9,9,9,9,9,13,9,9,9,9,9,9,9,9,9,9,9,9,9,9,9,9,9,9,9,9,9,9,9,9
9,9,13,9,9,9,9,9,9,13,9,9,9,9,9,9,9,9,9,9,9,9,9,9,9,9,9,9,9,9,9,9,9,9
9,9,13,9,9,9,9,9,9,13,9,9,9,9,9,9,9,9,9,9,9,9,9,9,9,9,9,9,9,9,9,9,9,9
9,9,13,9,9,9,9,9,9,13,9,9,9,9,9,9,9,9,9,9,9,9,9,9,9,9,9,9,9,9,9,9,9,9
9,9,13,9,9,9,9,9,9,13,9,9,9,9,9,9,9,9,9,9,9,9,9,9,9,9,9,9,9,9,9,9,9,9
9,9,9,13,13,13,13,13,13,9,9,9,9,9,9,9,9,9,9,9,9,9,9,9,9,9,9,9,9,9,9,9,9,9
9,9,9,9,9,9,9,9,9,9,9,9,9,9,9,9,9,9,9,9,9,9,9,9,9,9,9,9,9,9,9,9,9,9
9,9,9,9,9,9,9,9,9,9,9,9,9,9,9,9,9,9,9,9,9,9,9,9,9,9,9,9,9,9,9,9,9,9
9,9,9,9,9,9,9,9,9,9,9,9,9,9,9,9,9,9,9,9,9,9,9,9,9,9,9,9,9,9,9,9,9,9
9,9,9,9,9,9,9,9,9,9,9,9,9,9,9,9,9,9,9,9,9,9,9,9,9,9,9,9,9,9,9,9,9,9
9,9,9,9,9,9,9,9,9,9,9,9,9,9,9,9,9,9,9,9,9,9,9,9,9,9,9,9,9,9,9,9,9,9
9,9,9,9,9,9,9,9,9,9,9,9,9,9,9,9,9,9,9,9,9,9,9,9,9,9,9,9,9,9,9,9,9,9
9,9,9,9,9,9,9,9,9,9,9,9,9,9,9,9,9,9,9,9,9,9,9,9,9,9,9,9,9,9,9,9,9,9
9,9,9,9,9,9,9,9,9,9,9,9,9,9,9,9,9,9,9,9,9,9,9,9,9,9,9,9,9,9,9,9,9,9
9,9,9,9,9,9,9,9,9,9,9,9,9,9,9,9,9,9,9,9,9,9,9,9,9,9,9,9,9,9,9,9,9,9
9,9,9,9,9,9,9,9,9,9,9,9,9,9,9,9,9,9,9,9,9,9,9,9,9,9,9,9,9,9,9,9,9,9
9,9,9,9,9,9,9,9,9,9,9,9,9,9,9,9,9,9,9,9,9,9,9,9,9,9,9,9,9,9,9,9,9,9
9,9,9,9,9,9,9,9,9,9,9,9,9,9,9,9,9,9,9,9,9,9,9,9,9,9,9,9,9,9,9,9,9,9
9,9,9,9,9,9,9,9,9,9,9,9,9,9,9,9,9,9,9,9,9,9,9,9,9,9,9,9,9,9,9,9,9,9
9,9,9,9,9,9,9,9,9,9,9,9,9,9,9,9,9,9,9,9,9,9,9,9,9,9,9,9,9,9,9,9,9,9
9,9,9,9,9,9,9,9,9,9,9,9,9,9,9,9,9,9,9,9,9,9,9,9,9,9,9,9,9,9,9,9,9,9
9,9,9,9,9,9,9,9,9,9,9,9,9,9,9,9,9,9,9,9,9,9,9,9,9,9,9,9,9,9,9,9,9,9
9,9,9,9,9,9,9,9,9,9,9,9,9,9,9,9,9,9,9,9,9,9,9,9,9,9,9,9,9,9,9,9,9,9
9,9,9,9,9,9,9,9,9,9,9,9,9,9,9,9,9,9,9,9,9,9,9,9,9,9,9,9,9,9,9,9,9,9
9,9,9,9,9,9,9,9,9,9,9,9,9,9,9,9,9,9,9,9,9,9,9,9,9,9,9,9,9,9,9,9,9,9
9,9,9,9,9,9,9,9,9,9,9,9,9,9,9,9,9,9,9,9,9,9,9,9,9,9,9,9,9,9,9,9,9,9
9,9,9,9,9,9,9,9,9,9,9,9,9,9,9,9,9,9,9,9,9,9,9,9,9,9,9,9,9,9,9,9,9,9
9,9,9,9,9,9,9,9,9,9,9,9,9,9,9,9,9,9,9,9,9,9,9,9,9,9,9,9,9,9,9,9,9,9
9,9,9,9,9,9,9,9,9,9,9,9,9,9,9,9,9,9,9,9,9,9,9,9,9,9,9,9,9,9,9,9,9,9
9,9,9,9,9,9,9,9,9,9,9,9,9,9,9,9,9,9,9,9,9,9,9,9,9,9,9,9,9,9,9,9,9,9
endlayer


