# Converted from schematic
# THIS TEMPLATE USES DEFAULTS!  Please edit for corrections.
# If you need help, consult template_rules.txt
biomesToSpawnIn=alpine,alps,alps forest,alps mountainside,arctic,frost forest,frozenocean,glacier,ice montains,ice plains,ice wasteland,icy hills,snow forest,snowy coniferous forest,snowy dead forest,snowy rainforest,tundra,polar
weight=1
embed_into_distance=1
unacceptable_target_blocks=flowing_water,water,flowing_lava,lava,Natura:Cloud,red_mushroom_block,brown_mushroom_block,planks,cobblestone,end_stone,obsidian,purpur_block,iron_bars,purpur_slab,purpur_pillar,netherrack,soul_sand,quartz_ore
dimensions=8,11,12
allowable_overhang=0
max_cut_in=2
cut_in_buffer=1
max_leveling=2
leveling_buffer=0
preserve_water=0
preserve_lava=0
preserve_plants=0


rule1=0,100,cobblestone
rule2=0,100,sandstone
rule3=0,100,stone
rule4=0,100,sandstone-2
rule5=0,100,dirt
rule6=0,100,stone_slab
rule7=0,100,wooden_door-1
rule8=0,100,bookshelf
rule9=0,100,bed-10
rule10=0,100,bed-2
rule11=0,100,wooden_door
rule12=0,100,wall_sign-2
rule13=0,100,planks
rule14=0,100,wall_sign-5
rule15=0,100,crafting_table
rule16=0,100,MediumChest-4
rule17=0,100,glass_pane
rule18=0,100,wooden_door-8
rule19=0,100,diamond_ore
rule20=0,100,gold_ore
rule21=0,100,redstone_ore
rule22=2,100,torch-3
rule23=0,100,stone_slab-3
rule24=0,100,double_stone_slab


layer
3,3,3,3,3,1,1,1,1,1,1,1
3,3,3,3,3,3,3,3,3,3,3,2
3,3,3,3,3,3,3,3,3,3,3,2
3,3,3,4,4,4,4,4,4,3,3,2
3,3,3,4,3,3,3,3,4,3,3,1
3,3,3,4,3,4,4,3,4,3,3,1
3,3,3,4,3,3,3,3,4,3,3,1
3,3,3,4,4,4,4,4,4,3,3,2
3,3,3,3,3,3,3,3,3,3,3,2
3,3,3,3,5,3,3,3,3,3,3,2
3,3,3,3,3,2,2,2,2,2,2,2
endlayer

layer
6,6,6,6,6,0,0,0,6,6,6,6
6,3,3,3,3,3,11,3,3,3,3,6
6,3,13,13,13,12,0,0,0,8,3,6
6,3,14,14,14,0,0,0,0,0,3,6
6,3,0,0,0,0,0,0,0,0,3,0
6,3,0,0,0,0,0,0,0,0,7,0
6,3,0,0,0,0,0,0,0,0,3,0
6,3,0,0,0,0,0,0,0,0,3,6
6,3,16,16,15,0,0,10,9,8,3,6
6,3,3,3,3,3,3,3,3,3,3,6
6,6,6,6,6,6,6,6,6,6,6,6
endlayer

layer
0,0,0,0,0,0,0,0,0,0,0,0
0,3,3,3,3,3,18,3,17,17,3,0
0,3,21,20,19,0,0,0,0,0,17,0
0,3,0,0,0,0,0,0,0,0,17,0
0,3,0,0,0,0,0,0,0,0,3,0
0,3,0,0,0,0,0,0,0,0,18,0
0,3,0,0,0,0,0,0,0,0,3,0
0,3,0,0,0,0,0,0,0,0,17,0
0,3,0,0,0,0,0,0,0,0,17,0
0,3,3,3,3,3,3,17,17,3,3,0
0,0,0,0,0,0,0,0,0,0,0,0
endlayer

layer
0,0,0,0,0,0,0,0,0,0,0,0
0,3,3,3,3,3,3,3,17,17,3,0
0,3,0,0,0,0,0,0,0,0,17,0
0,3,0,0,0,0,0,0,0,0,17,0
0,3,0,0,0,0,0,0,0,22,3,0
0,3,0,0,0,0,0,0,0,0,3,0
0,3,0,0,0,0,0,0,0,22,3,0
0,3,0,0,0,0,0,0,0,0,17,0
0,3,0,0,0,0,0,0,0,0,17,0
0,3,3,3,3,3,3,17,17,3,3,0
0,0,0,0,0,0,0,0,0,0,0,0
endlayer

layer
0,0,0,0,0,0,0,0,6,6,0,0
0,3,3,3,3,3,3,3,3,3,3,0
0,3,3,3,3,3,3,3,3,3,3,6
0,3,3,3,3,3,3,3,3,3,3,6
0,3,3,3,4,4,4,4,3,3,3,0
0,3,3,3,4,3,3,4,3,3,3,0
0,3,3,3,4,4,4,4,3,3,3,0
0,3,3,3,3,3,3,3,3,3,3,6
0,3,3,3,3,3,3,3,3,3,3,6
0,3,3,3,3,3,3,3,3,3,3,0
0,0,0,0,0,0,0,23,23,0,0,0
endlayer

layer
0,6,6,6,6,6,6,6,6,6,6,0
6,6,24,24,24,24,24,24,24,24,6,6
6,24,24,24,24,24,24,24,24,24,24,6
6,24,24,24,24,24,24,24,24,24,24,6
6,24,24,24,24,24,24,24,24,24,24,6
6,24,24,24,24,24,24,24,24,24,24,6
6,24,24,24,24,24,24,24,24,24,24,6
6,24,24,24,24,24,24,24,24,24,24,6
6,24,24,24,24,24,24,24,24,24,24,6
6,6,24,24,24,24,24,24,24,24,6,6
0,6,6,6,6,6,6,6,6,6,6,0
endlayer

layer
0,0,0,0,0,0,0,0,0,0,0,0
0,0,0,0,0,0,0,0,0,0,0,0
0,0,0,6,6,6,6,6,6,0,0,0
0,0,6,6,6,6,6,6,6,6,0,0
0,0,6,24,24,24,24,24,24,6,0,0
0,0,6,24,24,24,24,24,24,6,0,0
0,0,6,24,24,24,24,24,24,6,0,0
0,0,6,6,6,6,6,6,6,6,0,0
0,0,0,6,6,6,6,6,6,0,0,0
0,0,0,0,0,0,0,0,0,0,0,0
0,0,0,0,0,0,0,0,0,0,0,0
endlayer

layer
0,0,0,0,0,0,0,0,0,0,0,0
0,0,0,0,0,0,0,0,0,0,0,0
0,0,0,0,0,0,0,0,0,0,0,0
0,0,0,0,0,0,0,0,0,0,0,0
0,0,0,0,0,0,0,0,0,0,0,0
0,0,0,0,6,6,6,6,0,0,0,0
0,0,0,0,0,0,0,0,0,0,0,0
0,0,0,0,0,0,0,0,0,0,0,0
0,0,0,0,0,0,0,0,0,0,0,0
0,0,0,0,0,0,0,0,0,0,0,0
0,0,0,0,0,0,0,0,0,0,0,0
endlayer

