# Author: Arrrg
# From: Minecraft Forums
biomesToSpawnIn=hell,autumn hills,autumn woods,bamboo forest,birch forest,bog,boneyard,boreal forest,brushland,chaparral,cherry blossom grove,coniferous forest,deciduous forest,extreme hills,extreme hills edge,fen,field,forest,forested field,forested hills,forested island,foresthills,fungi forest,garden,grassland,green hills,green swamplands,grove,heathland,highland,hot springs,jade cliffs,jungle,junglehills,lavender fields,lush redwoods,lush swamp,magical forest,majestic meadow,mangrove,maplewoods,marsh,meadow,meadow forest,mesa,mini jungle,mountain, mountain ridge,mountain taiga,mystic grove,orchard,outback,overgrown beach,overgrown greens,pasture,pasture meadow,pine forest,plains,prarie,quagmire,rainforest,redwood forest,sacred springs,savanna,savanna plateau,scrubland,seasonal forest,seasonal spruce forest,shield,spruce woods,steppe,sublime shrubland,swampland,taiga,taigahills,temperate rainforest,thick shrubland,thicket,thinned mystic grove,thinned pasture,thinned timber,timber,tropical rainforest,tropics mountain,tundra,wonderous woods,woodland,woodlands,wyvern biome,wetland
weight=3
uniqueMinDistance=2000
embed_into_distance=31
unacceptable_target_blocks=bedrock,flowing_water,water,flowing_lava,lava,Natura:Cloud,red_mushroom_block,brown_mushroom_block,planks,cobblestone,end_stone,obsidian,purpur_block,iron_bars,purpur_slab,purpur_pillar,soul_sand,quartz_ore
dimensions=46,12,12
allowable_overhang=36
max_cut_in=2
cut_in_buffer=1
max_leveling=31
leveling_buffer=-1
preserve_water=0
preserve_lava=0
preserve_plants=0

rule1=0,100,preserveBlock
rule2=0,100,glowstone
rule3=0,100,snow
rule4=0,100,cobblestone
rule5=0,100,double_stone_slab
rule6=1,100,torch
rule7=0,100,HardChest
rule8=0,100,HardMobSpawn
rule9=0,100,MediumMobSpawn
rule10=0,100,UprightMobSpawn





layer
1,1,1,1,4,4,4,4,1,1,1,1
1,1,4,4,4,4,4,4,4,4,4,1
1,4,4,4,4,4,4,4,4,4,4,4
1,4,4,4,4,4,4,4,4,4,4,4
4,4,4,4,4,4,4,4,4,4,4,4
4,4,4,4,4,4,4,4,4,4,4,4
4,4,4,4,4,4,4,4,4,4,4,4
4,4,4,4,4,4,4,4,4,4,4,4
1,4,4,4,4,4,4,4,4,4,4,4
1,4,4,4,4,4,4,4,4,4,4,4
1,1,4,4,4,4,4,4,4,4,4,1
1,1,1,1,4,4,4,4,1,1,1,1
endlayer

layer
1,1,1,1,4,4,4,4,1,1,1,1
1,1,4,4,4,4,4,4,4,4,4,1
1,4,4,4,4,4,4,4,4,4,4,4
1,4,4,4,4,4,4,4,4,4,4,4
4,4,4,4,4,4,4,4,4,4,4,4
4,4,4,4,4,4,4,4,4,4,4,4
4,4,4,4,4,4,4,4,4,4,4,4
4,4,4,4,4,4,4,4,4,4,4,4
1,4,4,4,4,4,4,4,4,4,4,4
1,4,4,4,4,4,4,4,4,4,4,4
1,1,4,4,4,4,4,4,4,4,4,1
1,1,1,1,4,4,4,4,1,1,1,1
endlayer

layer
1,1,1,1,4,4,4,4,1,1,1,1
1,1,4,4,5,5,5,5,4,4,4,1
1,4,5,5,5,5,5,5,5,5,5,4
1,4,5,5,5,5,5,5,5,4,5,4
4,5,5,5,5,5,5,5,5,4,5,4
4,5,5,5,5,5,5,5,5,4,5,4
4,5,5,5,5,5,5,5,5,4,5,4
4,5,5,5,5,5,5,5,5,4,5,4
1,4,5,5,5,5,5,5,5,4,5,4
1,4,5,5,5,5,5,5,5,5,5,4
1,1,4,4,5,5,5,5,4,4,4,1
1,1,1,1,4,4,4,4,1,1,1,1
endlayer

layer
1,1,1,1,4,4,4,4,1,1,1,1
1,1,4,4,0,0,0,0,4,4,4,1
1,4,0,0,0,0,0,0,0,0,0,4
1,4,0,9,0,0,0,0,0,4,5,4
4,0,0,0,0,0,0,0,0,4,0,4
4,0,0,0,0,0,0,5,0,4,0,4
4,0,0,0,0,0,0,5,0,4,0,4
4,0,0,0,0,0,0,0,0,4,0,4
1,4,0,9,0,0,0,0,0,4,0,4
1,4,0,0,0,0,0,0,0,0,0,4
1,1,4,4,0,0,0,0,4,4,4,1
1,1,1,1,4,4,4,4,1,1,1,1
endlayer

layer
1,1,1,1,4,0,0,4,1,1,1,1
1,1,4,4,0,0,0,0,4,4,4,1
1,4,0,0,0,0,0,0,0,0,6,4
1,4,0,0,0,0,0,0,0,4,0,4
4,0,0,0,0,0,0,0,0,4,5,4
0,0,0,0,0,0,0,0,0,4,0,4
0,0,0,0,0,0,0,8,0,4,0,4
4,0,0,0,0,0,0,0,0,4,0,4
1,4,0,0,0,0,0,0,0,4,0,4
1,4,0,0,0,0,0,0,0,0,6,4
1,1,4,4,0,0,0,0,4,4,4,1
1,1,1,1,4,0,0,4,1,1,1,1
endlayer

layer
1,1,1,1,4,0,0,4,1,1,1,1
1,1,4,4,0,0,0,0,4,4,4,1
1,4,0,0,0,0,0,0,0,0,0,4
1,4,0,0,0,0,0,0,0,4,0,4
4,0,0,0,0,0,0,0,0,4,0,4
0,0,0,0,0,0,0,0,0,4,5,4
0,0,0,0,0,0,0,0,0,4,0,4
4,0,0,0,0,0,0,0,0,4,0,4
1,4,0,0,0,0,0,0,0,4,0,4
1,4,0,0,0,0,0,0,0,0,0,4
1,1,4,4,0,0,0,0,4,4,4,1
1,1,1,1,4,0,0,4,1,1,1,1
endlayer

layer
1,1,1,1,4,0,0,4,1,1,1,1
1,1,4,4,0,0,0,0,4,4,4,1
1,4,0,0,0,0,0,0,0,0,0,4
1,4,0,0,0,0,0,0,0,4,0,4
4,0,0,0,0,0,0,0,0,4,0,4
0,0,0,0,0,0,0,0,0,4,0,4
0,0,0,0,0,0,0,0,0,4,5,4
4,0,0,0,0,0,0,0,0,4,0,4
1,4,0,0,0,0,0,0,0,4,0,4
1,4,0,0,0,0,0,0,0,0,0,4
1,1,4,4,0,0,0,0,4,4,4,1
1,1,1,1,4,0,0,4,1,1,1,1
endlayer

layer
1,1,1,1,4,0,0,4,1,1,1,1
1,1,4,4,0,0,0,0,4,4,4,1
1,4,0,0,0,0,0,0,0,0,0,4
1,4,0,0,0,0,0,0,0,4,0,4
4,0,0,0,0,0,0,0,0,4,0,4
0,0,0,0,0,0,0,0,0,4,0,4
0,0,0,0,0,0,0,0,0,4,0,4
4,0,0,0,0,0,0,0,0,4,5,4
1,4,0,0,0,0,0,0,0,4,0,4
1,4,0,0,0,0,0,0,0,0,0,4
1,1,4,4,0,0,0,0,4,4,4,1
1,1,1,1,4,0,0,4,1,1,1,1
endlayer

layer
1,1,1,1,4,4,4,4,1,1,1,1
1,1,4,4,0,0,0,0,4,4,4,1
1,4,0,0,0,0,0,0,0,0,0,4
1,4,0,0,0,0,0,0,0,4,0,4
4,0,0,0,0,0,0,0,0,4,0,4
4,0,0,0,0,0,0,0,0,4,0,4
4,0,0,0,0,0,0,0,0,4,0,4
4,0,0,0,0,0,0,0,0,4,0,4
1,4,0,0,0,0,0,0,0,4,5,4
1,4,0,0,0,0,0,0,0,0,0,4
1,1,4,4,0,0,0,0,4,4,4,1
1,1,1,1,4,4,4,4,1,1,1,1
endlayer

layer
1,1,1,1,4,4,4,4,1,1,1,1
1,1,4,4,5,5,5,5,4,4,4,1
1,4,5,5,0,5,5,5,5,5,5,4
1,4,5,5,5,5,5,5,5,4,0,4
4,5,5,5,5,0,5,5,5,4,0,4
4,5,5,5,5,5,5,5,5,4,0,4
4,5,5,0,5,5,5,5,5,4,0,4
4,5,5,5,5,5,5,5,5,4,0,4
1,4,5,5,5,0,5,5,5,4,0,4
1,4,5,5,5,5,5,5,5,5,5,4
1,1,4,4,5,5,5,5,4,4,4,1
1,1,1,1,4,4,4,4,1,1,1,1
endlayer

layer
1,1,1,1,4,4,4,4,1,1,1,1
1,1,4,4,0,0,0,0,4,4,4,1
1,4,0,0,0,0,0,0,0,0,0,4
1,4,0,9,0,0,0,0,0,4,5,4
4,0,0,0,0,0,0,0,0,4,0,4
4,0,0,0,0,0,0,5,0,4,0,4
4,0,0,0,0,0,0,5,0,4,0,4
4,0,0,0,0,0,0,0,0,4,0,4
1,4,0,9,0,0,0,0,0,4,0,4
1,4,0,0,0,0,0,0,0,0,0,4
1,1,4,4,0,0,0,0,4,4,4,1
1,1,1,1,4,4,4,4,1,1,1,1
endlayer

layer
1,1,1,1,4,0,0,4,1,1,1,1
1,1,4,4,0,0,0,0,4,4,4,1
1,4,0,0,0,0,0,0,0,0,6,4
1,4,0,0,0,0,0,0,0,4,0,4
4,0,0,0,0,0,0,0,0,4,5,4
0,0,0,0,0,0,0,0,0,4,0,4
0,0,0,0,0,0,0,8,0,4,0,4
4,0,0,0,0,0,0,0,0,4,0,4
1,4,0,0,0,0,0,0,0,4,0,4
1,4,0,0,0,0,0,0,0,0,6,4
1,1,4,4,0,0,0,0,4,4,4,1
1,1,1,1,4,0,0,4,1,1,1,1
endlayer

layer
1,1,1,1,4,0,0,4,1,1,1,1
1,1,4,4,0,0,0,0,4,4,4,1
1,4,0,0,0,0,0,0,0,0,0,4
1,4,0,0,0,0,0,0,0,4,0,4
4,0,0,0,0,0,0,0,0,4,0,4
0,0,0,0,0,0,0,0,0,4,5,4
0,0,0,0,0,0,0,0,0,4,0,4
4,0,0,0,0,0,0,0,0,4,0,4
1,4,0,0,0,0,0,0,0,4,0,4
1,4,0,0,0,0,0,0,0,0,0,4
1,1,4,4,0,0,0,0,4,4,4,1
1,1,1,1,4,0,0,4,1,1,1,1
endlayer

layer
1,1,1,1,4,0,0,4,1,1,1,1
1,1,4,4,0,0,0,0,4,4,4,1
1,4,0,0,0,0,0,0,0,0,0,4
1,4,0,0,0,0,0,0,0,4,0,4
4,0,0,0,0,0,0,0,0,4,0,4
0,0,0,0,0,0,0,0,0,4,0,4
0,0,0,0,0,0,0,0,0,4,5,4
4,0,0,0,0,0,0,0,0,4,0,4
1,4,0,0,0,0,0,0,0,4,0,4
1,4,0,0,0,0,0,0,0,0,0,4
1,1,4,4,0,0,0,0,4,4,4,1
1,1,1,1,4,0,0,4,1,1,1,1
endlayer

layer
1,1,1,1,4,0,0,4,1,1,1,1
1,1,4,4,0,0,0,0,4,4,4,1
1,4,0,0,0,0,0,0,0,0,0,4
1,4,0,0,0,0,0,0,0,4,0,4
4,0,0,0,0,0,0,0,0,4,0,4
0,0,0,0,0,0,0,0,0,4,0,4
0,0,0,0,0,0,0,0,0,4,0,4
4,0,0,0,0,0,0,0,0,4,5,4
1,4,0,0,0,0,0,0,0,4,0,4
1,4,0,0,0,0,0,0,0,0,0,4
1,1,4,4,0,0,0,0,4,4,4,1
1,1,1,1,4,0,0,4,1,1,1,1
endlayer

layer
1,1,1,1,4,4,4,4,1,1,1,1
1,1,4,4,0,0,0,0,4,4,4,1
1,4,0,0,0,0,0,0,0,0,0,4
1,4,0,0,0,0,0,0,0,4,0,4
4,0,0,0,0,0,0,0,0,4,0,4
4,0,0,0,0,0,0,0,0,4,0,4
4,0,0,0,0,0,0,0,0,4,0,4
4,0,0,0,0,0,0,0,0,4,0,4
1,4,0,0,0,0,0,0,0,4,5,4
1,4,0,0,0,0,0,0,0,0,0,4
1,1,4,4,0,0,0,0,4,4,4,1
1,1,1,1,4,4,4,4,1,1,1,1
endlayer

layer
1,1,1,1,4,4,4,4,1,1,1,1
1,1,4,4,5,5,5,5,4,4,4,1
1,4,5,0,5,5,5,0,5,5,5,4
1,4,5,5,5,5,5,5,5,4,0,4
4,5,5,5,0,5,0,5,5,4,0,4
4,5,5,5,5,5,5,5,5,4,0,4
4,5,0,5,5,0,5,5,5,4,0,4
4,5,5,5,5,5,5,5,5,4,0,4
1,4,5,5,0,5,0,5,5,4,0,4
1,4,5,5,5,5,5,5,5,5,5,4
1,1,4,4,5,5,5,5,4,4,4,1
1,1,1,1,4,4,4,4,1,1,1,1
endlayer

layer
1,1,1,1,4,4,4,4,1,1,1,1
1,1,4,4,0,0,0,0,4,4,4,1
1,4,0,0,0,0,0,0,0,0,0,4
1,4,0,9,0,0,0,0,0,4,5,4
4,0,0,0,0,0,0,0,0,4,0,4
4,0,0,0,0,0,0,5,0,4,0,4
4,0,0,0,0,0,0,5,0,4,0,4
4,0,0,0,0,0,0,0,0,4,0,4
1,4,0,9,0,0,0,0,0,4,0,4
1,4,0,0,0,0,0,0,0,0,0,4
1,1,4,4,0,0,0,0,4,4,4,1
1,1,1,1,4,4,4,4,1,1,1,1
endlayer

layer
1,1,1,1,4,0,0,4,1,1,1,1
1,1,4,4,0,0,0,0,4,4,4,1
1,4,0,0,0,0,0,0,0,0,6,4
1,4,0,0,0,0,0,0,0,4,0,4
4,0,0,0,0,0,0,0,0,4,5,4
0,0,0,0,0,0,0,0,0,4,0,4
0,0,0,0,0,0,0,8,0,4,0,4
4,0,0,0,0,0,0,0,0,4,0,4
1,4,0,0,0,0,0,0,0,4,0,4
1,4,0,0,0,0,0,0,0,0,6,4
1,1,4,4,0,0,0,0,4,4,4,1
1,1,1,1,4,0,0,4,1,1,1,1
endlayer

layer
1,1,1,1,4,0,0,4,1,1,1,1
1,1,4,4,0,0,0,0,4,4,4,1
1,4,0,0,0,0,0,0,0,0,0,4
1,4,0,0,0,0,0,0,0,4,0,4
4,0,0,0,0,0,0,0,0,4,0,4
0,0,0,0,0,0,0,0,0,4,5,4
0,0,0,0,0,0,0,0,0,4,0,4
4,0,0,0,0,0,0,0,0,4,0,4
1,4,0,0,0,0,0,0,0,4,0,4
1,4,0,0,0,0,0,0,0,0,0,4
1,1,4,4,0,0,0,0,4,4,4,1
1,1,1,1,4,0,0,4,1,1,1,1
endlayer

layer
1,1,1,1,4,0,0,4,1,1,1,1
1,1,4,4,0,0,0,0,4,4,4,1
1,4,0,0,0,0,0,0,0,0,0,4
1,4,0,0,0,0,0,0,0,4,0,4
4,0,0,0,0,0,0,0,0,4,0,4
0,0,0,0,0,0,0,0,0,4,0,4
0,0,0,0,0,0,0,0,0,4,5,4
4,0,0,0,0,0,0,0,0,4,0,4
1,4,0,0,0,0,0,0,0,4,0,4
1,4,0,0,0,0,0,0,0,0,0,4
1,1,4,4,0,0,0,0,4,4,4,1
1,1,1,1,4,0,0,4,1,1,1,1
endlayer

layer
1,1,1,1,4,0,0,4,1,1,1,1
1,1,4,4,0,0,0,0,4,4,4,1
1,4,0,0,0,0,0,0,0,0,0,4
1,4,0,0,0,0,0,0,0,4,0,4
4,0,0,0,0,0,0,0,0,4,0,4
0,0,0,0,0,0,0,0,0,4,0,4
0,0,0,0,0,0,0,0,0,4,0,4
4,0,0,0,0,0,0,0,0,4,5,4
1,4,0,0,0,0,0,0,0,4,0,4
1,4,0,0,0,0,0,0,0,0,0,4
1,1,4,4,0,0,0,0,4,4,4,1
1,1,1,1,4,0,0,4,1,1,1,1
endlayer

layer
1,1,1,1,4,4,4,4,1,1,1,1
1,1,4,4,0,0,0,0,4,4,4,1
1,4,0,0,0,0,0,0,0,0,0,4
1,4,0,0,0,0,0,0,0,4,0,4
4,0,0,0,0,0,0,0,0,4,0,4
4,0,0,0,0,0,0,0,0,4,0,4
4,0,0,0,0,0,0,0,0,4,0,4
4,0,0,0,0,0,0,0,0,4,0,4
1,4,0,0,0,0,0,0,0,4,5,4
1,4,0,0,0,0,0,0,0,0,0,4
1,1,4,4,0,0,0,0,4,4,4,1
1,1,1,1,4,4,4,4,1,1,1,1
endlayer

layer
1,1,1,1,4,4,4,4,1,1,1,1
1,1,4,4,5,5,5,5,4,4,4,1
1,4,5,5,0,5,0,5,0,5,5,4
1,4,5,5,5,5,5,5,5,4,0,4
4,5,0,5,5,0,5,0,5,4,0,4
4,5,5,5,5,5,5,5,5,4,0,4
4,5,5,0,5,5,0,5,5,4,0,4
4,0,5,5,5,5,5,5,5,4,0,4
1,4,5,5,5,0,5,0,5,4,0,4
1,4,5,5,5,5,5,5,5,5,5,4
1,1,4,4,5,5,0,5,4,4,4,1
1,1,1,1,4,4,4,4,1,1,1,1
endlayer

layer
1,1,1,1,4,4,4,4,1,1,1,1
1,1,4,4,0,0,0,0,4,4,4,1
1,4,0,0,0,0,0,0,0,0,0,4
1,4,0,9,0,0,0,0,0,4,5,4
4,0,0,0,0,0,0,0,0,4,0,4
4,0,0,0,0,0,0,5,0,4,0,4
4,0,0,0,0,0,0,5,0,4,0,4
4,0,0,0,0,0,0,0,0,4,0,4
1,4,0,9,0,0,0,0,0,4,0,4
1,4,0,0,0,0,0,0,0,0,0,4
1,1,4,4,0,0,0,0,4,4,4,1
1,1,1,1,4,4,4,4,1,1,1,1
endlayer

layer
1,1,1,1,4,0,0,4,1,1,1,1
1,1,4,4,0,0,0,0,4,4,4,1
1,4,0,0,0,0,0,0,0,0,6,4
1,4,0,0,0,0,0,0,0,4,0,4
4,0,0,0,0,0,0,0,0,4,5,4
0,0,0,0,0,0,0,0,0,4,0,4
0,0,0,0,0,0,0,8,0,4,0,4
4,0,0,0,0,0,0,0,0,4,0,4
1,4,0,0,0,0,0,0,0,4,0,4
1,4,0,0,0,0,0,0,0,0,6,4
1,1,4,4,0,0,0,0,4,4,4,1
1,1,1,1,4,0,0,4,1,1,1,1
endlayer

layer
1,1,1,1,4,0,0,4,1,1,1,1
1,1,4,4,0,0,0,0,4,4,4,1
1,4,0,0,0,0,0,0,0,0,0,4
1,4,0,0,0,0,0,0,0,4,0,4
4,0,0,0,0,0,0,0,0,4,0,4
0,0,0,0,0,0,0,0,0,4,5,4
0,0,0,0,0,0,0,0,0,4,0,4
4,0,0,0,0,0,0,0,0,4,0,4
1,4,0,0,0,0,0,0,0,4,0,4
1,4,0,0,0,0,0,0,0,0,0,4
1,1,4,4,0,0,0,0,4,4,4,1
1,1,1,1,4,0,0,4,1,1,1,1
endlayer

layer
1,1,1,1,4,0,0,4,1,1,1,1
1,1,4,4,0,0,0,0,4,4,4,1
1,4,0,0,0,0,0,0,0,0,0,4
1,4,0,0,0,0,0,0,0,4,0,4
4,0,0,0,0,0,0,0,0,4,0,4
0,0,0,0,0,0,0,0,0,4,0,4
0,0,0,0,0,0,0,0,0,4,5,4
4,0,0,0,0,0,0,0,0,4,0,4
1,4,0,0,0,0,0,0,0,4,0,4
1,4,0,0,0,0,0,0,0,0,0,4
1,1,4,4,0,0,0,0,4,4,4,1
1,1,1,1,4,0,0,4,1,1,1,1
endlayer

layer
1,1,1,1,4,0,0,4,1,1,1,1
1,1,4,4,0,0,0,0,4,4,4,1
1,4,0,0,0,0,0,0,0,0,0,4
1,4,0,0,0,0,0,0,0,4,0,4
4,0,0,0,0,0,0,0,0,4,0,4
0,0,0,0,0,0,0,0,0,4,0,4
0,0,0,0,0,0,0,0,0,4,0,4
4,0,0,0,0,0,0,0,0,4,5,4
1,4,0,0,0,0,0,0,0,4,0,4
1,4,0,0,0,0,0,0,0,0,0,4
1,1,4,4,0,0,0,0,4,4,4,1
1,1,1,1,4,0,0,4,1,1,1,1
endlayer

layer
1,1,1,1,4,4,4,4,1,1,1,1
1,1,4,4,0,0,0,0,4,4,4,1
1,4,0,0,0,0,0,0,0,0,0,4
1,4,0,0,0,0,0,0,0,4,0,4
4,0,0,0,0,0,0,0,0,4,0,4
4,0,0,0,0,0,0,0,0,4,0,4
4,0,0,0,0,0,0,0,0,4,0,4
4,0,0,0,0,0,0,0,0,4,0,4
1,4,0,0,0,0,0,0,0,4,5,4
1,4,0,0,0,0,0,0,0,0,0,4
1,1,4,4,0,0,0,0,4,4,4,1
1,1,1,1,4,4,4,4,1,1,1,1
endlayer

layer
1,1,1,1,4,4,4,4,1,1,1,1
1,1,4,4,5,5,5,5,4,4,4,1
1,4,5,0,5,0,5,5,0,5,5,4
1,4,5,5,5,5,5,5,5,4,0,4
4,5,5,0,5,5,0,5,0,4,0,4
4,5,0,5,5,5,5,5,0,4,0,4
4,5,5,5,0,5,0,5,5,4,0,4
4,5,0,5,5,0,5,5,5,4,0,4
1,4,5,5,5,5,0,5,0,4,0,4
1,4,5,5,0,5,5,5,5,5,5,4
1,1,4,4,5,5,5,0,4,4,4,1
1,1,1,1,4,4,4,4,1,1,1,1
endlayer

layer
1,1,1,1,4,4,4,4,1,1,1,1
1,1,4,4,0,0,0,0,4,4,4,1
1,4,0,0,0,0,0,0,0,0,0,4
1,4,0,9,0,0,0,0,0,4,5,4
4,0,0,0,0,0,0,0,0,4,0,4
4,0,0,0,0,0,0,5,0,4,0,4
4,0,0,0,0,0,0,5,0,4,0,4
4,0,0,0,0,0,0,0,0,4,0,4
1,4,0,9,0,0,0,0,0,4,0,4
1,4,0,0,0,0,0,0,0,0,0,4
1,1,4,4,0,0,0,0,4,4,4,1
1,1,1,1,4,4,4,4,1,1,1,1
endlayer

layer
1,1,1,1,4,0,0,4,1,1,1,1
1,1,4,4,0,0,0,0,4,4,4,1
1,4,0,0,0,0,0,0,0,0,6,4
1,4,0,0,0,0,0,0,0,4,0,4
4,0,0,0,0,0,0,0,0,4,5,4
0,0,0,0,0,0,0,0,0,4,0,4
0,0,0,0,0,0,0,8,0,4,0,4
4,0,0,0,0,0,0,0,0,4,0,4
1,4,0,0,0,0,0,0,0,4,0,4
1,4,0,0,0,0,0,0,0,0,6,4
1,1,4,4,0,0,0,0,4,4,4,1
1,1,1,1,4,0,0,4,1,1,1,1
endlayer

layer
1,1,1,1,4,0,0,4,1,1,1,1
1,1,4,4,0,0,0,0,4,4,4,1
1,4,0,0,0,0,0,0,0,0,0,4
1,4,0,0,0,0,0,0,0,4,0,4
4,0,0,0,0,0,0,0,0,4,0,4
0,0,0,0,0,0,0,0,0,4,5,4
0,0,0,0,0,0,0,0,0,4,0,4
4,0,0,0,0,0,0,0,0,4,0,4
1,4,0,0,0,0,0,0,0,4,0,4
1,4,0,0,0,0,0,0,0,0,0,4
1,1,4,4,0,0,0,0,4,4,4,1
1,1,1,1,4,0,0,4,1,1,1,1
endlayer

layer
1,1,1,1,4,0,0,4,1,1,1,1
1,1,4,4,0,0,0,0,4,4,4,1
1,4,0,0,0,0,0,0,0,0,0,4
1,4,0,0,0,0,0,0,0,4,0,4
4,0,0,0,0,0,0,0,0,4,0,4
0,0,0,0,0,0,0,0,0,4,0,4
0,0,0,0,0,0,0,0,0,4,5,4
4,0,0,0,0,0,0,0,0,4,0,4
1,4,0,0,0,0,0,0,0,4,0,4
1,4,0,0,0,0,0,0,0,0,0,4
1,1,4,4,0,0,0,0,4,4,4,1
1,1,1,1,4,0,0,4,1,1,1,1
endlayer

layer
1,1,1,1,4,0,0,4,1,1,1,1
1,1,4,4,0,0,0,0,4,4,4,1
1,4,0,0,0,0,0,0,0,0,0,4
1,4,0,0,0,0,0,0,0,4,0,4
4,0,0,0,0,0,0,0,0,4,0,4
0,0,0,0,0,0,0,0,0,4,0,4
0,0,0,0,0,0,0,0,0,4,0,4
4,0,0,0,0,0,0,0,0,4,5,4
1,4,0,0,0,0,0,0,0,4,0,4
1,4,0,0,0,0,0,0,0,0,0,4
1,1,4,4,0,0,0,0,4,4,4,1
1,1,1,1,4,0,0,4,1,1,1,1
endlayer

layer
1,1,1,1,4,4,4,4,1,1,1,1
1,1,4,4,0,0,0,0,4,4,4,1
1,4,0,0,0,0,0,0,0,0,0,4
1,4,0,0,0,0,0,0,0,4,0,4
4,0,0,0,0,0,0,0,0,4,0,4
4,0,0,0,0,0,0,0,0,4,0,4
4,0,0,0,0,0,0,0,0,4,0,4
4,0,0,0,0,0,0,0,0,4,0,4
1,4,0,0,0,0,0,0,0,4,5,4
1,4,0,0,0,0,0,0,0,0,0,4
1,1,4,4,0,0,0,0,4,4,4,1
1,1,1,1,4,4,4,4,1,1,1,1
endlayer

layer
1,1,1,1,4,4,4,4,1,1,1,1
1,1,4,4,5,5,0,5,4,4,4,1
1,4,0,5,0,5,5,0,5,5,5,4
1,4,5,5,5,5,5,5,5,4,0,4
4,5,0,5,5,0,5,0,5,4,0,4
4,5,0,5,5,5,0,5,0,4,0,4
4,5,5,0,5,0,5,5,0,4,0,4
4,0,5,5,0,5,5,5,5,4,0,4
1,4,5,5,5,0,5,0,5,4,0,4
1,4,5,0,5,5,5,5,0,5,5,4
1,1,4,4,5,0,5,0,4,4,4,1
1,1,1,1,4,4,4,4,1,1,1,1
endlayer

layer
1,1,1,1,4,4,4,4,1,1,1,1
1,1,4,4,0,0,0,0,4,4,4,1
1,4,0,0,0,0,0,0,0,0,0,4
1,4,0,9,0,0,0,0,0,4,5,4
4,0,0,0,0,0,0,0,0,4,0,4
4,0,0,0,0,0,0,5,0,4,0,4
4,0,0,0,0,0,0,5,0,4,0,4
4,0,0,0,0,0,0,0,0,4,0,4
1,4,0,9,0,0,0,0,0,4,0,4
1,4,0,0,0,0,0,0,0,0,0,4
1,1,4,4,0,0,0,0,4,4,4,1
1,1,1,1,4,4,4,4,1,1,1,1
endlayer

layer
1,1,1,1,4,0,0,4,1,1,1,1
1,1,4,4,0,0,0,0,4,4,4,1
1,4,0,0,0,0,0,0,0,0,6,4
1,4,0,0,0,0,0,0,0,4,0,4
4,0,0,0,0,0,0,0,0,4,5,4
0,0,0,0,0,0,0,0,0,4,0,4
0,0,0,0,0,0,0,8,0,4,0,4
4,0,0,0,0,0,0,0,0,4,0,4
1,4,0,0,0,0,0,0,0,4,0,4
1,4,0,0,0,0,0,0,0,0,6,4
1,1,4,4,0,0,0,0,4,4,4,1
1,1,1,1,4,0,0,4,1,1,1,1
endlayer

layer
1,1,1,1,4,0,0,4,1,1,1,1
1,1,4,4,0,0,0,0,4,4,4,1
1,4,0,0,0,0,0,0,0,0,0,4
1,4,0,0,0,0,0,0,0,4,0,4
4,0,0,0,0,0,0,0,0,4,0,4
0,0,0,0,0,0,0,0,0,4,5,4
0,0,0,0,0,0,0,0,0,4,0,4
4,0,0,0,0,0,0,0,0,4,0,4
1,4,0,0,0,0,0,0,0,4,0,4
1,4,0,0,0,0,0,0,0,0,0,4
1,1,4,4,0,0,0,0,4,4,4,1
1,1,1,1,4,0,0,4,1,1,1,1
endlayer

layer
1,1,1,1,4,0,0,4,1,1,1,1
1,1,4,4,0,0,0,0,4,4,4,1
1,4,0,0,0,0,0,0,0,0,0,4
1,4,0,0,0,0,0,0,0,4,0,4
4,0,0,0,0,0,0,0,0,4,0,4
0,0,0,0,0,0,0,0,0,4,0,4
0,0,0,0,0,0,0,0,0,4,5,4
4,0,0,0,0,0,0,0,0,4,0,4
1,4,0,0,0,0,0,0,0,4,0,4
1,4,0,0,0,0,0,0,0,0,0,4
1,1,4,4,0,0,0,0,4,4,4,1
1,1,1,1,4,0,0,4,1,1,1,1
endlayer

layer
1,1,1,1,4,0,0,4,1,1,1,1
1,1,4,4,0,0,0,0,4,4,4,1
1,4,0,0,0,0,0,0,0,0,0,4
1,4,0,0,0,0,0,0,0,4,0,4
4,0,0,0,0,0,0,0,0,4,0,4
0,0,0,0,0,0,0,0,0,4,0,4
0,0,0,0,0,0,0,0,0,4,0,4
4,0,0,0,0,0,0,0,0,4,5,4
1,4,0,0,0,0,0,0,0,4,0,4
1,4,0,0,0,0,0,0,0,0,0,4
1,1,4,4,0,0,0,0,4,4,4,1
1,1,1,1,4,0,0,4,1,1,1,1
endlayer

layer
1,1,1,1,4,4,4,4,1,1,1,1
1,1,4,4,0,0,0,0,4,4,4,1
1,4,0,0,0,0,0,0,0,0,0,4
1,4,0,0,0,0,0,0,0,4,0,4
4,0,0,0,0,0,0,0,0,4,0,4
4,0,0,0,0,0,0,0,0,4,0,4
4,0,0,0,0,0,0,0,0,4,0,4
4,0,0,0,0,0,0,0,0,4,0,4
1,4,0,0,0,0,0,0,0,4,5,4
1,4,0,0,0,0,0,0,0,0,0,4
1,1,4,4,0,0,0,0,4,4,4,1
1,1,1,1,4,4,4,4,1,1,1,1
endlayer

layer
1,1,1,1,4,4,4,4,1,1,1,1
1,1,4,4,5,5,5,5,4,4,4,1
1,4,5,5,5,5,5,5,5,5,5,4
1,4,5,5,5,5,5,5,5,5,0,4
4,5,5,5,5,5,5,5,5,5,0,4
4,5,5,5,5,5,5,5,5,5,0,4
4,5,5,5,5,5,5,5,5,5,0,4
4,5,5,5,5,5,5,5,5,5,0,4
1,4,5,5,5,5,5,5,5,5,0,4
1,4,5,5,5,5,5,5,5,5,5,4
1,1,4,4,5,5,5,5,4,4,4,1
1,1,1,1,4,4,4,4,1,1,1,1
endlayer

layer
1,1,1,1,4,4,4,4,1,1,1,1
1,1,4,4,0,0,0,0,4,4,4,1
1,4,0,0,0,0,0,0,0,0,0,4
1,4,0,10,0,0,0,0,0,0,0,4
4,0,0,0,0,0,0,0,0,0,0,4
4,0,0,0,0,0,0,0,0,0,0,4
4,0,7,0,0,0,0,0,0,0,0,4
4,0,0,0,0,0,0,0,0,0,0,4
1,4,0,10,0,0,0,0,0,0,0,4
1,4,0,0,0,0,0,0,0,0,0,4
1,1,4,4,0,0,0,0,4,4,4,1
1,1,1,1,4,4,4,4,1,1,1,1
endlayer
