# Converted from schematic
# THIS TEMPLATE USES DEFAULTS!  Please edit for corrections.
# If you need help, consult template_rules.txt
biomesToSpawnIn=autumn hills,autumn woods,bamboo forest,birch forest,bog,boneyard,boreal forest,brushland,chaparral,cherry blossom grove,coniferous forest,deciduous forest,extreme hills,extreme hills edge,fen,field,forest,forested field,forested hills,forested island,foresthills,fungi forest,garden,grassland,green hills,green swamplands,grove,heathland,highland,hot springs,jade cliffs,jungle,junglehills,lavender fields,lush redwoods,lush swamp,magical forest,majestic meadow,mangrove,maplewoods,marsh,meadow,meadow forest,mesa,mini jungle,mountain, mountain ridge,mountain taiga,mystic grove,orchard,outback,overgrown beach,overgrown greens,pasture,pasture meadow,pine forest,plains,prarie,quagmire,rainforest,redwood forest,sacred springs,savanna,savanna plateau,scrubland,seasonal forest,seasonal spruce forest,shield,spruce woods,steppe,sublime shrubland,swampland,taiga,taigahills,temperate rainforest,thick shrubland,thicket,thinned mystic grove,thinned pasture,thinned timber,timber,tropical rainforest,tropics mountain,tundra,wonderous woods,woodland,woodlands,wyvern biome,wetland
weight=1
embed_into_distance=2
unacceptable_target_blocks=flowing_water,water,flowing_lava,lava,Natura:Cloud,red_mushroom_block,brown_mushroom_block,planks,cobblestone,end_stone,obsidian,purpur_block,iron_bars,purpur_slab,purpur_pillar,netherrack,soul_sand,quartz_ore
dimensions=21,10,10
allowable_overhang=0
max_cut_in=2
cut_in_buffer=1
max_leveling=2
leveling_buffer=0
preserve_water=0
preserve_lava=0
preserve_plants=0


rule1=0,100,dirt
rule2=0,100,mossy_cobblestone
rule3=0,100,cobblestone
rule4=0,100,grass
rule5=0,100,crafting_table
rule6=0,100,stone_stairs-1
rule7=0,100,ladder-4
rule8=0,100,planks
rule9=0,100,furnace-5
rule10=2,100,torch-2
rule11=2,100,torch-3
rule12=2,100,torch-4
rule13=2,100,torch-1
rule14=0,100,glass
rule15=0,100,stone_stairs-3
rule16=0,100,stone_stairs
rule17=0,100,stone_stairs-2
rule18=2,100,torch-5


layer
1,1,1,1,1,1,1,1,1,1
1,1,1,1,1,1,1,1,1,1
1,1,1,1,1,1,1,1,1,1
1,1,1,1,1,1,1,1,1,1
1,1,1,1,1,1,1,1,1,1
1,1,1,1,1,1,1,1,1,1
1,1,1,1,1,1,1,1,1,1
1,1,1,1,1,1,1,1,1,1
1,1,1,1,1,1,1,1,1,1
1,1,1,1,1,1,1,1,1,1
endlayer

layer
1,1,1,1,1,1,1,1,1,1
1,1,1,1,1,1,1,1,1,1
1,1,1,1,1,1,1,1,1,1
1,1,2,2,3,3,3,2,1,1
1,1,2,3,3,3,3,2,1,1
1,1,3,3,2,2,2,3,1,1
1,1,2,3,3,2,3,2,1,1
1,1,1,2,3,3,2,1,1,1
1,1,1,1,1,1,1,1,1,1
1,1,1,1,1,1,1,1,1,1
endlayer

layer
4,4,4,4,4,4,4,4,4,4
4,4,4,3,3,3,3,4,4,4
4,4,3,9,6,6,5,2,4,4
4,2,0,0,0,0,0,0,3,4
4,2,0,0,7,7,0,0,2,4
4,3,0,0,8,8,0,0,3,4
4,3,0,0,0,0,0,0,3,4
4,4,3,0,0,0,0,3,4,4
4,4,4,3,3,3,3,4,4,4
4,4,4,4,4,4,4,4,4,4
endlayer

layer
0,0,0,0,0,0,0,0,0,0
0,0,0,2,0,0,2,0,0,0
0,0,3,0,0,0,0,3,0,0
0,2,0,0,0,0,0,0,2,0
0,3,0,0,7,7,0,0,3,0
0,2,0,0,8,8,0,0,3,0
0,2,0,0,0,0,0,0,3,0
0,0,2,0,0,0,0,3,0,0
0,0,0,3,3,3,3,0,0,0
0,0,0,0,0,0,0,0,0,0
endlayer

layer
0,0,0,0,0,0,0,0,0,0
0,0,0,3,0,0,2,0,0,0
0,0,3,12,0,0,0,3,0,0
0,3,13,0,0,0,0,0,3,0
0,2,0,0,7,7,0,0,2,0
0,2,0,0,8,8,0,0,3,0
0,3,0,0,0,0,0,10,2,0
0,0,2,0,0,0,11,3,0,0
0,0,0,2,3,3,2,0,0,0
0,0,0,0,0,0,0,0,0,0
endlayer

layer
0,0,0,0,0,0,0,0,0,0
0,0,0,3,3,3,2,0,0,0
0,0,0,3,3,3,2,0,0,0
0,0,3,3,0,0,3,2,0,0
0,0,3,0,7,7,0,2,0,0
0,0,3,0,8,8,0,3,0,0
0,0,3,3,0,0,3,3,0,0
0,0,0,3,3,3,3,0,0,0
0,0,0,0,0,0,0,0,0,0
0,0,0,0,0,0,0,0,0,0
endlayer

layer
0,0,0,0,0,0,0,0,0,0
0,0,0,0,0,0,0,0,0,0
0,0,0,3,3,3,2,0,0,0
0,0,3,3,0,0,3,3,0,0
0,0,3,0,7,7,0,2,0,0
0,0,3,0,8,8,0,3,0,0
0,0,3,3,0,0,3,3,0,0
0,0,0,3,3,3,2,0,0,0
0,0,0,0,0,0,0,0,0,0
0,0,0,0,0,0,0,0,0,0
endlayer

layer
0,0,0,0,0,0,0,0,0,0
0,0,0,0,0,0,0,0,0,0
0,0,0,0,8,8,0,0,0,0
0,0,0,3,0,0,2,0,0,0
0,0,8,0,7,7,0,8,0,0
0,0,8,0,8,8,0,8,0,0
0,0,0,3,0,0,2,0,0,0
0,0,0,0,8,8,0,0,0,0
0,0,0,0,0,0,0,0,0,0
0,0,0,0,0,0,0,0,0,0
endlayer

layer
0,0,0,0,0,0,0,0,0,0
0,0,0,0,0,0,0,0,0,0
0,0,0,0,0,0,0,0,0,0
0,0,0,3,3,2,2,0,0,0
0,0,0,3,7,7,3,0,0,0
0,0,0,3,8,8,2,0,0,0
0,0,0,3,3,3,2,0,0,0
0,0,0,0,0,0,0,0,0,0
0,0,0,0,0,0,0,0,0,0
0,0,0,0,0,0,0,0,0,0
endlayer

layer
0,0,0,0,0,0,0,0,0,0
0,0,0,0,0,0,0,0,0,0
0,0,0,0,0,0,0,0,0,0
0,0,0,3,14,14,3,0,0,0
0,0,0,14,7,7,14,0,0,0
0,0,0,14,8,8,14,0,0,0
0,0,0,3,14,14,3,0,0,0
0,0,0,0,0,0,0,0,0,0
0,0,0,0,0,0,0,0,0,0
0,0,0,0,0,0,0,0,0,0
endlayer

layer
0,0,0,0,0,0,0,0,0,0
0,0,0,0,0,0,0,0,0,0
0,0,0,0,0,0,0,0,0,0
0,0,0,3,14,14,3,0,0,0
0,0,0,14,7,7,14,0,0,0
0,0,0,14,8,8,14,0,0,0
0,0,0,3,14,14,2,0,0,0
0,0,0,0,0,0,0,0,0,0
0,0,0,0,0,0,0,0,0,0
0,0,0,0,0,0,0,0,0,0
endlayer

layer
0,0,0,0,0,0,0,0,0,0
0,0,0,0,0,0,0,0,0,0
0,0,0,0,0,0,0,0,0,0
0,0,0,3,14,14,2,0,0,0
0,0,0,14,7,7,14,0,0,0
0,0,0,14,8,8,14,0,0,0
0,0,0,3,14,14,3,0,0,0
0,0,0,0,0,0,0,0,0,0
0,0,0,0,0,0,0,0,0,0
0,0,0,0,0,0,0,0,0,0
endlayer

layer
0,0,0,0,0,0,0,0,0,0
0,0,0,0,0,0,0,0,0,0
0,0,0,0,0,0,0,0,0,0
0,0,0,2,3,3,2,0,0,0
0,0,0,2,7,7,3,0,0,0
0,0,0,3,8,8,3,0,0,0
0,0,0,2,3,3,2,0,0,0
0,0,0,0,0,0,0,0,0,0
0,0,0,0,0,0,0,0,0,0
0,0,0,0,0,0,0,0,0,0
endlayer

layer
0,0,0,0,3,3,0,0,0,0
0,0,0,0,3,3,0,0,0,0
0,0,3,3,3,3,3,2,0,0
0,0,3,3,3,3,3,3,0,0
0,0,3,3,7,7,3,3,0,0
0,0,3,3,8,8,3,3,0,0
0,0,2,3,3,3,3,2,0,0
0,0,3,3,2,3,3,2,0,0
0,0,0,0,0,0,0,0,0,0
0,0,0,0,0,0,0,0,0,0
endlayer

layer
0,0,0,3,0,0,3,0,0,0
0,2,3,3,0,0,3,3,2,0
0,3,3,6,0,0,6,3,2,0
0,3,17,0,0,0,0,15,3,0
0,3,17,0,0,0,0,15,3,0
0,3,17,0,0,0,0,15,3,0
0,3,17,0,0,0,0,15,3,0
0,3,3,16,16,16,16,3,3,0
0,3,2,2,3,3,3,2,2,0
0,0,0,0,0,0,0,0,0,0
endlayer

layer
0,2,3,3,0,0,3,3,3,0
2,3,12,0,0,0,0,11,3,3
2,13,0,0,0,0,0,0,13,3
3,0,0,0,0,0,0,0,0,3
3,0,0,0,0,0,0,0,0,3
3,0,0,0,0,0,0,0,0,3
3,0,0,0,0,0,0,0,0,3
3,10,0,0,0,0,0,0,10,3
3,3,12,0,0,0,0,11,3,3
0,3,3,3,3,3,3,3,2,0
endlayer

layer
0,14,14,14,0,0,14,14,14,0
14,18,0,0,0,0,0,0,18,14
14,0,0,0,0,0,0,0,0,14
14,0,0,0,0,0,0,0,0,14
14,0,0,0,0,0,0,0,0,14
14,0,0,0,0,0,0,0,0,14
14,0,0,0,0,0,0,0,0,14
14,0,0,0,0,0,0,0,0,14
14,18,0,0,0,0,0,0,18,14
0,14,14,14,14,14,14,14,14,0
endlayer

layer
0,0,0,0,0,0,0,0,0,0
0,8,8,8,8,8,8,8,8,0
0,8,0,0,0,0,0,0,8,0
0,8,0,0,0,0,0,0,8,0
0,8,0,0,0,0,0,0,8,0
0,8,0,0,0,0,0,0,8,0
0,8,0,0,0,0,0,0,8,0
0,8,0,0,0,0,0,0,8,0
0,8,8,8,8,8,8,8,8,0
0,0,0,0,0,0,0,0,0,0
endlayer

layer
0,0,0,0,0,0,0,0,0,0
0,0,0,0,0,0,0,0,0,0
0,0,3,14,14,14,14,3,0,0
0,0,14,0,0,0,0,14,0,0
0,0,14,0,0,0,0,14,0,0
0,0,14,0,0,0,0,14,0,0
0,0,14,0,0,0,0,14,0,0
0,0,3,14,14,14,14,3,0,0
0,0,0,0,0,0,0,0,0,0
0,0,0,0,0,0,0,0,0,0
endlayer

layer
0,0,0,0,0,0,0,0,0,0
0,0,0,0,0,0,0,0,0,0
0,0,0,0,0,0,0,0,0,0
0,0,0,3,3,3,3,0,0,0
0,0,0,3,0,0,3,0,0,0
0,0,0,3,0,0,3,0,0,0
0,0,0,3,3,3,3,0,0,0
0,0,0,0,0,0,0,0,0,0
0,0,0,0,0,0,0,0,0,0
0,0,0,0,0,0,0,0,0,0
endlayer

layer
0,0,0,0,0,0,0,0,0,0
0,0,0,0,0,0,0,0,0,0
0,0,0,0,0,0,0,0,0,0
0,0,0,0,0,0,0,0,0,0
0,0,0,0,14,14,0,0,0,0
0,0,0,0,14,14,0,0,0,0
0,0,0,0,0,0,0,0,0,0
0,0,0,0,0,0,0,0,0,0
0,0,0,0,0,0,0,0,0,0
0,0,0,0,0,0,0,0,0,0
endlayer

